Workbook

Sheet By site
A1: Scenario | B1: Simulation (t/h) | C1: Aerial (t/h) | D1: Partial (t/h) | E1: Total emissions (t/h) | F1: Total emissions P2.5 | G1: Total emissions P97.5 | H1: Aerial emissions P2.5 | I1: Aerial emissions P97.5 | J1: Aerial midstream emissions (t/h) | K1: Aerial midstream emissions P2.5 | L1: Aerial midstream emissions P97.5 | M1: Midstream partial detect (t/h) | N1: Midstream GHGI below min detect (t/h) | O1: Total emissions + midstream (t/h) | P1: Total emissions + midstream P2.5 | Q1: Total emissions + midstream P97.5 | R1: N | S1: % SDev of MC iterations | T1: Min detected emission | U1: Transition point | V1: Total covered production (t(CH4)/hr) | W1: Wells covered | X1: Well visits | Y1: Wells per site | Z1: # production plumes | AA1: # production plumes sel | AB1: # prod sources overall | AC1: # avg prod sources sim | AD1: # midstream plumes | AE1: # midstream sources | AF1: Total sim emissions | AG1: Stratify by covered prod | AH1: Include repeats | AI1: High prod | AJ1: Well site visits | AK1: Avg visits/well | AL1: SD to SErr factor | AM1: SErr of mean total emissions | AN1: Serr of sample mean | AO1: Simulation % | AP1: Aerial % | AQ1: Partial % | AR1: Methane fractional loss simulation | AS1: Methane fractional loss aerial | AT1: AerialFracLossP2.5 | AU1: AerialFracLossP97.5 | AV1: Methane fractional loss partial | AW1: FracLossProd | AX1: Methane fractional loss total | AY1: FracLossP2.5 | AZ1: FracLossP97.5 | BA1: FracLossP2.5Full | BB1: FracLossP97.5Full | BC1: FracLossMid | BD1: FracLossMidP2.5 | BE1: FracLossMidP97.5 | BF1: FracLossMidPartial | BG1: FracLossMidGHGI | BH1: % aerial | BI1: % aerial sel | BJ1: Fraction sim retained | BK1: Sites covered | BL1: % wells ever emitting | BM1: Avg % wells emitting | BN1: Avg % sites emitting | BO1: Total aerial | BP1: Total aerial+partial emissions | BQ1: Total sim emissions | BR1: Frac aerial | BS1: Frac aerial+partial | BT1: Frac sim | BU1: Frac midstream | BV1: Frac midstream aerial | BW1: Total production emissions | BX1: Total/Sim | BY1: Production/site covered | BZ1: State GHGI | CA1: NG methane fraction | CB1: kgCH4 per mcfNG
A2: Kairos_Permian | B2: 16.825157 | C2: 78.077834 | D2: 5.6664501 | E2: 100.56944 | F2: 93.161574 | G2: 108.96503 | H2: 71.065569 | I2: 86.565494 | J2: 73.685818 | K2: 67.418232 | L2: 84.05884 | M2: 6.224846 | N2: 7.4248658 | O2: 187.90497 | P2: 176.19115 | Q2: 202.41207 | R2: 1000 | S2: 0.064151927 | T2: 7.0962343 | U2: 19.098 | V2: 1952.0451 | W2: 21637 | X2: 81564 | Y2: 1.2 | Z2: 1083 | AA2: 1082.16 | AB2: 537 | AC2: 258.76 | AD2: 902 | AE2: 415 | AF2: 24.250023 | AG2: Yes | AH2: No | AI2: 20221205 | AJ2: 67970 | AK2: 3.7698281 | AL2: 0.51503795 | AM2: 0.033040677 | AN2: 0.0020286621 | AO2: 0.15310057 | AP2: 0.83492683 | AQ2: 0.011972604 | AR2: 0.008619246 | AS2: 0.039997965 | AT2: 0.033023206 | AU2: 0.048440229 | AV2: 0.0029028274 | AW2: 0.051520039 | AX2: 0.096260567 | AY2: -0.0060007955 | AZ2: 0.0074317411 | BA2: 0.090259771 | BB2: 0.10369231 | BC2: 0.03774801 | BD2: 0.03453723 | BE2: 0.043061935 | BF2: 0.0026089464 | BG2: 0.0038036343 | BH2: 0.0159335 | BI2: 0.015921142 | BJ2: 0.71824291 | BK2: 18030 | BL2: 0.029783694 | BM2: 0.011959144 | BN2: 0.014351636 | BO2: 151.76365 | BP2: 157.9885 | BQ2: 24.250023 | BR2: 0.80766092 | BS2: 0.84078911 | BT2: 0.12905485 | BU2: 0.46478545 | BV2: 0.39214306 | BW2: 100.56944 | BX2: 4.293181 | BY2: 0.10826651 | BZ2: 0.012478177 | CA2: 0.9 | CB2: 17.326203
A3: Permian_2019 | B3: 69.562887 | C3: 236.17715 | D3: 0 | E3: 305.74003 | F3: 296.70203 | G3: 315.23274 | H3: 227.02413 | I3: 245.79688 | J3: 212.50446 | K3: 200.0466 | L3: 227.06245 | M3: 0 | N3: 38.281727 | O3: 556.52621 | P3: 533.79178 | Q3: 580.1803 | R3: 1000 | S3: 0.030218086 | T3: 15.029525 | U3: 59.811 | V3: 10526.815 | W3: 84570 | X3: 326908 | Y3: 1.8250769 | Z3: 1749 | AA3: 1644.348 | AB3: 1054 | AC3: 483.38 | AD3: 1272 | AE3: 679 | AF3: 107.84461 | AG3: Yes | AH3: No | AI3: 20221204d | AJ3: 179120 | AK3: 3.8655934 | AL3: 0.50861822 | AM3: 0.015369469 | AN3: 0.0009555798 | AO3: 0.35168169 | AP3: 0.64831831 | AQ3: 0 | AR3: 0.006608161 | AS3: 0.022435765 | AT3: 0.020726241 | AU3: 0.02423246 | AV3: 0 | AW3: 0.029043926 | AX3: 0.052867484 | AY3: -0.0021596686 | AZ3: 0.0022470312 | BA3: 0.050707816 | BB3: 0.055114516 | BC3: 0.020186966 | BD3: 0.019003526 | BE3: 0.021569911 | BF3: 0 | BG3: 0.0036365916 | BH3: 0.0097644038 | BI3: 0.0091801474 | BJ3: 0.83196422 | BK3: 46337 | BL3: 0.022746401 | BM3: 0.0057157384 | BN3: 0.010431836 | BO3: 448.6816 | BP3: 448.6816 | BQ3: 107.84461 | BR3: 0.80621803 | BS3: 0.80621803 | BT3: 0.19378197 | BU3: 0.4506274 | BV3: 0.38184038 | BW3: 305.74003 | BX3: 3.6566221 | BY3: 0.22717946 | BZ3: 0.011491852 | CA3: 0.9 | CB3: 17.326203
A4: Permian_2020 | B4: 22.398764 | C4: 34.984191 | D4: 0 | E4: 57.382955 | F4: 53.988015 | G4: 61.131178 | H4: 31.644453 | I4: 38.657165 | J4: 60.257181 | K4: 53.463952 | L4: 67.551465 | M4: 0 | N4: 16.369542 | O4: 134.00968 | P4: 123.22026 | Q4: 145.27449 | R4: 1000 | S4: 0.054478886 | T4: 8.0919112 | U4: 82.869 | V4: 4766.5264 | W4: 17120 | X4: 48890 | Y4: 1.8250769 | Z4: 284 | AA4: 247.091 | AB4: 239 | AC4: 101.22 | AD4: 316 | AE4: 233 | AF4: 38.768306 | AG4: Yes | AH4: No | AI4: 20221204d | AJ4: 26787 | AK4: 2.8557569 | AL4: 0.59175152 | AM4: 0.032237963 | AN4: 0.0017227736 | AO4: 0.53308934 | AP4: 0.46691066 | AQ4: 0 | AR4: 0.0046991797 | AS4: 0.0073395569 | AT4: 0.0061555042 | AU4: 0.008641753 | AV4: 0 | AW4: 0.012038737 | AX4: 0.028114746 | AY4: -0.0022635809 | AZ4: 0.002363316 | BA4: 0.025851165 | BB4: 0.030478062 | BC4: 0.012641739 | BD4: 0.011216544 | BE4: 0.014172053 | BF4: 0 | BG4: 0.0034342708 | BH4: 0.010602158 | BI4: 0.0092242879 | BJ4: 0.83012067 | BK4: 9380 | BL4: 0.025479744 | BM4: 0.0059123832 | BN4: 0.010791045 | BO4: 95.241372 | BP4: 95.241372 | BQ4: 38.768306 | BR4: 0.71070425 | BS4: 0.71070425 | BT4: 0.28929575 | BU4: 0.57179907 | BV4: 0.4496468 | BW4: 57.382955 | BX4: 2.1266867 | BY4: 0.50815846 | BZ4: 0.010661119 | CA4: 0.9 | CB4: 17.326203
A5: Permian_fall2021 | B5: 30.321138 | C5: 35.319155 | D5: 0 | E5: 65.640293 | F5: 61.949749 | G5: 69.534381 | H5: 31.738068 | I5: 39.196222 | J5: 43.947497 | K5: 39.262628 | L5: 48.952687 | M5: 0 | N5: 21.388092 | O5: 130.97588 | P5: 121.10135 | Q5: 141.19418 | R5: 1000 | S5: 0.054669089 | T5: 23.348039 | U5: 77.929 | V5: 6227.8408 | W5: 19670 | X5: 94306 | Y5: 1.8250769 | Z5: 334 | AA5: 275.071 | AB5: 232 | AC5: 92.794 | AD5: 368 | AE5: 179 | AF5: 51.70923 | AG5: Yes | AH5: No | AI5: 20221204d | AJ5: 51672 | AK5: 4.7946553 | AL5: 0.45668979 | AM5: 0.024966815 | AN5: 0.0017287884 | AO5: 0.70390981 | AP5: 0.29609019 | AQ5: 0 | AR5: 0.0048686437 | AS5: 0.0056711717 | AT5: 0.0044120838 | AU5: 0.0070343243 | AV5: 0 | AW5: 0.010539815 | AX5: 0.021030705 | AY5: -0.0015855471 | AZ5: 0.0016407447 | BA5: 0.019445158 | BB5: 0.022671449 | BC5: 0.0070566186 | BD5: 0.0063043724 | BE5: 0.0078602983 | BF5: 0 | BG5: 0.0034342708 | BH5: 0.0064638489 | BI5: 0.0053234053 | BJ5: 0.82662615 | BK5: 10777 | BL5: 0.021527327 | BM5: 0.0047175394 | BN5: 0.0086103739 | BO5: 79.266652 | BP5: 79.266652 | BQ5: 51.70923 | BR5: 0.60519883 | BS5: 0.60519883 | BT5: 0.39480117 | BU5: 0.4988361 | BV5: 0.33553765 | BW5: 65.640293 | BX5: 1.7895201 | BY5: 0.5778826 | BZ5: 0.010661119 | CA5: 0.9 | CB5: 17.326203
A6: Permian_summer2021 | B6: 27.952419 | C6: 37.029505 | D6: 0 | E6: 64.981923 | F6: 61.778019 | G6: 68.904348 | H6: 33.834367 | I6: 40.823456 | J6: 45.083456 | K6: 41.315583 | L6: 49.20927 | M6: 0 | N6: 20.435387 | O6: 130.50077 | P6: 121.41993 | Q6: 139.83864 | R6: 1000 | S6: 0.048962285 | T6: 11.813408 | U6: 68.599 | V6: 5950.4297 | W6: 19040 | X6: 91907 | Y6: 1.8250769 | Z6: 416 | AA6: 360.056 | AB6: 296 | AC6: 124.698 | AD6: 477 | AE6: 232 | AF6: 48.387805 | AG6: Yes | AH6: No | AI6: 20221204d | AJ6: 50357 | AK6: 4.8271664 | AL6: 0.45514928 | AM6: 0.022285149 | AN6: 0.0015483234 | AO6: 0.70526178 | AP6: 0.29473822 | AQ6: 0 | AR6: 0.0046975462 | AS6: 0.0062229968 | AT6: 0.005043254 | AU6: 0.0076238401 | AV6: 0 | AW6: 0.010920543 | AX6: 0.021931318 | AY6: -0.0015260808 | AZ6: 0.0015692778 | BA6: 0.020405237 | BB6: 0.023500596 | BC6: 0.0075765043 | BD6: 0.006943294 | BE6: 0.0082698683 | BF6: 0 | BG6: 0.0034342708 | BH6: 0.0082610163 | BI6: 0.0071500685 | BJ6: 0.80381134 | BK6: 10432 | BL6: 0.028374233 | BM6: 0.0065492647 | BN6: 0.011953413 | BO6: 82.112961 | BP6: 82.112961 | BQ6: 48.387805 | BR6: 0.62921404 | BS6: 0.62921404 | BT6: 0.37078596 | BU6: 0.50205678 | BV6: 0.34546441 | BW6: 64.981923 | BX6: 1.8686506 | BY6: 0.57040162 | BZ6: 0.010661119 | CA6: 0.9 | CB6: 17.326203
A7: San_Joaquin_2016 | B7: 2.5780993 | C7: 2.3866348 | D7: 0 | E7: 4.9647341 | F7: 4.2076754 | G7: 5.8816704 | H7: 1.639804 | I7: 3.2973498 | J7: 4.7872085 | K7: 3.6665271 | L7: 6.2580108 | M7: 0 | N7: 1.1897866 | O7: 10.941729 | P7: 9.3638958 | Q7: 12.91999 | R7: 1000 | S7: 0.10291269 | T7: 9 | U7: 41.205 | V7: 264.97396 | W7: 41547 | X7: 81234 | Y7: 1.7471737 | Z7: 77 | AA7: 68.985 | AB7: 40 | AC7: 15.072 | AD7: 48 | AE7: 36 | AF7: 3.7678859 | AG7: Yes | AH7: No | AI7: 20221204d | AJ7: 46494 | AK7: 1.9552546 | AL7: 0.71515197 | AM7: 0.07359821 | AN7: 0.0032543849 | AO7: 0.75007171 | AP7: 0.24992829 | AQ7: 0 | AR7: 0.0097296328 | AS7: 0.0090070544 | AT7: 0.0050659249 | AU7: 0.013813023 | AV7: 0 | AW7: 0.018736687 | AX7: 0.041293602 | AY7: -0.0059546734 | AZ7: 0.0074658705 | BA7: 0.035338929 | BB7: 0.048759473 | BC7: 0.018066713 | BD7: 0.013837311 | BE7: 0.023617456 | BF7: 0 | BG7: 0.004490202 | BH7: 0.0016561277 | BI7: 0.0014837398 | BJ7: 0.98844529 | BK7: 23779 | BL7: 0.0016821565 | BM7: 0.00036276988 | BN7: 0.00063383658 | BO7: 7.1738433 | BP7: 7.1738433 | BQ7: 3.7678859 | BR7: 0.65563968 | BS7: 0.65563968 | BT7: 0.34436032 | BU7: 0.54625623 | BV7: 0.43751709 | BW7: 4.9647341 | BX7: 1.9034846 | BY7: 0.011143192 | BZ7: 0.057351807 | CA7: 0.9 | CB7: 17.326203
A8: San_Joaquin_2017 | B8: 2.6770725 | C8: 4.493467 | D8: 0 | E8: 7.1705394 | F8: 6.3948931 | G8: 8.0756842 | H8: 3.7270122 | I8: 5.3963916 | J8: 7.4184416 | K8: 6.1618503 | L8: 8.7972182 | M8: 0 | N8: 1.2427775 | O8: 15.831758 | P8: 14.144585 | Q8: 17.744774 | R8: 1000 | S8: 0.1170017 | T8: 11 | U8: 42.185 | V8: 284.66581 | W8: 40365 | X8: 192459 | Y8: 1.7471737 | Z8: 86 | AA8: 80.051 | AB8: 54 | AC8: 15.958 | AD8: 144 | AE8: 89 | AF8: 3.91985 | AG8: Yes | AH8: No | AI8: 20221204d | AJ8: 110154 | AK8: 4.7679522 | AL8: 0.45796686 | AM8: 0.053582901 | AN8: 0.0036999186 | AO8: 0.34370242 | AP8: 0.65629758 | AQ8: 0 | AR8: 0.0094042641 | AS8: 0.01578506 | AT8: 0.0099058747 | AU8: 0.022711054 | AV8: 0 | AW8: 0.025189324 | AX8: 0.055615243 | AY8: -0.0059268563 | AZ8: 0.0067202138 | BA8: 0.049688387 | BB8: 0.062335457 | BC8: 0.026060177 | BD8: 0.021645909 | BE8: 0.030903669 | BF8: 0 | BG8: 0.0043657419 | BH8: 0.00078072517 | BI8: 0.00072671896 | BJ8: 0.98466374 | BK8: 23103 | BL8: 0.0023373588 | BM8: 0.0003953425 | BN8: 0.00069073281 | BO8: 11.911909 | BP8: 11.911909 | BQ8: 3.91985 | BR8: 0.75240361 | BS8: 0.75240361 | BT8: 0.24759639 | BU8: 0.54707716 | BV8: 0.46857746 | BW8: 7.1705394 | BX8: 2.6374248 | BY8: 0.012321595 | BZ8: 0.054455461 | CA8: 0.9 | CB8: 17.326203
A9: San_Joaquin_fall2020 | B9: 1.8910147 | C9: 2.5556404 | D9: 0 | E9: 4.4466551 | F9: 3.8757148 | G9: 5.2930907 | H9: 1.9898396 | I9: 3.4036789 | J9: 3.8313755 | K9: 2.9730301 | L9: 5.0771716 | M9: 0 | N9: 0.92232287 | O9: 9.2003535 | P9: 7.9416575 | Q9: 10.894262 | R9: 1000 | S9: 0.20287696 | T9: 20.646402 | U9: 38.238248 | V9: 245.23328 | W9: 33090 | X9: 238974 | Y9: 1.995878 | Z9: 48 | AA9: 45.336 | AB9: 27 | AC9: 8.067 | AD9: 63 | AE9: 34 | AF9: 2.8133376 | AG9: Yes | AH9: No | AI9: 20221204d | AJ9: 119733 | AK9: 7.2219675 | AL9: 0.37211076 | AM9: 0.0754927 | AN9: 0.0064155328 | AO9: 0.4463468 | AP9: 0.5536532 | AQ9: 0 | AR9: 0.0077110853 | AS9: 0.010421263 | AT9: 0.0042209736 | AU9: 0.019714434 | AV9: 0 | AW9: 0.018132348 | AX9: 0.037516742 | AY9: -0.0051326475 | AZ9: 0.0069073364 | BA9: 0.032384094 | BB9: 0.044424078 | BC9: 0.015623392 | BD9: 0.012123274 | BE9: 0.020703437 | BF9: 0 | BG9: 0.0037610021 | BH9: 0.00040089198 | BI9: 0.00037864248 | BJ9: 0.98539647 | BK9: 16579 | BL9: 0.0016285663 | BM9: 0.00024378966 | BN9: 0.00048657941 | BO9: 6.3870159 | BP9: 6.3870159 | BQ9: 2.8133376 | BR9: 0.69418964 | BS9: 0.69418964 | BT9: 0.30581036 | BU9: 0.51666912 | BV9: 0.41641213 | BW9: 4.4466551 | BX9: 2.3171751 | BY9: 0.014791801 | BZ9: 0.061625508 | CA9: 0.9 | CB9: 17.326203
A10: San_Joaquin_summer2020 | B10: 1.8153271 | C10: 3.8496495 | D10: 0 | E10: 5.6649766 | F10: 5.0284506 | G10: 6.4800611 | H10: 3.2100549 | I10: 4.6728376 | J10: 4.1948634 | K10: 3.5413521 | L10: 5.0460512 | M10: 0 | N10: 0.87037445 | O10: 10.730214 | P10: 9.591028 | Q10: 12.080986 | R10: 1000 | S10: 0.14750423 | T10: 23.632192 | U10: 35.693644 | V10: 231.42089 | W10: 31919 | X10: 238393 | Y10: 1.995878 | Z10: 94 | AA10: 90.486 | AB10: 39 | AC10: 13.306 | AD10: 151 | AE10: 65 | AF10: 2.6857016 | AG10: Yes | AH10: No | AI10: 20221204d | AJ10: 119442 | AK10: 7.4688594 | AL10: 0.3659088 | AM10: 0.053973095 | AN10: 0.0046644932 | AO10: 0.25456728 | AP10: 0.74543272 | AQ10: 0 | AR10: 0.0078442666 | AS10: 0.01663484 | AT10: 0.0090816681 | AU10: 0.026356125 | AV10: 0 | AW10: 0.024479107 | AX10: 0.046366664 | AY10: -0.0049225741 | AZ10: 0.005836861 | BA10: 0.04144409 | BB10: 0.052203525 | BC10: 0.018126555 | BD10: 0.015302647 | BE10: 0.021804649 | BF10: 0 | BG10: 0.0037610021 | BH10: 0.00078699285 | BI10: 0.00075757271 | BJ10: 0.98554216 | BK10: 15992 | BL10: 0.0024387194 | BM10: 0.0004168677 | BN10: 0.00083204102 | BO10: 8.0445128 | BP10: 8.0445128 | BQ10: 2.6857016 | BR10: 0.74970017 | BS10: 0.74970017 | BT10: 0.25029983 | BU10: 0.47205065 | BV10: 0.39093418 | BW10: 5.6649766 | BX10: 3.0755197 | BY10: 0.014471041 | BZ10: 0.061625508 | CA10: 0.9 | CB10: 17.326203
A11: San_Joaquin_fall2021 | B11: 1.7282805 | C11: 1.7377402 | D11: 0 | E11: 3.4660207 | F11: 3.0228589 | G11: 3.972279 | H11: 1.3001712 | I11: 2.2378236 | J11: 0.78481578 | K11: 0.54959351 | L11: 1.0503954 | M11: 0 | N11: 0.74474802 | O11: 4.9955845 | P11: 4.3518135 | Q11: 5.6772638 | R11: 1000 | S11: 0.10928702 | T11: 15.95883 | U11: 22.65 | V11: 198.01851 | W11: 33418 | X11: 119340 | Y11: 1.995878 | Z11: 47 | AA11: 41.375 | AB11: 35 | AC11: 15.727 | AD11: 17 | AE11: 12 | AF11: 2.4730285 | AG11: Yes | AH11: No | AI11: 20221204d | AJ11: 59793 | AK11: 3.5712238 | AL11: 0.52916543 | AM11: 0.057830912 | AN11: 0.003455959 | AO11: 0.42525237 | AP11: 0.57474763 | AQ11: 0 | AR11: 0.0087278737 | AS11: 0.0087756455 | AT11: 0.0045997528 | AU11: 0.013548137 | AV11: 0 | AW11: 0.017503519 | AX11: 0.025227867 | AY11: -0.0032510647 | AZ11: 0.0034425029 | BA11: 0.021976802 | BB11: 0.02867037 | BC11: 0.0039633457 | BD11: 0.0027754654 | BE11: 0.0053045316 | BF11: 0 | BG11: 0.0037610021 | BH11: 0.00078604519 | BI11: 0.00069197063 | BJ11: 0.95976675 | BK11: 16743 | BL11: 0.0020904258 | BM11: 0.00047061464 | BN11: 0.00093931792 | BO11: 2.522556 | BP11: 2.522556 | BQ11: 2.4730285 | BR11: 0.50494698 | BS11: 0.50494698 | BT11: 0.49505302 | BU11: 0.30618291 | BV11: 0.15709834 | BW11: 3.4660207 | BX11: 1.924801 | BY11: 0.011826943 | BZ11: 0.061625508 | CA11: 0.9 | CB11: 17.326203
A12: Denver_summer2021 | B12: 12.234468 | C12: 2.3200421 | D12: 0 | E12: 14.55451 | F12: 13.822272 | G12: 15.414169 | H12: 1.6529576 | I12: 3.1666956 | J12: 0.69767269 | K12: 0.46040084 | L12: 1.0375998 | M12: 0 | N12: 6.246524 | O12: 21.498707 | P12: 19.585127 | Q12: 23.532087 | R12: 1000 | S12: 0.048155172 | T12: 11.102345 | U12: 74.394 | V12: 1997.3945 | W12: 11671 | X12: 59356 | Y12: 1.6088026 | Z12: 34 | AA12: 27.303 | AB12: 27 | AC12: 8.473 | AD12: 24 | AE12: 9 | AF12: 18.480992 | AG12: Yes | AH12: No | AI12: 20221204d | AJ12: 36894 | AK12: 5.0860215 | AL12: 0.44341553 | AM12: 0.021352751 | AN12: 0.0015228002 | AO12: 0.89945091 | AP12: 0.10054909 | AQ12: 0 | AR12: 0.0061252138 | AS12: 0.0011615342 | AT12: 0.00040834156 | AU12: 0.0021174749 | AV12: 0 | AW12: 0.007286748 | AX12: 0.010763376 | AY12: -0.00095803824 | AZ12: 0.0010180161 | BA12: 0.0098053373 | BB12: 0.011781392 | BC12: 0.00034929138 | BD12: 0.0002305007 | BE12: 0.00051947667 | BF12: 0 | BG12: 0.0031273362 | BH12: 0.00092155906 | BI12: 0.00074003903 | BJ12: 0.97700712 | BK12: 7254 | BL12: 0.0037220844 | BM12: 0.00072598749 | BN12: 0.0011680452 | BO12: 3.0177148 | BP12: 3.0177148 | BQ12: 18.480992 | BR12: 0.14036515 | BS12: 0.14036515 | BT12: 0.85963485 | BU12: 0.32300552 | BV12: 0.032451304 | BW12: 14.55451 | BX12: 1.1622844 | BY12: 0.27535077 | BZ12: 0.0097082922 | CA12: 0.9 | CB12: 17.326203
A13: Denver_fall2021 | B13: 12.339325 | C13: 2.3156748 | D13: 0 | E13: 14.655 | F13: 13.855377 | G13: 15.658204 | H13: 1.5785775 | I13: 3.3169494 | J13: 2.3299625 | K13: 1.5583906 | L13: 4.1121017 | M13: 0 | N13: 6.1693766 | O13: 23.154339 | P13: 20.830723 | Q13: 26.206328 | R13: 1000 | S13: 0.08969653 | T13: 10.160213 | U13: 67.633 | V13: 1972.7258 | W13: 11688 | X13: 67811 | Y13: 1.6088026 | Z13: 40 | AA13: 31.439 | AB13: 33 | AC13: 8.498 | AD13: 29 | AE13: 21 | AF13: 18.508702 | AG13: Yes | AH13: No | AI13: 20221204d | AJ13: 42149 | AK13: 5.8016518 | AL13: 0.41516829 | AM13: 0.037239155 | AN13: 0.0028364533 | AO13: 0.87637878 | AP13: 0.12362122 | AQ13: 0 | AR13: 0.0062549624 | AS13: 0.0011738453 | AT13: 0.00027386307 | AU13: 0.0023963831 | AV13: 0 | AW13: 0.0074288077 | AX13: 0.011737232 | AY13: -0.0011778708 | AZ13: 0.0015470919 | BA13: 0.010559361 | BB13: 0.013284324 | BC13: 0.0011810879 | BD13: 0.00078996821 | BE13: 0.0020844771 | BF13: 0 | BG13: 0.0031273362 | BH13: 0.00094901421 | BI13: 0.00074590144 | BJ13: 0.97501225 | BK13: 7265 | BL13: 0.0045423262 | BM13: 0.0007270705 | BN13: 0.0011697178 | BO13: 4.6456373 | BP13: 4.6456373 | BQ13: 18.508702 | BR13: 0.20063592 | BS13: 0.20063592 | BT13: 0.79936408 | BU13: 0.36707247 | BV13: 0.10062586 | BW13: 14.655 | BX13: 1.157992 | BY13: 0.2715383 | BZ13: 0.0097082922 | CA13: 0.9 | CB13: 17.326203
A14: Pennsylvania_2021 | B14: 11.887088 | C14: 38.618609 | D14: 0 | E14: 50.505698 | F14: 44.324884 | G14: 56.843126 | H14: 32.473322 | I14: 44.953614 | J14: 7.8387248 | K14: 5.5018292 | L14: 10.221656 | M14: 0 | N14: 18.142916 | O14: 76.487338 | P14: 66.764863 | Q14: 86.609245 | R14: 1000 | S14: 0.060215204 | T14: 92.241416 | U14: 105.96519 | V14: 10242.48 | W14: 16105 | X14: 27797 | Y14: 1.2580446 | Z14: 64 | AA14: 61.961 | AB14: 43 | AC14: 29.49 | AD14: 23 | AE14: 17 | AF14: 30.030004 | AG14: Yes | AH14: No | AI14: 20221204d | AJ14: 22095 | AK14: 1.726037 | AL14: 0.76115823 | AM14: 0.045833298 | AN14: 0.001904172 | AO14: 0.072735953 | AP14: 0.92726405 | AQ14: 0 | AR14: 0.0011605674 | AS14: 0.0037704354 | AT14: 0.0029821888 | AU14: 0.0045830168 | AV14: 0 | AW14: 0.0049310028 | AX14: 0.007467658 | AY14: -0.00094923052 | AZ14: 0.00098822811 | BA14: 0.0065184275 | BB14: 0.0084558861 | BC14: 0.00076531512 | BD14: 0.00053715791 | BE14: 0.00099796691 | BF14: 0 | BG14: 0.0017713401 | BH14: 0.0028965829 | BI14: 0.0028042996 | BJ14: 0.99285007 | BK14: 12801 | BL14: 0.0033591126 | BM14: 0.0018311084 | BN14: 0.0023037263 | BO14: 46.457334 | BP14: 46.457334 | BQ14: 30.030004 | BR14: 0.60738344 | BS14: 0.60738344 | BT14: 0.39261656 | BU14: 0.33968713 | BV14: 0.1024841 | BW14: 50.505698 | BX14: 4.2184119 | BY14: 0.80013124 | BZ14: 0.0054988291 | CA14: 0.9 | CB14: 17.326203
... A19: Permian_2019_F2021_Midland | B19: 8.9700354 | C19: 46.360864 | D19: 0 | E19: 55.330899 | F19: 51.877515 | G19: 59.20385 | H19: 42.897833 | I19: 50.170992 | J19: 38.241964 | K19: 31.850662 | L19: 45.919264 | M19: 0 | N19: 4.1551174 | O19: 97.727981 | P19: 89.894653 | Q19: 107.14931 | R19: 1000 | S19: 0.10456281 | T19: 16.353134 | U19: 113.01 | V19: 1142.5856 | W19: 9209 | X19: 51783 | Y19: 1.8250769 | Z19: 130 | AA19: 124.181 | AB19: 93 | AC19: 49.045 | AD19: 123 | AE19: 76 | AF19: 13.125153 | AG19: Yes | AH19: No | AI19: 20221204d | AJ19: 28373 | AK19: 5.6239841 | AL19: 0.4216751 | AM19: 0.044091535 | AN19: 0.0033065665 | AO19: 0.24043398 | AP19: 0.75956602 | AQ19: 0 | AR19: 0.007850646 | AS19: 0.040575396 | AT19: 0.0333877 | AU19: 0.048483508 | AV19: 0 | AW19: 0.048426042 | AX19: 0.085532304 | AY19: -0.0068557907 | AZ19: 0.0082456186 | BA19: 0.078676513 | BB19: 0.093777922 | BC19: 0.03346967 | BD19: 0.027875951 | BE19: 0.040188903 | BF19: 0 | BG19: 0.0036365916 | BH19: 0.0045818207 | BI19: 0.0043767314 | BJ19: 0.92630547 | BK19: 5045 | BL19: 0.018434093 | BM19: 0.0053257683 | BN19: 0.0097215064 | BO19: 84.602828 | BP19: 84.602828 | BQ19: 13.125153 | BR19: 0.86569583 | BS19: 0.86569583 | BT19: 0.13430417 | BU19: 0.43382428 | BV19: 0.39130676 | BW19: 55.330899 | BX19: 5.7138058 | BY19: 0.22647882 | BZ19: 0.011491852 | CA19: 0.9 | CB19: 17.326203
A20: Northeast_Pennsylvania_2021 | B20: 1.1080758 | C20: 19.420285 | D20: 0 | E20: 20.528361 | F20: 17.055863 | G20: 23.905477 | H20: 15.947922 | I20: 22.784746 | J20: 8.3596463 | K20: 5.7182021 | L20: 10.971639 | M20: 0 | N20: 9.0260916 | O20: 37.914099 | P20: 32.204061 | Q20: 43.913326 | R20: 1000 | S20: 0.069921149 | T20: 495.44526 | U20: 495.44526 | V20: 5095.6288 | W20: 2996 | X20: 4039 | Y20: 1.2580446 | Z20: 12 | AA20: 11 | AB20: 12 | AC20: 11.48 | AD20: 4 | AE20: 4 | AF20: 10.134167 | AG20: Yes | AH20: No | AI20: 20230308 | AJ20: 3210 | AK20: 1.348173 | AL20: 0.86124593 | AM20: 0.060219304 | AN20: 0.0022111009 | AO20: 0.020142089 | AP20: 0.97985791 | AQ20: 0 | AR20: 0.00021745615 | AS20: 0.0038111656 | AT20: 0.0030199402 | AU20: 0.0045778038 | AV20: 0 | AW20: 0.0040286217 | AX20: 0.0074405143 | AY20: -0.0011205757 | AZ20: 0.0011773282 | BA20: 0.0063199385 | BB20: 0.0086178425 | BC20: 0.0016405524 | BD20: 0.0011221779 | BE20: 0.0021531473 | BF20: 0 | BG20: 0.0017713401 | BH20: 0.0037383178 | BI20: 0.0034267913 | BJ20: 1 | BK20: 2381 | BL20: 0.0050398992 | BM20: 0.0038317757 | BN20: 0.0048215036 | BO20: 27.779931 | BP20: 27.779931 | BQ20: 10.134167 | BR20: 0.7327066 | BS20: 0.7327066 | BT20: 0.2672934 | BU20: 0.45855508 | BV20: 0.22048749 | BW20: 20.528361 | BX20: 18.527448 | BY20: 2.1401213 | BZ20: 0.0054988291 | CA20: 0.9 | CB20: 17.326203
A21: GHGI 2022 (for 2020) | AI21: 1 | AR21: 0.0048 | AW21: 0.004942 | AX21: =AW21+BG21 -> 0.010092 | AY21: -0.00204 | AZ21: 0.00213 | BA21: =AX21+AY21 -> 0.008052 | BB21: =AX21+AZ21 -> 0.012222 | BG21: 0.00515
A22: GHGI NM 2019
A23: GHGI TX 2021
A24: GHGI CA 2021
A25: GHGI CO 2021
A26: GHGI PA 2021 | U26: Fraction of national gas covered | V26: =V27/V30 -> 0.28137144
A27: Totals excluding repeats | O27: =O3+O7+O13+O14+O15+O16 -> 716.77204 | P27: =P3+P7+P13+P14+P15+P16 -> 675.76458 | Q27: =Q3+Q7+Q13+Q14+Q15+Q16 -> 760.29193 | V27: =V3+V7+V13+V14+V15+V16 -> 23994.401 | W27: =W3+W7+W13+W14+W15+W16 -> 170569 | X27: =X3+X7+X13+X14+X15+X16 -> 549072 | AC27: =AC3+AC7+AC13+AC14+AC15+AC16 -> 601.395 | AI27: 1 | AJ27: =AJ3+AJ7+AJ13+AJ14+AJ15+AJ16 -> 316771 | AK27: =X27/W27 -> 3.2190609 | AX27: =O27/$V27 -> 0.029872471 | AY27: =P27/$V27 -> 0.028163428 | AZ27: =Q27/$V27 -> 0.031686222 | BK27: =BK3+BK7+BK13+BK14+BK15+BK16 -> 100159 | BN27: =AC27/BK27 -> 0.006004403
A28: Totals including repeats (no 2019 subcampaigns) | O28: =SUM(O2:O16) -> 1362.42 | P28: =SUM(P2:P16) -> 1273.3115 | Q28: =SUM(Q2:Q16) -> 1458.9407 | V28: =SUM(V2:V16) -> 45847.976 | W28: =SUM(W2:W16) -> 398499 | X28: =SUM(X2:X16) -> 1714261 | AC28: =SUM(AC2:AC16) -> 1240.398 | AI28: 1 | AJ28: =SUM(AJ2:AJ16) -> 959573 | AK28: =AJ28/BK27 -> 9.580497 | AX28: =O28/$V28 -> 0.029716033 | AY28: =P28/$V28 -> 0.027772469 | AZ28: =Q28/$V28 -> 0.031821267 | BK28: =SUM(BK2:BK16) -> 228449 | BN28: =AC28/BK28 -> 0.0054296495
A29: Totals excluding high-prod campaigns | O29: =O2+O3+SUM(O7:O13)+O15+O16 -> 890.44629 | P29: =P2+P3+SUM(P7:P13)+P15+P16 -> 840.80508 | Q29: =Q2+Q3+SUM(Q7:Q13)+Q15+Q16 -> 946.02412 | V29: =V2+V3+SUM(V7:V13)+V15+V16 -> 18660.699 | AX29: =O29/$V29 -> 0.047717735 | AY29: =P29/$V29 -> 0.045057533 | AZ29: =Q29/$V29 -> 0.050696071
N30: Social cost of methane [$/t] | O30: 1500 | U30: 2021 US gas prod | V30: 85276.605 | BQ30: Methane fractional loss partial
A31: Permian total | N31: Hours per day | O31: 8760 | W31: =SUM(W2:W6) -> 162037 | X31: =SUM(X2:X6) -> 643575 | Z31: =SUM(Z2:Z6) -> 3866 | AA31: =SUM(AA2:AA6) -> 3608.726 | AB31: =SUM(AB2:AB6) -> 2358 | AC31: =SUM(AC2:AC6) -> 1060.852 | AD31: =SUM(AD2:AD6) -> 3335 | AE31: =SUM(AE2:AE6) -> 1738 | AJ31: =SUM(AJ2:AJ6) -> 375906 | AK31: =AJ31/BK31 -> 3.9587388 | BK31: =SUM(BK2:BK6) -> 94956 | BQ31: FracLossProd
A32: San Joaquin total | N32: GWP20 (IPCC 2021) | O32: 82.5 | P32: https://report.ipcc.ch/ar6/wg1/IPCC_AR6_WGI_FullReport.pdf | Q32: Table 7.15 | W32: =SUM(W7:W11) -> 180339 | X32: =SUM(X7:X11) -> 870400 | Z32: =SUM(Z7:Z11) -> 352 | AA32: =SUM(AA7:AA11) -> 326.233 | AB32: =SUM(AB7:AB11) -> 195 | AC32: =SUM(AC7:AC11) -> 68.13 | AD32: =SUM(AD7:AD11) -> 423 | AE32: =SUM(AE7:AE11) -> 236 | AJ32: =SUM(AJ7:AJ11) -> 455616 | AK32: =AJ32/BK32 -> 4.73633 | BK32: =SUM(BK7:BK11) -> 96196 | BQ32: Methane fractional loss total
A33: Denver total | N33: Emissions [tCH4/yr] | O33: =O27*$O$31 -> 6278923.1 | P33: =P27*$O$31 -> 5919697.7 | Q33: =Q27*$O$31 -> 6660157.3 | W33: =W12+W13 -> 23359 | X33: =X12+X13 -> 127167 | Z33: =Z12+Z13 -> 74 | AA33: =AA12+AA13 -> 58.742 | AB33: =AB12+AB13 -> 60 | AC33: =AC12+AC13 -> 16.971 | AD33: =AD12+AD13 -> 53 | AE33: =AE12+AE13 -> 30 | AJ33: =AJ12+AJ13 -> 79043 | AK33: =AJ33/BK33 -> 5.4441077 | BK33: =BK12+BK13 -> 14519 | BQ33: FracLossP2.5
A34: Per+SJ+DJ | N34: Emissions [tCO2e/yr] | O34: =O33*$O$32 -> 5.1801116e+08 | P34: =P33*$O$32 -> 4.8837506e+08 | Q34: =Q33*$O$32 -> 5.4946298e+08 | W34: =SUM(W31:W33) -> 365735 | X34: =SUM(X31:X33) -> 1641142 | AJ34: =SUM(AJ31:AJ33) -> 910565 | AK34: =AJ34/BK34 -> 4.4272892 | BK34: =SUM(BK31:BK33) -> 205671 | BQ34: FracLossP97.5
N35: Annual social cost of emissions [$/yr] | O35: =O33*$O$30 -> 9.4183846e+09 | P35: =P33*$O$30 -> 8.8795466e+09 | Q35: =Q33*$O$30 -> 9.990236e+09 | BQ35: FracLossP2.5Full
N36: NG cost [$/mcf] | O36: 3 | U36: =V27*$O31/$O37 -> 1.2128734e+10 | BQ36: FracLossP97.5Full
N37: tCH4/mcf(NG) | O37: 0.01733 | U37: =V30*$O31/$O37 -> 4.3105774e+10 | BQ37: FracLossMid
N38: Annual NG emissions [mcf/yr] | O38: =O33/$O$37 -> 3.6231524e+08 | P38: =P33/$O$37 -> 3.4158671e+08 | Q38: =Q33/$O$37 -> 3.8431375e+08 | BQ38: FracLossMidP2.5
N39: Annual NG value | O39: =O38*$O$36 -> 1.0869457e+09 | P39: =P38*$O$36 -> 1.0247601e+09 | Q39: =Q38*$O$36 -> 1.1529413e+09 | BQ39: FracLossMidP97.5
N40: Price/t(CH4) | O40: =O36/O37 -> 173.11021 | BQ40: FracLossMidPartial
BQ41: FracLossMidGHGI
BQ42: % aerial
BQ43: % aerial sel
BQ44: Fraction sim retained
...

Sheet GHGRP gas comp
A1: Scenario | B1: Simulation (t/h) | C1: Aerial (t/h) | D1: Partial (t/h) | E1: Total emissions (t/h) | F1: Total emissions P2.5 | G1: Total emissions P97.5 | H1: Aerial emissions P2.5 | I1: Aerial emissions P97.5 | J1: Aerial midstream emissions (t/h) | K1: Aerial midstream emissions P2.5 | L1: Aerial midstream emissions P97.5 | M1: Midstream partial detect (t/h) | N1: Midstream GHGI below min detect (t/h) | O1: Total emissions + midstream (t/h) | P1: Total emissions + midstream P2.5 | Q1: Total emissions + midstream P97.5 | R1: N | S1: % SDev of MC iterations | T1: Min detected emission | U1: Transition point | V1: Total covered production (t(CH4)/hr) | W1: Wells covered | X1: Well visits | Y1: Wells per site | Z1: # production plumes | AA1: # production plumes sel | AB1: # prod sources overall | AC1: # avg prod sources sim | AD1: # midstream plumes | AE1: # midstream sources | AF1: Total sim emissions | AG1: Stratify by covered prod | AH1: Include repeats | AI1: High prod | AJ1: Well site visits | AK1: Avg visits/well | AL1: SD to SErr factor | AM1: SErr of mean total emissions | AN1: Serr of sample mean | AO1: Simulation % | AP1: Aerial % | AQ1: Partial % | AR1: Methane fractional loss simulation | AS1: Methane fractional loss aerial | AT1: AerialFracLossP2.5 | AU1: AerialFracLossP97.5 | AV1: Methane fractional loss partial | AW1: FracLossProd | AX1: Methane fractional loss total | AY1: FracLossP2.5 | AZ1: FracLossP97.5 | BA1: FracLossP2.5Full | BB1: FracLossP97.5Full | BC1: FracLossMid | BD1: FracLossMidP2.5 | BE1: FracLossMidP97.5 | BF1: FracLossMidPartial | BG1: FracLossMidGHGI | BH1: % aerial | BI1: % aerial sel | BJ1: Fraction sim retained | BK1: Sites covered | BL1: % wells ever emitting | BM1: Avg % wells emitting | BN1: Avg % sites emitting | BO1: Total aerial | BP1: Total aerial+partial emissions | BQ1: Total sim emissions | BR1: Frac aerial | BS1: Frac aerial+partial | BT1: Frac sim | BU1: Frac midstream | BV1: Frac midstream aerial | BW1: Total production emissions | BX1: Total/Sim | BY1: Production/site covered | BZ1: State GHGI | CA1: NG methane fraction | CB1: kgCH4 per mcfNG
A2: Kairos_Permian | B2: 16.825598 | C2: 78.160959 | D2: 5.6541529 | E2: 100.64071 | F2: 93.596458 | G2: 109.47365 | H2: 71.066287 | I2: 86.784899 | J2: 73.600746 | K2: 67.258116 | L2: 83.875294 | M2: 6.2658452 | N2: 8.216505 | O2: 188.72381 | P2: 177.12981 | Q2: 203.66241 | R2: 1000 | S2: 0.06580505 | T2: 7.0962343 | U2: 19.125 | V2: 1388.3755 | W2: 21637 | X2: 81564 | Y2: 1.2 | Z2: 1083 | AA2: 1082.161 | AB2: 537 | AC2: 258.778 | AD2: 902 | AE2: 415 | AF2: 25.042103 | AG2: Yes | AH2: No | AI2: 20221204c | AJ2: 67970 | AK2: 3.7698281 | AL2: 0.51503795 | AM2: 0.033892098 | AN2: 0.0020809384 | AO2: 0.15312134 | AP2: 0.83485667 | AQ2: 0.012021984 | AR2: 0.012118911 | AS2: 0.056296702 | AT2: 0.046375 | AU2: 0.068357041 | AV2: 0.0040724956 | AW2: 0.072488108 | AX2: 0.13593139 | AY2: -0.008350767 | AZ2: 0.010759768 | BA2: 0.12758062 | BB2: 0.14669116 | BC2: 0.053012134 | BD2: 0.048443751 | BE2: 0.060412544 | BF2: 0.0036681585 | BG2: 0.0059180713 | BH2: 0.0159335 | BI2: 0.015921156 | BJ2: 0.71731139 | BK2: 18030 | BL2: 0.029783694 | BM2: 0.011959976 | BN2: 0.014352634 | BO2: 151.76171 | BP2: 158.02755 | BQ2: 25.042103 | BR2: 0.80414641 | BS2: 0.83734774 | BT2: 0.13269244 | BU2: 0.46672855 | BV2: 0.38998972 | BW2: 100.64071 | BX2: 4.290557 | BY2: 0.077003631 | BZ2: 0.017544221 | CA2: 0.64011733 | CB2: 12.323114
A3: Permian_2019 | B3: 69.489305 | C3: 236.22166 | D3: 0 | E3: 305.71096 | F3: 295.96222 | G3: 316.13296 | H3: 226.69534 | I3: 246.50276 | J3: 212.5112 | K3: 200.48743 | L3: 226.6524 | M3: 0 | N3: 42.363324 | O3: 560.58549 | P3: 537.54035 | Q3: 584.98518 | R3: 1000 | S3: 0.030554512 | T3: 15.029525 | U3: 59.787 | V3: 7487.1072 | W3: 84570 | X3: 326908 | Y3: 1.8250769 | Z3: 1749 | AA3: 1644.851 | AB3: 1054 | AC3: 483.402 | AD3: 1272 | AE3: 679 | AF3: 111.85263 | AG3: Yes | AH3: No | AI3: 20221204c | AJ3: 179120 | AK3: 3.8655934 | AL3: 0.50861822 | AM3: 0.015540582 | AN3: 0.0009662185 | AO3: 0.3531913 | AP3: 0.6468087 | AQ3: 0 | AR3: 0.0092811954 | AS3: 0.031550457 | AT3: 0.02904885 | AU3: 0.034250271 | AV3: 0 | AW3: 0.040831653 | AX3: 0.074873442 | AY3: -0.0030779767 | AZ3: 0.0032588947 | BA3: 0.071795465 | BB3: 0.078132336 | BC3: 0.028383619 | BD3: 0.026777689 | BE3: 0.030272359 | BF3: 0 | BG3: 0.0056581699 | BH3: 0.0097644038 | BI3: 0.0091829556 | BJ3: 0.82971733 | BK3: 46337 | BL3: 0.022746401 | BM3: 0.0057159986 | BN3: 0.010432311 | BO3: 448.73286 | BP3: 448.73286 | BQ3: 111.85263 | BR3: 0.80047167 | BS3: 0.80047167 | BT3: 0.19952833 | BU3: 0.45465755 | BV3: 0.37908774 | BW3: 305.71096 | BX3: 3.6502522 | BY3: 0.16157946 | BZ3: 0.016157454 | CA3: 0.64011733 | CB3: 12.323114
A4: Permian_2020 | B4: 22.373772 | C4: 35.02381 | D4: 0 | E4: 57.397582 | F4: 53.968669 | G4: 61.180328 | H4: 31.80234 | I4: 38.645861 | J4: 60.168404 | K4: 53.532429 | L4: 67.318494 | M4: 0 | N4: 18.105876 | O4: 135.67186 | P4: 124.8302 | Q4: 147.11112 | R4: 1000 | S4: 0.050538176 | T4: 8.0919112 | U4: 82.13 | V4: 3397.238 | W4: 17120 | X4: 48890 | Y4: 1.8250769 | Z4: 284 | AA4: 247.603 | AB4: 239 | AC4: 101.245 | AD4: 316 | AE4: 233 | AF4: 40.479648 | AG4: Yes | AH4: No | AI4: 20221204c | AJ4: 26787 | AK4: 2.8557569 | AL4: 0.59175152 | AM4: 0.029906043 | AN4: 0.0015981575 | AO4: 0.53308934 | AP4: 0.46691066 | AQ4: 0 | AR4: 0.0065858711 | AS4: 0.010309496 | AT4: 0.00870703 | AU4: 0.012111223 | AV4: 0 | AW4: 0.016895367 | AX4: 0.039935931 | AY4: -0.0031913181 | AZ4: 0.0033672242 | BA4: 0.036744613 | BB4: 0.043303155 | BC4: 0.017710977 | BD4: 0.015757633 | BE4: 0.019815654 | BF4: 0 | BG4: 0.0053295873 | BH4: 0.010602158 | BI4: 0.0092434017 | BJ4: 0.82919664 | BK4: 9380 | BL4: 0.025479744 | BM4: 0.0059138435 | BN4: 0.01079371 | BO4: 95.192215 | BP4: 95.192215 | BQ4: 40.479648 | BR4: 0.70163463 | BS4: 0.70163463 | BT4: 0.29836537 | BU4: 0.57693794 | BV4: 0.44348412 | BW4: 57.397582 | BX4: 2.1272204 | BY4: 0.36217889 | BZ4: 0.014958183 | CA4: 0.64145542 | CB4: 12.348874
A5: Permian_fall2021 | B5: 30.306 | C5: 35.332186 | D5: 0 | E5: 65.638186 | F5: 61.923953 | G5: 69.861354 | H5: 31.649449 | I5: 39.452821 | J5: 44.134437 | K5: 39.327962 | L5: 49.339199 | M5: 0 | N5: 23.599062 | O5: 133.37169 | P5: 123.03468 | Q5: 144.62584 | R5: 1000 | S5: 0.056321968 | T5: 23.348039 | U5: 78.128 | V5: 4484.25 | W5: 19670 | X5: 94306 | Y5: 1.8250769 | Z5: 334 | AA5: 274.886 | AB5: 232 | AC5: 92.825 | AD5: 368 | AE5: 179 | AF5: 53.905062 | AG5: Yes | AH5: No | AI5: 20221204c | AJ5: 51672 | AK5: 4.7946553 | AL5: 0.45668979 | AM5: 0.025721668 | AN5: 0.001781057 | AO5: 0.70390981 | AP5: 0.29609019 | AQ5: 0 | AR5: 0.0067583208 | AS5: 0.0078791741 | AT5: 0.0060808847 | AU5: 0.0098912903 | AV5: 0 | AW5: 0.014637495 | AX5: 0.02974225 | AY5: -0.0023051797 | AZ5: 0.0025097077 | BA5: 0.027437071 | BB5: 0.032251958 | BC5: 0.0098421001 | BD5: 0.0087702432 | BE5: 0.011002776 | BF5: 0 | BG5: 0.0052626554 | BH5: 0.0064638489 | BI5: 0.0053198251 | BJ5: 0.82664949 | BK5: 10777 | BL5: 0.021527327 | BM5: 0.0047191154 | BN5: 0.0086132504 | BO5: 79.466623 | BP5: 79.466623 | BQ5: 53.905062 | BR5: 0.59582544 | BS5: 0.59582544 | BT5: 0.40417456 | BU5: 0.50785537 | BV5: 0.33091186 | BW5: 65.638186 | BX5: 1.7903951 | BY5: 0.41609446 | BZ5: 0.014806435 | CA5: 0.64802956 | CB5: 12.475435
A6: Permian_summer2021 | B6: 27.894872 | C6: 37.083616 | D6: 0 | E6: 64.978488 | F6: 61.834649 | G6: 68.379499 | H6: 33.95668 | I6: 40.421547 | J6: 45.034612 | K6: 41.362358 | L6: 49.102822 | M6: 0 | N6: 22.547873 | O6: 132.56097 | P6: 123.5925 | Q6: 141.89731 | R6: 1000 | S6: 0.044988881 | T6: 11.813408 | U6: 67.618 | V6: 4284.5048 | W6: 19040 | X6: 91907 | Y6: 1.8250769 | Z6: 416 | AA6: 361.369 | AB6: 296 | AC6: 124.684 | AD6: 477 | AE6: 232 | AF6: 50.442744 | AG6: Yes | AH6: No | AI6: 20221204c | AJ6: 50357 | AK6: 4.8271664 | AL6: 0.45514928 | AM6: 0.020476657 | AN6: 0.0014226733 | AO6: 0.70526178 | AP6: 0.29473822 | AQ6: 0 | AR6: 0.0065106407 | AS6: 0.0086552863 | AT6: 0.0070518027 | AU6: 0.010366967 | AV6: 0 | AW6: 0.015165927 | AX6: 0.030939625 | AY6: -0.0020932342 | AZ6: 0.0021790943 | BA6: 0.028846391 | BB6: 0.033118719 | BC6: 0.010511042 | BD6: 0.0096539413 | BE6: 0.011460559 | BF6: 0 | BG6: 0.0052626554 | BH6: 0.0082610163 | BI6: 0.0071761423 | BJ6: 0.80104396 | BK6: 10432 | BL6: 0.028374233 | BM6: 0.0065485294 | BN6: 0.011952071 | BO6: 82.118228 | BP6: 82.118228 | BQ6: 50.442744 | BR6: 0.61947487 | BS6: 0.61947487 | BT6: 0.38052513 | BU6: 0.50982176 | BV6: 0.33972727 | BW6: 64.978488 | BX6: 1.8659495 | BY6: 0.4107079 | BZ6: 0.014806435 | CA6: 0.64802956 | CB6: 12.475435
A7: San_Joaquin_2016 | B7: 2.5833259 | C7: 2.3916837 | D7: 0 | E7: 4.9750095 | F7: 4.1661412 | G7: 5.8923778 | H7: 1.6039578 | I7: 3.316716 | J7: 4.7855843 | K7: 3.667111 | L7: 6.2559182 | M7: 0 | N7: 1.3815949 | O7: 11.142189 | P7: 9.5308319 | Q7: 13.212094 | R7: 1000 | S7: 0.10282682 | T7: 9 | U7: 41.104 | V7: 149.28349 | W7: 41547 | X7: 81234 | Y7: 1.7471737 | Z7: 77 | AA7: 69.045 | AB7: 40 | AC7: 15.041 | AD7: 48 | AE7: 36 | AF7: 3.9649208 | AG7: Yes | AH7: No | AI7: 20221204c | AJ7: 46494 | AK7: 1.9552546 | AL7: 0.71515197 | AM7: 0.073536804 | AN7: 0.0032516696 | AO7: 0.75007171 | AP7: 0.24992829 | AQ7: 0 | AR7: 0.017304833 | AS7: 0.016021086 | AT7: 0.0086426388 | AU7: 0.024685652 | AV7: 0 | AW7: 0.03332592 | AX7: 0.074637784 | AY7: -0.010793939 | AZ7: 0.013865598 | BA7: 0.063843845 | BB7: 0.088503382 | BC7: 0.032057024 | BD7: 0.024564746 | BE7: 0.041906297 | BF7: 0 | BG7: 0.0092548406 | BH7: 0.0016561277 | BI7: 0.0014850303 | BJ7: 0.98987945 | BK7: 23779 | BL7: 0.0016821565 | BM7: 0.00036202373 | BN7: 0.00063253291 | BO7: 7.177268 | BP7: 7.177268 | BQ7: 3.9649208 | BR7: 0.64414798 | BS7: 0.64414798 | BT7: 0.35585202 | BU7: 0.55349641 | BV7: 0.42949785 | BW7: 4.9750095 | BX7: 1.9063246 | BY7: 0.0062779548 | BZ7: 0.10179783 | CA7: 0.50705036 | CB7: 9.7613973
A8: San_Joaquin_2017 | B8: 2.672634 | C8: 4.4836227 | D8: 0 | E8: 7.1562567 | F8: 6.3872147 | G8: 8.0603015 | H8: 3.7366774 | I8: 5.3829448 | J8: 7.4170192 | K8: 6.1694421 | L8: 8.8375579 | M8: 0 | N8: 1.4567203 | O8: 16.029996 | P8: 14.233217 | Q8: 17.954099 | R8: 1000 | S8: 0.11504144 | T8: 11 | U8: 41.987 | V8: 151.94599 | W8: 40365 | X8: 192459 | Y8: 1.7471737 | Z8: 86 | AA8: 80.015 | AB8: 54 | AC8: 15.949 | AD8: 144 | AE8: 89 | AF8: 4.1293543 | AG8: Yes | AH8: No | AI8: 20221204c | AJ8: 110154 | AK8: 4.7679522 | AL8: 0.45796686 | AM8: 0.052685168 | AN8: 0.0036379298 | AO8: 0.34370242 | AP8: 0.65629758 | AQ8: 0 | AR8: 0.017589368 | AS8: 0.029508002 | AT8: 0.018773906 | AU8: 0.042431853 | AV8: 0 | AW8: 0.04709737 | AX8: 0.10549799 | AY8: -0.011825116 | AZ8: 0.01266307 | BA8: 0.093672869 | BB8: 0.11816106 | BC8: 0.048813523 | BD8: 0.040602861 | BE8: 0.058162493 | BF8: 0 | BG8: 0.0095870926 | BH8: 0.00078072517 | BI8: 0.00072639214 | BJ8: 0.98250454 | BK8: 23103 | BL8: 0.0023373588 | BM8: 0.00039511953 | BN8: 0.00069034325 | BO8: 11.900642 | BP8: 11.900642 | BQ8: 4.1293543 | BR8: 0.74239198 | BS8: 0.74239198 | BT8: 0.25760802 | BU8: 0.55356299 | BV8: 0.46268592 | BW8: 7.1562567 | BX8: 2.6307915 | BY8: 0.0065768945 | BZ8: 0.10202051 | CA8: 0.48039275 | CB8: 9.2482028
A9: San_Joaquin_fall2020 | B9: 1.8921156 | C9: 2.5685247 | D9: 0 | E9: 4.4606403 | F9: 3.8321635 | G9: 5.2698563 | H9: 1.9295777 | I9: 3.3722109 | J9: 3.8247168 | K9: 2.9692827 | L9: 5.037903 | M9: 0 | N9: 1.092702 | O9: 9.3780591 | P9: 8.0771744 | Q9: 11.023999 | R9: 1000 | S9: 0.19377337 | T9: 20.646402 | U9: 38.971856 | V9: 122.54336 | W9: 33090 | X9: 238974 | Y9: 1.995878 | Z9: 48 | AA9: 45.151 | AB9: 27 | AC9: 8.082 | AD9: 63 | AE9: 34 | AF9: 2.9848176 | AG9: Yes | AH9: No | AI9: 20221204c | AJ9: 119733 | AK9: 7.2219675 | AL9: 0.37211076 | AM9: 0.072105157 | AN9: 0.006127652 | AO9: 0.44720469 | AP9: 0.55279531 | AQ9: 0 | AR9: 0.015440376 | AS9: 0.02096013 | AT9: 0.0069480436 | AU9: 0.038584942 | AV9: 0 | AW9: 0.036400506 | AX9: 0.076528496 | AY9: -0.010615709 | AZ9: 0.013431488 | BA9: 0.065912787 | BB9: 0.089959984 | BC9: 0.03121113 | BD9: 0.024230466 | BE9: 0.041111187 | BF9: 0 | BG9: 0.0089168599 | BH9: 0.00040089198 | BI9: 0.00037709737 | BJ9: 0.98438024 | BK9: 16579 | BL9: 0.0016285663 | BM9: 0.00024424297 | BN9: 0.00048748417 | BO9: 6.3932415 | BP9: 6.3932415 | BQ9: 2.9848176 | BR9: 0.68169639 | BS9: 0.68169639 | BT9: 0.31830361 | BU9: 0.52433693 | BV9: 0.40780957 | BW9: 4.4606403 | BX9: 2.3206948 | BY9: 0.0073914808 | BZ9: 0.12332472 | CA9: 0.44973107 | CB9: 8.6579244
A10: San_Joaquin_summer2020 | B10: 1.8128958 | C10: 3.8640125 | D10: 0 | E10: 5.6769083 | F10: 4.9856671 | G10: 6.5499157 | H10: 3.1867883 | I10: 4.7404443 | J10: 4.1744367 | K10: 3.5456758 | L10: 5.0869761 | M10: 0 | N10: 1.0311572 | O10: 10.882502 | P10: 9.7209446 | Q10: 12.273466 | R10: 1000 | S10: 0.14481442 | T10: 23.632192 | U10: 35.437966 | V10: 115.64129 | W10: 31919 | X10: 238393 | Y10: 1.995878 | Z10: 94 | AA10: 90.532 | AB10: 39 | AC10: 13.345 | AD10: 151 | AE10: 65 | AF10: 2.844053 | AG10: Yes | AH10: No | AI10: 20221204c | AJ10: 119442 | AK10: 7.4688594 | AL10: 0.3659088 | AM10: 0.05298887 | AN10: 0.004579434 | AO10: 0.25463775 | AP10: 0.74536225 | AQ10: 0 | AR10: 0.01567689 | AS10: 0.033413778 | AT10: 0.017409111 | AU10: 0.05412627 | AV10: 0 | AW10: 0.049090667 | AX10: 0.094105677 | AY10: -0.010044488 | AZ10: 0.012028263 | BA10: 0.084061189 | BB10: 0.10613394 | BC10: 0.03609815 | BD10: 0.030660984 | BE10: 0.04398927 | BF10: 0 | BG10: 0.0089168599 | BH10: 0.00078699285 | BI10: 0.00075795784 | BJ10: 0.98376497 | BK10: 15992 | BL10: 0.0024387194 | BM10: 0.00041808954 | BN10: 0.00083447974 | BO10: 8.0384492 | BP10: 8.0384492 | BQ10: 2.844053 | BR10: 0.73865113 | BS10: 0.73865113 | BT10: 0.26134887 | BU10: 0.47833682 | BV10: 0.38358089 | BW10: 5.6769083 | BX10: 3.0805834 | BY10: 0.0072311964 | BZ10: 0.12332472 | CA10: 0.44973107 | CB10: 8.6579244
A11: San_Joaquin_fall2021 | B11: 1.7277919 | C11: 1.7508679 | D11: 0 | E11: 3.4786599 | F11: 3.0432302 | G11: 4.0198484 | H11: 1.3185926 | I11: 2.2849205 | J11: 0.78163419 | K11: 0.53911294 | L11: 1.0577359 | M11: 0 | N11: 0.91896709 | O11: 5.1792612 | P11: 4.4983875 | Q11: 5.9263284 | R11: 1000 | S11: 0.10755887 | T11: 15.95883 | U11: 22.777 | V11: 72.563435 | W11: 33418 | X11: 119340 | Y11: 1.995878 | Z11: 47 | AA11: 41.273 | AB11: 35 | AC11: 15.719 | AD11: 17 | AE11: 12 | AF11: 2.646759 | AG11: Yes | AH11: No | AI11: 20221204c | AJ11: 59793 | AK11: 3.5712238 | AL11: 0.52916543 | AM11: 0.056916434 | AN11: 0.00340131 | AO11: 0.42522831 | AP11: 0.57477169 | AQ11: 0 | AR11: 0.023810779 | AS11: 0.024128791 | AT11: 0.012871052 | AU11: 0.038037112 | AV11: 0 | AW11: 0.04793957 | AX11: 0.071375633 | AY11: -0.0093831508 | AZ11: 0.010295367 | BA11: 0.061992482 | BB11: 0.081671 | BC11: 0.010771736 | BD11: 0.0074295399 | BE11: 0.014576706 | BF11: 0 | BG11: 0.012664327 | BH11: 0.00078604519 | BI11: 0.00069026475 | BJ11: 0.96051018 | BK11: 16743 | BL11: 0.0020904258 | BM11: 0.00047037525 | BN11: 0.00093884011 | BO11: 2.5325021 | BP11: 2.5325021 | BQ11: 2.646759 | BR11: 0.48895291 | BS11: 0.48895291 | BT11: 0.51104709 | BU11: 0.32834425 | BV11: 0.15090674 | BW11: 3.4786599 | BX11: 1.9338738 | BY11: 0.0043339566 | BZ11: 0.16816997 | CA11: 0.32980297 | CB11: 6.3491482
A12: Denver_summer2021 | B12: 12.227617 | C12: 2.3034194 | D12: 0 | E12: 14.531036 | F12: 13.813533 | G12: 15.347104 | H12: 1.6350273 | I12: 3.111274 | J12: 0.70542377 | K12: 0.47123359 | L12: 1.0805712 | M12: 0 | N12: 6.6266569 | O12: 21.863117 | P12: 19.900551 | Q12: 23.930671 | R12: 1000 | S12: 0.045356774 | T12: 11.102345 | U12: 74.72 | V12: 1668.1967 | W12: 11671 | X12: 59356 | Y12: 1.6088026 | Z12: 34 | AA12: 27.209 | AB12: 27 | AC12: 8.469 | AD12: 24 | AE12: 9 | AF12: 18.854274 | AG12: Yes | AH12: No | AI12: 20221204c | AJ12: 36894 | AK12: 5.0860215 | AL12: 0.44341553 | AM12: 0.020111898 | AN12: 0.0014343071 | AO12: 0.89945091 | AP12: 0.10054909 | AQ12: 0 | AR12: 0.0073298411 | AS12: 0.001380784 | AT12: 0.0004771904 | AU12: 0.0024729158 | AV12: 0 | AW12: 0.0087106252 | AX12: 0.013105839 | AY12: -0.0011764596 | AZ12: 0.0012393949 | BA12: 0.011929379 | BB12: 0.014345234 | BC12: 0.00042286606 | BD12: 0.00028248083 | BE12: 0.00064774807 | BF12: 0 | BG12: 0.0039723474 | BH12: 0.00092155906 | BI12: 0.00073749119 | BJ12: 0.97650341 | BK12: 7254 | BL12: 0.0037220844 | BM12: 0.00072564476 | BN12: 0.0011674938 | BO12: 3.0088432 | BP12: 3.0088432 | BQ12: 18.854274 | BR12: 0.13761975 | BS12: 0.13761975 | BT12: 0.86238025 | BU12: 0.33536469 | BV12: 0.032265458 | BW12: 14.531036 | BX12: 1.1604572 | BY12: 0.22996922 | BZ12: 0.011624102 | CA12: 0.75166776 | CB12: 14.470609
A13: Denver_fall2021 | B13: 12.323515 | C13: 2.3342154 | D13: 0 | E13: 14.652963 | F13: 13.866967 | G13: 15.5922 | H13: 1.6101647 | I13: 3.2413286 | J13: 2.3407608 | K13: 1.5748146 | L13: 4.086929 | M13: 0 | N13: 6.5448146 | O13: 23.538539 | P13: 21.113583 | Q13: 26.594669 | R13: 1000 | S13: 0.08913732 | T13: 10.160213 | U13: 66.56 | V13: 1647.5937 | W13: 11688 | X13: 67811 | Y13: 1.6088026 | Z13: 40 | AA13: 31.505 | AB13: 33 | AC13: 8.481 | AD13: 29 | AE13: 21 | AF13: 18.86833 | AG13: Yes | AH13: No | AI13: 20221204c | AJ13: 42149 | AK13: 5.8016518 | AL13: 0.41516829 | AM13: 0.037006988 | AN13: 0.0028187696 | AO13: 0.87662603 | AP13: 0.12362122 | AQ13: 0 | AR13: 0.007479705 | AS13: 0.0014167421 | AT13: 0.00035823281 | AU13: 0.0027428755 | AV13: 0 | AW13: 0.0088935536 | AX13: 0.014286616 | AY13: -0.0014718164 | AZ13: 0.0018549051 | BA13: 0.012814799 | BB13: 0.016141521 | BC13: 0.0014207148 | BD13: 0.00095582701 | BE13: 0.0024805442 | BF13: 0 | BG13: 0.0039723474 | BH13: 0.00094901421 | BI13: 0.00074746732 | BJ13: 0.97391463 | BK13: 7265 | BL13: 0.0045423262 | BM13: 0.00072561602 | BN13: 0.0011673778 | BO13: 4.6749762 | BP13: 4.6749762 | BQ13: 18.86833 | BR13: 0.19860503 | BS13: 0.19860503 | BT13: 0.80159702 | BU13: 0.37749019 | BV13: 0.099441022 | BW13: 14.652963 | BX13: 1.158015 | BY13: 0.2267851 | BZ13: 0.011624102 | CA13: 0.75166776 | CB13: 14.470609
... A19: Permian_2019_F2021_Midland | B19: 8.9359119 | C19: 46.347477 | D19: 0 | E19: 55.283389 | F19: 51.74771 | G19: 59.277751 | H19: 42.826449 | I19: 50.351434 | J19: 38.266763 | K19: 31.933277 | L19: 47.581528 | M19: 0 | N19: 4.598136 | O19: 98.148288 | P19: 89.889073 | Q19: 108.48647 | R19: 1000 | S19: 0.10984746 | T19: 16.353134 | U19: 109.159 | V19: 812.65429 | W19: 9209 | X19: 51783 | Y19: 1.8250769 | Z19: 130 | AA19: 124.433 | AB19: 93 | AC19: 49.044 | AD19: 123 | AE19: 76 | AF19: 13.534048 | AG19: Yes | AH19: No | AI19: 20221204c | AJ19: 28373 | AK19: 5.6239841 | AL19: 0.4216751 | AM19: 0.046319939 | AN19: 0.0034736817 | AO19: 0.24043398 | AP19: 0.75956602 | AQ19: 0 | AR19: 0.010995957 | AS19: 0.057032219 | AT19: 0.046757127 | AU19: 0.068716597 | AV19: 0 | AW19: 0.068028176 | AX19: 0.12077496 | AY19: -0.010163258 | AZ19: 0.012721497 | BA19: 0.1106117 | BB19: 0.13349646 | BC19: 0.047088613 | BD19: 0.039295032 | BE19: 0.058550763 | BF19: 0 | BG19: 0.0056581699 | BH19: 0.0045818207 | BI19: 0.0043856131 | BJ19: 0.9223636 | BK19: 5045 | BL19: 0.018434093 | BM19: 0.0053256597 | BN19: 0.0097213082 | BO19: 84.614241 | BP19: 84.614241 | BQ19: 13.534048 | BR19: 0.86210594 | BS19: 0.86210594 | BT19: 0.13789406 | BU19: 0.43673575 | BV19: 0.38988671 | BW19: 55.283389 | BX19: 5.7064419 | BY19: 0.16108113 | BZ19: 0.016157454 | CA19: 0.64011733 | CB19: 12.323114
A20: GHGI 2022 (for 2020) | AI20: 1 | AR20: 0.0048 | AX20: =AR20+BG20 -> 0.0098 | AY20: -0.00196 | AZ20: 0.00205 | BG20: 0.005
A21: GHGI NM 2019
A22: GHGI TX 2021
A23: GHGI CA 2021
A24: GHGI CO 2021
A25: GHGI PA 2021 | U25: Fraction of national gas covered | V25: =V26/V29 -> 0.23420564
A26: Totals excluding repeats | O26: =O3+O7+O13+O14+O15+O16 -> 721.79676 | P26: =P3+P7+P13+P14+P15+P16 -> 680.38551 | Q26: =Q3+Q7+Q13+Q14+Q15+Q16 -> 766.75384 | V26: =V3+V7+V13+V14+V15+V16 -> 19972.262 | W26: =W3+W7+W13+W14+W15+W16 -> 170569 | X26: =X3+X7+X13+X14+X15+X16 -> 549072 | AC26: =AC3+AC7+AC13+AC14+AC15+AC16 -> 601.364 | AI26: 1 | AJ26: =AJ3+AJ7+AJ13+AJ14+AJ15+AJ16 -> 316771 | AK26: =X26/W26 -> 3.2190609 | BK26: =BK3+BK7+BK13+BK14+BK15+BK16 -> 100159 | BN26: =AC26/BK26 -> 0.0060040935
A27: Totals including repeats (no 2019 subcampaigns) | O27: =SUM(O2:O16) -> 1375.458 | P27: =SUM(P2:P16) -> 1285.403 | Q27: =SUM(Q2:Q16) -> 1475.1591 | V27: =SUM(V2:V16) -> 35657.521 | W27: =SUM(W2:W16) -> 398499 | X27: =SUM(X2:X16) -> 1714261 | AC27: =SUM(AC2:AC16) -> 1240.46 | AI27: 1 | AJ27: =SUM(AJ2:AJ16) -> 959573 | AK27: =AJ27/BK26 -> 9.580497 | AX27: =O27/$V27 -> 0.038574135 | AY27: =P27/$V27 -> 0.036048579 | AZ27: =Q27/$V27 -> 0.041370209 | BK27: =SUM(BK2:BK16) -> 228449 | BN27: =AC27/BK27 -> 0.0054299209
A28: Totals excluding high-prod campaigns | O28: =O2+O3+SUM(O7:O13)+O15+O16 -> 897.13677 | P28: =P2+P3+SUM(P7:P13)+P15+P16 -> 846.98463 | Q28: =Q2+Q3+SUM(Q7:Q13)+Q15+Q16 -> 954.26046 | V28: =V2+V3+SUM(V7:V13)+V15+V16 -> 13683.312 | AX28: =O28/$V28 -> 0.065564297 | AY28: =P28/$V28 -> 0.061899093 | AZ28: =Q28/$V28 -> 0.069738995
U29: 2021 US gas prod | V29: 85276.605 | BQ29: Methane fractional loss partial
A30: Permian total | W30: =SUM(W2:W6) -> 162037 | X30: =SUM(X2:X6) -> 643575 | Z30: =SUM(Z2:Z6) -> 3866 | AA30: =SUM(AA2:AA6) -> 3610.87 | AB30: =SUM(AB2:AB6) -> 2358 | AC30: =SUM(AC2:AC6) -> 1060.934 | AD30: =SUM(AD2:AD6) -> 3335 | AE30: =SUM(AE2:AE6) -> 1738 | AJ30: =SUM(AJ2:AJ6) -> 375906 | AK30: =AJ30/BK30 -> 3.9587388 | BK30: =SUM(BK2:BK6) -> 94956 | BQ30: FracLossProd
A31: San Joaquin total | W31: =SUM(W7:W11) -> 180339 | X31: =SUM(X7:X11) -> 870400 | Z31: =SUM(Z7:Z11) -> 352 | AA31: =SUM(AA7:AA11) -> 326.016 | AB31: =SUM(AB7:AB11) -> 195 | AC31: =SUM(AC7:AC11) -> 68.136 | AD31: =SUM(AD7:AD11) -> 423 | AE31: =SUM(AE7:AE11) -> 236 | AJ31: =SUM(AJ7:AJ11) -> 455616 | AK31: =AJ31/BK31 -> 4.73633 | BK31: =SUM(BK7:BK11) -> 96196 | BQ31: Methane fractional loss total
A32: Denver total | W32: =W12+W13 -> 23359 | X32: =X12+X13 -> 127167 | Z32: =Z12+Z13 -> 74 | AA32: =AA12+AA13 -> 58.714 | AB32: =AB12+AB13 -> 60 | AC32: =AC12+AC13 -> 16.95 | AD32: =AD12+AD13 -> 53 | AE32: =AE12+AE13 -> 30 | AJ32: =AJ12+AJ13 -> 79043 | AK32: =AJ32/BK32 -> 5.4441077 | BK32: =BK12+BK13 -> 14519 | BQ32: FracLossP2.5
A33: Per+SJ+DJ | W33: =SUM(W30:W32) -> 365735 | X33: =SUM(X30:X32) -> 1641142 | AJ33: =SUM(AJ30:AJ32) -> 910565 | AK33: =AJ33/BK33 -> 4.4272892 | BK33: =SUM(BK30:BK32) -> 205671 | BQ33: FracLossP97.5
BQ34: FracLossP2.5Full
BQ35: FracLossP97.5Full
BQ36: FracLossMid
BQ37: FracLossMidP2.5
BQ38: FracLossMidP97.5
BQ39: FracLossMidPartial
BQ40: FracLossMidGHGI
BQ41: % aerial
BQ42: % aerial sel
BQ43: Fraction sim retained
BQ44: Sites covered
BQ45: % wells ever emitting
...

Sheet By site visit
A1: Scenario | B1: Simulation (t/h) | C1: Aerial (t/h) | D1: Partial (t/h) | E1: Total emissions (t/h) | F1: Total emissions P2.5 | G1: Total emissions P97.5 | H1: Aerial emissions P2.5 | I1: Aerial emissions P97.5 | J1: Aerial midstream emissions (t/h) | K1: Aerial midstream emissions P2.5 | L1: Aerial midstream emissions P97.5 | M1: Midstream partial detect (t/h) | N1: Midstream GHGI below min detect (t/h) | O1: Total emissions + midstream (t/h) | P1: Total emissions + midstream P2.5 | Q1: Total emissions + midstream P97.5 | R1: N | S1: % SDev of MC iterations | T1: Min detected emission | U1: Transition point | V1: Total covered production (t(CH4)/hr) | W1: Wells covered | X1: Well visits | Y1: Wells per site | Z1: # production plumes | AA1: # production plumes sel | AB1: # prod sources overall | AC1: # avg prod sources sim | AD1: # midstream plumes | AE1: # midstream sources | AF1: Total sim emissions | AG1: Stratify by covered prod | AH1: Include repeats | AI1: High prod | AJ1: Well site visits | AK1: Avg visits/well | AL1: SD to SErr factor | AM1: SErr of mean total emissions | AN1: Serr of sample mean | AO1: Simulation % | AP1: Aerial % | AQ1: Partial % | AR1: Methane fractional loss simulation | AS1: Methane fractional loss aerial | AT1: AerialFracLossP2.5 | AU1: AerialFracLossP97.5 | AV1: Methane fractional loss partial | AW1: FracLossProd | AX1: Methane fractional loss total | AY1: FracLossP2.5 | AZ1: FracLossP97.5 | BA1: FracLossP2.5Full | BB1: FracLossP97.5Full | BC1: FracLossMid | BD1: FracLossMidP2.5 | BE1: FracLossMidP97.5 | BF1: FracLossMidPartial | BG1: FracLossMidGHGI | BH1: % aerial | BI1: % aerial sel | BJ1: Fraction sim retained | BK1: Sites covered | BL1: % wells ever emitting | BM1: Avg % wells emitting | BN1: Avg % sites emitting | BO1: Total aerial | BP1: Total aerial+partial emissions | BQ1: Total sim emissions | BR1: Frac aerial | BS1: Frac aerial+partial | BT1: Frac sim | BU1: Frac midstream | BV1: Frac midstream aerial | BW1: Total production emissions | BX1: Total/Sim | BY1: Production/site covered | BZ1: State GHGI
A2: Kairos Permian
A3: Permian_2019 | B3: 296.12135 | C3: 920.28875 | D3: 0 | E3: 1216.4101 | F3: 1199.2861 | G3: 1233.9008 | H3: 903.21532 | I3: 937.77791 | J3: 828.48949 | K3: 809.62931 | L3: 852.68466 | M3: 0 | N3: 281.35125 | O3: 2326.2509 | P3: 2247.4129 | Q3: 2405.9036 | R3: 1000 | S3: 0.0064158762 | T3: 15.029525 | U3: 113 | V3: 81546.389 | W3: 84570 | X3: 326908 | Y3: 1.8250769 | Z3: 1749 | AA3: 1502 | AB3: 1054 | AC3: 483.512 | AD3: 1272 | AE3: 679 | AF3: 577.47261 | AG3: Yes | AH3: Yes | AI3: 20221127b | AJ3: 179120 | AK3: 3.8655934 | AL3: 0.50861822 | AM3: 0.0032632315 | AN3: 0.00020288782 | AO3: 0.26599034 | AP3: 0.73400966 | AQ3: 0 | AR3: 0.0036313239 | AS3: 0.011285463 | AT3: 0.011076092 | AU3: 0.011499932 | AV3: 0 | AW3: 0.014916787 | AX3: 0.028526718 | AY3: -0.00096678715 | AZ3: 0.00097677824 | BA3: 0.027559931 | BB3: 0.029503496 | BC3: 0.010159732 | BD3: 0.0099284508 | BE3: 0.010456437 | BF3: 0 | BG3: 0.0034501988 | BH3: 0.0097644038 | BI3: 0.0083854399 | BJ3: 0.91416876 | BK3: 46337 | BL3: 0.022746401 | BM3: 0.0057172993 | BN3: 0.010434685 | BO3: 1748.7782 | BP3: 1748.7782 | BQ3: 577.47261 | BR3: 0.75175825 | BS3: 0.75175825 | BT3: 0.24824175 | BU3: 0.47709419 | BV3: 0.35614796 | BW3: 1216.4101 | BX3: 3.7552326 | BY3: 1.7598547 | BZ3: 0.011061675
A4: Permian/2020 | AI4: 0.5 | AJ4: =X4/Y4 -> #DIV/0! | AK4: =X4/W4 -> #DIV/0! | AL4: =1/SQRT(AK4) -> #DIV/0! | AM4: =S4/SQRT(AK4) -> #DIV/0! | AN4: =B4/$BV4 -> #DIV/0! | AO4: =C4/$BV4 -> #DIV/0! | AP4: =D4/$BV4 -> #DIV/0! | AQ4: =B4/$V4 -> #DIV/0! | AR4: =C4/$V4 -> #DIV/0! | AS4: =H4/$V4 -> #DIV/0! | AT4: =I4/$V4 -> #DIV/0! | AU4: =D4/$V4 -> #DIV/0! | AV4: =AQ4+AR4+AU4 -> #DIV/0! | AW4: =O4/$V4 -> #DIV/0! | AX4: =P4/$V4-AW4 -> #DIV/0! | AY4: =Q4/$V4-AW4 -> #DIV/0! | AZ4: =$AW4+AX4 -> #DIV/0! | BA4: =$AW4+AY4 -> #DIV/0! | BB4: =J4/$V4 -> #DIV/0! | BC4: =K4/$V4 -> #DIV/0! | BD4: =L4/$V4 -> #DIV/0! | BE4: =M4/$V4 -> #DIV/0! | BF4: =N4/$V4 -> #DIV/0! | BG4: =Z4/X4 -> #DIV/0! | BH4: =AA4/X4 -> #DIV/0! | BI4: =B4/AF4 -> #DIV/0! | BJ4: =W4/Y4 -> #DIV/0! | BK4: =AB4/W4 -> #DIV/0! | BL4: =AC4/W4 -> #DIV/0! | BM4: =AC4/BJ4 -> #DIV/0! | BN4: =C4+J4 -> 0 | BO4: =C4+D4+J4+M4 -> 0 | BP4: =B4+N4 -> 0 | BQ4: =BN4/$O4 -> #DIV/0! | BR4: =BO4/$O4 -> #DIV/0! | BS4: =BP4/$O4 -> #DIV/0! | BT4: =(J4+M4+N4)/O4 -> #DIV/0! | BU4: =J4/$O4 -> #DIV/0! | BV4: =SUM(B4:D4) -> 0 | BW4: =BV4/AF4 -> #DIV/0! | BX4: =V4/X4 -> #DIV/0!
A5: Permian/Summer 2021 | AI5: 0.5 | AJ5: =X5/Y5 -> #DIV/0! | AK5: =X5/W5 -> #DIV/0! | AL5: =1/SQRT(AK5) -> #DIV/0! | AM5: =S5/SQRT(AK5) -> #DIV/0! | AN5: =B5/$BV5 -> #DIV/0! | AO5: =C5/$BV5 -> #DIV/0! | AP5: =D5/$BV5 -> #DIV/0! | AQ5: =B5/$V5 -> #DIV/0! | AR5: =C5/$V5 -> #DIV/0! | AS5: =H5/$V5 -> #DIV/0! | AT5: =I5/$V5 -> #DIV/0! | AU5: =D5/$V5 -> #DIV/0! | AV5: =AQ5+AR5+AU5 -> #DIV/0! | AW5: =O5/$V5 -> #DIV/0! | AX5: =P5/$V5-AW5 -> #DIV/0! | AY5: =Q5/$V5-AW5 -> #DIV/0! | AZ5: =$AW5+AX5 -> #DIV/0! | BA5: =$AW5+AY5 -> #DIV/0! | BB5: =J5/$V5 -> #DIV/0! | BC5: =K5/$V5 -> #DIV/0! | BD5: =L5/$V5 -> #DIV/0! | BE5: =M5/$V5 -> #DIV/0! | BF5: =N5/$V5 -> #DIV/0! | BG5: =Z5/X5 -> #DIV/0! | BH5: =AA5/X5 -> #DIV/0! | BI5: =B5/AF5 -> #DIV/0! | BJ5: =W5/Y5 -> #DIV/0! | BK5: =AB5/W5 -> #DIV/0! | BL5: =AC5/W5 -> #DIV/0! | BM5: =AC5/BJ5 -> #DIV/0! | BN5: =C5+J5 -> 0 | BO5: =C5+D5+J5+M5 -> 0 | BP5: =B5+N5 -> 0 | BQ5: =BN5/$O5 -> #DIV/0! | BR5: =BO5/$O5 -> #DIV/0! | BS5: =BP5/$O5 -> #DIV/0! | BT5: =(J5+M5+N5)/O5 -> #DIV/0! | BU5: =J5/$O5 -> #DIV/0! | BV5: =SUM(B5:D5) -> 0 | BW5: =BV5/AF5 -> #DIV/0! | BX5: =V5/X5 -> #DIV/0!
A6: Permian/Fall 2021 | AI6: 0.5 | AJ6: =X6/Y6 -> #DIV/0! | AK6: =X6/W6 -> #DIV/0! | AL6: =1/SQRT(AK6) -> #DIV/0! | AM6: =S6/SQRT(AK6) -> #DIV/0! | AN6: =B6/$BV6 -> #DIV/0! | AO6: =C6/$BV6 -> #DIV/0! | AP6: =D6/$BV6 -> #DIV/0! | AQ6: =B6/$V6 -> #DIV/0! | AR6: =C6/$V6 -> #DIV/0! | AS6: =H6/$V6 -> #DIV/0! | AT6: =I6/$V6 -> #DIV/0! | AU6: =D6/$V6 -> #DIV/0! | AV6: =AQ6+AR6+AU6 -> #DIV/0! | AW6: =O6/$V6 -> #DIV/0! | AX6: =P6/$V6-AW6 -> #DIV/0! | AY6: =Q6/$V6-AW6 -> #DIV/0! | AZ6: =$AW6+AX6 -> #DIV/0! | BA6: =$AW6+AY6 -> #DIV/0! | BB6: =J6/$V6 -> #DIV/0! | BC6: =K6/$V6 -> #DIV/0! | BD6: =L6/$V6 -> #DIV/0! | BE6: =M6/$V6 -> #DIV/0! | BF6: =N6/$V6 -> #DIV/0! | BG6: =Z6/X6 -> #DIV/0! | BH6: =AA6/X6 -> #DIV/0! | BI6: =B6/AF6 -> #DIV/0! | BJ6: =W6/Y6 -> #DIV/0! | BK6: =AB6/W6 -> #DIV/0! | BL6: =AC6/W6 -> #DIV/0! | BM6: =AC6/BJ6 -> #DIV/0! | BN6: =C6+J6 -> 0 | BO6: =C6+D6+J6+M6 -> 0 | BP6: =B6+N6 -> 0 | BQ6: =BN6/$O6 -> #DIV/0! | BR6: =BO6/$O6 -> #DIV/0! | BS6: =BP6/$O6 -> #DIV/0! | BT6: =(J6+M6+N6)/O6 -> #DIV/0! | BU6: =J6/$O6 -> #DIV/0! | BV6: =SUM(B6:D6) -> 0 | BW6: =BV6/AF6 -> #DIV/0! | BX6: =V6/X6 -> #DIV/0!
A7: San Joaquin/2016 | AI7: 1 | AJ7: =X7/Y7 -> #DIV/0! | AK7: =X7/W7 -> #DIV/0! | AL7: =1/SQRT(AK7) -> #DIV/0! | AM7: =S7/SQRT(AK7) -> #DIV/0! | AN7: =B7/$BV7 -> #DIV/0! | AO7: =C7/$BV7 -> #DIV/0! | AP7: =D7/$BV7 -> #DIV/0! | AQ7: =B7/$V7 -> #DIV/0! | AR7: =C7/$V7 -> #DIV/0! | AS7: =H7/$V7 -> #DIV/0! | AT7: =I7/$V7 -> #DIV/0! | AU7: =D7/$V7 -> #DIV/0! | AV7: =AQ7+AR7+AU7 -> #DIV/0! | AW7: =O7/$V7 -> #DIV/0! | AX7: =P7/$V7-AW7 -> #DIV/0! | AY7: =Q7/$V7-AW7 -> #DIV/0! | AZ7: =$AW7+AX7 -> #DIV/0! | BA7: =$AW7+AY7 -> #DIV/0! | BB7: =J7/$V7 -> #DIV/0! | BC7: =K7/$V7 -> #DIV/0! | BD7: =L7/$V7 -> #DIV/0! | BE7: =M7/$V7 -> #DIV/0! | BF7: =N7/$V7 -> #DIV/0! | BG7: =Z7/X7 -> #DIV/0! | BH7: =AA7/X7 -> #DIV/0! | BI7: =B7/AF7 -> #DIV/0! | BJ7: =W7/Y7 -> #DIV/0! | BK7: =AB7/W7 -> #DIV/0! | BL7: =AC7/W7 -> #DIV/0! | BM7: =AC7/BJ7 -> #DIV/0! | BN7: =C7+J7 -> 0 | BO7: =C7+D7+J7+M7 -> 0 | BP7: =B7+N7 -> 0 | BQ7: =BN7/$O7 -> #DIV/0! | BR7: =BO7/$O7 -> #DIV/0! | BS7: =BP7/$O7 -> #DIV/0! | BT7: =(J7+M7+N7)/O7 -> #DIV/0! | BU7: =J7/$O7 -> #DIV/0! | BV7: =SUM(B7:D7) -> 0 | BW7: =BV7/AF7 -> #DIV/0! | BX7: =V7/X7 -> #DIV/0!
A8: San Joaquin/2017 | AI8: 1 | AJ8: =X8/Y8 -> #DIV/0! | AK8: =X8/W8 -> #DIV/0! | AL8: =1/SQRT(AK8) -> #DIV/0! | AM8: =S8/SQRT(AK8) -> #DIV/0! | AN8: =B8/$BV8 -> #DIV/0! | AO8: =C8/$BV8 -> #DIV/0! | AP8: =D8/$BV8 -> #DIV/0! | AQ8: =B8/$V8 -> #DIV/0! | AR8: =C8/$V8 -> #DIV/0! | AS8: =H8/$V8 -> #DIV/0! | AT8: =I8/$V8 -> #DIV/0! | AU8: =D8/$V8 -> #DIV/0! | AV8: =AQ8+AR8+AU8 -> #DIV/0! | AW8: =O8/$V8 -> #DIV/0! | AX8: =P8/$V8-AW8 -> #DIV/0! | AY8: =Q8/$V8-AW8 -> #DIV/0! | AZ8: =$AW8+AX8 -> #DIV/0! | BA8: =$AW8+AY8 -> #DIV/0! | BB8: =J8/$V8 -> #DIV/0! | BC8: =K8/$V8 -> #DIV/0! | BD8: =L8/$V8 -> #DIV/0! | BE8: =M8/$V8 -> #DIV/0! | BF8: =N8/$V8 -> #DIV/0! | BG8: =Z8/X8 -> #DIV/0! | BH8: =AA8/X8 -> #DIV/0! | BI8: =B8/AF8 -> #DIV/0! | BJ8: =W8/Y8 -> #DIV/0! | BK8: =AB8/W8 -> #DIV/0! | BL8: =AC8/W8 -> #DIV/0! | BM8: =AC8/BJ8 -> #DIV/0! | BN8: =C8+J8 -> 0 | BO8: =C8+D8+J8+M8 -> 0 | BP8: =B8+N8 -> 0 | BQ8: =BN8/$O8 -> #DIV/0! | BR8: =BO8/$O8 -> #DIV/0! | BS8: =BP8/$O8 -> #DIV/0! | BT8: =(J8+M8+N8)/O8 -> #DIV/0! | BU8: =J8/$O8 -> #DIV/0! | BV8: =SUM(B8:D8) -> 0 | BW8: =BV8/AF8 -> #DIV/0! | BX8: =V8/X8 -> #DIV/0!
A9: San Joaquin/2016-2017 | AI9: 0.5
A10: San Joaquin/COVID 2020 | AI10: 1 | AJ10: =X10/Y10 -> #DIV/0! | AK10: =X10/W10 -> #DIV/0! | AL10: =1/SQRT(AK10) -> #DIV/0! | AM10: =S10/SQRT(AK10) -> #DIV/0! | AN10: =B10/$BV10 -> #DIV/0! | AO10: =C10/$BV10 -> #DIV/0! | AP10: =D10/$BV10 -> #DIV/0! | AQ10: =B10/$V10 -> #DIV/0! | AR10: =C10/$V10 -> #DIV/0! | AS10: =H10/$V10 -> #DIV/0! | AT10: =I10/$V10 -> #DIV/0! | AU10: =D10/$V10 -> #DIV/0! | AV10: =AQ10+AR10+AU10 -> #DIV/0! | AW10: =O10/$V10 -> #DIV/0! | AX10: =P10/$V10-AW10 -> #DIV/0! | AY10: =Q10/$V10-AW10 -> #DIV/0! | AZ10: =$AW10+AX10 -> #DIV/0! | BA10: =$AW10+AY10 -> #DIV/0! | BB10: =J10/$V10 -> #DIV/0! | BC10: =K10/$V10 -> #DIV/0! | BD10: =L10/$V10 -> #DIV/0! | BE10: =M10/$V10 -> #DIV/0! | BF10: =N10/$V10 -> #DIV/0! | BG10: =Z10/X10 -> #DIV/0! | BH10: =AA10/X10 -> #DIV/0! | BI10: =B10/AF10 -> #DIV/0! | BJ10: =W10/Y10 -> #DIV/0! | BK10: =AB10/W10 -> #DIV/0! | BL10: =AC10/W10 -> #DIV/0! | BM10: =AC10/BJ10 -> #DIV/0! | BN10: =C10+J10 -> 0 | BO10: =C10+D10+J10+M10 -> 0 | BP10: =B10+N10 -> 0 | BQ10: =BN10/$O10 -> #DIV/0! | BR10: =BO10/$O10 -> #DIV/0! | BS10: =BP10/$O10 -> #DIV/0! | BT10: =(J10+M10+N10)/O10 -> #DIV/0! | BU10: =J10/$O10 -> #DIV/0! | BV10: =SUM(B10:D10) -> 0 | BW10: =BV10/AF10 -> #DIV/0! | BX10: =V10/X10 -> #DIV/0!
