Workbook

Sheet ReadMe
A1: These data represent model outputs for Sherwin et al. 2023
A2: Methane emissions quantities are presented in metric ton per hour
A3: Field descriptions
A4: Run# : Number identifying the Run in question. A Run is A full simulation of A selected scenario.
A5: Batch counter: Each scenario run often includes multiple batches of Monte Carlo iterations, run in series to circumvent memory and CPU limitations. This tracks each batch through a numerical identifier of 1-10.
A6: scenario: the scenario to Run, including the aerial campaign, basin, year, any additional geographic restrictions, etc.
A7: Prod simulation (t/h): Estimated scenario-wide production emissions in metric tons per hour from the Rutherford et al. simulation.
A8: Prod simulation P2.5: The 2.5% confidence interval of the above.
A9: Prod simulation P97.5: The 97.5% confidence interval of the above.
A10: Prod aerial (t/h): Estimated scenario-wide production emissions from aerially measured plumes above the transition point, in metric tons per hour.
A11: Prod aerial P2.5: The 2.5% confidence interval of the above.
A12: Prod aerial P97.5: The 97.5% confidence interval of the above.
... A141: Total aerial mid emissions inc below transition P97.5: The 97.5% confidence interval of the above.

Sheet By site
A1: Scenario | B1: Prod simulation (t/h) | C1: Prod simulation P2.5 | D1: Prod simulation P97.5 | E1: Prod aerial (t/h) | F1: Prod aerial P2.5 | G1: Prod aerial P97.5 | H1: Prod partial (t/h) | I1: Prod partial P2.5 | J1: Prod partial P97.5 | K1: Prod emissions (t/h) | L1: Prod emissions P2.5 | M1: Prod emissions P97.5 | N1: Aerial midstream emissions (t/h) | O1: Aerial midstream emissions P2.5 | P1: Aerial midstream emissions P97.5 | Q1: Midstream partial detect (t/h) | R1: Midstream GHGI below min detect (t/h) | S1: Total emissions (t/h) | T1: Total emissions P2.5 | U1: Total emissions P97.5 | V1: N | W1: % SDev of MC iterations | X1: Min detected emission | Y1: Transition point | Z1: Total covered production (t(CH4)/hr) | AA1: Wells covered | AB1: Well visits | AC1: Wells per site | AD1: # production plumes | AE1: # production plumes sel | AF1: # prod sources overall | AG1: # avg prod sources sim | AH1: # midstream plumes | AI1: # midstream sources | AJ1: # avg midstream sources sim | AK1: Total sim emissions | AL1: Stratify by covered prod | AM1: Include repeats | AN1: Date | AO1: Remove negative Kairos emissions | AP1: Well site visits | AQ1: Avg visits/well site | AR1: SD to SErr factor | AS1: SErr of mean total emissions | AT1: SErr of sample mean | AU1: Simulation % prod | AV1: Aerial % prod | AW1: Partial % prod | AX1: Methane fractional loss simulation prod | AY1: Methane fractional loss simulation prodP2.5 | AZ1: Methane fractional loss simulation prodP97.5 | BA1: Methane fractional loss aerial prod | BB1: AerialFracLossProdP2.5 | BC1: AerialFracLossProdP97.5 | BD1: Methane fractional loss partial prod | BE1: Methane fractional loss partial prodP2.5 | BF1: Methane fractional loss partial prodP97.5 | BG1: FracLossProd | BH1: FracLossProdP2.5 | BI1: FracLossProdP97.5 | BJ1: Methane fractional loss total | BK1: FracLossP2.5 | BL1: FracLossP97.5 | BM1: FracLossP2.5Full | BN1: FracLossP97.5Full | BO1: FracLossMidAerial | BP1: FracLossMidAerialP2.5 | BQ1: FracLossMidAerialP97.5 | BR1: FracLossMidPartial | BS1: FracLossMidPartialP2.5 | BT1: FracLossMidPartialP97.5 | BU1: FracLossMidGHGI | BV1: FracLossMidGHGIP2.5 | BW1: FracLossMidGHGIP97.5 | BX1: FracLossMidstream total | BY1: FracLossMidstream totalP2.5 | BZ1: FracLossMidstream totalP97.5 | CA1: % well site visits with plume | CB1: % well site visits with selected plume | CC1: Fraction sim retained | CD1: Well sites covered | CE1: % well sites ever emitting | CF1: Avg % wells emitting | CG1: Avg % sites emitting | CH1: Total aerial | CI1: Total aerialP2.5 | CJ1: Total aerialP97.5 | CK1: Total aerial+partial emissions | CL1: Total aerial+partial emissionsP2.5 | CM1: Total aerial+partial emissionsP97.5 | CN1: Total sim emissions | CO1: Total sim emissionsP2.5 | CP1: Total sim emissionsP97.5 | CQ1: Total aerial all segments inc below transition | CR1: Total aerial all segments inc below transition P2.5 | CS1: Total aerial all segments inc below transition P97.5 | CT1: Total pipeline emissions | CU1: Total pipeline emissions P2.5 | CV1: Total pipeline emissions P97.5 | CW1: Total compressor emissions | CX1: Total compressor emissions P2.5 | CY1: Total compressor emissions P97.5 | CZ1: Total processing emissions | DA1: Total processing emissions P2.5 | DB1: Total processing emissions P97.5 | DC1: Total other midstream emissions | DD1: Total other midstream emissions P2.5 | DE1: Total other midstream emissions P97.5 | DF1: Frac aerial | DG1: Frac aerial+partial | DH1: Frac sim | DI1: Frac midstream | DJ1: Frac midstream aerial | DK1: Total production emissions | DL1: Total/Sim | DM1: Production/site covered | DN1: State GHGI | DO1: NG methane fraction | DP1: kgCH4 per mcfNG | DQ1: Full upper errorbar % total | DR1: Full lower errorbar % total | DS1: Partial prod % total | DT1: Partial mid % total | DU1: Tot sim emissions loss rate | DV1: Tot sim emissions loss rate P2.5 | DW1: Tot sim emissions loss rate P97.5 | DX1: Prod-only state GHGI loss | DY1: Prod-only state GHGI loss low | DZ1: Prod-only state GHGI loss high | EA1: Total aerial prod emissions inc below transition | EB1: Total aerial prod emissions inc below transition P2.5 | EC1: Total aerial prod emissions inc below transition P97.5 | ED1: Total aerial mid emissions inc below transition | EE1: Total aerial mid emissions inc below transition P2.5 | EF1: Total aerial mid emissions inc below transition P97.5
A2: Kairos_Permian | B2: 17.938779 | C2: 17.537212 | D2: 18.321862 | E2: 86.566381 | F2: 80.642076 | G2: 93.122774 | H2: 4.7355434 | I2: 4.0494611 | J2: 5.5423589 | K2: 109.2407 | L2: 103.17568 | M2: 115.81004 | N2: 66.430697 | O2: 58.652113 | P2: 77.999431 | Q2: 4.9483802 | R2: 7.4248658 | S2: 188.04465 | T2: 176.88794 | U2: 201.73658 | V2: 1000 | W2: 0.062371522 | X2: 5.9464547 | Y2: 24.348 | Z2: 1952.0451 | AA2: 21637 | AB2: 81564 | AC2: 1.2 | AD2: NAN | AE2: 1276.962 | AF2: 627 | AG2: 299.748 | AH2: 706 | AI2: 331 | AJ2: 184.177 | AK2: 25.363645 | AL2: Yes | AM2: No | AN2: 20230815j | AO2: Yes | AP2: 67970 | AQ2: 3.7698281 | AR2: 0.51503795 | AS2: 0.032123701 | AT2: 0.0019723607 | AU2: =B2/K2 -> 0.16421332 | AV2: =E2/K2 -> 0.79243705 | AW2: 0.0075465881 | AX2: 0.0091897357 | AY2: 0.008790317 | AZ2: 0.00957077 | BA2: 0.044346506 | BB2: 0.038453888 | BC2: 0.050867832 | BD2: 0.0024259395 | BE2: 0.0017435268 | BF2: 0.0032284397 | BG2: 0.055962181 | BH2: 0.052855169 | BI2: 0.059327542 | BJ2: 0.09633212 | BK2: -0.0057153944 | BL2: 0.0070141501 | BM2: 0.090616726 | BN2: 0.10334627 | BO2: 0.034031333 | BP2: 0.030046494 | BQ2: 0.039957801 | BR2: 0.0025349722 | BS2: 0.0021686161 | BT2: 0.0029349755 | BU2: 0.0038036343 | BV2: 0.0031189801 | BW2: 0.0044882884 | BX2: 0.040369939 | BY2: 0.035722549 | BZ2: 0.047037132 | CA2: NAN | CB2: 0.018787141 | CC2: 0.76504823 | CD2: 18030 | CE2: 0.034775374 | CF2: 0.013853492 | CG2: 0.016624958 | CH2: 152.99708 | CI2: 145.21849 | CJ2: 164.56581 | CK2: 157.94546 | CL2: 149.45173 | CM2: 170.29502 | CN2: 25.363645 | CO2: 23.625602 | CP2: 27.083204 | CQ2: Null | CR2: Null | CS2: Null | CT2: 18.533637 | CU2: 15.035303 | CV2: 27.374749 | CW2: 7.2517353 | CX2: 6.0661008 | CY2: 8.6236383 | CZ2: 3.7354098 | DA2: 2.9033645 | DB2: 5.0994946 | DC2: 0 | DD2: 0 | DE2: 0 | DF2: 0.81361973 | DG2: 0.83993488 | DH2: 0.13488203 | DI2: 0.41906837 | DJ2: 0.35326831 | DK2: 109.2407 | DL2: 4.6588483 | DM2: 0.10826651 | DN2: 0.012478177 | DO2: 0.9 | DP2: 17.326203 | DQ2: 0.072808105 | DR2: -0.059332818 | DS2: 0.025183087 | DT2: 0.020380615 | DU2: 0.012012076 | DV2: 0.01165823 | DW2: 0.012498427 | DX2: 0.0072701048 | DY2: 0.0082075578 | DZ2: 0.0063326517 | EA2: 86.636049 | EB2: 80.71695 | EC2: 93.193038 | ED2: 66.430697 | EE2: 66.430697 | EF2: 66.430697
A3: Permian_2019 | B3: 69.580027 | C3: 68.519378 | D3: 70.901879 | E3: 236.16161 | F3: 226.64774 | G3: 245.90586 | H3: 0 | I3: 0 | J3: 0 | K3: 305.74163 | L3: 296.0079 | M3: 315.64347 | N3: 212.41877 | O3: 199.59987 | P3: 226.53175 | Q3: 0 | R3: 38.281727 | S3: 556.44213 | T3: 534.24524 | U3: 580.31292 | V3: 1000 | W3: 0.030752221 | X3: 15.029525 | Y3: 59.992 | Z3: 10526.815 | AA3: 84570 | AB3: 326908 | AC3: 1.8250769 | AD3: 1749 | AE3: 1644.303 | AF3: 1054 | AG3: 483.45 | AH3: 1272 | AI3: 679 | AJ3: 374.749 | AK3: 107.86175 | AL3: Yes | AM3: No | AN3: 20230815j | AO3: Yes | AP3: 179120 | AQ3: 3.8655934 | AR3: 0.50861822 | AS3: 0.01564114 | AT3: 0.00097247062 | AU3: =B3/K3 -> 0.22757786 | AV3: =E3/K3 -> 0.77242214 | AW3: 0 | AX3: 0.0066097893 | AY3: 0.0064116901 | AZ3: 0.0068566737 | BA3: 0.022434289 | BB3: 0.020657368 | BC3: 0.02425424 | BD3: 0 | BE3: 0 | BF3: 0 | BG3: 0.029044079 | BH3: 0.028119418 | BI3: 0.029984709 | BJ3: 0.052859497 | BK3: -0.0021086043 | BL3: 0.0022676178 | BM3: 0.050750893 | BN3: 0.055127115 | BO3: 0.020178827 | BP3: 0.018961089 | BQ3: 0.021519496 | BR3: 0 | BS3: 0 | BT3: 0 | BU3: 0.0036365916 | BV3: 0.0029820052 | BW3: 0.0042911781 | BX3: 0.023815418 | BY3: 0.021943094 | BZ3: 0.025810674 | CA3: 0.0097644038 | CB3: 0.0091798962 | CC3: 0.83068004 | CD3: 46337 | CE3: 0.022746401 | CF3: 0.0057165662 | CG3: 0.010433347 | CH3: 448.58038 | CI3: 435.76148 | CJ3: 462.69336 | CK3: 448.58038 | CL3: 435.76148 | CM3: 462.69336 | CN3: 107.86175 | CO3: 99.910394 | CP3: 116.07432 | CQ3: Null | CR3: Null | CS3: Null | CT3: 102.22473 | CU3: 96.187212 | CV3: 108.96359 | CW3: 80.67663 | CX3: 74.18584 | CY3: 88.813901 | CZ3: 29.517409 | DA3: 21.726646 | DB3: 40.24946 | DC3: 0 | DD3: 0 | DE3: 0 | DF3: 0.80615799 | DG3: 0.80615799 | DH3: 0.19384201 | DI3: 0.4505417 | DJ3: 0.38174434 | DK3: 305.74163 | DL3: 3.6500974 | DM3: 0.22717946 | DN3: 0.011491852 | DO3: 0.9 | DP3: 17.326203 | DQ3: 0.042899306 | DR3: -0.039889736 | DS3: 0 | DT3: 0 | DU3: 0.0079571138 | DV3: 0.0077886365 | DW3: 0.0081416008 | DX3: 0.0065125 | DY3: 0.0074087833 | DZ3: 0.0056162167 | EA3: 236.70487 | EB3: 227.20281 | EC3: 246.43552 | ED3: 212.41877 | EE3: 212.41877 | EF3: 212.41877
A4: Permian_2020 | B4: 22.418627 | C4: 21.54058 | D4: 23.361923 | E4: 35.06961 | F4: 31.834884 | G4: 38.466001 | H4: 0 | I4: 0 | J4: 0 | K4: 57.488237 | L4: 54.024138 | M4: 60.921672 | N4: 60.225576 | O4: 53.956927 | P4: 67.829268 | Q4: 0 | R4: 16.369542 | S4: 134.08336 | T4: 123.91983 | U4: 145.34294 | V4: 1000 | W4: 0.052282299 | X4: 8.0919112 | Y4: 82.192 | Z4: 4766.5264 | AA4: 17120 | AB4: 48890 | AC4: 1.8250769 | AD4: 284 | AE4: 247.56 | AF4: 239 | AG4: 101.175 | AH4: 316 | AI4: 233 | AJ4: 121.254 | AK4: 38.788169 | AL4: Yes | AM4: No | AN4: 20230815j | AO4: Yes | AP4: 26787 | AQ4: 2.8557569 | AR4: 0.59175152 | AS4: 0.03093813 | AT4: 0.0016533115 | AU4: =B4/K4 -> 0.38996894 | AV4: =E4/K4 -> 0.61003106 | AW4: 0 | AX4: 0.0047033469 | AY4: 0.0043920489 | AZ4: 0.005037778 | BA4: 0.0073574774 | BB4: 0.006210655 | BC4: 0.0085616153 | BD4: 0 | BE4: 0 | BF4: 0 | BG4: 0.012060824 | BH4: 0.011334069 | BI4: 0.012781146 | BJ4: 0.028130203 | BK4: -0.0021322699 | BL4: 0.0023622194 | BM4: 0.025997933 | BN4: 0.030492423 | BO4: 0.012635108 | BP4: 0.011319968 | BQ4: 0.014230335 | BR4: 0 | BS4: 0 | BT4: 0 | BU4: 0.0034342708 | BV4: 0.002816102 | BW4: 0.0040524395 | BX4: 0.016069379 | BY4: 0.01413607 | BZ4: 0.018282775 | CA4: 0.010602158 | CB4: 0.0092417964 | CC4: 0.82852318 | CD4: 9380 | CE4: 0.025479744 | CF4: 0.0059097547 | CG4: 0.010786247 | CH4: 95.295187 | CI4: 89.026537 | CJ4: 102.89888 | CK4: 95.295187 | CL4: 89.026537 | CM4: 102.89888 | CN4: 38.788169 | CO4: 34.963605 | CP4: 42.677983 | CQ4: Null | CR4: Null | CS4: Null | CT4: 17.601996 | CU4: 13.22755 | CV4: 22.927495 | CW4: 33.473177 | CX4: 29.547449 | CY4: 37.755434 | CZ4: 9.0609697 | DA4: 6.6539509 | DB4: 11.686924 | DC4: 0.089432821 | DD4: 0.036510813 | DE4: 0.31173622 | DF4: 0.71071587 | DG4: 0.71071587 | DH4: 0.28928413 | DI4: 0.57124989 | DJ4: 0.44916475 | DK4: 57.488237 | DL4: 2.1245893 | DM4: 0.50815846 | DN4: 0.010661119 | DO4: 0.9 | DP4: 17.326203 | DQ4: 0.083975556 | DR4: -0.07579509 | DS4: 0 | DT4: 0 | DU4: 0.0056768084 | DV4: 0.0054097277 | DW4: 0.0059965985 | DX4: 0.0059587926 | DY4: 0.0068052114 | DZ4: 0.0051123738 | EA4: 35.573971 | EB4: 32.328174 | EC4: 38.957863 | ED4: 60.225576 | EE4: 60.225576 | EF4: 60.225576
A5: Permian_summer2021 | B5: 27.934123 | C5: 27.216176 | D5: 28.726177 | E5: 37.160026 | F5: 34.012259 | G5: 40.762672 | H5: 0 | I5: 0 | J5: 0 | K5: 65.094149 | L5: 61.848884 | M5: 68.769617 | N5: 45.0828 | O5: 41.187588 | P5: 49.250154 | Q5: 0 | R5: 20.435387 | S5: 130.61234 | T5: 121.88537 | U5: 139.57285 | V5: 1000 | W5: 0.047531726 | X5: 11.813408 | Y5: 68.158 | Z5: 5950.4297 | AA5: 19040 | AB5: 91907 | AC5: 1.8250769 | AD5: 416 | AE5: 360.723 | AF5: 296 | AG5: 124.728 | AH5: 477 | AI5: 232 | AJ5: 125.094 | AK5: 48.36951 | AL5: Yes | AM5: No | AN5: 20230815j | AO5: Yes | AP5: 50357 | AQ5: 4.8271664 | AR5: 0.45514928 | AS5: 0.021634031 | AT5: 0.0015030852 | AU5: =B5/K5 -> 0.42913416 | AV5: =E5/K5 -> 0.57086584 | AW5: 0 | AX5: 0.0046944716 | AY5: 0.0044293834 | AZ5: 0.0049869224 | BA5: 0.0062449315 | BB5: 0.0050826794 | BC5: 0.007575139 | BD5: 0 | BE5: 0 | BF5: 0 | BG5: 0.010939403 | BH5: 0.01039402 | BI5: 0.011557084 | BJ5: 0.021950068 | BK5: -0.0014666118 | BL5: 0.0015058601 | BM5: 0.020483456 | BN5: 0.023455928 | BO5: 0.007576394 | BP5: 0.0069217838 | BQ5: 0.0082767391 | BR5: 0 | BS5: 0 | BT5: 0 | BU5: 0.0034342708 | BV5: 0.002816102 | BW5: 0.0040524395 | BX5: 0.011010665 | BY5: 0.0097378858 | BZ5: 0.012329179 | CA5: 0.0082610163 | CB5: 0.0071633139 | CC5: 0.80404036 | CD5: 10432 | CE5: 0.028374233 | CF5: 0.0065508403 | CG5: 0.011956288 | CH5: 82.242826 | CI5: 78.347614 | CJ5: 86.41018 | CK5: 82.242826 | CL5: 78.347614 | CM5: 86.41018 | CN5: 48.36951 | CO5: 43.973193 | CP5: 52.839934 | CQ5: Null | CR5: Null | CS5: Null | CT5: 12.902514 | CU5: 11.368935 | CV5: 14.719217 | CW5: 25.131574 | CX5: 22.254505 | CY5: 28.484006 | CZ5: 7.048712 | DA5: 5.4584397 | DB5: 8.9005072 | DC5: 0 | DD5: 0 | DE5: 0 | DF5: 0.62967063 | DG5: 0.62967063 | DH5: 0.37032937 | DI5: 0.50162406 | DJ5: 0.34516512 | DK5: 65.094149 | DL5: 1.8736485 | DM5: 0.57040162 | DN5: 0.010661119 | DO5: 0.9 | DP5: 17.326203 | DQ5: 0.068597696 | DR5: -0.066816488 | DS5: 0 | DT5: 0 | DU5: 0.005838681 | DV5: 0.005668303 | DW5: 0.0060558166 | DX5: 0.0059587926 | DY5: 0.0068052114 | DZ5: 0.0051123738 | EA5: 37.770042 | EB5: 34.617556 | EC5: 41.375723 | ED5: 45.0828 | EE5: 45.0828 | EF5: 45.0828
A6: Permian_fall2021 | B6: 30.380379 | C6: 29.622945 | D6: 31.1051 | E6: 35.225184 | F6: 31.686307 | G6: 39.223327 | H6: 0 | I6: 0 | J6: 0 | K6: 65.605564 | L6: 62.042179 | M6: 69.658255 | N6: 44.058223 | O6: 39.430739 | P6: 49.400636 | Q6: 0 | R6: 21.388092 | S6: 131.05188 | T6: 121.10926 | U6: 141.60052 | V6: 1000 | W6: 0.055525155 | X6: 23.348039 | Y6: 78.553 | Z6: 6227.8408 | AA6: 19670 | AB6: 94306 | AC6: 1.8250769 | AD6: 334 | AE6: 274.453 | AF6: 232 | AG6: 92.758 | AH6: 368 | AI6: 179 | AJ6: 91.007 | AK6: 51.768471 | AL6: Yes | AM6: No | AN6: 20230815j | AO6: Yes | AP6: 51672 | AQ6: 4.7946553 | AR6: 0.45668979 | AS6: 0.025357771 | AT6: 0.0017558596 | AU6: =B6/K6 -> 0.46307626 | AV6: =E6/K6 -> 0.53692374 | AW6: 0 | AX6: 0.004878156 | AY6: 0.0046118469 | AZ6: 0.0051329633 | BA6: 0.005656083 | BB6: 0.0044118358 | BC6: 0.0070618049 | BD6: 0 | BE6: 0 | BF6: 0 | BG6: 0.010534239 | BH6: 0.0099620689 | BI6: 0.011184977 | BJ6: 0.021042907 | BK6: -0.0015964791 | BL6: 0.0016937872 | BM6: 0.019446428 | BN6: 0.022736695 | BO6: 0.0070743977 | BP6: 0.0063313658 | BQ6: 0.0079322252 | BR6: 0 | BS6: 0 | BT6: 0 | BU6: 0.0034342708 | BV6: 0.002816102 | BW6: 0.0040524395 | BX6: 0.010508668 | BY6: 0.0091474679 | BZ6: 0.011984665 | CA6: 0.0064638489 | CB6: 0.0053114453 | CC6: 0.82791961 | CD6: 10777 | CE6: 0.021527327 | CF6: 0.0047157092 | CG6: 0.0086070335 | CH6: 79.283407 | CI6: 74.655923 | CJ6: 84.625821 | CK6: 79.283407 | CL6: 74.655923 | CM6: 84.625821 | CN6: 51.768471 | CO6: 47.16118 | CP6: 56.343048 | CQ6: Null | CR6: Null | CS6: Null | CT6: 6.8500923 | CU6: 6.0282531 | CV6: 7.7161175 | CW6: 27.270887 | CX6: 23.458161 | CY6: 31.548215 | CZ6: 9.9372431 | DA6: 7.3995793 | DB6: 13.087737 | DC6: 0 | DD6: 0 | DE6: 0 | DF6: 0.60497608 | DG6: 0.60497608 | DH6: 0.39502392 | DI6: 0.49939238 | DJ6: 0.33618859 | DK6: 65.605564 | DL6: 1.787872 | DM6: 0.5778826 | DN6: 0.010661119 | DO6: 0.9 | DP6: 17.326203 | DQ6: 0.080491867 | DR6: -0.07587247 | DS6: 0 | DT6: 0 | DU6: 0.0058921178 | DV6: 0.0057140848 | DW6: 0.0061175685 | DX6: 0.0059587926 | DY6: 0.0068052114 | DZ6: 0.0051123738 | EA6: 35.836546 | EB6: 32.260772 | EC6: 39.81077 | ED6: 44.058223 | EE6: 44.058223 | EF6: 44.058223
A7: San_Joaquin_2016 | B7: 2.5786294 | C7: 2.4625641 | D7: 2.6955783 | E7: 2.3753053 | F7: 1.6435167 | G7: 3.2646716 | H7: 0 | I7: 0 | J7: 0 | K7: 4.9539347 | L7: 4.2155634 | M7: 5.8578011 | N7: 4.7790585 | O7: 3.6709295 | P7: 6.2204779 | Q7: 0 | R7: 1.1897866 | S7: 10.92278 | T7: 9.3560896 | U7: 12.75963 | V7: 1000 | W7: 0.10083074 | X7: 9 | Y7: 40.093 | Z7: 264.97396 | AA7: 41547 | AB7: 81234 | AC7: 1.7471737 | AD7: 77 | AE7: 69.083 | AF7: 40 | AG7: 15.06 | AH7: 48 | AI7: 36 | AJ7: 18.156 | AK7: 3.768416 | AL7: Yes | AM7: No | AN7: 20230815j | AO7: Yes | AP7: 46494 | AQ7: 1.9552546 | AR7: 0.71515197 | AS7: 0.072109302 | AT7: 0.003188548 | AU7: =B7/K7 -> 0.52052147 | AV7: =E7/K7 -> 0.47947853 | AW7: 0 | AX7: 0.0097316334 | AY7: 0.0091191406 | AZ7: 0.010348789 | BA7: 0.0089642973 | BB7: 0.0051025475 | BC7: 0.013657606 | BD7: 0 | BE7: 0 | BF7: 0 | BG7: 0.018695931 | BH7: 0.01590935 | BI7: 0.022107082 | BJ7: 0.041222088 | BK7: -0.0059126194 | BL7: 0.0069321914 | BM7: 0.035309469 | BN7: 0.04815428 | BO7: 0.018035955 | BP7: 0.013853926 | BQ7: 0.023475809 | BR7: 0 | BS7: 0 | BT7: 0 | BU7: 0.004490202 | BV7: 0.0036819657 | BW7: 0.0052984384 | BX7: 0.022526157 | BY7: 0.017535892 | BZ7: 0.028774247 | CA7: 0.0016561277 | CB7: 0.0014858476 | CC7: 0.98844576 | CD7: 23779 | CE7: 0.0016821565 | CF7: 0.00036248105 | CG7: 0.00063333193 | CH7: 7.1543638 | CI7: 6.0462349 | CJ7: 8.5957832 | CK7: 7.1543638 | CL7: 6.0462349 | CM7: 8.5957832 | CN7: 3.768416 | CO7: 3.4381891 | CP7: 4.0995264 | CQ7: Null | CR7: Null | CS7: Null | CT7: 1.8744095 | CU7: 1.2774239 | CV7: 2.5158976 | CW7: 0 | CX7: 0 | CY7: 0 | CZ7: 0.76594244 | DA7: 0.53845299 | DB7: 1.0601965 | DC7: 1.8197725 | DD7: 1.0127034 | DE7: 3.1629884 | DF7: 0.65499014 | DG7: 0.65499014 | DH7: 0.34500986 | DI7: 0.54645794 | DJ7: 0.43752954 | DK7: 4.9539347 | DL7: 1.8989686 | DM7: 0.011143192 | DN7: 0.057351807 | DO7: 0.9 | DP7: 17.326203 | DQ7: 0.16816245 | DR7: -0.14341434 | DS7: 0 | DT7: 0 | DU7: 0.0098454149 | DV7: 0.0093884916 | DW7: 0.010321626 | DX7: 0.051203662 | DY7: 0.052310328 | DZ7: 0.050096995 | EA7: 2.3934668 | EB7: 1.6638554 | EC7: 3.2925485 | ED7: 4.7790585 | EE7: 4.7790585 | EF7: 4.7790585
A8: San_Joaquin_2017 | B8: 2.6738462 | C8: 2.59204 | D8: 2.7619707 | E8: 4.4850098 | F8: 3.7496228 | G8: 5.3525914 | H8: 0 | I8: 0 | J8: 0 | K8: 7.158856 | L8: 6.4174512 | M8: 8.0364765 | N8: 7.420913 | O8: 6.1701771 | P8: 8.8715321 | Q8: 0 | R8: 1.2427775 | S8: 15.822547 | T8: 14.081623 | U8: 17.66552 | V8: 1000 | W8: 0.11593182 | X8: 11 | Y8: 41.571 | Z8: 284.66581 | AA8: 40365 | AB8: 192459 | AC8: 1.7471737 | AD8: 86 | AE8: 80.167 | AF8: 54 | AG8: 15.926 | AH8: 144 | AI8: 89 | AJ8: 25.256 | AK8: 3.9166237 | AL8: Yes | AM8: No | AN8: 20230815j | AO8: Yes | AP8: 110154 | AQ8: 4.7679522 | AR8: 0.45796686 | AS8: 0.05309293 | AT8: 0.0036660859 | AU8: =B8/K8 -> 0.37350188 | AV8: =E8/K8 -> 0.62649812 | AW8: 0 | AX8: 0.0093929305 | AY8: 0.0087654257 | AZ8: 0.0100689 | BA8: 0.015755351 | BB8: 0.010114475 | BC8: 0.022410242 | BD8: 0 | BE8: 0 | BF8: 0 | BG8: 0.025148281 | BH8: 0.022543807 | BI8: 0.028231267 | BJ8: 0.055582883 | BK8: -0.006115675 | BL8: 0.006474164 | BM8: 0.049467208 | BN8: 0.062057047 | BO8: 0.026068859 | BP8: 0.02167516 | BQ8: 0.031164726 | BR8: 0 | BS8: 0 | BT8: 0 | BU8: 0.0043657419 | BV8: 0.0035799084 | BW8: 0.0051515755 | BX8: 0.030434601 | BY8: 0.025255069 | BZ8: 0.036316302 | CA8: 0.00078072517 | CB8: 0.00072777203 | CC8: 0.9841056 | CD8: 23103 | CE8: 0.0023373588 | CF8: 0.00039454973 | CG8: 0.0006893477 | CH8: 11.905923 | CI8: 10.655187 | CJ8: 13.356542 | CK8: 11.905923 | CL8: 10.655187 | CM8: 13.356542 | CN8: 3.9166237 | CO8: 3.6111175 | CP8: 4.2284481 | CQ8: Null | CR8: Null | CS8: Null | CT8: 2.4012658 | CU8: 1.7192153 | CV8: 3.3039107 | CW8: 0 | CX8: 0 | CY8: 0 | CZ8: 0.13683804 | DA8: 0.074170753 | DB8: 0.46361156 | DC8: 4.2485882 | DD8: 3.3414871 | DE8: 5.5716504 | DF8: 0.75246435 | DG8: 0.75246435 | DH8: 0.24753565 | DI8: 0.54755131 | DJ8: 0.46900604 | DK8: 7.158856 | DL8: 2.6348455 | DM8: 0.012321595 | DN8: 0.054455461 | DO8: 0.9 | DP8: 17.326203 | DQ8: 0.11645967 | DR8: -0.11002947 | DS8: 0 | DT8: 0 | DU8: 0.0095446349 | DV8: 0.0092493407 | DW8: 0.0098772482 | DX8: 0.048477731 | DY8: 0.049553722 | DZ8: 0.047401739 | EA8: 4.487298 | EB8: 3.7515272 | EC8: 5.3565463 | ED8: 7.420913 | EE8: 7.420913 | EF8: 7.420913
A9: San_Joaquin_summer2020 | B9: 1.8129082 | C9: 1.764809 | D9: 1.8677498 | E9: 3.8390357 | F9: 3.1488634 | G9: 4.6782201 | H9: 0 | I9: 0 | J9: 0 | K9: 5.6519439 | L9: 4.954928 | M9: 6.4950692 | N9: 4.1744364 | O9: 3.5147462 | P9: 5.0413469 | Q9: 0 | R9: 0.87037445 | S9: 10.696755 | T9: 9.5587843 | U9: 11.992815 | V9: 1000 | W9: 0.14375971 | X9: 23.632192 | Y9: 36.04 | Z9: 231.42089 | AA9: 31919 | AB9: 238393 | AC9: 1.995878 | AD9: 94 | AE9: 90.481 | AF9: 39 | AG9: 13.316 | AH9: 151 | AI9: 65 | AJ9: 16.923 | AK9: 2.6832826 | AL9: Yes | AM9: No | AN9: 20230815j | AO9: Yes | AP9: 119442 | AQ9: 7.4688594 | AR9: 0.3659088 | AS9: 0.052602945 | AT9: 0.0045460813 | AU9: =B9/K9 -> 0.32075835 | AV9: =E9/K9 -> 0.67924165 | AW9: 0 | AX9: 0.0078338141 | AY9: 0.0072657954 | AZ9: 0.0084814552 | BA9: 0.016588977 | BB9: 0.0084385163 | BC9: 0.026499167 | BD9: 0 | BE9: 0 | BF9: 0 | BG9: 0.024422791 | BH9: 0.021410894 | BI9: 0.028066046 | BJ9: 0.04622208 | BK9: -0.0049173195 | BL9: 0.0056004471 | BM9: 0.04130476 | BN9: 0.051822527 | BO9: 0.018038287 | BP9: 0.015187679 | BQ9: 0.021784321 | BR9: 0 | BS9: 0 | BT9: 0 | BU9: 0.0037610021 | BV9: 0.0030840217 | BW9: 0.0044379825 | BX9: 0.021799289 | BY9: 0.018271701 | BZ9: 0.026222304 | CA9: 0.00078699285 | CB9: 0.00075753085 | CC9: 0.98453792 | CD9: 15992 | CE9: 0.0024387194 | CF9: 0.00041718099 | CG9: 0.00083266633 | CH9: 8.0134721 | CI9: 7.353782 | CJ9: 8.8803826 | CK9: 8.0134721 | CL9: 7.353782 | CM9: 8.8803826 | CN9: 2.6832826 | CO9: 2.478516 | CP9: 2.8947916 | CQ9: Null | CR9: Null | CS9: Null | CT9: 3.5507971 | CU9: 2.9860522 | CV9: 4.2293741 | CW9: 0.53065559 | CX9: 0.35326015 | CY9: 1.2350055 | CZ9: 0.018424458 | DA9: 0.011470981 | DB9: 0.081021726 | DC9: 0.074559245 | DD9: 0.047277361 | DE9: 0.24669531 | DF9: 0.7491447 | DG9: 0.7491447 | DH9: 0.2508553 | DI9: 0.47162395 | DJ9: 0.39025379 | DK9: 5.6519439 | DL9: 3.0694221 | DM9: 0.014471041 | DN9: 0.061625508 | DO9: 0.9 | DP9: 17.326203 | DQ9: 0.12113414 | DR9: -0.10637622 | DS9: 0 | DT9: 0 | DU9: 0.0079568373 | DV9: 0.0077383942 | DW9: 0.0082181918 | DX9: 0.056475809 | DY9: 0.057402754 | DZ9: 0.055548863 | EA9: 3.8364016 | EB9: 3.145006 | EC9: 4.6792194 | ED9: 4.1744364 | EE9: 4.1744364 | EF9: 4.1744364
A10: San_Joaquin_fall2020 | B10: 1.8940764 | C10: 1.8478948 | D10: 1.945551 | E10: 2.5830142 | F10: 1.9634269 | G10: 3.4360583 | H10: 0 | I10: 0 | J10: 0 | K10: 4.4770906 | L10: 3.8522785 | M10: 5.3324641 | N10: 3.8266225 | O10: 2.9742498 | P10: 5.0812801 | Q10: 0 | R10: 0.92232287 | S10: 9.226036 | T10: 7.9750556 | U10: 10.849985 | V10: 1000 | W10: 0.19681256 | X10: 20.646402 | Y10: 39.525 | Z10: 245.23328 | AA10: 33090 | AB10: 238974 | AC10: 1.995878 | AD10: 48 | AE10: 45.291 | AF10: 27 | AG10: 8.083 | AH10: 63 | AI10: 34 | AJ10: 9.256 | AK10: 2.8163993 | AL10: Yes | AM10: No | AN10: 20230815j | AO10: Yes | AP10: 119733 | AQ10: 7.2219675 | AR10: 0.37211076 | AS10: 0.073236072 | AT10: 0.0062237596 | AU10: =B10/K10 -> 0.42305965 | AV10: =E10/K10 -> 0.57694035 | AW10: 0 | AX10: 0.00772357 | AY10: 0.0072174921 | AZ10: 0.0082876514 | BA10: 0.010532886 | BB10: 0.0037431812 | BC10: 0.019880911 | BD10: 0 | BE10: 0 | BF10: 0 | BG10: 0.018256456 | BH10: 0.015708629 | BI10: 0.021744456 | BJ10: 0.037621469 | BK10: -0.0051011852 | BL10: 0.0066220591 | BM10: 0.032520283 | BN10: 0.044243528 | BO10: 0.01560401 | BP10: 0.012128247 | BQ10: 0.02072019 | BR10: 0 | BS10: 0 | BT10: 0 | BU10: 0.0037610021 | BV10: 0.0030840217 | BW10: 0.0044379825 | BX10: 0.019365012 | BY10: 0.015212269 | BZ10: 0.025158172 | CA10: 0.00040089198 | CB10: 0.00037826664 | CC10: 0.98765233 | CD10: 16579 | CE10: 0.0016285663 | CF10: 0.00024427319 | CG10: 0.00048754448 | CH10: 6.4096367 | CI10: 5.557264 | CJ10: 7.6642943 | CK10: 6.4096367 | CL10: 5.557264 | CM10: 7.6642943 | CN10: 2.8163993 | CO10: 2.6041995 | CP10: 3.033892 | CQ10: Null | CR10: Null | CS10: Null | CT10: 2.9139611 | CU10: 2.2312743 | CV10: 3.8446759 | CW10: 0.68784333 | CX10: 0.43188942 | CY10: 1.6933961 | CZ10: 0.22481801 | DA10: 0.15575801 | DB10: 0.28740109 | DC10: 0 | DD10: 0 | DE10: 0 | DF10: 0.69471808 | DG10: 0.69471808 | DH10: 0.30528192 | DI10: 0.51473029 | DJ10: 0.41475641 | DK10: 4.4770906 | DL10: 2.3345778 | DM10: 0.014791801 | DN10: 0.061625508 | DO10: 0.9 | DP10: 17.326203 | DQ10: 0.17606106 | DR10: -0.1355664 | DS10: 0 | DT10: 0 | DU10: 0.0078201421 | DV10: 0.0076168605 | DW10: 0.0080565944 | DX10: 0.056475809 | DY10: 0.057402754 | DZ10: 0.055548863 | EA10: 2.5787796 | EB10: 1.9563801 | EC10: 3.4320675 | ED10: 3.8266225 | EE10: 3.8266225 | EF10: 3.8266225
A11: San_Joaquin_fall2021 | B11: 1.7289646 | C11: 1.6668152 | D11: 1.7969909 | E11: 1.742841 | F11: 1.3037721 | G11: 2.2675445 | H11: 0 | I11: 0 | J11: 0 | K11: 3.4718056 | L11: 3.0245577 | M11: 3.9939014 | N11: 0.78305004 | O11: 0.53935306 | P11: 1.0403486 | Q11: 0 | R11: 0.74474802 | S11: 4.9996037 | T11: 4.3676606 | U11: 5.7445127 | V11: 1000 | W11: 0.11192146 | X11: 15.95883 | Y11: 22.967 | Z11: 198.01851 | AA11: 33418 | AB11: 119340 | AC11: 1.995878 | AD11: 47 | AE11: 41.278 | AF11: 35 | AG11: 15.732 | AH11: 17 | AI11: 12 | AJ11: 6.294 | AK11: 2.4737126 | AL11: Yes | AM11: No | AN11: 20230815j | AO11: Yes | AP11: 59793 | AQ11: 3.5712238 | AR11: 0.52916543 | AS11: 0.05922497 | AT11: 0.0035392675 | AU11: =B11/K11 -> 0.49800155 | AV11: =E11/K11 -> 0.50199845 | AW11: 0 | AX11: 0.0087313283 | AY11: 0.0081382126 | AZ11: 0.00938053 | BA11: 0.0088014048 | BB11: 0.0046111984 | BC11: 0.013808856 | BD11: 0 | BE11: 0 | BF11: 0 | BG11: 0.017532733 | BH11: 0.015274116 | BI11: 0.020169334 | BJ11: 0.025248164 | BK11: -0.0031913333 | BL11: 0.0037618153 | BM11: 0.022056831 | BN11: 0.029009979 | BO11: 0.0039544286 | BP11: 0.0027237508 | BQ11: 0.0052537949 | BR11: 0 | BS11: 0 | BT11: 0 | BU11: 0.0037610021 | BV11: 0.0030840217 | BW11: 0.0044379825 | BX11: 0.0077154307 | BY11: 0.0058077725 | BZ11: 0.0096917774 | CA11: 0.00078604519 | CB11: 0.00069034837 | CC11: 0.96016776 | CD11: 16743 | CE11: 0.0020904258 | CF11: 0.00047076426 | CG11: 0.00093961656 | CH11: 2.5258911 | CI11: 2.2821941 | CJ11: 2.7831896 | CK11: 2.5258911 | CL11: 2.2821941 | CM11: 2.7831896 | CN11: 2.4737126 | CO11: 2.2775086 | CP11: 2.6757936 | CQ11: Null | CR11: Null | CS11: Null | CT11: 0.53186871 | CU11: 0.35924908 | CV11: 0.75512912 | CW11: 0.25118133 | CX11: 0.12527535 | CY11: 0.41111972 | CZ11: 0 | DA11: 0 | DB11: 0 | DC11: 0 | DD11: 0 | DE11: 0 | DF11: 0.50520963 | DG11: 0.50520963 | DH11: 0.49479037 | DI11: 0.30558614 | DJ11: 0.15662152 | DK11: 3.4718056 | DL11: 1.9280619 | DM11: 0.011826943 | DN11: 0.061625508 | DO11: 0.9 | DP11: 17.326203 | DQ11: 0.14895133 | DR11: -0.12639244 | DS11: 0 | DT11: 0 | DU11: 0.0090935977 | DV11: 0.0087149042 | DW11: 0.0094851696 | DX11: 0.056475809 | DY11: 0.057402754 | DZ11: 0.055548863 | EA11: 1.7527287 | EB11: 1.3083655 | EC11: 2.2787194 | ED11: 0.78305004 | EE11: 0.78305004 | EF11: 0.78305004
A12: Denver_summer2021 | B12: 12.231211 | C12: 11.938716 | D12: 12.542433 | E12: 2.270036 | F12: 1.6445207 | G12: 3.0319765 | H12: 0 | I12: 0 | J12: 0 | K12: 14.501247 | L12: 13.761864 | M12: 15.305016 | N12: 0.69206906 | O12: 0.45026155 | P12: 1.033131 | Q12: 0 | R12: 6.246524 | S12: 21.43984 | T12: 19.523046 | U12: 23.400043 | V12: 1000 | W12: 0.046460142 | X12: 11.102345 | Y12: 75.256 | Z12: 1997.3945 | AA12: 11671 | AB12: 59356 | AC12: 1.6088026 | AD12: 34 | AE12: 27.18 | AF12: 27 | AG12: 8.472 | AH12: 24 | AI12: 9 | AJ12: 4.408 | AK12: 18.477735 | AL12: Yes | AM12: No | AN12: 20230815j | AO12: Yes | AP12: 36894 | AQ12: 5.0860215 | AR12: 0.44341553 | AS12: 0.020601149 | AT12: 0.0014691987 | AU12: =B12/K12 -> 0.84345925 | AV12: =E12/K12 -> 0.15654075 | AW12: 0 | AX12: 0.0061235828 | AY12: 0.0057933327 | AZ12: 0.0064749788 | BA12: 0.0011364986 | BB12: 0.00043024085 | BC12: 0.0019967914 | BD12: 0 | BE12: 0 | BF12: 0 | BG12: 0.0072600814 | BH12: 0.006889908 | BI12: 0.0076624904 | BJ12: 0.010733903 | BK12: -0.00095964717 | BL12: 0.00098138035 | BM12: 0.0097742563 | BN12: 0.011715284 | BO12: 0.00034648592 | BP12: 0.00022542445 | BQ12: 0.00051723935 | BR12: 0 | BS12: 0 | BT12: 0 | BU12: 0.0031273362 | BV12: 0.0025644157 | BW12: 0.0036902567 | BX12: 0.0034738221 | BY12: 0.0027898401 | BZ12: 0.004207496 | CA12: 0.00092155906 | CB12: 0.00073670516 | CC12: 0.9769196 | CD12: 7254 | CE12: 0.0037220844 | CF12: 0.00072590181 | CG12: 0.0011679074 | CH12: 2.9621051 | CI12: 2.7202975 | CJ12: 3.303167 | CK12: 2.9621051 | CL12: 2.7202975 | CM12: 3.303167 | CN12: 18.477735 | CO12: 17.060866 | CP12: 19.913332 | CQ12: Null | CR12: Null | CS12: Null | CT12: 0.21325536 | CU12: 0.12269682 | CV12: 0.40544493 | CW12: 0.25055746 | CX12: 0.13600658 | CY12: 0.4442458 | CZ12: 0.22825624 | DA12: 0.12595979 | DB12: 0.48481499 | DC12: 0 | DD12: 0 | DE12: 0 | DF12: 0.13815737 | DG12: 0.13815737 | DH12: 0.86184263 | DI12: 0.32363203 | DJ12: 0.032279504 | DK12: 14.501247 | DL12: 1.1582274 | DM12: 0.27535077 | DN12: 0.0097082922 | DO12: 0.9 | DP12: 17.326203 | DQ12: 0.091429317 | DR12: -0.089403224 | DS12: 0 | DT12: 0 | DU12: 0.0062682849 | DV12: 0.0061037267 | DW12: 0.0064419473 | DX12: 0.0054262314 | DY12: 0.0061970023 | DZ12: 0.0046554604 | EA12: 2.3137271 | EB12: 1.6887056 | EC12: 3.0717352 | ED12: 0.69206906 | EE12: 0.69206906 | EF12: 0.69206906
A13: Denver_fall2021 | B13: 12.325246 | C13: 12.044994 | D13: 12.599762 | E13: 2.2936579 | F13: 1.5677798 | G13: 3.222526 | H13: 0 | I13: 0 | J13: 0 | K13: 14.618904 | L13: 13.855272 | M13: 15.577143 | N13: 2.3243964 | O13: 1.5381348 | P13: 4.0793651 | Q13: 0 | R13: 6.1693766 | S13: 23.112677 | T13: 20.756346 | U13: 26.16947 | V13: 1000 | W13: 0.08924113 | X13: 10.160213 | Y13: 66.296 | Z13: 1972.7258 | AA13: 11688 | AB13: 67811 | AC13: 1.6088026 | AD13: 40 | AE13: 31.573 | AF13: 33 | AG13: 8.476 | AH13: 29 | AI13: 21 | AJ13: 7.105 | AK13: 18.494623 | AL13: Yes | AM13: No | AN13: 20230815j | AO13: Yes | AP13: 42149 | AQ13: 5.8016518 | AR13: 0.41516829 | AS13: 0.037050087 | AT13: 0.0028220523 | AU13: =B13/K13 -> 0.84310329 | AV13: =E13/K13 -> 0.15689671 | AW13: 0 | AX13: 0.0062478253 | AY13: 0.0059056428 | AZ13: 0.0065830049 | BA13: 0.0011626846 | BB13: 0.0002764009 | BC13: 0.0022968155 | BD13: 0 | BE13: 0 | BF13: 0 | BG13: 0.0074105099 | BH13: 0.007023415 | BI13: 0.0078962538 | BJ13: 0.011716112 | BK13: -0.0011944543 | BL13: 0.0015495279 | BM13: 0.010521658 | BN13: 0.01326564 | BO13: 0.0011782664 | BP13: 0.00077970029 | BQ13: 0.0020678825 | BR13: 0 | BS13: 0 | BT13: 0 | BU13: 0.0031273362 | BV13: 0.0025644157 | BW13: 0.0036902567 | BX13: 0.0043056025 | BY13: 0.0033441159 | BZ13: 0.0057581392 | CA13: 0.00094901421 | CB13: 0.00074908064 | CC13: 0.97362403 | CD13: 7265 | CE13: 0.0045423262 | CF13: 0.00072518823 | CG13: 0.0011666896 | CH13: 4.6180543 | CI13: 3.8317927 | CJ13: 6.3730229 | CK13: 4.6180543 | CL13: 3.8317927 | CM13: 6.3730229 | CN13: 18.494623 | CO13: 17.103883 | CP13: 19.879627 | CQ13: Null | CR13: Null | CS13: Null | CT13: 1.1496303 | CU13: 0.67234024 | CV13: 2.8163342 | CW13: 0.7503185 | CX13: 0.52286886 | CY13: 1.1166869 | CZ13: 0.42444766 | DA13: 0.24866864 | DB13: 0.69552513 | DC13: 0 | DD13: 0 | DE13: 0 | DF13: 0.19980274 | DG13: 0.19980274 | DH13: 0.80019726 | DI13: 0.36749659 | DJ13: 0.10056822 | DK13: 14.618904 | DL13: 1.1548135 | DM13: 0.2715383 | DN13: 0.0097082922 | DO13: 0.9 | DP13: 17.326203 | DQ13: 0.13225246 | DR13: -0.10194738 | DS13: 0 | DT13: 0 | DU13: 0.0064170869 | DV13: 0.0062580725 | DW13: 0.0065783542 | DX13: 0.0054262314 | DY13: 0.0061970023 | DZ13: 0.0046554604 | EA13: 2.3568777 | EB13: 1.6279208 | EC13: 3.2850411 | ED13: 2.3243964 | EE13: 2.3243964 | EF13: 2.3243964
A14: Pennsylvania_2021 | B14: 11.885117 | C14: 11.385451 | D14: 12.398218 | E14: 38.544969 | F14: 32.880604 | G14: 45.144812 | H14: 0 | I14: 0 | J14: 0 | K14: 50.430085 | L14: 44.761295 | M14: 57.06807 | N14: 7.8602057 | O14: 5.7011458 | P14: 10.21195 | Q14: 0 | R14: 18.142916 | S14: 76.433207 | T14: 67.117503 | U14: 86.31827 | V14: 1000 | W14: 0.057925134 | X14: 92.241416 | Y14: 117.519 | Z14: 10242.48 | AA14: 16105 | AB14: 27797 | AC14: 1.2580446 | AD14: 64 | AE14: 62 | AF14: 43 | AG14: 29.518 | AH14: 23 | AI14: 17 | AJ14: 11.584 | AK14: 30.028032 | AL14: Yes | AM14: No | AN14: 20230815j | AO14: Yes | AP14: 22095 | AQ14: 1.726037 | AR14: 0.76115823 | AS14: 0.044090192 | AT14: 0.0018317536 | AU14: =B14/K14 -> 0.23567513 | AV14: =E14/K14 -> 0.76432487 | AW14: 0 | AX14: 0.0011603749 | AY14: 0.0010962835 | AZ14: 0.0012261897 | BA14: 0.0037632457 | BB14: 0.0030366863 | BC14: 0.0046097975 | BD14: 0 | BE14: 0 | BF14: 0 | BG14: 0.0049236206 | BH14: 0.0043701618 | BI14: 0.0055717043 | BJ14: 0.007462373 | BK14: -0.00090951641 | BL14: 0.00096510449 | BM14: 0.0065528566 | BN14: 0.0084274775 | BO14: 0.00076741235 | BP14: 0.00055661771 | BQ14: 0.00099701927 | BR14: 0 | BS14: 0 | BT14: 0 | BU14: 0.0017713401 | BV14: 0.0014524989 | BW14: 0.0020901813 | BX14: 0.0025387524 | BY14: 0.0020091166 | BZ14: 0.0030872006 | CA14: 0.0028965829 | CB14: 0.0028060647 | CC14: 0.99462558 | CD14: 12801 | CE14: 0.0033591126 | CF14: 0.0018328469 | CG14: 0.0023059136 | CH14: 46.405174 | CI14: 44.246114 | CJ14: 48.756919 | CK14: 46.405174 | CL14: 44.246114 | CM14: 48.756919 | CN14: 30.028032 | CO14: 26.262642 | CP14: 33.806859 | CQ14: Null | CR14: Null | CS14: Null | CT14: 1.3812545 | CU14: 0.50684294 | CV14: 2.3884464 | CW14: 6.3743316 | CX14: 4.4725952 | CY14: 8.4286312 | CZ14: 0.10461956 | DA14: 0.024987521 | DB14: 0.39051931 | DC14: 0 | DD14: 0 | DE14: 0 | DF14: 0.60713254 | DG14: 0.60713254 | DH14: 0.39286746 | DI14: 0.34020763 | DJ14: 0.10283718 | DK14: 50.430085 | DL14: 4.2203797 | DM14: 0.80013124 | DN14: 0.0054988291 | DO14: 0.9 | DP14: 17.326203 | DQ14: 0.12932996 | DR14: -0.12188068 | DS14: 0 | DT14: 0 | DU14: 0.0011666454 | DV14: 0.0011155753 | DW14: 0.0012227046 | DX14: 0.0030734467 | DY14: 0.0035100156 | DZ14: 0.0026368779 | EA14: 38.516625 | EB14: 32.706724 | EC14: 45.16276 | ED14: 7.8602057 | EE14: 7.8602057 | EF14: 7.8602057
A15: Uinta_2020 | B15: 10.53272 | C15: 10.270858 | D15: 10.811015 | E15: 5.9004589 | F15: 4.7390936 | G15: 7.0531675 | H15: 0 | I15: 0 | J15: 0 | K15: 16.433179 | L15: 15.248982 | M15: 17.65356 | N15: 2.3542205 | O15: 1.7154669 | P15: 3.1768716 | Q15: 0 | R15: 1.3191311 | S15: 20.10653 | T15: 18.483144 | U15: 21.786348 | V15: 1000 | W15: 0.069309834 | X15: 8.3545392 | Y15: 52.054 | Z15: 350.73927 | AA15: 9185 | AB15: 32340 | AC15: 1.7099474 | AD15: 56 | AE15: 41.451 | AF15: 42 | AG15: 24.919 | AH15: 52 | AI15: 25 | AJ15: 16.324 | AK15: 11.851851 | AL15: Yes | AM15: No | AN15: 20230815j | AO15: Yes | AP15: 18912 | AQ15: 3.521132 | AR15: 0.53291611 | AS15: 0.036936327 | AT15: 0.0021917694 | AU15: =B15/K15 -> 0.64094233 | AV15: =E15/K15 -> 0.35905767 | AW15: 0 | AX15: 0.030030056 | AY15: 0.028629088 | AZ15: 0.031518946 | BA15: 0.016822921 | BB15: 0.010609574 | BC15: 0.022989954 | BD15: 0 | BE15: 0 | BF15: 0 | BG15: 0.046852976 | BH15: 0.04347669 | BI15: 0.05033243 | BJ15: 0.057326145 | BK15: -0.0046284693 | BL15: 0.0047893635 | BM15: 0.052697676 | BN15: 0.062115509 | BO15: 0.0067121669 | BP15: 0.0048910034 | BQ15: 0.0090576446 | BR15: 0 | BS15: 0 | BT15: 0 | BU15: 0.0037610021 | BV15: 0.0030840217 | BW15: 0.0044379825 | BX15: 0.010473169 | BY15: 0.0079750251 | BZ15: 0.013495627 | CA15: 0.0029610829 | CB15: 0.002191783 | CC15: 0.94730616 | CD15: 5371 | CE15: 0.0078197729 | CF15: 0.0027130103 | CG15: 0.0046395457 | CH15: 8.2546794 | CI15: 7.6159258 | CJ15: 9.0773305 | CK15: 8.2546794 | CL15: 7.6159258 | CM15: 9.0773305 | CN15: 11.851851 | CO15: 11.352546 | CP15: 12.36759 | CQ15: Null | CR15: Null | CS15: Null | CT15: 1.804398 | CU15: 1.2920157 | CV15: 2.4430816 | CW15: 0.26491334 | CX15: 0.15337398 | CY15: 0.43004633 | CZ15: 0.28490917 | DA15: 0.13307648 | DB15: 0.84249828 | DC15: 0 | DD15: 0 | DE15: 0 | DF15: 0.41054397 | DG15: 0.41054397 | DH15: 0.58945603 | DI15: 0.18269415 | DJ15: 0.11708599 | DK15: 16.433179 | DL15: 1.4779899 | DM15: 0.065302414 | DN15: 0.024005542 | DO15: 0.9 | DP15: 17.326203 | DQ15: 0.083545415 | DR15: -0.080746109 | DS15: 0 | DT15: 0 | DU15: 0.031700608 | DV15: 0.030731271 | DW15: 0.032851578 | DX15: 0.018855842 | DY15: 0.019782788 | DZ15: 0.017928897 | EA15: 6.0334886 | EB15: 4.8731954 | EC15: 7.197444 | ED15: 2.3542205 | EE15: 2.3542205 | EF15: 2.3542205
A16: Fort_Worth_2021 | B16: 3.4353186 | C16: 3.1649515 | D16: 3.6990699 | E16: 10.208639 | F16: 8.8098415 | G16: 11.920752 | H16: 2.0963499 | I16: 1.5200698 | J16: 2.7806441 | K16: 15.740307 | L16: 14.133997 | M16: 17.582245 | N16: 1.7197543 | O16: 1.4082262 | P16: 2.0583191 | Q16: 1.9173475 | R16: 2.1864876 | S16: 21.563897 | T16: 19.44596 | U16: 23.917269 | V16: 1000 | W16: 0.058670259 | X16: 6.5248199 | Y16: 45.425 | Z16: 636.66722 | AA16: 7474 | AB16: 12982 | AC16: 1.6224651 | AD16: 80 | AE16: 79.98 | AF16: 49 | AG16: 40.022 | AH16: 49 | AI16: 23 | AJ16: 20.169 | AK16: 5.6218062 | AL16: Yes | AM16: No | AN16: 20230815j | AO16: Yes | AP16: 8001 | AQ16: 1.7370821 | AR16: 0.7587345 | AS16: 0.044515149 | AT16: 0.0018553165 | AU16: =B16/K16 -> 0.21824978 | AV16: =E16/K16 -> 0.64856668 | AW16: 0.095694459 | AX16: 0.0053957837 | AY16: 0.0048360887 | AZ16: 0.0059417834 | BA16: 0.016034497 | BB16: 0.013138805 | BC16: 0.019578794 | BD16: 0.0032926933 | BE16: 0.0020997185 | BF16: 0.0047092715 | BG16: 0.024722974 | BH16: 0.022199977 | BI16: 0.027616067 | BJ16: 0.033869965 | BK16: -0.003326599 | BL16: 0.0036963932 | BM16: 0.030543366 | BN16: 0.037566359 | BO16: 0.0027011824 | BP16: 0.0022118717 | BQ16: 0.0032329591 | BR16: 0.0030115379 | BS16: 0.0023741141 | BT16: 0.0037230439 | BU16: 0.0034342708 | BV16: 0.002816102 | BW16: 0.0040524395 | BX16: 0.009146991 | BY16: 0.0076667894 | BZ16: 0.010710913 | CA16: 0.0099987502 | CB16: 0.0099962505 | CC16: 0.97283619 | CD16: 4606 | CE16: 0.010638298 | CF16: 0.0053548301 | CG16: 0.0086891012 | CH16: 11.928393 | CI16: 11.616865 | CJ16: 12.266958 | CK16: 13.845741 | CL16: 13.128386 | CM16: 14.637298 | CN16: 5.6218062 | CO16: 4.9578714 | CP16: 6.2791253 | CQ16: Null | CR16: Null | CS16: Null | CT16: 0.68601512 | CU16: 0.54091128 | CV16: 0.83351701 | CW16: 0.63557155 | CX16: 0.42419222 | CY16: 0.9021843 | CZ16: 0.39816759 | DA16: 0.22609926 | DB16: 0.56171741 | DC16: Null | DD16: Null | DE16: Null | DF16: 0.55316468 | DG16: 0.64207943 | DH16: 0.26070437 | DI16: 0.27006235 | DJ16: 0.079751579 | DK16: 15.740307 | DL16: 4.4574934 | DM16: 0.13822562 | DN16: 0.010661119 | DO16: 0.9 | DP16: 17.326203 | DQ16: 0.10912855 | DR16: -0.098216044 | DS16: 0.097216203 | DT16: 0.07790393 | DU16: 0.005546457 | DV16: 0.0051912928 | DW16: 0.0059417881 | DX16: 0.0059587926 | DY16: 0.0068052114 | DZ16: 0.0051123738 | EA16: 10.25094 | EB16: 8.8565537 | EC16: 11.952636 | ED16: 1.7197543 | EE16: 1.7197543 | EF16: 1.7197543
A17: Permian_2019_F2021_bounds | B17: 22.12924 | C17: 21.750152 | D17: 22.561452 | E17: 104.29261 | F17: 99.332901 | G17: 109.62273 | H17: 0 | I17: 0 | J17: 0 | K17: 126.42185 | L17: 121.36929 | M17: 131.72557 | N17: 75.59937 | O17: 68.826253 | P17: 83.946186 | Q17: 0 | R17: 17.29491 | S17: 219.31613 | T17: 207.57437 | U17: 231.95129 | V17: 1000 | W17: 0.066276663 | X17: 16.353134 | Y17: 57.852 | Z17: 4755.8021 | AA17: 17164 | AB17: 152653 | AC17: 1.8250769 | AD17: 1052 | AE17: 998.613 | AF17: 540 | AG17: 166.809 | AH17: 681 | AI17: 278 | AJ17: 101.632 | AK17: 39.42415 | AL17: Yes | AM17: No | AN17: 20230815j | AO17: Yes | AP17: 83641 | AQ17: 8.894194 | AR17: 0.33531015 | AS17: 0.022223238 | AT17: 0.0020958521 | AU17: =B17/K17 -> 0.17504284 | AV17: =E17/K17 -> 0.82495716 | AW17: 0 | AX17: 0.0046531036 | AY17: 0.0044153817 | AZ17: 0.0049241395 | BA17: 0.021929552 | BB17: 0.018819371 | BC17: 0.025272013 | BD17: 0 | BE17: 0 | BF17: 0 | BG17: 0.026582655 | BH17: 0.025520257 | BI17: 0.027697865 | BJ17: 0.046115486 | BK17: -0.0024689338 | BL17: 0.0026567888 | BM17: 0.043646553 | BN17: 0.048772275 | BO17: 0.01589624 | BP17: 0.01447206 | BQ17: 0.01765132 | BR17: 0 | BS17: 0 | BT17: 0 | BU17: 0.0036365916 | BV17: 0.0029820052 | BW17: 0.0042911781 | BX17: 0.019532831 | BY17: 0.017454065 | BZ17: 0.021942498 | CA17: 0.012577564 | CB17: 0.011939276 | CC17: 0.77434917 | CD17: 9404 | CE17: 0.057422373 | CF17: 0.0097185388 | CG17: 0.01773809 | CH17: 179.89198 | CI17: 173.11886 | CJ17: 188.23879 | CK17: 179.89198 | CL17: 173.11886 | CM17: 188.23879 | CN17: 39.42415 | CO17: 35.931979 | CP17: 42.969446 | CQ17: Null | CR17: Null | CS17: Null | CT17: 22.375711 | CU17: 20.179122 | CV17: 25.042305 | CW17: 34.83336 | CX17: 31.203319 | CY17: 39.494749 | CZ17: 18.390299 | DA17: 13.739198 | DB17: 24.782895 | DC17: 0 | DD17: 0 | DE17: 0 | DF17: 0.82024019 | DG17: 0.82024019 | DH17: 0.17975981 | DI17: 0.42356193 | DJ17: 0.34470335 | DK17: 126.42185 | DL17: 4.4238167 | DM17: 0.5057212 | DN17: 0.011491852 | DO17: 0.9 | DP17: 17.326203 | DQ17: 0.057607519 | DR17: -0.053538709 | DS17: 0 | DT17: 0 | DU17: 0.006009084 | DV17: 0.0058552048 | DW17: 0.0061840029 | DX17: 0.0059587926 | DY17: 0.0068052114 | DZ17: 0.0051123738 | EA17: 104.35405 | EB17: 99.414307 | EC17: 109.69378 | ED17: 75.59937 | EE17: 75.59937 | EF17: 75.59937
A18: Permian_2019_F2021_bounds_Delaware | B18: 13.570649 | C18: 13.317593 | D18: 13.848657 | E18: 57.963754 | F18: 54.35855 | G18: 61.733493 | H18: 0 | I18: 0 | J18: 0 | K18: 71.534403 | L18: 67.902781 | M18: 75.329041 | N18: 37.16463 | O18: 33.921715 | P18: 41.396783 | Q18: 0 | R18: 13.139793 | S18: 121.83883 | T18: 114.29878 | U18: 129.57369 | V18: 1000 | W18: 0.082255993 | X18: 16.353134 | Y18: 53.271 | Z18: 3613.2165 | AA18: 7955 | AB18: 100870 | AC18: 1.8250769 | AD18: 922 | AE18: 875.71 | AF18: 447 | AG18: 117.767 | AH18: 558 | AI18: 202 | AJ18: 64.254 | AK18: 26.710442 | AL18: Yes | AM18: No | AN18: 20230815j | AO18: Yes | AP18: 55268 | AQ18: 12.681964 | AR18: 0.28080623 | AS18: 0.023097995 | AT18: 0.0026011629 | AU18: =B18/K18 -> 0.18970801 | AV18: =E18/K18 -> 0.81029199 | AW18: 0 | AX18: 0.0037558361 | AY18: 0.0035064251 | AZ18: 0.0040298402 | BA18: 0.016042148 | BB18: 0.01248887 | BC18: 0.019757591 | BD18: 0 | BE18: 0 | BF18: 0 | BG18: 0.019797984 | BH18: 0.01879289 | BI18: 0.020848195 | BJ18: 0.033720323 | BK18: -0.002086797 | BL18: 0.0021407152 | BM18: 0.031633525 | BN18: 0.035861038 | BO18: 0.010285747 | BP18: 0.009388232 | BQ18: 0.011457045 | BR18: 0 | BS18: 0 | BT18: 0 | BU18: 0.0036365916 | BV18: 0.0029820052 | BW18: 0.0042911781 | BX18: 0.013922338 | BY18: 0.012370237 | BZ18: 0.015748223 | CA18: 0.016682348 | CB18: 0.015844793 | CC18: 0.72615997 | CD18: 4358 | CE18: 0.10256999 | CF18: 0.014804148 | CG18: 0.027023176 | CH18: 95.128384 | CI18: 91.885469 | CJ18: 99.360537 | CK18: 95.128384 | CL18: 91.885469 | CM18: 99.360537 | CN18: 26.710442 | CO18: 24.092223 | CP18: 29.353613 | CQ18: Null | CR18: Null | CS18: Null | CT18: 9.4932598 | CU18: 7.9643412 | CV18: 11.551443 | CW18: 24.073446 | CX18: 21.928996 | CY18: 26.682089 | CZ18: 3.5979241 | DA18: 2.7159382 | DB18: 6.9514051 | DC18: 0 | DD18: 0 | DE18: 0 | DF18: 0.78077149 | DG18: 0.78077149 | DH18: 0.21922851 | DI18: 0.4128765 | DJ18: 0.30503034 | DK18: 71.534403 | DL18: 3.8277851 | DM18: 0.8290997 | DN18: 0.011491852 | DO18: 0.9 | DP18: 17.326203 | DQ18: 0.063488741 | DR18: -0.061886351 | DS18: 0 | DT18: 0 | DU18: 0.0051722413 | DV18: 0.0050303998 | DW18: 0.00536128 | DX18: 0.0059587926 | DY18: 0.0068052114 | DZ18: 0.0051123738 | EA18: 58.014009 | EB18: 54.406725 | EC18: 61.80782 | ED18: 37.16463 | EE18: 37.16463 | EF18: 37.16463
A19: Permian_2019_F2021_Midland | B19: 8.9461014 | C19: 8.6088789 | D19: 9.3172786 | E19: 46.314951 | F19: 42.719838 | G19: 50.157066 | H19: 0 | I19: 0 | J19: 0 | K19: 55.261053 | L19: 51.639424 | M19: 59.111992 | N19: 38.236992 | O19: 31.798971 | P19: 46.60895 | Q19: 0 | R19: 4.1551174 | S19: 97.653162 | T19: 89.498598 | U19: 107.15235 | V19: 1000 | W19: 0.1087704 | X19: 16.353134 | Y19: 112.03 | Z19: 1142.5856 | AA19: 9209 | AB19: 51783 | AC19: 1.8250769 | AD19: 130 | AE19: 124.215 | AF19: 93 | AG19: 49.093 | AH19: 123 | AI19: 76 | AJ19: 37.3 | AK19: 13.101219 | AL19: Yes | AM19: No | AN19: 20230815j | AO19: Yes | AP19: 28373 | AQ19: 5.6239841 | AR19: 0.4216751 | AS19: 0.04586577 | AT19: 0.0034396221 | AU19: =B19/K19 -> 0.161888 | AV19: =E19/K19 -> 0.838112 | AW19: 0 | AX19: 0.0078296989 | AY19: 0.0071297765 | AZ19: 0.0086000958 | BA19: 0.040535213 | BB19: 0.033073372 | BC19: 0.048509716 | BD19: 0 | BE19: 0 | BF19: 0 | BG19: 0.048364912 | BH19: 0.045195233 | BI19: 0.051735284 | BJ19: 0.085466822 | BK19: -0.0071369393 | BL19: 0.0083137679 | BM19: 0.078329882 | BN19: 0.093780589 | BO19: 0.033465318 | BP19: 0.027830711 | BQ19: 0.040792522 | BR19: 0 | BS19: 0 | BT19: 0 | BU19: 0.0036365916 | BV19: 0.0029820052 | BW19: 0.0042911781 | BX19: 0.03710191 | BY19: 0.030812716 | BZ19: 0.045083701 | CA19: 0.0045818207 | CB19: 0.0043779297 | CC19: 0.92388966 | CD19: 5045 | CE19: 0.018434093 | CF19: 0.0053309806 | CG19: 0.0097310208 | CH19: 84.551943 | CI19: 78.113922 | CJ19: 92.923901 | CK19: 84.551943 | CL19: 78.113922 | CM19: 92.923901 | CN19: 13.101219 | CO19: 12.016075 | CP19: 14.220317 | CQ19: Null | CR19: Null | CS19: Null | CT19: 12.795885 | CU19: 11.341734 | CV19: 14.31526 | CW19: 10.753404 | CX19: 8.3043926 | CY19: 15.365421 | CZ19: 14.687704 | DA19: 9.721858 | DB19: 22.035026 | DC19: 0 | DD19: 0 | DE19: 0 | DF19: 0.86583848 | DG19: 0.86583848 | DH19: 0.13416152 | DI19: 0.4341033 | DJ19: 0.39155306 | DK19: 55.261053 | DL19: 5.7070868 | DM19: 0.22647882 | DN19: 0.011491852 | DO19: 0.9 | DP19: 17.326203 | DQ19: 0.097272679 | DR19: -0.083492219 | DS19: 0 | DT19: 0 | DU19: 0.0084749071 | DV19: 0.0081136749 | DW19: 0.0090008934 | DX19: 0.0059587926 | DY19: 0.0068052114 | DZ19: 0.0051123738 | EA19: 46.360011 | EB19: 42.742754 | EC19: 50.220237 | ED19: 38.236992 | EE19: 38.236992 | EF19: 38.236992
A20: Northeast_Pennsylvania_2021 | B20: 1.112309 | C20: 0.97338802 | D20: 1.2805855 | E20: 19.424811 | F20: 16.225261 | G20: 22.594975 | H20: 0 | I20: 0 | J20: 0 | K20: 20.53712 | L20: 17.330177 | M20: 23.70724 | N20: 3.3981762 | O20: 1.9954665 | P20: 5.0193139 | Q20: 0 | R20: 9.0260916 | S20: 32.961388 | T20: 27.716284 | U20: 38.40836 | V20: 1000 | W20: 0.066973407 | X20: 495.44526 | Y20: 495.44526 | Z20: 5095.6288 | AA20: 2996 | AB20: 4039 | AC20: 1.2580446 | AD20: 12 | AE20: 11 | AF20: 12 | AG20: 11.48 | AH20: 4 | AI20: 4 | AJ20: 3 | AK20: 10.138401 | AL20: Yes | AM20: No | AN20: 20230815j | AO20: Yes | AP20: 3210 | AQ20: 1.348173 | AR20: 0.86124593 | AS20: 0.057680574 | AT20: 0.0021178851 | AU20: =B20/K20 -> 0.054160905 | AV20: =E20/K20 -> 0.9458391 | AW20: 0 | AX20: 0.0002182869 | AY20: 0.00018663186 | AZ20: 0.00025663099 | BA20: 0.0038120538 | BB20: 0.0030829927 | BC20: 0.0045344189 | BD20: 0 | BE20: 0 | BF20: 0 | BG20: 0.0040303407 | BH20: 0.0034009889 | BI20: 0.0046524661 | BJ20: 0.0064685614 | BK20: -0.001029334 | BL20: 0.00106895 | BM20: 0.0054392275 | BN20: 0.0075375115 | BO20: 0.00066688063 | BP20: 0.00039160359 | BQ20: 0.00098502347 | BR20: 0 | BS20: 0 | BT20: 0 | BU20: 0.0017713401 | BV20: 0.0014524989 | BW20: 0.0020901813 | BX20: 0.0024382207 | BY20: 0.0018441025 | BZ20: 0.0030752048 | CA20: 0.0037383178 | CB20: 0.0034267913 | CC20: 1 | CD20: 2381 | CE20: 0.0050398992 | CF20: 0.0038317757 | CG20: 0.0048215036 | CH20: 22.822987 | CI20: 21.420278 | CJ20: 24.444125 | CK20: 22.822987 | CL20: 21.420278 | CM20: 24.444125 | CN20: 10.138401 | CO20: 8.3747831 | CP20: 11.931374 | CQ20: Null | CR20: Null | CS20: Null | CT20: 0.53582662 | CU20: 0.074348125 | CV20: 1.3641708 | CW20: 2.8623495 | CX20: 1.7478377 | CY20: 4.0999653 | CZ20: 0 | DA20: 0 | DB20: 0 | DC20: 0 | DD20: 0 | DE20: 0 | DF20: 0.69241549 | DG20: 0.69241549 | DH20: 0.30758451 | DI20: 0.37693378 | DJ20: 0.10309505 | DK20: 20.53712 | DL20: 18.465205 | DM20: 2.1401213 | DN20: 0.0054988291 | DO20: 0.9 | DP20: 17.326203 | DQ20: 0.16526248 | DR20: -0.15912634 | DS20: 0 | DT20: 0 | DU20: 0.0002182869 | DV20: 0.00019102412 | DW20: 0.00025131059 | DX20: 0.0030734467 | DY20: 0.0035100156 | DZ20: 0.0026368779 | EA20: 19.745809 | EB20: 16.575784 | EC20: 22.844796 | ED20: 3.3981762 | EE20: 3.3981762 | EF20: 3.3981762
A21: GHGI 2022 (for 2020) | AI21: 1 | AT21: 0.0048 | AX21: =BG21 -> 0.004942 | AY21: =BH21 -> 0.0039430226 | AZ21: =BI21 -> 0.0059850499 | BG21: 0.004942 | BH21: =$BG$21+BK21*$BG$21/$BJ$21 -> 0.0039430226 | BI21: =$BG$21+BL21*$BG$21/$BJ$21 -> 0.0059850499 | BJ21: =BG21+BU21 -> 0.010092 | BK21: -0.00204 | BL21: 0.00213 | BM21: =BJ21+BK21 -> 0.008052 | BN21: =BJ21+BL21 -> 0.012222 | BU21: 0.00515 | BV21: =$BU$21+BK21*$BU$21/$BJ$21 -> 0.0041089774 | BW21: =$BU$21+BL21*$BU$21/$BJ$21 -> 0.0062369501
Y22: Fraction of national gas covered | Z22: =Z23/Z26 -> 0.28137144
A23: Totals excluding repeats | K23: =K3+K7+K13+K14+K15+K16 -> 407.91804 | L23: =L3+L7+L13+L14+L15+L16 -> 388.22301 | M23: =M3+M7+M13+M14+M15+M16 -> 429.38229 | N23: =N3+N7+N13+N14+N15+N16 -> 231.4564 | O23: =O3+O7+O13+O14+O15+O16 -> 213.63378 | P23: =P3+P7+P13+P14+P15+P16 -> 252.27873 | Q23: =Q3+Q7+Q13+Q14+Q15+Q16 -> 1.9173475 | R23: =R3+R7+R13+R14+R15+R16 -> 67.289424 | ... U23: =U3+U7+U13+U14+U15+U16 -> 751.26391 | Z23: =Z3+Z7+Z13+Z14+Z15+Z16 -> 23994.401 | AA23: =AA3+AA7+AA13+AA14+AA15+AA16 -> 170569 | AB23: =AB3+AB7+AB13+AB14+AB15+AB16 -> 549072 | AG23: =AG3+AG7+AG13+AG14+AG15+AG16 -> 601.445 | AP23: 1 | AQ23: =AQ3+AQ7+AQ13+AQ14+AQ15+AQ16 -> 18.606751 | AR23: =AB23/AA23 -> 3.2190609 | BE23: =S23/$Z23 -> 0.029531107 | BF23: =T23/$Z23 -> 0.027898354 | BG23: =U23/$Z23 -> 0.031309967 | BR23: =BR3+BR7+BR13+BR14+BR15+BR16 -> 0.0030115379 | BU23: =AG23/BR23 -> 199713.57 | BV23: =BV3+BV7+BV13+BV14+BV15+BV16 -> 0.016581009 | CH23: =CH3+CH7+CH13+CH14+CH15+CH16 -> 526.94104 | EA23: =EA3+EA7+EA13+EA14+EA15+EA16 -> 296.25627 | EB23: =EB3+EB7+EB13+EB14+EB15+EB16 -> 276.93106 | EC23: =EC3+EC7+EC13+EC14+EC15+EC16 -> 317.32595 | ED23: =ED3+ED7+ED13+ED14+ED15+ED16 -> 231.4564 | EE23: =EE3+EE7+EE13+EE14+EE15+EE16 -> 231.4564 | EF23: =EF3+EF7+EF13+EF14+EF15+EF16 -> 231.4564
A24: Totals including repeats (no 2019 subcampaigns) | N24: =N23+Q23+R23 -> 300.66318 | S24: =SUM(S2:S16) -> 1354.5582 | T24: =SUM(T2:T16) -> 1268.7129 | U24: =SUM(U2:U16) -> 1449.1697 | Z24: =SUM(Z2:Z16) -> 45847.976 | AA24: =SUM(AA2:AA16) -> 398499 | AB24: =SUM(AB2:AB16) -> 1714261 | AG24: =SUM(AG2:AG16) -> 1281.383 | AP24: 1 | AQ24: =SUM(AQ2:AQ16) -> 62.970182 | AR24: =AQ24/BR23 -> 20909.643 | BE24: =S24/$Z24 -> 0.029544559 | BF24: =T24/$Z24 -> 0.027672167 | BG24: =U24/$Z24 -> 0.031608149 | BR24: =SUM(BR2:BR16) -> 0.0055465101 | BU24: =AG24/BR24 -> 231025.09 | CG24: Aerially measured/Total emissions | CH24: =CH23/S23 -> 0.74365652 | DZ24: Aerially measured/Total emissions | EA24: =EA23/K23 -> 0.72626419 | ED24: =ED23/N24 -> 0.7698196
A25: Totals excluding high-prod campaigns | S25: =S3+S7+S13+S15+S16 -> 632.14801 | T25: =T3+T7+T13+T15+T16 -> 602.28678 | U25: =U3+U7+U13+U15+U16 -> 664.94564 | Z25: =Z3+Z7+Z13+Z15+Z16 -> 13751.921 | BE25: =S25/$Z25 -> 0.045967979 | BF25: =T25/$Z25 -> 0.043796557 | BG25: =U25/$Z25 -> 0.048352928
R26: Social cost of methane [$/t] | S26: 1500 | Y26: 2021 US gas prod | Z26: 85276.605 | CO26: GHGI midstream sub-aerial fraction | CP26: =0.7303 -> 0.7303
A27: Permian total | R27: Hours per day | S27: 8760 | Y27: [Enverus, t(CH4)/h] | AA27: =SUM(W2:W6) -> 0.24846292 | AB27: =SUM(X2:X6) -> 64.229338 | AD27: =SUM(Z2:Z6) -> 29423.657 | AE27: =SUM(AA2:AA6) -> 162037 | AF27: =SUM(AB2:AB6) -> 643575 | AG27: =SUM(AC2:AC6) -> 8.5003077 | AH27: =SUM(AD2:AD6) -> 2783 | AI27: =SUM(AE2:AE6) -> 3804.001 | AQ27: =SUM(AK2:AK6) -> 272.15155 | AR27: =AQ27/BR27 -> 1312.868 | BR27: =SUM(BM2:BM6) -> 0.20729544
A28: San Joaquin total | R28: GWP20 (IPCC 2021) | S28: 82.5 | T28: https://report.ipcc.ch/ar6/wg1/IPCC_AR6_WGI_FullReport.pdf | U28: Table 7.15 | AA28: =SUM(W7:W11) -> 0.6692563 | AB28: =SUM(X7:X11) -> 80.237423 | AD28: =SUM(Z7:Z11) -> 1224.3124 | AE28: =SUM(AA7:AA11) -> 180339 | AF28: =SUM(AB7:AB11) -> 870400 | AG28: =SUM(AC7:AC11) -> 9.4819814 | AH28: =SUM(AD7:AD11) -> 352 | AI28: =SUM(AE7:AE11) -> 326.3 | AQ28: =SUM(AK7:AK11) -> 15.658434 | AR28: =AQ28/BR28 -> 86.674193 | BR28: =SUM(BM7:BM11) -> 0.18065855
A29: Denver total | R29: Emissions [tCH4/yr] | S29: =S23*$S$27 -> 6207171.5 | T29: =T23*$S$27 -> 5863981.5 | U29: =U23*$S$27 -> 6581071.8 | AA29: =W12+W13 -> 0.13570127 | AB29: =X12+X13 -> 21.262557 | AD29: =Z12+Z13 -> 3970.1203 | AE29: =AA12+AA13 -> 23359 | AF29: =AB12+AB13 -> 127167 | AG29: =AC12+AC13 -> 3.2176052 | AH29: =AD12+AD13 -> 74 | AI29: =AE12+AE13 -> 58.753 | AQ29: =AK12+AK13 -> 36.972357 | AR29: =AQ29/BR29 -> 1821.665 | BR29: =BM12+BM13 -> 0.020295914
A30: Per+SJ+DJ | R30: Emissions [tCO2e/yr] | S30: =S29*$S$28 -> 5.1209165e+08 | T30: =T29*$S$28 -> 4.8377848e+08 | U30: =U29*$S$28 -> 5.4293843e+08 | AA30: =SUM(AA27:AA29) -> 1.0534205 | AB30: =SUM(AB27:AB29) -> 165.72932 | AQ30: =SUM(AQ27:AQ29) -> 324.78234 | AR30: =AQ30/BR30 -> 795.54787 | BR30: =SUM(BR27:BR29) -> 0.4082499
R31: Annual social cost of emissions [$/yr] | S31: =S29*$S$26 -> 9.3107572e+09 | T31: =T29*$S$26 -> 8.7959723e+09 | U31: =U29*$S$26 -> 9.8716078e+09
R32: NG cost [$/mcf] | S32: 3 | Y32: =Z23*$S27/$S33 -> 1.2128734e+10
R33: tCH4/mcf(NG) | S33: 0.01733 | Y33: =Z26*$S27/$S33 -> 4.3105774e+10
R34: Annual NG emissions [mcf/yr] | S34: =S29/$S$33 -> 3.5817493e+08 | T34: =T29/$S$33 -> 3.383717e+08 | U34: =U29/$S$33 -> 3.7975025e+08
R35: Annual NG value | S35: =S34*$S$32 -> 1.0745248e+09 | T35: =T34*$S$32 -> 1.0151151e+09 | U35: =U34*$S$32 -> 1.1392508e+09
R36: Price/t(CH4) | S36: =S32/S33 -> 173.11021

Sheet Tables for paper
I1: REVISIT | J1: From Jupyter code
A2: Table 7 | B2: {='By site'!Y1:Y20} -> Transition point | C2: {='By site'!X1:X20} -> Min detected emission | D2: {='By site'!AD1:AD20} -> # production plumes | E2: {='By site'!AE1:AE20} -> # production plumes sel | H2: Table 5 | I2: Avg emissions/site | J2: Logormal fit mean | K2: Lognormal/This study | M2: Table 23 | N2: {='By site'!CD1:CD20} -> Well sites covered | O2: {='By site'!AD1:AD20} -> # production plumes | P2: {='By site'!AF1:AF20} -> # prod sources overall | Q2: {='By site'!AQ1:AQ20} -> Avg visits/well site | R2: {='By site'!AG1:AG20} -> # avg prod sources sim | S2: {='By site'!CG1:CG20} -> Avg % sites emitting
A3: Kairos_Permian | B3: 24.348 | C3: 5.9464547 | D3: NAN | E3: 1276.962 | H3: Kairos_Permian | I3: =1000*'By site'!K2/'By site'!CD2 -> 6.0588299 | J3: 3.188375 | K3: =J3/I3 -> 0.5262361 | M3: Kairos_Permian | N3: 18030 | O3: NAN | P3: 627 | Q3: 3.7698281 | R3: 299.748 | S3: 0.016624958
A4: Permian_2019 | B4: 59.992 | C4: 15.029525 | D4: 1749 | E4: 1644.303 | H4: Permian_2019 | I4: =1000*'By site'!K3/'By site'!CD3 -> 6.5982181 | J4: 3.823909 | K4: =J4/I4 -> 0.57953661 | M4: Permian_2019 | N4: 46337 | O4: 1749 | P4: 1054 | Q4: 3.8655934 | R4: 483.45 | S4: 0.010433347
A5: Permian_2020 | B5: 82.192 | C5: 8.0919112 | D5: 284 | E5: 247.56 | H5: Permian_2020 | I5: =1000*'By site'!K4/'By site'!CD4 -> 6.1288099 | J5: 5.315017 | K5: =J5/I5 -> 0.86721844 | M5: Permian_2020 | N5: 9380 | O5: 284 | P5: 239 | Q5: 2.8557569 | R5: 101.175 | S5: 0.010786247
A6: Permian_summer2021 | B6: 68.158 | C6: 11.813408 | D6: 416 | E6: 360.723 | H6: Permian_summer2021 | I6: =1000*'By site'!K5/'By site'!CD5 -> 6.2398532 | J6: 7.700567 | K6: =J6/I6 -> 1.2340943 | M6: Permian_summer2021 | N6: 10432 | O6: 416 | P6: 296 | Q6: 4.8271664 | R6: 124.728 | S6: 0.011956288
A7: Permian_fall2021 | B7: 78.553 | C7: 23.348039 | D7: 334 | E7: 274.453 | H7: Permian_fall2021 | I7: =1000*'By site'!K6/'By site'!CD6 -> 6.0875535 | J7: 7.498451 | K7: =J7/I7 -> 1.2317676 | M7: Permian_fall2021 | N7: 10777 | O7: 334 | P7: 232 | Q7: 4.7946553 | R7: 92.758 | S7: 0.0086070335
A8: San_Joaquin_2016 | B8: 40.093 | C8: 9 | D8: 77 | E8: 69.083 | H8: San_Joaquin_2016 | I8: =1000*'By site'!K7/'By site'!CD7 -> 0.20833234 | J8: 0.521041 | K8: =J8/I8 -> 2.5010087 | M8: San_Joaquin_2016 | N8: 23779 | O8: 77 | P8: 40 | Q8: 1.9552546 | R8: 15.06 | S8: 0.00063333193
A9: San_Joaquin_2017 | B9: 41.571 | C9: 11 | D9: 86 | E9: 80.167 | H9: San_Joaquin_2017 | I9: =1000*'By site'!K8/'By site'!CD8 -> 0.30986694 | J9: 0.539929 | K9: =J9/I9 -> 1.7424543 | M9: San_Joaquin_2017 | N9: 23103 | O9: 86 | P9: 54 | Q9: 4.7679522 | R9: 15.926 | S9: 0.0006893477
A10: San_Joaquin_summer2020 | B10: 36.04 | C10: 23.632192 | D10: 94 | E10: 90.481 | H10: San_Joaquin_summer2020 | I10: =1000*'By site'!K9/'By site'!CD9 -> 0.35342321 | J10: 0.545917 | K10: =J10/I10 -> 1.5446552 | M10: San_Joaquin_summer2020 | N10: 15992 | O10: 94 | P10: 39 | Q10: 7.4688594 | R10: 13.316 | S10: 0.00083266633
A11: San_Joaquin_fall2020 | B11: 39.525 | C11: 20.646402 | D11: 48 | E11: 45.291 | H11: San_Joaquin_fall2020 | I11: =1000*'By site'!K10/'By site'!CD10 -> 0.27004588 | J11: 0.523525 | K11: =J11/I11 -> 1.9386521 | M11: San_Joaquin_fall2020 | N11: 16579 | O11: 48 | P11: 27 | Q11: 7.2219675 | R11: 8.083 | S11: 0.00048754448
A12: San_Joaquin_fall2021 | B12: 22.967 | C12: 15.95883 | D12: 47 | E12: 41.278 | H12: San_Joaquin_fall2021 | I12: =1000*'By site'!K11/'By site'!CD11 -> 0.20735863 | J12: 0.509176 | K12: =J12/I12 -> 2.4555331 | M12: San_Joaquin_fall2021 | N12: 16743 | O12: 47 | P12: 35 | Q12: 3.5712238 | R12: 15.732 | S12: 0.00093961656
A13: Denver_summer2021 | B13: 75.256 | C13: 11.102345 | D13: 34 | E13: 27.18 | H13: Denver_summer2021 | I13: =1000*'By site'!K12/'By site'!CD12 -> 1.999069 | J13: 4.579421 | K13: =J13/I13 -> 2.2907768 | M13: Denver_summer2021 | N13: 7254 | O13: 34 | P13: 27 | Q13: 5.0860215 | R13: 8.472 | S13: 0.0011679074
A14: Denver_fall2021 | B14: 66.296 | C14: 10.160213 | D14: 40 | E14: 31.573 | H14: Denver_fall2021 | I14: =1000*'By site'!K13/'By site'!CD13 -> 2.0122373 | J14: 4.605823 | K14: =J14/I14 -> 2.2889065 | M14: Denver_fall2021 | N14: 7265 | O14: 40 | P14: 33 | Q14: 5.8016518 | R14: 8.476 | S14: 0.0011666896
A15: Pennsylvania_2021 | B15: 117.519 | C15: 92.241416 | D15: 64 | E15: 62 | H15: Pennsylvania_2021 | I15: =1000*'By site'!K14/'By site'!CD14 -> 3.9395426 | J15: 1.678679 | K15: =J15/I15 -> 0.42611012 | M15: Pennsylvania_2021 | N15: 12801 | O15: 64 | P15: 43 | Q15: 1.726037 | R15: 29.518 | S15: 0.0023059136
... A17: Fort_Worth_2021 | B17: 45.425 | C17: 6.5248199 | D17: 80 | E17: 79.98 | H17: Fort_Worth_2021 | I17: =1000*'By site'!K16/'By site'!CD16 -> 3.4173485 | J17: 1.691088 | K17: =J17/I17 -> 0.49485383 | M17: Fort_Worth_2021 | N17: 4606 | O17: 80 | P17: 49 | Q17: 1.7370821 | R17: 40.022 | S17: 0.0086891012
A18: Permian_2019_F2021_bounds | B18: 57.852 | C18: 16.353134 | D18: 1052 | E18: 998.613 | H18: Permian_2019_F2021_bounds | I18: =1000*'By site'!K17/'By site'!CD17 -> 13.443412 | M18: Permian_2019_F2021_bounds | N18: 9404 | O18: 1052 | P18: 540 | Q18: 8.894194 | R18: 166.809 | S18: 0.01773809
