Workbook

Sheet By site
A1: Scenario | B1: Simulation (t/h) | C1: Simulation P2.5 | D1: Simulation P97.5 | E1: Aerial (t/h) | F1: Aerial P2.5 | G1: Aerial P97.5 | H1: Partial (t/h) | I1: Partial P2.5 | J1: Partial P97.5 | K1: Well site emissions (t/h) | L1: Well site emissions P2.5 | M1: Well site emissions P97.5 | N1: Aerial emissions P2.5 | O1: Aerial emissions P97.5 | P1: Aerial midstream emissions (t/h) | Q1: Aerial midstream emissions P2.5 | R1: Aerial midstream emissions P97.5 | S1: Midstream partial detect (t/h) | T1: Midstream GHGI below min detect (t/h) | U1: Total emissions + midstream (t/h) | V1: Total emissions + midstream P2.5 | W1: Total emissions + midstream P97.5 | X1: N | Y1: % SDev of MC iterations | Z1: Min detected emission | AA1: Transition point | AB1: Total covered production (t(CH4)/hr) | AC1: Wells covered | AD1: Well visits | AE1: Wells per site | AF1: # production plumes | AG1: # production plumes sel | AH1: # prod sources overall | AI1: # avg prod sources sim | AJ1: # midstream plumes | AK1: # midstream sources | AM1: Total sim emissions | AN1: Stratify by covered prod | AO1: Include repeats | AP1: Date | AQ1: Well site visits | AR1: Avg visits/well site | AS1: SD to SErr factor | AT1: SErr of mean total emissions | AU1: SErr of sample mean | AV1: Simulation % well site | AW1: Aerial % well site | AX1: Partial % well site | AY1: Methane fractional loss simulation well site | AZ1: Methane fractional loss simulation well siteP2.5 | BA1: Methane fractional loss simulation well siteP97.5 | BB1: Methane fractional loss aerial well site | BC1: AerialFracLossP2.5 | BD1: AerialFracLossP97.5 | BE1: Methane fractional loss partial | BF1: Methane fractional loss partialP2.5 | BG1: Methane fractional loss partialP97.5 | BH1: FracLossProd | BI1: FracLossProdP2.5 | BJ1: FracLossProdP97.5 | BK1: Methane fractional loss total | BL1: FracLossP2.5 | BM1: FracLossP97.5 | BN1: FracLossP2.5Full | BO1: FracLossP97.5Full | BP1: FracLossMidAerial | BQ1: FracLossMidAerialP2.5 | BR1: FracLossMidAerialP97.5 | BS1: FracLossMidPartial | BT1: FracLossMidPartialP2.5 | BU1: FracLossMidPartialP97.5 | BV1: FracLossMidGHGI | BW1: FracLossMidGHGIP2.5 | BX1: FracLossMidGHGIP97.5 | BY1: FracLossMidstream total | BZ1: FracLossMidstream totalP2.5 | CA1: FracLossMidstream totalP97.5 | CB1: % well site visits with plume | CC1: % well site visits with selected plume | CD1: Fraction sim retained | CE1: Well sites covered | CF1: % well sites ever emitting | CG1: Avg % wells emitting | CH1: Avg % sites emitting | CI1: Total aerial | CJ1: Total aerialP2.5 | CK1: Total aerialP97.5 | CL1: Total aerial+partial emissions | CM1: Total aerial+partial emissionsP2.5 | CN1: Total aerial+partial emissionsP97.5 | CO1: Total sim emissions | CP1: Total sim emissionsP2.5 | CQ1: Total sim emissionsP97.5 | CR1: Total aerial all segments inc below transition | CS1: Total aerial all segments inc below transition P2.5 | CT1: Total aerial all segments inc below transition P97.5 | CU1: Total pipeline emissions | CV1: Total pipeline emissions P2.5 | CW1: Total pipeline emissions P97.5 | CX1: Total compressor emissions | CY1: Total compressor emissions P2.5 | CZ1: Total compressor emissions P97.5 | DA1: Total processing emissions | DB1: Total processing emissions P2.5 | DC1: Total processing emissions P97.5 | DD1: Total other midstream emissions | DE1: Total other midstream emissions P2.5 | DF1: Total other midstream emissions P97.5 | DG1: Frac aerial | DH1: Frac aerial+partial | DI1: Frac sim | DJ1: Frac midstream | DK1: Frac midstream aerial | DL1: Total production emissions | DM1: Total/Sim | DN1: Production/site covered | DO1: State GHGI | DP1: NG methane fraction | DQ1: kgCH4 per mcfNG | DR1: Full upper errorbar % total | DS1: Full lower errorbar % total | DT1: Partial prod % total | DU1: Partial mid % total | DV1: Tot sim emissions loss rate | DW1: Tot sim emissions loss rate P2.5 | DX1: Tot sim emissions loss rate P97.5 | DY1: Prod-only state GHGI loss | DZ1: Prod-only state GHGI loss low | EA1: Prod-only state GHGI loss high | EB1: Total aerial prod emissions inc below transition | EC1: Total aerial prod emissions inc below transition P2.5 | ED1: Total aerial prod emissions inc below transition P97.5 | EE1: Total aerial mid emissions inc below transition | EF1: Total aerial mid emissions inc below transition P2.5 | EG1: Total aerial mid emissions inc below transition P97.5
A2: Kairos_Permian | B2: 17.929621 | C2: 17.498568 | D2: 18.323946 | E2: 87.90226 | F2: 82.080806 | G2: 94.348573 | H2: 4.7456111 | I2: 4.1197691 | J2: 5.4383812 | K2: 110.57749 | L2: 104.77317 | M2: 117.17932 | N2: 82.080806 | O2: 94.348573 | P2: 65.779434 | Q2: 58.254286 | R2: 77.335407 | S2: 4.5816481 | T2: 7.4248658 | U2: 188.36344 | V2: 177.02613 | W2: 202.45964 | X2: 1000 | Y2: 0.062551355 | Z2: 7.0962343 | AA2: 24.324 | AB2: 1952.0451 | AC2: 21637 | AD2: 81564 | AE2: 1.2 | AF2: 1279 | AG2: 1276.97 | AH2: 625 | AI2: 305.158 | AJ2: 706 | AK2: 331 | AM2: 25.354486 | AN2: Yes | AO2: No | AP2: 20230329b | AQ2: 67970 | AR2: 3.7698281 | AS2: 0.51503795 | AT2: 0.032216322 | AU2: 0.0019780475 | AV2: 0.14190018 | AW2: 0.85336403 | AX2: 0.0047357967 | AY2: 0.0091850441 | AZ2: 0.0087562971 | BA2: 0.0095772608 | BB2: 0.045030854 | BC2: 0.039240536 | BD2: 0.051442689 | BE2: 0.002431097 | BF2: 0.0018086024 | BG2: 0.0031201618 | BH2: 0.056646995 | BI2: 0.05367354 | BJ2: 0.060029001 | BK2: 0.096495433 | BL2: -0.0058079115 | BM2: 0.007221247 | BN2: 0.090687521 | BO2: 0.10371668 | BP2: 0.033697702 | BQ2: 0.029842694 | BR2: 0.039617633 | BS2: 0.0023471015 | BT2: 0.0019939591 | BU2: 0.0027481 | BV2: 0.0038036343 | BW2: 0.0031189801 | BX2: 0.0044882884 | BY2: 0.039848437 | BZ2: 0.035203038 | CA2: 0.046494395 | CB2: 0.018817125 | CC2: 0.018787259 | CD2: 0.76546051 | CE2: 18030 | CF2: 0.034664448 | CG2: 0.014103526 | CH2: 0.016925014 | CI2: 153.68169 | CJ2: 146.15655 | CK2: 165.23767 | CL2: 158.26334 | CM2: 150.04884 | CN2: 170.60208 | CO2: 25.354486 | CP2: 23.586958 | CQ2: 27.085288 | CR2: 153.75365 | CS2: 142.45922 | CT2: 166.27038 | CU2: 18.631948 | CV2: 15.131157 | CW2: 27.765681 | CX2: 6.9420468 | CY2: 5.7684392 | CZ2: 8.3373798 | DA2: 3.8004511 | DB2: 2.9824595 | DC2: 5.1953953 | DD2: 36.404989 | DE2: 30.915008 | DF2: 43.947117 | DG2: 0.81587695 | DH2: 0.84020066 | DI2: 0.13460513 | DJ2: 0.4129543 | DK2: 0.34921249 | DL2: 110.57749 | DM2: 4.7208363 | DN2: 0.10826651 | DO2: 0.012478177 | DP2: 0.9 | DQ2: 17.326203 | DR2: 0.074834071 | DS2: -0.060183905 | DT2: 0.025194203 | DU2: 0.01886395 | DV2: 0.011999418 | DW2: 0.011647352 | DX2: 0.012462307 | DY2: 0.0072701048 | DZ2: 0.0082075578 | EA2: 0.0063326517 | EB2: 87.974216 | EE2: 65.779434
A3: Permian_2019 | B3: 69.417499 | C3: 68.443659 | D3: 70.635571 | E3: 236.18653 | F3: 226.22581 | G3: 246.32564 | H3: 0 | I3: 0 | J3: 0 | K3: 305.60403 | L3: 295.52415 | M3: 315.79026 | N3: 226.22581 | O3: 246.32564 | P3: 212.57883 | Q3: 199.64633 | R3: 226.59878 | S3: 0 | T3: 38.281727 | U3: 556.46459 | V3: 532.92556 | W3: 580.16778 | X3: 1000 | Y3: 0.032662483 | Z3: 15.029525 | AA3: 59.283 | AB3: 10526.815 | AC3: 84570 | AD3: 326908 | AE3: 1.8250769 | AF3: 1749 | AG3: 1645.742 | AH3: 1054 | AI3: 483.449 | AJ3: 1272 | AK3: 679 | AM3: 107.69923 | AN3: Yes | AO3: No | AP3: 20230328 | AQ3: 179120 | AR3: 3.8655934 | AS3: 0.50861822 | AT3: 0.016612734 | AU3: 0.0010328784 | AV3: 0.35168169 | AW3: 0.64831831 | AX3: 0 | AY3: 0.0065943499 | AZ3: 0.0064124641 | BA3: 0.0068218512 | BB3: 0.022436657 | BC3: 0.020576275 | BD3: 0.024330355 | BE3: 0 | BF3: 0 | BG3: 0 | BH3: 0.029031007 | BI3: 0.028073463 | BJ3: 0.029998653 | BK3: 0.05286163 | BL3: -0.002236102 | BM3: 0.0022516968 | BN3: 0.050625528 | BO3: 0.055113327 | BP3: 0.020194031 | BQ3: 0.018965503 | BR3: 0.021525864 | BS3: 0 | BT3: 0 | BU3: 0 | BV3: 0.0036365916 | BW3: 0.0029820052 | BX3: 0.0042911781 | BY3: 0.023830623 | BZ3: 0.021947508 | CA3: 0.025817042 | CB3: 0.0097644038 | CC3: 0.0091879299 | CD3: 0.82970308 | CE3: 46337 | CF3: 0.022746401 | CG3: 0.0057165543 | CH3: 0.010433325 | CI3: 448.76536 | CJ3: 435.83287 | CK3: 462.78531 | CL3: 448.76536 | CM3: 435.83287 | CN3: 462.78531 | CO3: 107.69923 | CP3: 99.834675 | CQ3: 115.80801 | CR3: 449.28444 | CS3: 429.65375 | CT3: 469.2687 | CU3: 102.36225 | CV3: 96.655735 | CW3: 109.023 | CX3: 80.647514 | CY3: 74.031141 | CZ3: 87.886074 | DA3: 29.569065 | DB3: 21.381253 | DC3: 39.986645 | DD3: 0 | DE3: 0 | DF3: 0 | DG3: 0.80645778 | DH3: 0.80645778 | DI3: 0.19354222 | DJ3: 0.4508109 | DK3: 0.38201627 | DL3: 305.60403 | DM3: 3.6526892 | DN3: 0.22717946 | DO3: 0.011491852 | DP3: 0.9 | DQ3: 17.326203 | DR3: 0.042594731 | DS3: -0.042301958 | DT3: 0 | DU3: 0 | DY3: 0.0065 | DZ3: 0.0074 | EA3: 0.0056 | EB3: 237.16313 | EE3: 212.57883
A4: Permian_2020 | B4: 22.486001 | C4: 21.673996 | D4: 23.318745 | E4: 34.947969 | F4: 31.679793 | G4: 38.044824 | H4: 0 | I4: 0 | J4: 0 | K4: 57.43397 | L4: 53.993234 | M4: 60.597126 | N4: 31.679793 | O4: 38.044824 | P4: 60.160964 | Q4: 53.506687 | R4: 67.679217 | S4: 0 | T4: 16.369542 | U4: 133.96448 | V4: 123.22217 | W4: 145.20185 | X4: 1000 | Y4: 0.052643636 | Z4: 8.0919112 | AA4: 83.968 | AB4: 4766.5264 | AC4: 17120 | AD4: 48890 | AE4: 1.8250769 | AF4: 284 | AG4: 246.309 | AH4: 239 | AI4: 101.24 | AJ4: 316 | AK4: 233 | AM4: 38.855543 | AN4: Yes | AO4: No | AP4: 20230328 | AQ4: 26787 | AR4: 2.8557569 | AS4: 0.59175152 | AT4: 0.031151952 | AU4: 0.0016647379 | AV4: 0.5330928 | AW4: 0.4669072 | AX4: 0 | AY4: 0.0047174817 | AZ4: 0.0044295977 | BA4: 0.0050127183 | BB4: 0.0073319575 | BC4: 0.0061732762 | BD4: 0.0084298998 | BE4: 0 | BF4: 0 | BG4: 0 | BH4: 0.012049439 | BI4: 0.011327585 | BJ4: 0.012713058 | BK4: 0.028105263 | BL4: -0.002253696 | BM4: 0.0023575603 | BN4: 0.025851567 | BO4: 0.030462823 | BP4: 0.012621553 | BQ4: 0.011225509 | BR4: 0.014198855 | BS4: 0 | BT4: 0 | BU4: 0 | BV4: 0.0034342708 | BW4: 0.002816102 | BX4: 0.0040524395 | BY4: 0.016055823 | BZ4: 0.014041611 | CA4: 0.018251295 | CB4: 0.010602158 | CC4: 0.0091950946 | CD4: 0.83174076 | CE4: 9380 | CF4: 0.025479744 | CG4: 0.0059135514 | CH4: 0.010793177 | CI4: 95.108933 | CJ4: 88.454656 | CK4: 102.62719 | CL4: 95.108933 | CM4: 88.454656 | CN4: 102.62719 | CO4: 38.855543 | CP4: 35.09702 | CQ4: 42.634805 | CR4: 95.64559 | CS4: 90.148802 | CT4: 100.85393 | CU4: 17.672909 | CV4: 13.507861 | CW4: 23.020384 | CX4: 33.372115 | CY4: 29.311477 | CZ4: 37.495659 | DA4: 9.0276573 | DB4: 6.4483394 | DC4: 11.889321 | DD4: 0.088283211 | DE4: 0.036041487 | DF4: 0.3095367 | DG4: 0.70995479 | DH4: 0.70995479 | DI4: 0.29004521 | DJ4: 0.57127414 | DK4: 0.44908039 | DL4: 57.43397 | DM4: 2.1244741 | DN4: 0.50815846 | DO4: 0.010661119 | DP4: 0.9 | DQ4: 17.326203 | DR4: 0.083879362 | DS4: -0.080194747 | DT4: 0 | DU4: 0 | DY4: 0.006 | DZ4: 0.0068 | EA4: 0.0051 | EB4: 35.52104 | EE4: 60.160964
A5: Permian_summer2021 | B5: 27.970658 | C5: 27.235759 | D5: 28.760886 | E5: 37.106306 | F5: 33.87838 | G5: 40.490546 | H5: 0 | I5: 0 | J5: 0 | K5: 65.076964 | L5: 61.82595 | M5: 68.604409 | N5: 33.87838 | O5: 40.490546 | P5: 45.081584 | Q5: 41.453676 | R5: 49.191029 | S5: 0 | T5: 20.435387 | U5: 130.59393 | V5: 121.72804 | W5: 139.72156 | X5: 1000 | Y5: 0.046598349 | Z5: 11.813408 | AA5: 68.187 | AB5: 5950.4297 | AC5: 19040 | AD5: 91907 | AE5: 1.8250769 | AF5: 416 | AG5: 360.585 | AH5: 296 | AI5: 124.71 | AJ5: 477 | AK5: 232 | AM5: 48.406044 | AN5: Yes | AO5: No | AP5: 20230328 | AQ5: 50357 | AR5: 4.8271664 | AS5: 0.45514928 | AT5: 0.021209205 | AU5: 0.0014735692 | AV5: 0.70526178 | AW5: 0.29473822 | AX5: 0 | AY5: 0.0047006114 | AZ5: 0.0044292643 | BA5: 0.0049923881 | BB5: 0.0062359036 | BC5: 0.0050440543 | BD5: 0.0074854689 | BE5: 0 | BF5: 0 | BG5: 0 | BH5: 0.010936515 | BI5: 0.010390166 | BJ5: 0.01152932 | BK5: 0.021946975 | BL5: -0.0014899593 | BM5: 0.001533944 | BN5: 0.020457016 | BO5: 0.023480919 | BP5: 0.0075761897 | BQ5: 0.0069665013 | BR5: 0.0082668028 | BS5: 0 | BT5: 0 | BU5: 0 | BV5: 0.0034342708 | BW5: 0.002816102 | BX5: 0.0040524395 | BY5: 0.01101046 | BZ5: 0.0097826034 | CA5: 0.012319242 | CB5: 0.0082610163 | CC5: 0.0071605735 | CD5: 0.80417693 | CE5: 10432 | CF5: 0.028374233 | CG5: 0.006549895 | CH5: 0.011954563 | CI5: 82.18789 | CJ5: 78.559982 | CK5: 86.297335 | CL5: 82.18789 | CM5: 78.559982 | CN5: 86.297335 | CO5: 48.406044 | CP5: 43.992776 | CQ5: 52.874643 | CR5: 82.806661 | CS5: 75.697858 | CT5: 90.314383 | CU5: 12.903725 | CV5: 11.509695 | CW5: 14.693035 | CX5: 25.157451 | CY5: 22.22628 | CZ5: 28.530747 | DA5: 7.0204076 | DB5: 5.5240477 | DC5: 8.7435956 | DD5: 0 | DE5: 0 | DF5: 0 | DG5: 0.62933819 | DH5: 0.62933819 | DI5: 0.37066181 | DJ5: 0.50168381 | DK5: 0.34520246 | DL5: 65.076964 | DM5: 1.8710164 | DN5: 0.57040162 | DO5: 0.010661119 | DP5: 0.9 | DQ5: 17.326203 | DR5: 0.069895233 | DS5: -0.067885611 | DT5: 0 | DU5: 0 | DY5: 0.006 | DZ5: 0.0068 | EA5: 0.0051 | EB5: 37.760186 | EE5: 45.081584
A6: Permian_fall2021 | B6: 30.311881 | C6: 29.522823 | D6: 31.02066 | E6: 35.308872 | F6: 31.630299 | G6: 38.974685 | H6: 0 | I6: 0 | J6: 0 | K6: 65.620754 | L6: 61.90244 | M6: 69.343708 | N6: 31.630299 | O6: 38.974685 | P6: 43.968884 | Q6: 39.066203 | R6: 49.17745 | S6: 0 | T6: 21.388092 | U6: 130.97773 | V6: 121.07967 | W6: 141.31724 | X6: 1000 | Y6: 0.05670148 | Z6: 23.348039 | AA6: 77.865 | AB6: 6227.8408 | AC6: 19670 | AD6: 94306 | AE6: 1.8250769 | AF6: 334 | AG6: 275.15 | AH6: 232 | AI6: 92.785 | AJ6: 368 | AK6: 179 | AM6: 51.699973 | AN6: Yes | AO6: No | AP6: 20230328 | AQ6: 51672 | AR6: 4.7946553 | AS6: 0.45668979 | AT6: 0.025894987 | AU6: 0.0017930582 | AV6: 0.70390981 | AW6: 0.29609019 | AX6: 0 | AY6: 0.0048671574 | AZ6: 0.0045897292 | BA6: 0.0051163595 | BB6: 0.0056695207 | BC6: 0.0043761573 | BD6: 0.0069583976 | BE6: 0 | BF6: 0 | BG6: 0 | BH6: 0.010536678 | BI6: 0.0099396311 | BJ6: 0.01113447 | BK6: 0.021031001 | BL6: -0.0015893245 | BM6: 0.0016602085 | BN6: 0.019441677 | BO6: 0.02269121 | BP6: 0.0070600527 | BQ6: 0.0062728327 | BR6: 0.0078963885 | BS6: 0 | BT6: 0 | BU6: 0 | BV6: 0.0034342708 | BW6: 0.002816102 | BX6: 0.0040524395 | BY6: 0.010494323 | BZ6: 0.0090889347 | CA6: 0.011948828 | CB6: 0.0064638489 | CC6: 0.0053249342 | CD6: 0.82560543 | CE6: 10777 | CF6: 0.021527327 | CG6: 0.0047170819 | CH6: 0.0086095388 | CI6: 79.277757 | CJ6: 74.375076 | CK6: 84.486323 | CL6: 79.277757 | CM6: 74.375076 | CN6: 84.486323 | CO6: 51.699973 | CP6: 47.061058 | CQ6: 56.258608 | CR6: 79.887014 | CS6: 71.821563 | CT6: 87.991379 | CU6: 6.8527874 | CV6: 6.0377973 | CW6: 7.6694456 | CX6: 27.253138 | CY6: 23.385949 | CZ6: 31.538087 | DA6: 9.8629588 | DB6: 7.3800637 | DC6: 12.806862 | DD6: 0 | DE6: 0 | DF6: 0 | DG6: 0.60527477 | DH6: 0.60527477 | DI6: 0.39472523 | DJ6: 0.4989915 | DK6: 0.33569476 | DL6: 65.620754 | DM6: 1.7873165 | DN6: 0.5778826 | DO6: 0.010661119 | DP6: 0.9 | DQ6: 17.326203 | DR6: 0.078945316 | DS6: -0.075576803 | DT6: 0 | DU6: 0 | DY6: 0.006 | DZ6: 0.0068 | EA6: 0.0051 | EB6: 36.012901 | EE6: 43.968884
A7: San_Joaquin_2016 | B7: 2.5759401 | C7: 2.4579689 | D7: 2.6996033 | E7: 2.3746385 | F7: 1.5859806 | G7: 3.2118143 | H7: 0 | I7: 0 | J7: 0 | K7: 4.9505785 | L7: 4.1643477 | M7: 5.8156382 | N7: 1.5859806 | O7: 3.2118143 | P7: 4.7719796 | Q7: 3.7142929 | R7: 6.1650359 | S7: 0 | T7: 1.1897866 | U7: 10.912345 | V7: 9.3412725 | W7: 12.709885 | X7: 1000 | Y7: 0.098709591 | Z7: 9 | AA7: 40.415 | AB7: 264.97396 | AC7: 41547 | AD7: 81234 | AE7: 1.7471737 | AF7: 77 | AG7: 69.132 | AH7: 40 | AI7: 15.074 | AJ7: 48 | AK7: 36 | AM7: 3.7657267 | AN7: Yes | AO7: No | AP7: 20230328 | AQ7: 46494 | AR7: 1.9552546 | AS7: 0.71515197 | AT7: 0.070592358 | AU7: 0.0031214714 | AV7: 0.75007171 | AW7: 0.24992829 | AX7: 0 | AY7: 0.009721484 | AZ7: 0.0090989336 | BA7: 0.010374072 | BB7: 0.0089617806 | BC7: 0.0047999242 | BD7: 0.013379673 | BE7: 0 | BF7: 0 | BG7: 0 | BH7: 0.018683265 | BI7: 0.015716064 | BJ7: 0.021947962 | BK7: 0.041182707 | BL7: -0.0059291569 | BM7: 0.0067838395 | BN7: 0.03525355 | BO7: 0.047966546 | BP7: 0.01800924 | BQ7: 0.014017577 | BR7: 0.023266573 | BS7: 0 | BT7: 0 | BU7: 0 | BV7: 0.004490202 | BW7: 0.0036819657 | BX7: 0.0052984384 | BY7: 0.022499442 | BZ7: 0.017699543 | CA7: 0.028565012 | CB7: 0.0016561277 | CC7: 0.0014869015 | CD7: 0.98852887 | CE7: 23779 | CF7: 0.0016821565 | CG7: 0.00036281801 | CH7: 0.00063392069 | CI7: 7.146618 | CJ7: 6.0889314 | CK7: 8.5396744 | CL7: 7.146618 | CM7: 6.0889314 | CN7: 8.5396744 | CO7: 3.7657267 | CP7: 3.4335939 | CQ7: 4.1035515 | CR7: 7.167857 | CS7: 6.0722207 | CT7: 8.3426882 | CU7: 1.8801136 | CV7: 1.2898468 | CW7: 2.4821492 | CX7: 0 | CY7: 0 | CZ7: 0 | DA7: 0.76830901 | DB7: 0.52142333 | DC7: 1.0600763 | DD7: 1.8020435 | DE7: 1.0162878 | DF7: 3.057949 | DG7: 0.65490953 | DH7: 0.65490953 | DI7: 0.34509047 | DJ7: 0.54633458 | DK7: 0.43730236 | DL7: 4.9505785 | DM7: 1.8998225 | DN7: 0.011143192 | DO7: 0.057351807 | DP7: 0.9 | DQ7: 17.326203 | DR7: 0.16471306 | DS7: -0.14396371 | DT7: 0 | DU7: 0 | DY7: 0.0512 | DZ7: 0.0523 | EA7: 0.0501 | EB7: 2.401159 | EE7: 4.77198
A8: San_Joaquin_2017 | B8: 2.6703882 | C8: 2.5766783 | D8: 2.7519744 | E8: 4.4668887 | F8: 3.7241194 | G8: 5.2793177 | H8: 0 | I8: 0 | J8: 0 | K8: 7.1372769 | L8: 6.3912522 | M8: 7.9535315 | N8: 3.7241194 | O8: 5.2793177 | P8: 7.4447858 | Q8: 6.2324804 | R8: 8.9789547 | S8: 0 | T8: 1.2427775 | U8: 15.82484 | V8: 14.093118 | W8: 17.838027 | X8: 1000 | Y8: 0.11924573 | Z8: 11 | AA8: 40.99 | AB8: 284.66581 | AC8: 40365 | AD8: 192459 | AE8: 1.7471737 | AF8: 86 | AG8: 80.173 | AH8: 54 | AI8: 15.945 | AJ8: 144 | AK8: 89 | AM8: 3.9131657 | AN8: Yes | AO8: No | AP8: 20230328 | AQ8: 110154 | AR8: 4.7679522 | AS8: 0.45796686 | AT8: 0.054610591 | AU8: 0.003770881 | AV8: 0.34370242 | AW8: 0.65629758 | AX8: 0 | AY8: 0.0093807831 | AZ8: 0.0086619693 | BA8: 0.0100066 | BB8: 0.015691693 | BC8: 0.0099941905 | BD8: 0.02192353 | BE8: 0 | BF8: 0 | BG8: 0 | BH8: 0.025072477 | BI8: 0.022451773 | BJ8: 0.02793989 | BK8: 0.05559094 | BL8: -0.0060833526 | BM8: 0.0070721074 | BN8: 0.049507588 | BO8: 0.062663048 | BP8: 0.026152722 | BQ8: 0.021894025 | BR8: 0.03154209 | BS8: 0 | BT8: 0 | BU8: 0 | BV8: 0.0043657419 | BW8: 0.0035799084 | BX8: 0.0051515755 | BY8: 0.030518464 | BZ8: 0.025473933 | CA8: 0.036693665 | CB8: 0.00078072517 | CC8: 0.0007278265 | CD8: 0.98053415 | CE8: 23103 | CF8: 0.0023373588 | CG8: 0.00039502044 | CH8: 0.00069017011 | CI8: 11.911675 | CJ8: 10.699369 | CK8: 13.445843 | CL8: 11.911675 | CM8: 10.699369 | CN8: 13.445843 | CO8: 3.9131657 | CP8: 3.5957558 | CQ8: 4.2184518 | CR8: 11.914754 | CS8: 10.294406 | CT8: 13.677368 | CU8: 2.4029565 | CV8: 1.7642831 | CW8: 3.2514504 | CX8: 0 | CY8: 0 | CZ8: 0 | DA8: 0.13845571 | DB8: 0.075047583 | DC8: 0.44879336 | DD8: 4.2590312 | DE8: 3.3091377 | DF8: 5.6232244 | DG8: 0.75271877 | DH8: 0.75271877 | DI8: 0.24728123 | DJ8: 0.54898166 | DK8: 0.47044781 | DL8: 7.1372769 | DM8: 2.6207325 | DN8: 0.012321595 | DO8: 0.054455461 | DP8: 0.9 | DQ8: 17.326203 | DR8: 0.12720407 | DS8: -0.10943445 | DT8: 0 | DU8: 0 | DY8: 0.0485 | DZ8: 0.0496 | EA8: 0.0474 | EB8: 4.474922 | EE8: 7.444786
A9: San_Joaquin_summer2020 | B9: 1.8137632 | C9: 1.7684535 | D9: 1.8701691 | E9: 3.8353497 | F9: 3.1684788 | G9: 4.645684 | H9: 0 | I9: 0 | J9: 0 | K9: 5.6491128 | L9: 4.9786474 | M9: 6.45781 | N9: 3.1684788 | O9: 4.645684 | P9: 4.1889557 | Q9: 3.5147838 | R9: 5.1391793 | S9: 0 | T9: 0.87037445 | U9: 10.708443 | V9: 9.5566091 | W9: 12.07745 | X9: 1000 | Y9: 0.14962666 | Z9: 23.632192 | AA9: 36.556644 | AB9: 231.42089 | AC9: 31919 | AD9: 238393 | AE9: 1.995878 | AF9: 94 | AG9: 90.462 | AH9: 39 | AI9: 13.337 | AJ9: 151 | AK9: 65 | AM9: 2.6841376 | AN9: Yes | AO9: No | AP9: 20230328 | AQ9: 119442 | AR9: 7.4688594 | AS9: 0.3659088 | AT9: 0.054749711 | AU9: 0.0047316104 | AV9: 0.25471912 | AW9: 0.74528088 | AX9: 0 | AY9: 0.0078375085 | AZ9: 0.0073024323 | BA9: 0.0085036243 | BB9: 0.016573049 | BC9: 0.0086977631 | BD9: 0.02614254 | BE9: 0 | BF9: 0 | BG9: 0 | BH9: 0.024410557 | BI9: 0.021513388 | BJ9: 0.027905044 | BK9: 0.046272587 | BL9: -0.0049772253 | BM9: 0.0059156607 | BN9: 0.041295361 | BO9: 0.052188247 | BP9: 0.018101027 | BQ9: 0.015187842 | BR9: 0.022207068 | BS9: 0 | BT9: 0 | BU9: 0 | BV9: 0.0037610021 | BW9: 0.0030840217 | BX9: 0.0044379825 | BY9: 0.021862029 | BZ9: 0.018271864 | CA9: 0.02664505 | CB9: 0.00078699285 | CC9: 0.00075737178 | CD9: 0.9836107 | CE9: 15992 | CF9: 0.0024387194 | CG9: 0.0004178389 | CH9: 0.00083397949 | CI9: 8.0243054 | CJ9: 7.3501335 | CK9: 8.974529 | CL9: 8.0243054 | CM9: 7.3501335 | CN9: 8.974529 | CO9: 2.6841376 | CP9: 2.4821605 | CQ9: 2.897211 | CR9: 8.0265417 | CS9: 6.2056205 | CT9: 10.237035 | CU9: 3.570701 | CV9: 2.9721721 | CW9: 4.2543052 | CX9: 0.52539665 | CY9: 0.34291688 | CZ9: 1.2972067 | DA9: 0.01867589 | DB9: 0.011462354 | DC9: 0.075036913 | DD9: 0.074182202 | DE9: 0.047038281 | DF9: 0.23743176 | DG9: 0.74933357 | DH9: 0.74933357 | DI9: 0.25066643 | DJ9: 0.47245103 | DK9: 0.39116881 | DL9: 5.6491128 | DM9: 3.0636929 | DN9: 0.014471041 | DO9: 0.061625508 | DP9: 0.9 | DQ9: 17.326203 | DR9: 0.12785159 | DS9: -0.10756282 | DT9: 0 | DU9: 0 | DY9: 0.0565 | DZ9: 0.0574 | EA9: 0.0555 | EB9: 3.843429 | EE9: 4.188956
A10: San_Joaquin_fall2020 | B10: 1.8878621 | C10: 1.8370948 | D10: 1.941767 | E10: 2.5737452 | F10: 1.9474368 | G10: 3.4763426 | H10: 0 | I10: 0 | J10: 0 | K10: 4.4616073 | L10: 3.8333958 | M10: 5.3713353 | N10: 1.9474368 | O10: 3.4763426 | P10: 3.7938049 | Q10: 2.9650902 | R10: 4.9503656 | S10: 0 | T10: 0.92232287 | U10: 9.177735 | V10: 7.8798002 | W10: 10.67418 | X10: 1000 | Y10: 0.19641561 | Z10: 20.646402 | AA10: 37.591104 | AB10: 245.23328 | AC10: 33090 | AD10: 238974 | AE10: 1.995878 | AF10: 48 | AG10: 45.261 | AH10: 27 | AI10: 8.067 | AJ10: 63 | AK10: 34 | AM10: 2.810185 | AN10: Yes | AO10: No | AP10: 20230328 | AQ10: 119733 | AR10: 7.2219675 | AS10: 0.37211076 | AT10: 0.073088364 | AU10: 0.0062112071 | AV10: 0.44663385 | AW10: 0.55336615 | AX10: 0 | AY10: 0.0076982298 | AZ10: 0.0071418996 | BA10: 0.0082889431 | BB10: 0.010495089 | BC10: 0.0036317326 | BD10: 0.020386141 | BE10: 0 | BF10: 0 | BG10: 0 | BH10: 0.018193319 | BI10: 0.01563163 | BJ10: 0.021902963 | BK10: 0.037424509 | BL10: -0.0052926536 | BM10: 0.0061021268 | BN10: 0.032131856 | BO10: 0.043526636 | BP10: 0.015470188 | BQ10: 0.012090897 | BR10: 0.020186353 | BS10: 0 | BT10: 0 | BU10: 0 | BV10: 0.0037610021 | BW10: 0.0030840217 | BX10: 0.0044379825 | BY10: 0.01923119 | BZ10: 0.015174919 | CA10: 0.024624336 | CB10: 0.00040089198 | CC10: 0.00037801609 | CD10: 0.98378097 | CE10: 16579 | CF10: 0.0016285663 | CG10: 0.00024378966 | CH10: 0.00048657941 | CI10: 6.36755 | CJ10: 5.5388354 | CK10: 7.5241107 | CL10: 6.36755 | CM10: 5.5388354 | CN10: 7.5241107 | CO10: 2.810185 | CP10: 2.5933995 | CQ10: 3.030108 | CR10: 6.3643979 | CS10: 4.6697632 | CT10: 8.7994818 | CU10: 2.8943582 | CV10: 2.2094105 | CW10: 3.8017291 | CX10: 0.6748833 | CY10: 0.42375196 | CZ10: 1.5724615 | DA10: 0.22456333 | DB10: 0.15450208 | DC10: 0.28627927 | DD10: 0 | DE10: 0 | DF10: 0 | DG10: 0.69379041 | DH10: 0.69379041 | DI10: 0.30620959 | DJ10: 0.51385383 | DK10: 0.41335314 | DL10: 4.4616073 | DM10: 2.3250252 | DN10: 0.014791801 | DO10: 0.061625508 | DP10: 0.9 | DQ10: 17.326203 | DR10: 0.163021 | DS10: -0.14142859 | DT10: 0 | DU10: 0 | DY10: 0.0565 | DZ10: 0.0574 | EA10: 0.0555 | EB10: 2.580516 | EE10: 3.793805
A11: San_Joaquin_fall2021 | B11: 1.7279457 | C11: 1.666497 | D11: 1.7912582 | E11: 1.7547684 | F11: 1.2914509 | G11: 2.3126099 | H11: 0 | I11: 0 | J11: 0 | K11: 3.4827141 | L11: 3.0250833 | M11: 4.0385923 | N11: 1.2914509 | O11: 2.3126099 | P11: 0.79395397 | Q11: 0.55990172 | R11: 1.0641179 | S11: 0 | T11: 0.74474802 | U11: 5.0214161 | V11: 4.3764156 | W11: 5.7468923 | X11: 1000 | Y11: 0.11142142 | Z11: 15.95883 | AA11: 23.223 | AB11: 198.01851 | AC11: 33418 | AD11: 119340 | AE11: 1.995878 | AF11: 47 | AG11: 41.14 | AH11: 35 | AI11: 15.716 | AJ11: 17 | AK11: 12 | AM11: 2.4726937 | AN11: Yes | AO11: No | AP11: 20230328 | AQ11: 59793 | AR11: 3.5712238 | AS11: 0.52916543 | AT11: 0.058960365 | AU11: 0.0035234547 | AV11: 0.42546891 | AW11: 0.57453109 | AX11: 0 | AY11: 0.0087261829 | AZ11: 0.0081397538 | BA11: 0.009330399 | BB11: 0.0088616383 | BC11: 0.0044400181 | BD11: 0.014185338 | BE11: 0 | BF11: 0 | BG11: 0 | BH11: 0.017587821 | BI11: 0.015276771 | BJ11: 0.020395025 | BK11: 0.025358317 | BL11: -0.0032572739 | BM11: 0.003663679 | BN11: 0.022101043 | BO11: 0.029021996 | BP11: 0.0040094938 | BQ11: 0.0028275222 | BR11: 0.0053738307 | BS11: 0 | BT11: 0 | BU11: 0 | BV11: 0.0037610021 | BW11: 0.0030840217 | BX11: 0.0044379825 | BY11: 0.0077704959 | BZ11: 0.005911544 | CA11: 0.0098118133 | CB11: 0.00078604519 | CC11: 0.00068804041 | CD11: 0.96072198 | CE11: 16743 | CF11: 0.0020904258 | CG11: 0.00047028547 | CH11: 0.00093866093 | CI11: 2.5487223 | CJ11: 2.3146701 | CK11: 2.8188863 | CL11: 2.5487223 | CM11: 2.3146701 | CN11: 2.8188863 | CO11: 2.4726937 | CP11: 2.2771904 | CQ11: 2.6700609 | CR11: 2.5597313 | CS11: 1.6740932 | CT11: 3.6189042 | CU11: 0.53770521 | CV11: 0.36721408 | CW11: 0.75176112 | CX11: 0.25624876 | CY11: 0.12427099 | CZ11: 0.4367343 | DA11: 0 | DB11: 0 | DC11: 0 | DD11: 0 | DE11: 0 | DF11: 0 | DG11: 0.50756012 | DH11: 0.50756012 | DI11: 0.49243988 | DJ11: 0.30642374 | DK11: 0.15810584 | DL11: 3.4827141 | DM11: 1.936358 | DN11: 0.011826943 | DO11: 0.061625508 | DP11: 0.9 | DQ11: 17.326203 | DR11: 0.14446356 | DS11: -0.12844561 | DT11: 0 | DU11: 0 | DY11: 0.0565 | DZ11: 0.0574 | EA11: 0.0555 | EB11: 1.776413 | EE11: 0.793954
A12: Denver_summer2021 | B12: 12.232833 | C12: 11.960012 | D12: 12.51506 | E12: 2.3047932 | F12: 1.6525682 | G12: 3.0979952 | H12: 0 | I12: 0 | J12: 0 | K12: 14.537626 | L12: 13.816908 | M12: 15.398868 | N12: 1.6525682 | O12: 3.0979952 | P12: 0.71351519 | Q12: 0.47193469 | R12: 1.0533051 | S12: 0 | T12: 6.246524 | U12: 21.497665 | V12: 19.584265 | W12: 23.515509 | X12: 1000 | Y12: 0.047402712 | Z12: 11.102345 | AA12: 75.042 | AB12: 1997.3945 | AC12: 11671 | AD12: 59356 | AE12: 1.6088026 | AF12: 34 | AG12: 27.151 | AH12: 27 | AI12: 8.491 | AJ12: 24 | AK12: 9 | AM12: 18.479357 | AN12: Yes | AO12: No | AP12: 20230328 | AQ12: 36894 | AR12: 5.0860215 | AS12: 0.44341553 | AT12: 0.021019099 | AU12: 0.0014990054 | AV12: 0.89945091 | AW12: 0.10054909 | AX12: 0 | AY12: 0.006124395 | AZ12: 0.0058163584 | BA12: 0.0064430522 | BB12: 0.0011538998 | BC12: 0.00041748479 | BD12: 0.0020494894 | BE12: 0 | BF12: 0 | BG12: 0 | BH12: 0.0072782948 | BI12: 0.0069174656 | BJ12: 0.0077094773 | BK12: 0.010762854 | BL12: -0.00095794812 | BM12: 0.001010238 | BN12: 0.0098049058 | BO12: 0.011773092 | BP12: 0.00035722297 | BQ12: 0.00023627515 | BR12: 0.00052733954 | BS12: 0 | BT12: 0 | BU12: 0 | BV12: 0.0031273362 | BW12: 0.0025644157 | BX12: 0.0036902567 | BY12: 0.0034845591 | BZ12: 0.0028006908 | CA12: 0.0042175962 | CB12: 0.00092155906 | CC12: 0.00073591912 | CD12: 0.97703263 | CE12: 7254 | CF12: 0.0037220844 | CG12: 0.00072752977 | CH12: 0.0011705266 | CI12: 3.0183084 | CJ12: 2.7767279 | CK12: 3.3580982 | CL12: 3.0183084 | CM12: 2.7767279 | CN12: 3.3580982 | CO12: 18.479357 | CP12: 17.082162 | CQ12: 19.885958 | CR12: 3.063132 | CS12: 1.5951947 | CT12: 4.8604373 | CU12: 0.21942916 | CV12: 0.1252747 | CW12: 0.40408769 | CX12: 0.25155834 | CY12: 0.13947767 | CZ12: 0.45244345 | DA12: 0.24252769 | DB12: 0.13470518 | DC12: 0.51540879 | DD12: 0 | DE12: 0 | DF12: 0 | DG12: 0.1403988 | DH12: 0.1403988 | DI12: 0.8596012 | DJ12: 0.32376 | DK12: 0.03319053 | DL12: 14.537626 | DM12: 1.161116 | DN12: 0.27535077 | DO12: 0.0097082922 | DP12: 0.9 | DQ12: 17.326203 | DR12: 0.093858945 | DS12: -0.089003162 | DT12: 0 | DU12: 0 | DY12: 0.0054 | DZ12: 0.0062 | EA12: 0.0047 | EB12: 2.362062 | EE12: 0.713515
A13: Denver_fall2021 | B13: 12.319771 | C13: 12.061479 | D13: 12.593345 | E13: 2.306704 | F13: 1.5837147 | G13: 3.1750613 | H13: 0 | I13: 0 | J13: 0 | K13: 14.626475 | L13: 13.84779 | M13: 15.537186 | N13: 1.5837147 | O13: 3.1750613 | P13: 2.332878 | Q13: 1.5725196 | R13: 4.098675 | S13: 0 | T13: 6.1693766 | U13: 23.12873 | V13: 20.796505 | W13: 26.224278 | X13: 1000 | Y13: 0.089035172 | Z13: 10.160213 | AA13: 66.55 | AB13: 1972.7258 | AC13: 11688 | AD13: 67811 | AE13: 1.6088026 | AF13: 40 | AG13: 31.592 | AH13: 33 | AI13: 8.473 | AJ13: 29 | AK13: 21 | AM13: 18.489148 | AN13: Yes | AO13: No | AP13: 20230328 | AQ13: 42149 | AR13: 5.8016518 | AS13: 0.41516829 | AT13: 0.03696458 | AU13: 0.0028155394 | AV13: 0.87637878 | AW13: 0.12362122 | AX13: 0 | AY13: 0.0062450501 | AZ13: 0.0059296804 | BA13: 0.0065790786 | BB13: 0.0011692979 | BC13: 0.00028654123 | BD13: 0.0022295461 | BE13: 0 | BF13: 0 | BG13: 0 | BH13: 0.007414348 | BI13: 0.0070196222 | BJ13: 0.0078759988 | BK13: 0.01172425 | BL13: -0.0011822349 | BM13: 0.0015691728 | BN13: 0.010542015 | BO13: 0.013293423 | BP13: 0.0011825658 | BQ13: 0.00079713036 | BR13: 0.0020776709 | BS13: 0 | BT13: 0 | BU13: 0 | BV13: 0.0031273362 | BW13: 0.0025644157 | BX13: 0.0036902567 | BY13: 0.004309902 | BZ13: 0.003361546 | CA13: 0.0057679276 | CB13: 0.00094901421 | CC13: 0.00074953142 | CD13: 0.97363305 | CE13: 7265 | CF13: 0.0045423262 | CG13: 0.00072493155 | CH13: 0.0011662767 | CI13: 4.639582 | CJ13: 3.8792236 | CK13: 6.405379 | CL13: 4.639582 | CM13: 3.8792236 | CN13: 6.405379 | CO13: 18.489148 | CP13: 17.120368 | CQ13: 19.873209 | CR13: 4.7008626 | CS13: 2.9447912 | CT13: 6.8126629 | CU13: 1.1640808 | CV13: 0.68079136 | CW13: 2.8266944 | CX13: 0.74421681 | CY13: 0.51435544 | CZ13: 1.0647944 | DA13: 0.42458042 | DB13: 0.24874888 | DC13: 0.70625726 | DD13: 0 | DE13: 0 | DF13: 0 | DG13: 0.20059553 | DH13: 0.20059553 | DI13: 0.79940447 | DJ13: 0.36760607 | DK13: 0.10086374 | DL13: 14.626475 | DM13: 1.1559367 | DN13: 0.2715383 | DO13: 0.0097082922 | DP13: 0.9 | DQ13: 17.326203 | DR13: 0.13383552 | DS13: -0.1008379 | DT13: 0 | DU13: 0 | DY13: 0.0054 | DZ13: 0.0062 | EA13: 0.0047 | EB13: 2.372246 | EE13: 2.332878
A14: Pennsylvania_2021 | B14: 11.879673 | C14: 11.396827 | D14: 12.404131 | E14: 38.481574 | F14: 32.707202 | G14: 44.704702 | H14: 0 | I14: 0 | J14: 0 | K14: 50.361247 | L14: 44.568236 | M14: 56.582978 | N14: 32.707202 | O14: 44.704702 | P14: 7.8447682 | Q14: 5.6389987 | R14: 10.17957 | S14: 0 | T14: 18.142916 | U14: 76.348931 | V14: 67.057398 | W14: 86.328208 | X14: 1000 | Y14: 0.057544121 | Z14: 92.241416 | AA14: 105.41319 | AB14: 10242.48 | AC14: 16105 | AD14: 27797 | AE14: 1.2580446 | AF14: 64 | AG14: 62 | AH14: 43 | AI14: 29.502 | AJ14: 23 | AK14: 17 | AM14: 30.022589 | AN14: Yes | AO14: No | AP14: 20230328 | AQ14: 22095 | AR14: 1.726037 | AS14: 0.76115823 | AT14: 0.043800181 | AU14: 0.0018197049 | AV14: 0.072745246 | AW14: 0.92725475 | AX14: 0 | AY14: 0.0011598434 | AZ14: 0.0010979095 | BA14: 0.0012271148 | BB14: 0.0037570562 | BC14: 0.0030163864 | BD14: 0.0045552874 | BE14: 0 | BF14: 0 | BG14: 0 | BH14: 0.0049168997 | BI14: 0.004351313 | BJ14: 0.0055243435 | BK14: 0.0074541449 | BL14: -0.00090715654 | BM14: 0.00097430283 | BN14: 0.0065469884 | BO14: 0.0084284478 | BP14: 0.00076590515 | BQ14: 0.00055055012 | BR14: 0.00099385792 | BS14: 0 | BT14: 0 | BU14: 0 | BV14: 0.0017713401 | BW14: 0.0014524989 | BX14: 0.0020901813 | BY14: 0.0025372452 | BZ14: 0.002003049 | CA14: 0.0030840392 | CB14: 0.0028965829 | CC14: 0.0028060647 | CD14: 0.99311756 | CE14: 12801 | CF14: 0.0033591126 | CG14: 0.0018318535 | CH14: 0.0023046637 | CI14: 46.326342 | CJ14: 44.120572 | CK14: 48.661143 | CL14: 46.326342 | CM14: 44.120572 | CN14: 48.661143 | CO14: 30.022589 | CP14: 26.274018 | CQ14: 33.812771 | CR14: 46.30476 | CS14: 38.648639 | CT14: 54.503801 | CU14: 1.3835087 | CV14: 0.55639226 | CW14: 2.3588597 | CX14: 6.3610066 | CY14: 4.3455191 | CZ14: 8.5359151 | DA14: 0.10025282 | DB14: 0.02394456 | DC14: 0.38702772 | DD14: 0 | DE14: 0 | DF14: 0 | DG14: 0.60676838 | DH14: 0.60676838 | DI14: 0.39323162 | DJ14: 0.34038117 | DK14: 0.10274796 | DL14: 50.361247 | DM14: 4.2101392 | DN14: 0.80013124 | DO14: 0.0054988291 | DP14: 0.9 | DQ14: 17.326203 | DR14: 0.1306994 | DS14: -0.12170612 | DT14: 0 | DU14: 0 | DY14: 0.0031 | DZ14: 0.0035 | EA14: 0.0026 | EB14: 38.544592 | EE14: 7.844768
A15: Uinta_2020 | B15: 10.546107 | C15: 10.285607 | D15: 10.815668 | E15: 5.8726323 | F15: 4.7375277 | G15: 7.0345028 | H15: 0 | I15: 0 | J15: 0 | K15: 16.418739 | L15: 15.274613 | M15: 17.584309 | N15: 4.7375277 | O15: 7.0345028 | P15: 2.3677981 | Q15: 1.7530518 | R15: 3.2232782 | S15: 0 | T15: 1.3191311 | U15: 20.105669 | V15: 18.449824 | W15: 21.724096 | X15: 1000 | Y15: 0.070991531 | Z15: 8.3545392 | AA15: 52.98 | AB15: 350.73927 | AC15: 9185 | AD15: 32340 | AE15: 1.7099474 | AF15: 56 | AG15: 41.13 | AH15: 42 | AI15: 24.905 | AJ15: 52 | AK15: 25 | AM15: 11.865238 | AN15: Yes | AO15: No | AP15: 20230328 | AQ15: 18912 | AR15: 3.521132 | AS15: 0.53291611 | AT15: 0.03783253 | AU15: 0.0022449493 | AV15: 0.70703016 | AW15: 0.29296984 | AX15: 0 | AY15: 0.030068225 | AZ15: 0.028674538 | BA15: 0.031510386 | BB15: 0.016743584 | BC15: 0.010670732 | BD15: 0.022959633 | BE15: 0 | BF15: 0 | BG15: 0 | BH15: 0.046811809 | BI15: 0.043549767 | BJ15: 0.050134987 | BK15: 0.057323689 | BL15: -0.0047210145 | BM15: 0.004614333 | BN15: 0.052602674 | BO15: 0.061938022 | BP15: 0.0067508782 | BQ15: 0.0049981624 | BR15: 0.0091899554 | BS15: 0 | BT15: 0 | BU15: 0 | BV15: 0.0037610021 | BW15: 0.0030840217 | BX15: 0.0044379825 | BY15: 0.01051188 | BZ15: 0.0080821841 | CA15: 0.013627938 | CB15: 0.0029610829 | CC15: 0.0021748096 | CD15: 0.9481536 | CE15: 5371 | CF15: 0.0078197729 | CG15: 0.0027114861 | CH15: 0.0046369391 | CI15: 8.2404304 | CJ15: 7.6256842 | CK15: 9.0959106 | CL15: 8.2404304 | CM15: 7.6256842 | CN15: 9.0959106 | CO15: 11.865238 | CP15: 11.367294 | CQ15: 12.372243 | CR15: 8.3755421 | CS15: 6.2608101 | CT15: 10.581536 | CU15: 1.809119 | CV15: 1.3290974 | CW15: 2.4350056 | CX15: 0.2653703 | CY15: 0.17108015 | CZ15: 0.41351091 | DA15: 0.29330879 | DB15: 0.13699981 | DC15: 0.87323479 | DD15: 0 | DE15: 0 | DF15: 0 | DG15: 0.409853 | DH15: 0.409853 | DI15: 0.590147 | DJ15: 0.18337649 | DK15: 0.11776603 | DL15: 16.418739 | DM15: 1.4761386 | DN15: 0.065302414 | DO15: 0.024005542 | DP15: 0.9 | DQ15: 17.326203 | DR15: 0.08050515 | DS15: -0.082370586 | DT15: 0 | DU15: 0 | DY15: 0.0189 | DZ15: 0.0198 | EA15: 0.0179 | EB15: 6.040912 | EE15: 2.367798
A16: Fort_Worth_2021 | B16: 3.5016955 | C16: 3.2833694 | D16: 3.7428101 | E16: 15.138765 | F16: 13.030171 | G16: 17.581124 | H16: 0.75265304 | I16: 0.52351724 | J16: 1.0772285 | K16: 19.393114 | L16: 17.218757 | M16: 21.850881 | N16: 13.030171 | O16: 17.581124 | P16: 2.5528017 | Q16: 2.1109539 | R16: 3.0565756 | S16: 1.6072708 | T16: 2.186488 | U16: 25.739674 | V16: 23.080581 | W16: 28.645476 | X16: 1000 | Y16: 0.065015162 | Z16: 10.889258 | AA16: 55.886 | AB16: 636.66735 | AC16: 7474 | AD16: 12982 | AE16: 1.6224651 | AF16: 80 | AG16: 80 | AH16: 49 | AI16: 40.006 | AJ16: 49 | AK16: 23 | AM16: 5.6881835 | AN16: Yes | AO16: No | AP16: 20230328 | AQ16: 8001 | AR16: 1.7370821 | AS16: 0.7587345 | AT16: 0.049329247 | AU16: 0.00205596 | AV16: 0.15345486 | AW16: 0.83086326 | AX16: 0.015681874 | AY16: 0.0055000393 | AZ16: 0.0050480761 | BA16: 0.005999178 | BB16: 0.02377814 | BC16: 0.019413076 | BD16: 0.02883414 | BE16: 0.0011821763 | BF16: 0.00070783542 | BG16: 0.0018540895 | BH16: 0.030460355 | BI16: 0.02704514 | BJ16: 0.034320719 | BK16: 0.040428764 | BL16: -0.0041765812 | BM16: 0.0045640813 | BN16: 0.036252183 | BO16: 0.044992846 | BP16: 0.0040096319 | BQ16: 0.0033156308 | BR16: 0.004800899 | BS16: 0.0025245064 | BT16: 0.0019803151 | BU16: 0.0031013627 | BV16: 0.0034342708 | BW16: 0.002816102 | BX16: 0.0040524395 | BY16: 0.009968409 | BZ16: 0.0083660291 | CA16: 0.011602155 | CB16: 0.0099987502 | CC16: 0.0099987502 | CD16: 0.98912832 | CE16: 4606 | CF16: 0.010638298 | CG16: 0.0053526893 | CH16: 0.0086856274 | CI16: 17.691567 | CJ16: 17.249719 | CK16: 18.195341 | CL16: 19.298838 | CM16: 18.510521 | CN16: 20.169877 | CO16: 5.6881835 | CP16: 5.0762896 | CQ16: 6.322866 | CR16: 17.72156 | CS16: 14.944751 | CT16: 20.94021 | CU16: 1.0166129 | CV16: 0.81235059 | CW16: 1.2215896 | CX16: 0.94529093 | CY16: 0.63345602 | CZ16: 1.323353 | DA16: 0.59089787 | DB16: 0.34228087 | DC16: 0.83922829 | DD16: Null | DE16: Null | DF16: Null | DG16: 0.68732508 | DH16: 0.74976836 | DI16: 0.22099088 | DJ16: 0.24656858 | DK16: 0.099178231 | DL16: 19.393114 | DM16: 5.4781952 | DN16: 0.13822565 | DO16: 0.010661119 | DP16: 0.9 | DQ16: 17.326203 | DR16: 0.11288133 | DS16: -0.10329695 | DT16: 0.029240759 | DU16: 0.06007805 | DY16: 0.006 | DZ16: 0.0068 | EA16: 0.0051 | EB16: 15.168759 | EE16: 2.552802
A17: Permian_2019_F2021_bounds | B17: 22.148702 | C17: 21.735113 | D17: 22.645529 | E17: 104.3653 | F17: 99.447983 | G17: 110.04035 | H17: 0 | I17: 0 | J17: 0 | K17: 126.51401 | L17: 121.56414 | M17: 132.25819 | N17: 99.447983 | O17: 110.04035 | P17: 75.485924 | Q17: 68.82265 | R17: 83.688109 | S17: 0 | T17: 17.29491 | U17: 219.29484 | V17: 207.36829 | W17: 232.04808 | X17: 1000 | Y17: 0.066200513 | Z17: 16.353134 | AA17: 58.47 | AB17: 4755.8021 | AC17: 17164 | AD17: 152653 | AE17: 1.8250769 | AF17: 1052 | AG17: 998.006 | AH17: 540 | AI17: 166.933 | AJ17: 681 | AK17: 278 | AM17: 39.443612 | AN17: Yes | AO17: No | AP17: 20230328 | AQ17: 83641 | AR17: 8.894194 | AS17: 0.33531015 | AT17: 0.022197704 | AU17: 0.002093444 | AV17: 0.34217279 | AW17: 0.65782721 | AX17: 0 | AY17: 0.0046571958 | AZ17: 0.0043978385 | BA17: 0.0049687511 | BB17: 0.021944837 | BC17: 0.018861237 | BD17: 0.025503598 | BE17: 0 | BF17: 0 | BG17: 0 | BH17: 0.026602033 | BI17: 0.025561228 | BJ17: 0.027809861 | BK17: 0.04611101 | BL17: -0.0025077886 | BM17: 0.0026816161 | BN17: 0.043603221 | BO17: 0.048792626 | BP17: 0.015872385 | BQ17: 0.014471302 | BR17: 0.017597054 | BS17: 0 | BT17: 0 | BU17: 0 | BV17: 0.0036365916 | BW17: 0.0029820052 | BX17: 0.0042911781 | BY17: 0.019508977 | BZ17: 0.017453307 | CA17: 0.021888232 | CB17: 0.012577564 | CC17: 0.011932019 | CD17: 0.77723967 | CE17: 9404 | CF17: 0.057422373 | CG17: 0.0097257632 | CH17: 0.017751276 | CI17: 179.85123 | CJ17: 173.18795 | CK17: 188.05341 | CL17: 179.85123 | CM17: 173.18795 | CN17: 188.05341 | CO17: 39.443612 | CP17: 35.916939 | CQ17: 43.053523 | CR17: 179.92729 | CS17: 165.2598 | CT17: 196.87586 | CU17: 22.333899 | CV17: 20.041045 | CW17: 24.937251 | CX17: 34.922741 | CY17: 31.38451 | CZ17: 39.550834 | DA17: 18.229284 | DB17: 13.569312 | DC17: 24.782488 | DD17: 0 | DE17: 0 | DF17: 0 | DG17: 0.82013382 | DH17: 0.82013382 | DI17: 0.17986618 | DJ17: 0.42308642 | DK17: 0.34422003 | DL17: 126.51401 | DM17: 4.4396245 | DN17: 0.5057212 | DO17: 0.011491852 | DP17: 0.9 | DQ17: 17.326203 | DR17: 0.058154851 | DS17: -0.054391392 | DT17: 0 | DU17: 0 | DY17: 0.006 | DZ17: 0.0068 | EA17: 0.0051
A18: Permian_2019_F2021_bounds_Delaware | B18: 13.618146 | C18: 13.368396 | D18: 13.906352 | E18: 57.866334 | F18: 54.50886 | G18: 61.619504 | H18: 0 | I18: 0 | J18: 0 | K18: 71.484479 | L18: 68.148976 | M18: 75.257285 | N18: 54.50886 | O18: 61.619504 | P18: 37.214472 | Q18: 34.109332 | R18: 41.35431 | S18: 0 | T18: 13.139793 | U18: 121.83874 | V18: 114.57394 | W18: 129.61674 | X18: 1000 | Y18: 0.079024395 | Z18: 16.353134 | AA18: 53.834 | AB18: 3613.2165 | AC18: 7955 | AD18: 100870 | AE18: 1.8250769 | AF18: 922 | AG18: 875.148 | AH18: 447 | AI18: 117.859 | AJ18: 558 | AK18: 202 | AM18: 26.757939 | AN18: Yes | AO18: No | AP18: 20230328 | AQ18: 55268 | AR18: 12.681964 | AS18: 0.28080623 | AT18: 0.022190542 | AU18: 0.0024989708 | AV18: 0.39189647 | AW18: 0.60810353 | AX18: 0 | AY18: 0.0037689814 | AZ18: 0.003522829 | BA18: 0.0040530367 | BB18: 0.016015186 | BC18: 0.012706071 | BD18: 0.019714298 | BE18: 0 | BF18: 0 | BG18: 0 | BH18: 0.019784167 | BI18: 0.018861028 | BJ18: 0.020828335 | BK18: 0.0337203 | BL18: -0.0020106208 | BM18: 0.0021526514 | BN18: 0.031709679 | BO18: 0.035872951 | BP18: 0.010299541 | BQ18: 0.0094401571 | BR18: 0.01144529 | BS18: 0 | BT18: 0 | BU18: 0 | BV18: 0.0036365916 | BW18: 0.0029820052 | BX18: 0.0042911781 | BY18: 0.013936133 | BZ18: 0.012422162 | CA18: 0.015736468 | CB18: 0.016682348 | CC18: 0.015834624 | CD18: 0.72979374 | CE18: 4358 | CF18: 0.10256999 | CG18: 0.014815713 | CH18: 0.027044286 | CI18: 95.080806 | CJ18: 91.975665 | CK18: 99.220643 | CL18: 95.080806 | CM18: 91.975665 | CN18: 99.220643 | CO18: 26.757939 | CP18: 24.143026 | CQ18: 29.411308 | CR18: 95.140759 | CS18: 83.076043 | CT18: 108.50894 | CU18: 9.544423 | CV18: 8.0163724 | CW18: 11.521331 | CX18: 24.126113 | CY18: 22.06504 | CZ18: 26.915883 | DA18: 3.5439364 | DB18: 2.6744617 | DC18: 6.8036968 | DD18: 0 | DE18: 0 | DF18: 0 | DG18: 0.78038188 | DH18: 0.78038188 | DI18: 0.21961812 | DJ18: 0.41328555 | DK18: 0.30543943 | DL18: 71.484479 | DM18: 3.8309006 | DN18: 0.8290997 | DO18: 0.011491852 | DP18: 0.9 | DQ18: 17.326203 | DR18: 0.063840824 | DS18: -0.059625543 | DT18: 0 | DU18: 0 | DY18: 0.006 | DZ18: 0.0068 | EA18: 0.0051
A19: Permian_2019_F2021_Midland | B19: 8.943957 | C19: 8.5812303 | D19: 9.3585013 | E19: 46.320256 | F19: 42.849983 | G19: 50.10698 | H19: 0 | I19: 0 | J19: 0 | K19: 55.264213 | L19: 51.75283 | M19: 59.060329 | N19: 42.849983 | O19: 50.10698 | P19: 38.320203 | Q19: 31.78791 | R19: 47.375104 | S19: 0 | T19: 4.1551174 | U19: 97.739534 | V19: 89.163126 | W19: 107.897 | X19: 1000 | Y19: 0.11291444 | Z19: 16.353134 | AA19: 109.707 | AB19: 1142.5856 | AC19: 9209 | AD19: 51783 | AE19: 1.8250769 | AF19: 130 | AG19: 124.363 | AH19: 93 | AI19: 49.05 | AJ19: 123 | AK19: 76 | AM19: 13.099074 | AN19: Yes | AO19: No | AP19: 20230328 | AQ19: 28373 | AR19: 5.6239841 | AS19: 0.4216751 | AT19: 0.047613209 | AU19: 0.0035706682 | AV19: 0.2402536 | AW19: 0.7597464 | AX19: 0 | AY19: 0.007827822 | AZ19: 0.0070749645 | BA19: 0.0086882296 | BB19: 0.040539855 | BC19: 0.03333713 | BD19: 0.048399393 | BE19: 0 | BF19: 0 | BG19: 0 | BH19: 0.048367677 | BI19: 0.045294487 | BJ19: 0.051690068 | BK19: 0.085542415 | BL19: -0.0075061397 | BM19: 0.0088898957 | BN19: 0.078036275 | BO19: 0.09443231 | BP19: 0.033538146 | BQ19: 0.027821031 | BR19: 0.041463067 | BS19: 0 | BT19: 0 | BU19: 0 | BV19: 0.0036365916 | BW19: 0.0029820052 | BX19: 0.0042911781 | BY19: 0.037174737 | BZ19: 0.030803036 | CA19: 0.045754245 | CB19: 0.0045818207 | CC19: 0.0043831459 | CD19: 0.92333209 | CE19: 5045 | CF19: 0.018434093 | CG19: 0.0053263112 | CH19: 0.0097224975 | CI19: 84.640459 | CJ19: 78.108166 | CK19: 93.69536 | CL19: 84.640459 | CM19: 78.108166 | CN19: 93.69536 | CO19: 13.099074 | CP19: 11.988427 | CQ19: 14.26154 | CR19: 84.692902 | CS19: 76.434283 | CT19: 93.697522 | CU19: 12.806178 | CV19: 11.355719 | CW19: 14.288722 | CX19: 10.881274 | CY19: 8.2420504 | CZ19: 15.634552 | DA19: 14.632752 | DB19: 9.5841244 | DC19: 22.283186 | DD19: 0 | DE19: 0 | DF19: 0 | DG19: 0.86597895 | DH19: 0.86597895 | DI19: 0.13402105 | DJ19: 0.43457483 | DK19: 0.39206235 | DL19: 55.264213 | DM19: 5.705342 | DN19: 0.22647882 | DO19: 0.011491852 | DP19: 0.9 | DQ19: 17.326203 | DR19: 0.10391132 | DS19: -0.087738922 | DT19: 0 | DU19: 0 | DY19: 0.006 | DZ19: 0.0068 | EA19: 0.0051
A20: Northeast_Pennsylvania_2021 | B20: 1.1107842 | C20: 0.98236924 | D20: 1.2763473 | E20: 19.430811 | F20: 15.450309 | G20: 22.976908 | H20: 0 | I20: 0 | J20: 0 | K20: 20.541595 | L20: 16.581193 | M20: 24.063487 | N20: 15.450309 | O20: 22.976908 | P20: 8.3888537 | Q20: 5.8558225 | R20: 11.146641 | S20: 0 | T20: 9.0260916 | U20: 37.956541 | V20: 31.826936 | W20: 43.92599 | X20: 1000 | Y20: 0.073058183 | Z20: 495.44526 | AA20: 495.44526 | AB20: 5095.6288 | AC20: 2996 | AD20: 4039 | AE20: 1.2580446 | AF20: 12 | AG20: 11 | AH20: 12 | AI20: 11.47 | AJ20: 0 | AK20: 0 | AM20: 10.136876 | AN20: Yes | AO20: No | AP20: 20230328 | AQ20: 3210 | AR20: 1.348173 | AS20: 0.86124593 | AT20: 0.062921063 | AU20: 0.0023103026 | AV20: 0.020145114 | AW20: 0.97985489 | AX20: 0 | AY20: 0.00021798767 | AZ20: 0.00018872656 | BA20: 0.00025571346 | BB20: 0.0038132313 | BC20: 0.0029062196 | BD20: 0.0046212579 | BE20: 0 | BF20: 0 | BG20: 0 | BH20: 0.004031219 | BI20: 0.0032540034 | BJ20: 0.0047223782 | BK20: 0.0074488433 | BL20: -0.0012029143 | BM20: 0.0011714843 | BN20: 0.0062459291 | BO20: 0.0086203276 | BP20: 0.0016462843 | BQ20: 0.0011491855 | BR20: 0.0021874909 | BS20: 0 | BT20: 0 | BU20: 0 | BV20: 0.0017713401 | BW20: 0.0014524989 | BX20: 0.0020901813 | BY20: 0.0034176244 | BZ20: 0.0026016843 | CA20: 0.0042776722 | CB20: 0.0037383178 | CC20: 0.0034267913 | CD20: 1 | CE20: 2381 | CF20: 0.0050398992 | CG20: 0.0038284379 | CH20: 0.0048173037 | CI20: 27.819665 | CJ20: 25.286634 | CK20: 30.577453 | CL20: 27.819665 | CM20: 25.286634 | CN20: 30.577453 | CO20: 10.136876 | CP20: 8.3837643 | CQ20: 11.927135 | CR20: 28.133483 | CS20: 23.695833 | CT20: 32.175263 | CU20: 1.3883667 | CV20: 0.41255719 | CW20: 2.548771 | CX20: 6.9026293 | CY20: 4.7297497 | CZ20: 9.3505775 | DA20: 0.09785773 | DB20: 0.013578159 | DC20: 0.39998094 | DD20: 0 | DE20: 0 | DF20: 0 | DG20: 0.73293438 | DH20: 0.73293438 | DI20: 0.26706562 | DJ20: 0.45881195 | DK20: 0.22101087 | DL20: 20.541595 | DM20: 18.493792 | DN20: 2.1401213 | DO20: 0.0054988291 | DP20: 0.9 | DQ20: 17.326203 | DR20: 0.1572749 | DS20: -0.16149121 | DT20: 0 | DU20: 0 | DY20: 0.0031 | DZ20: 0.0035 | EA20: 0.0026
A21: GHGI 2022 (for 2020) | AK21: 1 | AU21: 0.0048 | AY21: =BH21 -> 0.004942 | AZ21: =BI21 -> 0.0039430226 | BA21: =BJ21 -> 0.0059850499 | BH21: 0.004942 | BI21: =$BH$21+BL21*$BH$21/$BK$21 -> 0.0039430226 | BJ21: =$BH$21+BM21*$BH$21/$BK$21 -> 0.0059850499 | BK21: =BH21+BV21 -> 0.010092 | BL21: -0.00204 | BM21: 0.00213 | BN21: =BK21+BL21 -> 0.008052 | BO21: =BK21+BM21 -> 0.012222 | BV21: 0.00515 | BW21: =$BV$21+BL21*$BV$21/$BK$21 -> 0.0041089774 | BX21: =$BV$21+BM21*$BV$21/$BK$21 -> 0.0062369501
A22: GHGI NM 2019
A23: GHGI TX 2021
A24: GHGI CA 2021
A25: GHGI CO 2021
A26: GHGI PA 2021 | AA26: Fraction of national gas covered | AB26: =AB27/AB30 -> 0.28137144
A27: Totals excluding repeats | K27: =K3+K7+K13+K14+K15+K16 -> 411.35419 | L27: =L3+L7+L13+L14+L15+L16 -> 390.59789 | M27: =M3+M7+M13+M14+M15+M16 -> 433.16125 | N27: =N3+N7+N13+N14+N15+N16 -> 279.8704 | O27: =O3+O7+O13+O14+O15+O16 -> 322.03284 | P27: =P3+P7+P13+P14+P15+P16 -> 232.44905 | Q27: =Q3+Q7+Q13+Q14+Q15+Q16 -> 214.43615 | R27: =R3+R7+R13+R14+R15+R16 -> 253.32191 | ... W27: =W3+W7+W13+W14+W15+W16 -> 755.79972 | AB27: =AB3+AB7+AB13+AB14+AB15+AB16 -> 23994.401 | AC27: =AC3+AC7+AC13+AC14+AC15+AC16 -> 170569 | AD27: =AD3+AD7+AD13+AD14+AD15+AD16 -> 549072 | AI27: =AI3+AI7+AI13+AI14+AI15+AI16 -> 601.409 | AQ27: 1 | AR27: =AR3+AR7+AR13+AR14+AR15+AR16 -> 18.606751 | AS27: =AD27/AC27 -> 3.2190609 | BF27: =U27/$AB27 -> 0.02970276 | BG27: =V27/$AB27 -> 0.027991994 | BH27: =W27/$AB27 -> 0.031499004 | BS27: =BS3+BS7+BS13+BS14+BS15+BS16 -> 0.0025245064 | BV27: =AI27/BS27 -> 238228.35 | BW27: =BW3+BW7+BW13+BW14+BW15+BW16 -> 0.016581009 | CI27: =CI3+CI7+CI13+CI14+CI15+CI16 -> 532.8099 | EB27: =EB3+EB7+EB13+EB14+EB15+EB16 -> 301.6908 | EC27: =EC3+EC7+EC13+EC14+EC15+EC16 -> 0 | ED27: =ED3+ED7+ED13+ED14+ED15+ED16 -> 0 | EE27: =EE3+EE7+EE13+EE14+EE15+EE16 -> 232.44905 | EF27: =EF3+EF7+EF13+EF14+EF15+EF16 -> 0 | EG27: =EG3+EG7+EG13+EG14+EG15+EG16 -> 0
A28: Totals including repeats (no 2019 subcampaigns) | O28: Tot midstream excl repeats | P28: =P27+S27+T27 -> 301.34575 | U28: =SUM(U2:U16) -> 1358.8296 | V28: =SUM(V2:V16) -> 1270.1974 | W28: =SUM(W2:W16) -> 1454.3521 | AB28: =SUM(AB2:AB16) -> 45847.976 | AC28: =SUM(AC2:AC16) -> 398499 | AD28: =SUM(AD2:AD16) -> 1714261 | AI28: =SUM(AI2:AI16) -> 1286.858 | AQ28: 1 | AR28: =SUM(AR2:AR16) -> 62.970182 | AS28: =AR28/BS27 -> 24943.562 | BF28: =U28/$AB28 -> 0.029637723 | BG28: =V28/$AB28 -> 0.027704546 | BH28: =W28/$AB28 -> 0.031721184 | BS28: =SUM(BS2:BS16) -> 0.0048716079 | BV28: =AI28/BS28 -> 264154.67 | CH28: Aerially measured/Total emissions | CI28: =CI27/U27 -> 0.74759359 | EA28: Aerially measured/Total emissions | EB28: =EB27/K27 -> 0.73340884 | EE28: =EE27/P28 -> 0.77136994
A29: Totals excluding high-prod campaigns | U29: =U3+U7+U13+U15+U16 -> 636.351 | V29: =V3+V7+V13+V15+V16 -> 604.59374 | W29: =W3+W7+W13+W15+W16 -> 669.47152 | AB29: =AB3+AB7+AB13+AB15+AB16 -> 13751.921 | BF29: =U29/$AB29 -> 0.046273608 | BG29: =V29/$AB29 -> 0.043964311 | BH29: =W29/$AB29 -> 0.048682036
T30: Social cost of methane [$/t] | U30: 1500 | AA30: 2021 US gas prod | AB30: 85276.605 | CP30: GHGI midstream sub-aerial fraction | CQ30: =0.7303 -> 0.7303
A31: Permian total | T31: Hours per day | U31: 8760 | AC31: =SUM(Y2:Y6) -> 0.2511573 | AD31: =SUM(Z2:Z6) -> 65.379118 | AF31: =SUM(AB2:AB6) -> 29423.657 | AG31: =SUM(AC2:AC6) -> 162037 | AH31: =SUM(AD2:AD6) -> 643575 | AI31: =SUM(AE2:AE6) -> 8.5003077 | AJ31: =SUM(AF2:AF6) -> 4062 | AK31: =SUM(AG2:AG6) -> 3804.756 | AR31: =SUM(AM2:AM6) -> 272.01527 | AS31: =AR31/BS31 -> 1313.6817 | BS31: =SUM(BN2:BN6) -> 0.20706331
A32: San Joaquin total | T32: GWP20 (IPCC 2021) | U32: 82.5 | V32: https://report.ipcc.ch/ar6/wg1/IPCC_AR6_WGI_FullReport.pdf | W32: Table 7.15 | AC32: =SUM(Y7:Y11) -> 0.67541901 | AD32: =SUM(Z7:Z11) -> 80.237423 | AF32: =SUM(AB7:AB11) -> 1224.3124 | AG32: =SUM(AC7:AC11) -> 180339 | AH32: =SUM(AD7:AD11) -> 870400 | AI32: =SUM(AE7:AE11) -> 9.4819814 | AJ32: =SUM(AF7:AF11) -> 352 | AK32: =SUM(AG7:AG11) -> 326.168 | AR32: =SUM(AM7:AM11) -> 15.645909 | AS32: =AR32/BS32 -> 86.78219 | BS32: =SUM(BN7:BN11) -> 0.1802894
A33: Denver total | T33: Emissions [tCH4/yr] | U33: =U27*$U$31 -> 6243251.4 | V33: =V27*$U$31 -> 5883663.9 | W33: =W27*$U$31 -> 6620805.6 | AC33: =Y12+Y13 -> 0.13643788 | AD33: =Z12+Z13 -> 21.262557 | AF33: =AB12+AB13 -> 3970.1203 | AG33: =AC12+AC13 -> 23359 | AH33: =AD12+AD13 -> 127167 | AI33: =AE12+AE13 -> 3.2176052 | AJ33: =AF12+AF13 -> 74 | AK33: =AG12+AG13 -> 58.743 | AR33: =AM12+AM13 -> 36.968505 | AS33: =AR33/BS33 -> 1816.9091 | BS33: =BN12+BN13 -> 0.020346921
A34: Per+SJ+DJ | T34: Emissions [tCO2e/yr] | U34: =U33*$U$32 -> 5.1506824e+08 | V34: =V33*$U$32 -> 4.8540228e+08 | W34: =W33*$U$32 -> 5.4621646e+08 | AC34: =SUM(AC31:AC33) -> 1.0630142 | AD34: =SUM(AD31:AD33) -> 166.8791 | AR34: =SUM(AR31:AR33) -> 324.62969 | AS34: =AR34/BS34 -> 796.2472 | BS34: =SUM(BS31:BS33) -> 0.40769963
T35: Annual social cost of emissions [$/yr] | U35: =U33*$U$30 -> 9.3648771e+09 | V35: =V33*$U$30 -> 8.8254959e+09 | W35: =W33*$U$30 -> 9.9312084e+09
T36: NG cost [$/mcf] | U36: 3 | AA36: =AB27*$U31/$U37 -> 1.2128734e+10
T37: tCH4/mcf(NG) | U37: 0.01733 | AA37: =AB30*$U31/$U37 -> 4.3105774e+10
T38: Annual NG emissions [mcf/yr] | U38: =U33/$U$37 -> 3.6025686e+08 | V38: =V33/$U$37 -> 3.3950744e+08 | W38: =W33/$U$37 -> 3.8204302e+08
T39: Annual NG value | U39: =U38*$U$36 -> 1.0807706e+09 | V39: =V38*$U$36 -> 1.0185223e+09 | W39: =W38*$U$36 -> 1.1461291e+09
T40: Price/t(CH4) | U40: =U36/U37 -> 173.11021
...

Sheet Tables for paper
I1: REVISIT | J1: From Jupyter code
A2: Table 7 | B2: {='By site'!AA1:AA20} -> Transition point | C2: {='By site'!Z1:Z20} -> Min detected emission | D2: {='By site'!AF1:AF20} -> # production plumes | E2: {='By site'!AG1:AG20} -> # production plumes sel | H2: Table 8 | I2: Avg emissions/site | J2: Logormal fit mean | K2: Lognormal/This study | M2: Table 23 | N2: {='By site'!CE1:CE20} -> Well sites covered | O2: {='By site'!AF1:AF20} -> # production plumes | P2: {='By site'!AH1:AH20} -> # prod sources overall | Q2: {='By site'!AR1:AR20} -> Avg visits/well site | R2: {='By site'!AI1:AI20} -> # avg prod sources sim | S2: {='By site'!CH1:CH20} -> Avg % sites emitting
A3: Kairos_Permian | B3: 24.324 | C3: 7.0962343 | D3: 1279 | E3: 1276.97 | H3: Kairos_Permian | I3: =1000*'By site'!K2/'By site'!CE2 -> 6.1329724 | J3: 3.188375 | K3: =J3/I3 -> 0.51987435 | M3: Kairos_Permian | N3: 18030 | O3: 1279 | P3: 625 | Q3: 3.7698281 | R3: 305.158 | S3: 0.016925014
A4: Permian_2019 | B4: 59.283 | C4: 15.029525 | D4: 1749 | E4: 1645.742 | H4: Permian_2019 | I4: =1000*'By site'!K3/'By site'!CE3 -> 6.5952486 | J4: 3.823909 | K4: =J4/I4 -> 0.57979755 | M4: Permian_2019 | N4: 46337 | O4: 1749 | P4: 1054 | Q4: 3.8655934 | R4: 483.449 | S4: 0.010433325
A5: Permian_2020 | B5: 83.968 | C5: 8.0919112 | D5: 284 | E5: 246.309 | H5: Permian_2020 | I5: =1000*'By site'!K4/'By site'!CE4 -> 6.1230245 | J5: 5.315017 | K5: =J5/I5 -> 0.86803785 | M5: Permian_2020 | N5: 9380 | O5: 284 | P5: 239 | Q5: 2.8557569 | R5: 101.24 | S5: 0.010793177
A6: Permian_summer2021 | B6: 68.187 | C6: 11.813408 | D6: 416 | E6: 360.585 | H6: Permian_summer2021 | I6: =1000*'By site'!K5/'By site'!CE5 -> 6.2382059 | J6: 7.700567 | K6: =J6/I6 -> 1.2344201 | M6: Permian_summer2021 | N6: 10432 | O6: 416 | P6: 296 | Q6: 4.8271664 | R6: 124.71 | S6: 0.011954563
A7: Permian_fall2021 | B7: 77.865 | C7: 23.348039 | D7: 334 | E7: 275.15 | H7: Permian_fall2021 | I7: =1000*'By site'!K6/'By site'!CE6 -> 6.088963 | J7: 7.498451 | K7: =J7/I7 -> 1.2314824 | M7: Permian_fall2021 | N7: 10777 | O7: 334 | P7: 232 | Q7: 4.7946553 | R7: 92.785 | S7: 0.0086095388
A8: San_Joaquin_2016 | B8: 40.415 | C8: 9 | D8: 77 | E8: 69.132 | H8: San_Joaquin_2016 | I8: =1000*'By site'!K7/'By site'!CE7 -> 0.2081912 | J8: 0.521041 | K8: =J8/I8 -> 2.5027043 | M8: San_Joaquin_2016 | N8: 23779 | O8: 77 | P8: 40 | Q8: 1.9552546 | R8: 15.074 | S8: 0.00063392069
A9: San_Joaquin_2017 | B9: 40.99 | C9: 11 | D9: 86 | E9: 80.173 | H9: San_Joaquin_2017 | I9: =1000*'By site'!K8/'By site'!CE8 -> 0.30893291 | J9: 0.539929 | K9: =J9/I9 -> 1.7477225 | M9: San_Joaquin_2017 | N9: 23103 | O9: 86 | P9: 54 | Q9: 4.7679522 | R9: 15.945 | S9: 0.00069017011
A10: San_Joaquin_summer2020 | B10: 36.556644 | C10: 23.632192 | D10: 94 | E10: 90.462 | H10: San_Joaquin_summer2020 | I10: =1000*'By site'!K9/'By site'!CE9 -> 0.35324617 | J10: 0.545917 | K10: =J10/I10 -> 1.5454293 | M10: San_Joaquin_summer2020 | N10: 15992 | O10: 94 | P10: 39 | Q10: 7.4688594 | R10: 13.337 | S10: 0.00083397949
A11: San_Joaquin_fall2020 | B11: 37.591104 | C11: 20.646402 | D11: 48 | E11: 45.261 | H11: San_Joaquin_fall2020 | I11: =1000*'By site'!K10/'By site'!CE10 -> 0.26911197 | J11: 0.523525 | K11: =J11/I11 -> 1.9453799 | M11: San_Joaquin_fall2020 | N11: 16579 | O11: 48 | P11: 27 | Q11: 7.2219675 | R11: 8.067 | S11: 0.00048657941
A12: San_Joaquin_fall2021 | B12: 23.223 | C12: 15.95883 | D12: 47 | E12: 41.14 | H12: San_Joaquin_fall2021 | I12: =1000*'By site'!K11/'By site'!CE11 -> 0.20801016 | J12: 0.509176 | K12: =J12/I12 -> 2.447842 | M12: San_Joaquin_fall2021 | N12: 16743 | O12: 47 | P12: 35 | Q12: 3.5712238 | R12: 15.716 | S12: 0.00093866093
A13: Denver_summer2021 | B13: 75.042 | C13: 11.102345 | D13: 34 | E13: 27.151 | H13: Denver_summer2021 | I13: =1000*'By site'!K12/'By site'!CE12 -> 2.0040841 | J13: 4.579421 | K13: =J13/I13 -> 2.2850443 | M13: Denver_summer2021 | N13: 7254 | O13: 34 | P13: 27 | Q13: 5.0860215 | R13: 8.491 | S13: 0.0011705266
A14: Denver_fall2021 | B14: 66.55 | C14: 10.160213 | D14: 40 | E14: 31.592 | H14: Denver_fall2021 | I14: =1000*'By site'!K13/'By site'!CE13 -> 2.0132795 | J14: 4.605823 | K14: =J14/I14 -> 2.2877216 | M14: Denver_fall2021 | N14: 7265 | O14: 40 | P14: 33 | Q14: 5.8016518 | R14: 8.473 | S14: 0.0011662767
... A17: Fort_Worth_2021 | B17: 55.886 | C17: 10.889258 | D17: 80 | E17: 80 | H17: Fort_Worth_2021 | I17: =1000*'By site'!K16/'By site'!CE16 -> 4.2104024 | J17: 1.691088 | K17: =J17/I17 -> 0.40164522 | M17: Fort_Worth_2021 | N17: 4606 | O17: 80 | P17: 49 | Q17: 1.7370821 | R17: 40.006 | S17: 0.0086856274
A18: Permian_2019_F2021_bounds | B18: 58.47 | C18: 16.353134 | D18: 1052 | E18: 998.006 | H18: Permian_2019_F2021_bounds | I18: =1000*'By site'!K17/'By site'!CE17 -> 13.453212 | M18: Permian_2019_F2021_bounds | N18: 9404 | O18: 1052 | P18: 540 | Q18: 8.894194 | R18: 166.933 | S18: 0.017751276
A19: Permian_2019_F2021_bounds_Delaware | B19: 53.834 | C19: 16.353134 | D19: 922 | E19: 875.148 | H19: Permian_2019_F2021_bounds_Delaware | I19: =1000*'By site'!K18/'By site'!CE18 -> 16.403047 | M19: Permian_2019_F2021_bounds_Delaware | N19: 4358 | O19: 922 | P19: 447 | Q19: 12.681964 | R19: 117.859 | S19: 0.027044286
A20: Permian_2019_F2021_Midland | B20: 109.707 | C20: 16.353134 | D20: 130 | E20: 124.363 | H20: Permian_2019_F2021_Midland | I20: =1000*'By site'!K19/'By site'!CE19 -> 10.954254 | M20: Permian_2019_F2021_Midland | N20: 5045 | O20: 130 | P20: 93 | Q20: 5.6239841 | R20: 49.05 | S20: 0.0097224975
A21: Northeast_Pennsylvania_2021 | B21: 495.44526 | C21: 495.44526 | D21: 12 | E21: 11 | H21: Northeast_Pennsylvania_2021 | I21: =1000*'By site'!K20/'By site'!CE20 -> 8.6272975 | M21: Northeast_Pennsylvania_2021 | N21: 2381 | O21: 12 | P21: 12 | Q21: 1.348173 | R21: 11.47 | S21: 0.0048173037
A23: Table 24 | B23: Methane emissions [t/hr] | C23: {='By site'!AB1:AB20} -> Total covered production (t(CH4)/hr) | D23: Methane loss rate [%] | G23: Table 25 | H23: Production: Simulated [%] | I23: Production: Aerial [%] | J23: Production: Aerial partial [%] | K23: Production: Total [%] | N23: Table 26 | O23: Midstream: Simulated [%] | P23: Midstream: Aerial [%] | Q23: Midstream: Aerial partial [%] | R23: Midstream: Total [%] | T23: Table 27 | U23: Production: Simulated full distribution [%] | V23: Production: GHGI [%] | W23: % difference
A24: Kairos_Permian | B24: =ROUND('By site'!U2, 0) & " [" & ROUND('By site'!V2, 0) & ", " & ROUND('By site'!W2, 0) & "]" -> 188 [177, 202] | C24: 1952.0451 | D24: =ROUND('By site'!BK2*100, 2) & " [" & ROUND('By site'!BN2*100, 2) & ", " & ROUND('By site'!BO2*100, 2) & "]" -> 9.65 [9.07, 10.37] | G24: Kairos_Permian | H24: =ROUND('By site'!AY2*100, 2) & CHAR(10) & "[" & ROUND('By site'!AZ2*100, 2) & ", " & ROUND('By site'!BA2*100, 2) & "]" -> 0.92 [0.88, 0.96] | I24: =ROUND('By site'!BB2*100, 2) & CHAR(10) & "[" & ROUND('By site'!BC2*100, 2) & ", " & ROUND('By site'!BD2*100, 2) & "]" -> 4.5 [3.92, 5.14] | J24: =ROUND('By site'!BE2*100, 2) & CHAR(10) & "[" & ROUND('By site'!BF2*100, 2) & ", " & ROUND('By site'!BG2*100, 2) & "]" -> 0.24 [0.18, 0.31] | K24: =ROUND('By site'!BH2*100, 2) & CHAR(10) & "[" & ROUND('By site'!BI2*100, 2) & ", " & ROUND('By site'!BJ2*100, 2) & "]" -> 5.66 [5.37, 6] | N24: Kairos_Permian | O24: =ROUND('By site'!BV2*100, 2) & CHAR(10) & "[" & ROUND('By site'!BW2*100, 2) & ", " & ROUND('By site'!BX2*100, 2) & "]" -> 0.38 [0.31, 0.45] | P24: =ROUND('By site'!BP2*100, 2) & CHAR(10) & "[" & ROUND('By site'!BQ2*100, 2) & ", " & ROUND('By site'!BR2*100, 2) & "]" -> 3.37 [2.98, 3.96] | Q24: =ROUND('By site'!BS2*100, 2) & CHAR(10) & "[" & ROUND('By site'!BT2*100, 2) & ", " & ROUND('By site'!BU2*100, 2) & "]" -> 0.23 [0.2, 0.27] | R24: =ROUND('By site'!BY2*100, 2) & CHAR(10) & "[" & ROUND('By site'!BZ2*100, 2) & ", " & ROUND('By site'!CA2*100, 2) & "]" -> 3.98 [3.52, 4.65] | T24: Kairos_Permian | U24: {='By site'!BH2:BH20/'By site'!DM2:DM20} -> 0.011999356 | V24: {='By site'!DY2:DY20} -> 0.0072701048 | W24: =(U24-V24)/V24 -> 0.6505066
