Workbook

Sheet By site
A1: Scenario | B1: Simulation (t/h) | C1: Simulation P2.5 | D1: Simulation P97.5 | E1: Aerial (t/h) | F1: Aerial P2.5 | G1: Aerial P97.5 | H1: Partial (t/h) | I1: Partial P2.5 | J1: Partial P97.5 | K1: Well site emissions (t/h) | L1: Well site emissions P2.5 | M1: Well site emissions P97.5 | N1: Aerial emissions P2.5 | O1: Aerial emissions P97.5 | P1: Aerial midstream emissions (t/h) | Q1: Aerial midstream emissions P2.5 | R1: Aerial midstream emissions P97.5 | S1: Midstream partial detect (t/h) | T1: Midstream GHGI below min detect (t/h) | U1: Total emissions + midstream (t/h) | V1: Total emissions + midstream P2.5 | W1: Total emissions + midstream P97.5 | X1: N | Y1: % SDev of MC iterations | Z1: Min detected emission | AA1: Transition point | AB1: Total covered production (t(CH4)/hr) | AC1: Wells covered | AD1: Well visits | AE1: Wells per site | AF1: # production plumes | AG1: # production plumes sel | AH1: # prod sources overall | AI1: # avg prod sources sim | AJ1: # midstream plumes | AK1: # midstream sources | AL1: Total sim emissions | AM1: Stratify by covered prod | AN1: Include repeats | AO1: Date | AP1: Well site visits | AQ1: Avg visits/well site | AR1: SD to SErr factor | AS1: SErr of mean total emissions | AT1: SErr of sample mean | AU1: Simulation % well site | AV1: Aerial % well site | AW1: Partial % well site | AX1: Methane fractional loss simulation well site | AY1: Methane fractional loss simulation well siteP2.5 | AZ1: Methane fractional loss simulation well siteP97.5 | BA1: Methane fractional loss aerial well site | BB1: AerialFracLossP2.5 | BC1: AerialFracLossP97.5 | BD1: Methane fractional loss partial | BE1: Methane fractional loss partialP2.5 | BF1: Methane fractional loss partialP97.5 | BG1: FracLossProd | BH1: FracLossProdP2.5 | BI1: FracLossProdP97.5 | BJ1: Methane fractional loss total | BK1: FracLossP2.5 | BL1: FracLossP97.5 | BM1: FracLossP2.5Full | BN1: FracLossP97.5Full | BO1: FracLossMidAerial | BP1: FracLossMidAerialP2.5 | BQ1: FracLossMidAerialP97.5 | BR1: FracLossMidPartial | BS1: FracLossMidPartialP2.5 | BT1: FracLossMidPartialP97.5 | BU1: FracLossMidGHGI | BV1: FracLossMidGHGIP2.5 | BW1: FracLossMidGHGIP97.5 | BX1: FracLossMidstream total | BY1: FracLossMidstream totalP2.5 | BZ1: FracLossMidstream totalP97.5 | CA1: % well site visits with plume | CB1: % well site visits with selected plume | CC1: Fraction sim retained | CD1: Well sites covered | CE1: % well sites ever emitting | CF1: Avg % wells emitting | CG1: Avg % sites emitting | CH1: Total aerial | CI1: Total aerialP2.5 | CJ1: Total aerialP97.5 | CK1: Total aerial+partial emissions | CL1: Total aerial+partial emissionsP2.5 | CM1: Total aerial+partial emissionsP97.5 | CN1: Total sim emissions | CO1: Total sim emissionsP2.5 | CP1: Total sim emissionsP97.5 | CQ1: Total aerial all segments inc below min detect | CR1: Total aerial all segments inc below min detect P2.5 | CS1: Total aerial all segments inc below min detect P97.5 | CT1: Total pipeline emissions | CU1: Total pipeline emissions P2.5 | CV1: Total pipeline emissions P97.5 | CW1: Total compressor emissions | CX1: Total compressor emissions P2.5 | CY1: Total compressor emissions P97.5 | CZ1: Total processing emissions | DA1: Total processing emissions P2.5 | DB1: Total processing emissions P97.5 | DC1: Total other midstream emissions | DD1: Total other midstream emissions P2.5 | DE1: Total other midstream emissions P97.5 | DF1: Frac aerial | DG1: Frac aerial+partial | DH1: Frac sim | DI1: Frac midstream | DJ1: Frac midstream aerial | DK1: Total production emissions | DL1: Total/Sim | DM1: Production/site covered | DN1: State GHGI | DO1: NG methane fraction | DP1: kgCH4 per mcfNG | DQ1: Full upper errorbar % total | DR1: Full lower errorbar % total | DS1: Partial prod % total | DT1: Partial mid % total | DU1: Tot sim emissions loss rate | DV1: Tot sim emissions loss rate P2.5 | DW1: Tot sim emissions loss rate P97.5 | DX1: Prod-only state GHGI loss | DY1: Prod-only state GHGI loss low | DZ1: Prod-only state GHGI loss high
A2: Kairos_Permian | B2: 18.100939 | C2: 17.689639 | D2: 18.480781 | E2: 77.998841 | F2: 71.256368 | G2: 86.169375 | H2: 4.8301886 | I2: 4.1985295 | J2: 5.5623194 | K2: 100.92997 | L2: 94.190505 | M2: 109.09475 | N2: 71.256368 | O2: 86.169375 | P2: 73.649936 | Q2: 66.938137 | R2: 83.350239 | S2: 4.9034948 | T2: 7.4248658 | U2: 186.90827 | V2: 175.5562 | W2: 200.3277 | X2: 1000 | Y2: 0.062336739 | Z2: 7.0962343 | AA2: 25.365 | AB2: 1952.0451 | AC2: 21637 | AD2: 81564 | AE2: 1.2 | AF2: 1083 | AG2: 1081.878 | AH2: 537 | AI2: 258.721 | AJ2: 902 | AK2: 415 | AL2: 25.525805 | AM2: Yes | AN2: No | AO2: 20230328 | AP2: 67970 | AQ2: 3.7698281 | AR2: 0.51503795 | AS2: 0.032105786 | AT2: 0.0019712608 | AU2: 0.15365656 | AV2: 0.83702346 | AW2: 0.0093199825 | AX2: 0.0092728077 | AY2: 0.0088637069 | AZ2: 0.0096506177 | BA2: 0.039957499 | BB2: 0.033251088 | BC2: 0.048084332 | BD2: 0.0024744247 | BE2: 0.001846144 | BF2: 0.0032026396 | BG2: 0.051704731 | BH2: 0.048252217 | BI2: 0.055887412 | BJ2: 0.095749971 | BK2: -0.0058154743 | BL2: 0.0068745508 | BM2: 0.089934497 | BN2: 0.10262452 | BO2: 0.037729628 | BP2: 0.034291285 | BQ2: 0.04269893 | BR2: 0.0025119782 | BS2: 0.0021185293 | BT2: 0.0029334725 | BU2: 0.0038036343 | BV2: 0.0031189801 | BW2: 0.0044882884 | BX2: 0.04404524 | BY2: 0.039867375 | BZ2: 0.049745139 | CA2: 0.0159335 | CB2: 0.015916993 | CC2: 0.77126584 | CD2: 18030 | CE2: 0.029783694 | CF2: 0.011957342 | CG2: 0.014349473 | CH2: 151.64878 | CI2: 144.93698 | CJ2: 161.34908 | CK2: 156.55227 | CL2: 149.07244 | CM2: 167.07535 | CN2: 25.525805 | CO2: 23.778028 | CP2: 27.242122 | CQ2: 151.72207 | CR2: 138.6427 | CS2: 167.57349 | CT2: 18.502832 | CU2: 15.091665 | CV2: 27.565307 | CW2: 6.9547925 | CX2: 5.7364258 | CY2: 8.3062942 | CZ2: 3.8015686 | DA2: 2.9803303 | DB2: 5.1433204 | DC2: 25.732057 | DD2: 22.260038 | DE2: 29.940208 | DF2: 0.81135366 | DG2: 0.83758853 | DH2: 0.13656897 | DI2: 0.46000284 | DJ2: 0.3940432 | DK2: 100.92997 | DL2: 4.3005263 | DM2: 0.10826651 | DN2: 0.012478177 | DO2: 0.9 | DP2: 17.326203 | DQ2: 0.071800021 | DR2: -0.060737349 | DS2: 0.025842495 | DT2: 0.020565413 | DX2: 0.0073 | DY2: 0.0082 | DZ2: 0.0063
A3: Permian_2019 | B3: 69.417499 | C3: 68.443659 | D3: 70.635571 | E3: 236.18653 | F3: 226.22581 | G3: 246.32564 | H3: 0 | I3: 0 | J3: 0 | K3: 305.60403 | L3: 295.52415 | M3: 315.79026 | N3: 226.22581 | O3: 246.32564 | P3: 212.57883 | Q3: 199.64633 | R3: 226.59878 | S3: 0 | T3: 38.281727 | U3: 556.46459 | V3: 532.92556 | W3: 580.16778 | X3: 1000 | Y3: 0.032662483 | Z3: 15.029525 | AA3: 59.283 | AB3: 10526.815 | AC3: 84570 | AD3: 326908 | AE3: 1.8250769 | AF3: 1749 | AG3: 1645.742 | AH3: 1054 | AI3: 483.449 | AJ3: 0 | AK3: 0 | AL3: 107.69923 | AM3: Yes | AN3: No | AO3: 20230328 | AP3: 179120 | AQ3: 3.8655934 | AR3: 0.50861822 | AS3: 0.016612734 | AT3: 0.0010328784 | AU3: 0.35168169 | AV3: 0.64831831 | AW3: 0 | AX3: 0.0065943499 | AY3: 0.0064124641 | AZ3: 0.0068218512 | BA3: 0.022436657 | BB3: 0.020576275 | BC3: 0.024330355 | BD3: 0 | BE3: 0 | BF3: 0 | BG3: 0.029031007 | BH3: 0.028073463 | BI3: 0.029998653 | BJ3: 0.05286163 | BK3: -0.002236102 | BL3: 0.0022516968 | BM3: 0.050625528 | BN3: 0.055113327 | BO3: 0.020194031 | BP3: 0.018965503 | BQ3: 0.021525864 | BR3: 0 | BS3: 0 | BT3: 0 | BU3: 0.0036365916 | BV3: 0.0029820052 | BW3: 0.0042911781 | BX3: 0.023830623 | BY3: 0.021947508 | BZ3: 0.025817042 | CA3: 0.0097644038 | CB3: 0.0091879299 | CC3: 0.82970308 | CD3: 46337 | CE3: 0.022746401 | CF3: 0.0057165543 | CG3: 0.010433325 | CH3: 448.76536 | CI3: 435.83287 | CJ3: 462.78531 | CK3: 448.76536 | CL3: 435.83287 | CM3: 462.78531 | CN3: 107.69923 | CO3: 99.834675 | CP3: 115.80801 | CQ3: 449.28444 | CR3: 429.65375 | CS3: 469.2687 | CT3: 102.36225 | CU3: 96.655735 | CV3: 109.023 | CW3: 80.647514 | CX3: 74.031141 | CY3: 87.886074 | CZ3: 29.569065 | DA3: 21.381253 | DB3: 39.986645 | DC3: 0 | DD3: 0 | DE3: 0 | DF3: 0.80645778 | DG3: 0.80645778 | DH3: 0.19354222 | DI3: 0.4508109 | DJ3: 0.38201627 | DK3: 305.60403 | DL3: 3.6526892 | DM3: 0.22717946 | DN3: 0.011491852 | DO3: 0.9 | DP3: 17.326203 | DQ3: 0.042594731 | DR3: -0.042301958 | DS3: 0 | DT3: 0 | DX3: 0.0065 | DY3: 0.0074 | DZ3: 0.0056
A4: Permian_2020 | B4: 22.486001 | C4: 21.673996 | D4: 23.318745 | E4: 34.947969 | F4: 31.679793 | G4: 38.044824 | H4: 0 | I4: 0 | J4: 0 | K4: 57.43397 | L4: 53.993234 | M4: 60.597126 | N4: 31.679793 | O4: 38.044824 | P4: 60.160964 | Q4: 53.506687 | R4: 67.679217 | S4: 0 | T4: 16.369542 | U4: 133.96448 | V4: 123.22217 | W4: 145.20185 | X4: 1000 | Y4: 0.052643636 | Z4: 8.0919112 | AA4: 83.968 | AB4: 4766.5264 | AC4: 17120 | AD4: 48890 | AE4: 1.8250769 | AF4: 284 | AG4: 246.309 | AH4: 239 | AI4: 101.24 | AJ4: 0 | AK4: 0 | AL4: 38.855543 | AM4: Yes | AN4: No | AO4: 20230328 | AP4: 26787 | AQ4: 2.8557569 | AR4: 0.59175152 | AS4: 0.031151952 | AT4: 0.0016647379 | AU4: 0.5330928 | AV4: 0.4669072 | AW4: 0 | AX4: 0.0047174817 | AY4: 0.0044295977 | AZ4: 0.0050127183 | BA4: 0.0073319575 | BB4: 0.0061732762 | BC4: 0.0084298998 | BD4: 0 | BE4: 0 | BF4: 0 | BG4: 0.012049439 | BH4: 0.011327585 | BI4: 0.012713058 | BJ4: 0.028105263 | BK4: -0.002253696 | BL4: 0.0023575603 | BM4: 0.025851567 | BN4: 0.030462823 | BO4: 0.012621553 | BP4: 0.011225509 | BQ4: 0.014198855 | BR4: 0 | BS4: 0 | BT4: 0 | BU4: 0.0034342708 | BV4: 0.002816102 | BW4: 0.0040524395 | BX4: 0.016055823 | BY4: 0.014041611 | BZ4: 0.018251295 | CA4: 0.010602158 | CB4: 0.0091950946 | CC4: 0.83174076 | CD4: 9380 | CE4: 0.025479744 | CF4: 0.0059135514 | CG4: 0.010793177 | CH4: 95.108933 | CI4: 88.454656 | CJ4: 102.62719 | CK4: 95.108933 | CL4: 88.454656 | CM4: 102.62719 | CN4: 38.855543 | CO4: 35.09702 | CP4: 42.634805 | CQ4: 95.64559 | CR4: 90.148802 | CS4: 100.85393 | CT4: 17.672909 | CU4: 13.507861 | CV4: 23.020384 | CW4: 33.372115 | CX4: 29.311477 | CY4: 37.495659 | CZ4: 9.0276573 | DA4: 6.4483394 | DB4: 11.889321 | DC4: 0.088283211 | DD4: 0.036041487 | DE4: 0.3095367 | DF4: 0.70995479 | DG4: 0.70995479 | DH4: 0.29004521 | DI4: 0.57127414 | DJ4: 0.44908039 | DK4: 57.43397 | DL4: 2.1244741 | DM4: 0.50815846 | DN4: 0.010661119 | DO4: 0.9 | DP4: 17.326203 | DQ4: 0.083879362 | DR4: -0.080194747 | DS4: 0 | DT4: 0 | DX4: 0.006 | DY4: 0.0068 | DZ4: 0.0051
A5: Permian_summer2021 | B5: 27.970658 | C5: 27.235759 | D5: 28.760886 | E5: 37.106306 | F5: 33.87838 | G5: 40.490546 | H5: 0 | I5: 0 | J5: 0 | K5: 65.076964 | L5: 61.82595 | M5: 68.604409 | N5: 33.87838 | O5: 40.490546 | P5: 45.081584 | Q5: 41.453676 | R5: 49.191029 | S5: 0 | T5: 20.435387 | U5: 130.59393 | V5: 121.72804 | W5: 139.72156 | X5: 1000 | Y5: 0.046598349 | Z5: 11.813408 | AA5: 68.187 | AB5: 5950.4297 | AC5: 19040 | AD5: 91907 | AE5: 1.8250769 | AF5: 416 | AG5: 360.585 | AH5: 296 | AI5: 124.71 | AJ5: 0 | AK5: 0 | AL5: 48.406044 | AM5: Yes | AN5: No | AO5: 20230328 | AP5: 50357 | AQ5: 4.8271664 | AR5: 0.45514928 | AS5: 0.021209205 | AT5: 0.0014735692 | AU5: 0.70526178 | AV5: 0.29473822 | AW5: 0 | AX5: 0.0047006114 | AY5: 0.0044292643 | AZ5: 0.0049923881 | BA5: 0.0062359036 | BB5: 0.0050440543 | BC5: 0.0074854689 | BD5: 0 | BE5: 0 | BF5: 0 | BG5: 0.010936515 | BH5: 0.010390166 | BI5: 0.01152932 | BJ5: 0.021946975 | BK5: -0.0014899593 | BL5: 0.001533944 | BM5: 0.020457016 | BN5: 0.023480919 | BO5: 0.0075761897 | BP5: 0.0069665013 | BQ5: 0.0082668028 | BR5: 0 | BS5: 0 | BT5: 0 | BU5: 0.0034342708 | BV5: 0.002816102 | BW5: 0.0040524395 | BX5: 0.01101046 | BY5: 0.0097826034 | BZ5: 0.012319242 | CA5: 0.0082610163 | CB5: 0.0071605735 | CC5: 0.80417693 | CD5: 10432 | CE5: 0.028374233 | CF5: 0.006549895 | CG5: 0.011954563 | CH5: 82.18789 | CI5: 78.559982 | CJ5: 86.297335 | CK5: 82.18789 | CL5: 78.559982 | CM5: 86.297335 | CN5: 48.406044 | CO5: 43.992776 | CP5: 52.874643 | CQ5: 82.806661 | CR5: 75.697858 | CS5: 90.314383 | CT5: 12.903725 | CU5: 11.509695 | CV5: 14.693035 | CW5: 25.157451 | CX5: 22.22628 | CY5: 28.530747 | CZ5: 7.0204076 | DA5: 5.5240477 | DB5: 8.7435956 | DC5: 0 | DD5: 0 | DE5: 0 | DF5: 0.62933819 | DG5: 0.62933819 | DH5: 0.37066181 | DI5: 0.50168381 | DJ5: 0.34520246 | DK5: 65.076964 | DL5: 1.8710164 | DM5: 0.57040162 | DN5: 0.010661119 | DO5: 0.9 | DP5: 17.326203 | DQ5: 0.069895233 | DR5: -0.067885611 | DS5: 0 | DT5: 0 | DX5: 0.006 | DY5: 0.0068 | DZ5: 0.0051
A6: Permian_fall2021 | B6: 30.311881 | C6: 29.522823 | D6: 31.02066 | E6: 35.308872 | F6: 31.630299 | G6: 38.974685 | H6: 0 | I6: 0 | J6: 0 | K6: 65.620754 | L6: 61.90244 | M6: 69.343708 | N6: 31.630299 | O6: 38.974685 | P6: 43.968884 | Q6: 39.066203 | R6: 49.17745 | S6: 0 | T6: 21.388092 | U6: 130.97773 | V6: 121.07967 | W6: 141.31724 | X6: 1000 | Y6: 0.05670148 | Z6: 23.348039 | AA6: 77.865 | AB6: 6227.8408 | AC6: 19670 | AD6: 94306 | AE6: 1.8250769 | AF6: 334 | AG6: 275.15 | AH6: 232 | AI6: 92.785 | AJ6: 0 | AK6: 0 | AL6: 51.699973 | AM6: Yes | AN6: No | AO6: 20230328 | AP6: 51672 | AQ6: 4.7946553 | AR6: 0.45668979 | AS6: 0.025894987 | AT6: 0.0017930582 | AU6: 0.70390981 | AV6: 0.29609019 | AW6: 0 | AX6: 0.0048671574 | AY6: 0.0045897292 | AZ6: 0.0051163595 | BA6: 0.0056695207 | BB6: 0.0043761573 | BC6: 0.0069583976 | BD6: 0 | BE6: 0 | BF6: 0 | BG6: 0.010536678 | BH6: 0.0099396311 | BI6: 0.01113447 | BJ6: 0.021031001 | BK6: -0.0015893245 | BL6: 0.0016602085 | BM6: 0.019441677 | BN6: 0.02269121 | BO6: 0.0070600527 | BP6: 0.0062728327 | BQ6: 0.0078963885 | BR6: 0 | BS6: 0 | BT6: 0 | BU6: 0.0034342708 | BV6: 0.002816102 | BW6: 0.0040524395 | BX6: 0.010494323 | BY6: 0.0090889347 | BZ6: 0.011948828 | CA6: 0.0064638489 | CB6: 0.0053249342 | CC6: 0.82560543 | CD6: 10777 | CE6: 0.021527327 | CF6: 0.0047170819 | CG6: 0.0086095388 | CH6: 79.277757 | CI6: 74.375076 | CJ6: 84.486323 | CK6: 79.277757 | CL6: 74.375076 | CM6: 84.486323 | CN6: 51.699973 | CO6: 47.061058 | CP6: 56.258608 | CQ6: 79.887014 | CR6: 71.821563 | CS6: 87.991379 | CT6: 6.8527874 | CU6: 6.0377973 | CV6: 7.6694456 | CW6: 27.253138 | CX6: 23.385949 | CY6: 31.538087 | CZ6: 9.8629588 | DA6: 7.3800637 | DB6: 12.806862 | DC6: 0 | DD6: 0 | DE6: 0 | DF6: 0.60527477 | DG6: 0.60527477 | DH6: 0.39472523 | DI6: 0.4989915 | DJ6: 0.33569476 | DK6: 65.620754 | DL6: 1.7873165 | DM6: 0.5778826 | DN6: 0.010661119 | DO6: 0.9 | DP6: 17.326203 | DQ6: 0.078945316 | DR6: -0.075576803 | DS6: 0 | DT6: 0 | DX6: 0.006 | DY6: 0.0068 | DZ6: 0.0051
A7: San_Joaquin_2016 | B7: 2.5759401 | C7: 2.4579689 | D7: 2.6996033 | E7: 2.3746385 | F7: 1.5859806 | G7: 3.2118143 | H7: 0 | I7: 0 | J7: 0 | K7: 4.9505785 | L7: 4.1643477 | M7: 5.8156382 | N7: 1.5859806 | O7: 3.2118143 | P7: 4.7719796 | Q7: 3.7142929 | R7: 6.1650359 | S7: 0 | T7: 1.1897866 | U7: 10.912345 | V7: 9.3412725 | W7: 12.709885 | X7: 1000 | Y7: 0.098709591 | Z7: 9 | AA7: 40.415 | AB7: 264.97396 | AC7: 41547 | AD7: 81234 | AE7: 1.7471737 | AF7: 77 | AG7: 69.132 | AH7: 40 | AI7: 15.074 | AJ7: 48 | AK7: 36 | AL7: 3.7657267 | AM7: Yes | AN7: No | AO7: 20230328 | AP7: 46494 | AQ7: 1.9552546 | AR7: 0.71515197 | AS7: 0.070592358 | AT7: 0.0031214714 | AU7: 0.75007171 | AV7: 0.24992829 | AW7: 0 | AX7: 0.009721484 | AY7: 0.0090989336 | AZ7: 0.010374072 | BA7: 0.0089617806 | BB7: 0.0047999242 | BC7: 0.013379673 | BD7: 0 | BE7: 0 | BF7: 0 | BG7: 0.018683265 | BH7: 0.015716064 | BI7: 0.021947962 | BJ7: 0.041182707 | BK7: -0.0059291569 | BL7: 0.0067838395 | BM7: 0.03525355 | BN7: 0.047966546 | BO7: 0.01800924 | BP7: 0.014017577 | BQ7: 0.023266573 | BR7: 0 | BS7: 0 | BT7: 0 | BU7: 0.004490202 | BV7: 0.0036819657 | BW7: 0.0052984384 | BX7: 0.022499442 | BY7: 0.017699543 | BZ7: 0.028565012 | CA7: 0.0016561277 | CB7: 0.0014869015 | CC7: 0.98852887 | CD7: 23779 | CE7: 0.0016821565 | CF7: 0.00036281801 | CG7: 0.00063392069 | CH7: 7.146618 | CI7: 6.0889314 | CJ7: 8.5396744 | CK7: 7.146618 | CL7: 6.0889314 | CM7: 8.5396744 | CN7: 3.7657267 | CO7: 3.4335939 | CP7: 4.1035515 | CQ7: 7.167857 | CR7: 6.0722207 | CS7: 8.3426882 | CT7: 1.8801136 | CU7: 1.2898468 | CV7: 2.4821492 | CW7: 0 | CX7: 0 | CY7: 0 | CZ7: 0.76830901 | DA7: 0.52142333 | DB7: 1.0600763 | DC7: 1.8020435 | DD7: 1.0162878 | DE7: 3.057949 | DF7: 0.65490953 | DG7: 0.65490953 | DH7: 0.34509047 | DI7: 0.54633458 | DJ7: 0.43730236 | DK7: 4.9505785 | DL7: 1.8998225 | DM7: 0.011143192 | DN7: 0.057351807 | DO7: 0.9 | DP7: 17.326203 | DQ7: 0.16471306 | DR7: -0.14396371 | DS7: 0 | DT7: 0 | DX7: 0.0512 | DY7: 0.0523 | DZ7: 0.0501
A8: San_Joaquin_2017 | B8: 2.6703882 | C8: 2.5766783 | D8: 2.7519744 | E8: 4.4668887 | F8: 3.7241194 | G8: 5.2793177 | H8: 0 | I8: 0 | J8: 0 | K8: 7.1372769 | L8: 6.3912522 | M8: 7.9535315 | N8: 3.7241194 | O8: 5.2793177 | P8: 7.4447858 | Q8: 6.2324804 | R8: 8.9789547 | S8: 0 | T8: 1.2427775 | U8: 15.82484 | V8: 14.093118 | W8: 17.838027 | X8: 1000 | Y8: 0.11924573 | Z8: 11 | AA8: 40.99 | AB8: 284.66581 | AC8: 40365 | AD8: 192459 | AE8: 1.7471737 | AF8: 86 | AG8: 80.173 | AH8: 54 | AI8: 15.945 | AJ8: 144 | AK8: 89 | AL8: 3.9131657 | AM8: Yes | AN8: No | AO8: 20230328 | AP8: 110154 | AQ8: 4.7679522 | AR8: 0.45796686 | AS8: 0.054610591 | AT8: 0.003770881 | AU8: 0.34370242 | AV8: 0.65629758 | AW8: 0 | AX8: 0.0093807831 | AY8: 0.0086619693 | AZ8: 0.0100066 | BA8: 0.015691693 | BB8: 0.0099941905 | BC8: 0.02192353 | BD8: 0 | BE8: 0 | BF8: 0 | BG8: 0.025072477 | BH8: 0.022451773 | BI8: 0.02793989 | BJ8: 0.05559094 | BK8: -0.0060833526 | BL8: 0.0070721074 | BM8: 0.049507588 | BN8: 0.062663048 | BO8: 0.026152722 | BP8: 0.021894025 | BQ8: 0.03154209 | BR8: 0 | BS8: 0 | BT8: 0 | BU8: 0.0043657419 | BV8: 0.0035799084 | BW8: 0.0051515755 | BX8: 0.030518464 | BY8: 0.025473933 | BZ8: 0.036693665 | CA8: 0.00078072517 | CB8: 0.0007278265 | CC8: 0.98053415 | CD8: 23103 | CE8: 0.0023373588 | CF8: 0.00039502044 | CG8: 0.00069017011 | CH8: 11.911675 | CI8: 10.699369 | CJ8: 13.445843 | CK8: 11.911675 | CL8: 10.699369 | CM8: 13.445843 | CN8: 3.9131657 | CO8: 3.5957558 | CP8: 4.2184518 | CQ8: 11.914754 | CR8: 10.294406 | CS8: 13.677368 | CT8: 2.4029565 | CU8: 1.7642831 | CV8: 3.2514504 | CW8: 0 | CX8: 0 | CY8: 0 | CZ8: 0.13845571 | DA8: 0.075047583 | DB8: 0.44879336 | DC8: 4.2590312 | DD8: 3.3091377 | DE8: 5.6232244 | DF8: 0.75271877 | DG8: 0.75271877 | DH8: 0.24728123 | DI8: 0.54898166 | DJ8: 0.47044781 | DK8: 7.1372769 | DL8: 2.6207325 | DM8: 0.012321595 | DN8: 0.054455461 | DO8: 0.9 | DP8: 17.326203 | DQ8: 0.12720407 | DR8: -0.10943445 | DS8: 0 | DT8: 0 | DX8: 0.0485 | DY8: 0.0496 | DZ8: 0.0474
A9: San_Joaquin_summer2020 | B9: 1.8137632 | C9: 1.7684535 | D9: 1.8701691 | E9: 3.8353497 | F9: 3.1684788 | G9: 4.645684 | H9: 0 | I9: 0 | J9: 0 | K9: 5.6491128 | L9: 4.9786474 | M9: 6.45781 | N9: 3.1684788 | O9: 4.645684 | P9: 4.1889557 | Q9: 3.5147838 | R9: 5.1391793 | S9: 0 | T9: 0.87037445 | U9: 10.708443 | V9: 9.5566091 | W9: 12.07745 | X9: 1000 | Y9: 0.14962666 | Z9: 23.632192 | AA9: 36.556644 | AB9: 231.42089 | AC9: 31919 | AD9: 238393 | AE9: 1.995878 | AF9: 94 | AG9: 90.462 | AH9: 39 | AI9: 13.337 | AJ9: 0 | AK9: 0 | AL9: 2.6841376 | AM9: Yes | AN9: No | AO9: 20230328 | AP9: 119442 | AQ9: 7.4688594 | AR9: 0.3659088 | AS9: 0.054749711 | AT9: 0.0047316104 | AU9: 0.25471912 | AV9: 0.74528088 | AW9: 0 | AX9: 0.0078375085 | AY9: 0.0073024323 | AZ9: 0.0085036243 | BA9: 0.016573049 | BB9: 0.0086977631 | BC9: 0.02614254 | BD9: 0 | BE9: 0 | BF9: 0 | BG9: 0.024410557 | BH9: 0.021513388 | BI9: 0.027905044 | BJ9: 0.046272587 | BK9: -0.0049772253 | BL9: 0.0059156607 | BM9: 0.041295361 | BN9: 0.052188247 | BO9: 0.018101027 | BP9: 0.015187842 | BQ9: 0.022207068 | BR9: 0 | BS9: 0 | BT9: 0 | BU9: 0.0037610021 | BV9: 0.0030840217 | BW9: 0.0044379825 | BX9: 0.021862029 | BY9: 0.018271864 | BZ9: 0.02664505 | CA9: 0.00078699285 | CB9: 0.00075737178 | CC9: 0.9836107 | CD9: 15992 | CE9: 0.0024387194 | CF9: 0.0004178389 | CG9: 0.00083397949 | CH9: 8.0243054 | CI9: 7.3501335 | CJ9: 8.974529 | CK9: 8.0243054 | CL9: 7.3501335 | CM9: 8.974529 | CN9: 2.6841376 | CO9: 2.4821605 | CP9: 2.897211 | CQ9: 8.0265417 | CR9: 6.2056205 | CS9: 10.237035 | CT9: 3.570701 | CU9: 2.9721721 | CV9: 4.2543052 | CW9: 0.52539665 | CX9: 0.34291688 | CY9: 1.2972067 | CZ9: 0.01867589 | DA9: 0.011462354 | DB9: 0.075036913 | DC9: 0.074182202 | DD9: 0.047038281 | DE9: 0.23743176 | DF9: 0.74933357 | DG9: 0.74933357 | DH9: 0.25066643 | DI9: 0.47245103 | DJ9: 0.39116881 | DK9: 5.6491128 | DL9: 3.0636929 | DM9: 0.014471041 | DN9: 0.061625508 | DO9: 0.9 | DP9: 17.326203 | DQ9: 0.12785159 | DR9: -0.10756282 | DS9: 0 | DT9: 0 | DX9: 0.0565 | DY9: 0.0574 | DZ9: 0.0555
A10: San_Joaquin_fall2020 | B10: 1.8878621 | C10: 1.8370948 | D10: 1.941767 | E10: 2.5737452 | F10: 1.9474368 | G10: 3.4763426 | H10: 0 | I10: 0 | J10: 0 | K10: 4.4616073 | L10: 3.8333958 | M10: 5.3713353 | N10: 1.9474368 | O10: 3.4763426 | P10: 3.7938049 | Q10: 2.9650902 | R10: 4.9503656 | S10: 0 | T10: 0.92232287 | U10: 9.177735 | V10: 7.8798002 | W10: 10.67418 | X10: 1000 | Y10: 0.19641561 | Z10: 20.646402 | AA10: 37.591104 | AB10: 245.23328 | AC10: 33090 | AD10: 238974 | AE10: 1.995878 | AF10: 48 | AG10: 45.261 | AH10: 27 | AI10: 8.067 | AJ10: 0 | AK10: 0 | AL10: 2.810185 | AM10: Yes | AN10: No | AO10: 20230328 | AP10: 119733 | AQ10: 7.2219675 | AR10: 0.37211076 | AS10: 0.073088364 | AT10: 0.0062112071 | AU10: 0.44663385 | AV10: 0.55336615 | AW10: 0 | AX10: 0.0076982298 | AY10: 0.0071418996 | AZ10: 0.0082889431 | BA10: 0.010495089 | BB10: 0.0036317326 | BC10: 0.020386141 | BD10: 0 | BE10: 0 | BF10: 0 | BG10: 0.018193319 | BH10: 0.01563163 | BI10: 0.021902963 | BJ10: 0.037424509 | BK10: -0.0052926536 | BL10: 0.0061021268 | BM10: 0.032131856 | BN10: 0.043526636 | BO10: 0.015470188 | BP10: 0.012090897 | BQ10: 0.020186353 | BR10: 0 | BS10: 0 | BT10: 0 | BU10: 0.0037610021 | BV10: 0.0030840217 | BW10: 0.0044379825 | BX10: 0.01923119 | BY10: 0.015174919 | BZ10: 0.024624336 | CA10: 0.00040089198 | CB10: 0.00037801609 | CC10: 0.98378097 | CD10: 16579 | CE10: 0.0016285663 | CF10: 0.00024378966 | CG10: 0.00048657941 | CH10: 6.36755 | CI10: 5.5388354 | CJ10: 7.5241107 | CK10: 6.36755 | CL10: 5.5388354 | CM10: 7.5241107 | CN10: 2.810185 | CO10: 2.5933995 | CP10: 3.030108 | CQ10: 6.3643979 | CR10: 4.6697632 | CS10: 8.7994818 | CT10: 2.8943582 | CU10: 2.2094105 | CV10: 3.8017291 | CW10: 0.6748833 | CX10: 0.42375196 | CY10: 1.5724615 | CZ10: 0.22456333 | DA10: 0.15450208 | DB10: 0.28627927 | DC10: 0 | DD10: 0 | DE10: 0 | DF10: 0.69379041 | DG10: 0.69379041 | DH10: 0.30620959 | DI10: 0.51385383 | DJ10: 0.41335314 | DK10: 4.4616073 | DL10: 2.3250252 | DM10: 0.014791801 | DN10: 0.061625508 | DO10: 0.9 | DP10: 17.326203 | DQ10: 0.163021 | DR10: -0.14142859 | DS10: 0 | DT10: 0 | DX10: 0.0565 | DY10: 0.0574 | DZ10: 0.0555
A11: San_Joaquin_fall2021 | B11: 1.7279457 | C11: 1.666497 | D11: 1.7912582 | E11: 1.7547684 | F11: 1.2914509 | G11: 2.3126099 | H11: 0 | I11: 0 | J11: 0 | K11: 3.4827141 | L11: 3.0250833 | M11: 4.0385923 | N11: 1.2914509 | O11: 2.3126099 | P11: 0.79395397 | Q11: 0.55990172 | R11: 1.0641179 | S11: 0 | T11: 0.74474802 | U11: 5.0214161 | V11: 4.3764156 | W11: 5.7468923 | X11: 1000 | Y11: 0.11142142 | Z11: 15.95883 | AA11: 23.223 | AB11: 198.01851 | AC11: 33418 | AD11: 119340 | AE11: 1.995878 | AF11: 47 | AG11: 41.14 | AH11: 35 | AI11: 15.716 | AJ11: 0 | AK11: 0 | AL11: 2.4726937 | AM11: Yes | AN11: No | AO11: 20230328 | AP11: 59793 | AQ11: 3.5712238 | AR11: 0.52916543 | AS11: 0.058960365 | AT11: 0.0035234547 | AU11: 0.42546891 | AV11: 0.57453109 | AW11: 0 | AX11: 0.0087261829 | AY11: 0.0081397538 | AZ11: 0.009330399 | BA11: 0.0088616383 | BB11: 0.0044400181 | BC11: 0.014185338 | BD11: 0 | BE11: 0 | BF11: 0 | BG11: 0.017587821 | BH11: 0.015276771 | BI11: 0.020395025 | BJ11: 0.025358317 | BK11: -0.0032572739 | BL11: 0.003663679 | BM11: 0.022101043 | BN11: 0.029021996 | BO11: 0.0040094938 | BP11: 0.0028275222 | BQ11: 0.0053738307 | BR11: 0 | BS11: 0 | BT11: 0 | BU11: 0.0037610021 | BV11: 0.0030840217 | BW11: 0.0044379825 | BX11: 0.0077704959 | BY11: 0.005911544 | BZ11: 0.0098118133 | CA11: 0.00078604519 | CB11: 0.00068804041 | CC11: 0.96072198 | CD11: 16743 | CE11: 0.0020904258 | CF11: 0.00047028547 | CG11: 0.00093866093 | CH11: 2.5487223 | CI11: 2.3146701 | CJ11: 2.8188863 | CK11: 2.5487223 | CL11: 2.3146701 | CM11: 2.8188863 | CN11: 2.4726937 | CO11: 2.2771904 | CP11: 2.6700609 | CQ11: 2.5597313 | CR11: 1.6740932 | CS11: 3.6189042 | CT11: 0.53770521 | CU11: 0.36721408 | CV11: 0.75176112 | CW11: 0.25624876 | CX11: 0.12427099 | CY11: 0.4367343 | CZ11: 0 | DA11: 0 | DB11: 0 | DC11: 0 | DD11: 0 | DE11: 0 | DF11: 0.50756012 | DG11: 0.50756012 | DH11: 0.49243988 | DI11: 0.30642374 | DJ11: 0.15810584 | DK11: 3.4827141 | DL11: 1.936358 | DM11: 0.011826943 | DN11: 0.061625508 | DO11: 0.9 | DP11: 17.326203 | DQ11: 0.14446356 | DR11: -0.12844561 | DS11: 0 | DT11: 0 | DX11: 0.0565 | DY11: 0.0574 | DZ11: 0.0555
A12: Denver_summer2021 | B12: 12.232833 | C12: 11.960012 | D12: 12.51506 | E12: 2.3047932 | F12: 1.6525682 | G12: 3.0979952 | H12: 0 | I12: 0 | J12: 0 | K12: 14.537626 | L12: 13.816908 | M12: 15.398868 | N12: 1.6525682 | O12: 3.0979952 | P12: 0.71351519 | Q12: 0.47193469 | R12: 1.0533051 | S12: 0 | T12: 6.246524 | U12: 21.497665 | V12: 19.584265 | W12: 23.515509 | X12: 1000 | Y12: 0.047402712 | Z12: 11.102345 | AA12: 75.042 | AB12: 1997.3945 | AC12: 11671 | AD12: 59356 | AE12: 1.6088026 | AF12: 34 | AG12: 27.151 | AH12: 27 | AI12: 8.491 | AJ12: 0 | AK12: 0 | AL12: 18.479357 | AM12: Yes | AN12: No | AO12: 20230328 | AP12: 36894 | AQ12: 5.0860215 | AR12: 0.44341553 | AS12: 0.021019099 | AT12: 0.0014990054 | AU12: 0.89945091 | AV12: 0.10054909 | AW12: 0 | AX12: 0.006124395 | AY12: 0.0058163584 | AZ12: 0.0064430522 | BA12: 0.0011538998 | BB12: 0.00041748479 | BC12: 0.0020494894 | BD12: 0 | BE12: 0 | BF12: 0 | BG12: 0.0072782948 | BH12: 0.0069174656 | BI12: 0.0077094773 | BJ12: 0.010762854 | BK12: -0.00095794812 | BL12: 0.001010238 | BM12: 0.0098049058 | BN12: 0.011773092 | BO12: 0.00035722297 | BP12: 0.00023627515 | BQ12: 0.00052733954 | BR12: 0 | BS12: 0 | BT12: 0 | BU12: 0.0031273362 | BV12: 0.0025644157 | BW12: 0.0036902567 | BX12: 0.0034845591 | BY12: 0.0028006908 | BZ12: 0.0042175962 | CA12: 0.00092155906 | CB12: 0.00073591912 | CC12: 0.97703263 | CD12: 7254 | CE12: 0.0037220844 | CF12: 0.00072752977 | CG12: 0.0011705266 | CH12: 3.0183084 | CI12: 2.7767279 | CJ12: 3.3580982 | CK12: 3.0183084 | CL12: 2.7767279 | CM12: 3.3580982 | CN12: 18.479357 | CO12: 17.082162 | CP12: 19.885958 | CQ12: 3.063132 | CR12: 1.5951947 | CS12: 4.8604373 | CT12: 0.21942916 | CU12: 0.1252747 | CV12: 0.40408769 | CW12: 0.25155834 | CX12: 0.13947767 | CY12: 0.45244345 | CZ12: 0.24252769 | DA12: 0.13470518 | DB12: 0.51540879 | DC12: 0 | DD12: 0 | DE12: 0 | DF12: 0.1403988 | DG12: 0.1403988 | DH12: 0.8596012 | DI12: 0.32376 | DJ12: 0.03319053 | DK12: 14.537626 | DL12: 1.161116 | DM12: 0.27535077 | DN12: 0.0097082922 | DO12: 0.9 | DP12: 17.326203 | DQ12: 0.093858945 | DR12: -0.089003162 | DS12: 0 | DT12: 0 | DX12: 0.0054 | DY12: 0.0062 | DZ12: 0.0047
A13: Denver_fall2021 | B13: 12.319771 | C13: 12.061479 | D13: 12.593345 | E13: 2.306704 | F13: 1.5837147 | G13: 3.1750613 | H13: 0 | I13: 0 | J13: 0 | K13: 14.626475 | L13: 13.84779 | M13: 15.537186 | N13: 1.5837147 | O13: 3.1750613 | P13: 2.332878 | Q13: 1.5725196 | R13: 4.098675 | S13: 0 | T13: 6.1693766 | U13: 23.12873 | V13: 20.796505 | W13: 26.224278 | X13: 1000 | Y13: 0.089035172 | Z13: 10.160213 | AA13: 66.55 | AB13: 1972.7258 | AC13: 11688 | AD13: 67811 | AE13: 1.6088026 | AF13: 40 | AG13: 31.592 | AH13: 33 | AI13: 8.473 | AJ13: 0 | AK13: 0 | AL13: 18.489148 | AM13: Yes | AN13: No | AO13: 20230328 | AP13: 42149 | AQ13: 5.8016518 | AR13: 0.41516829 | AS13: 0.03696458 | AT13: 0.0028155394 | AU13: 0.87637878 | AV13: 0.12362122 | AW13: 0 | AX13: 0.0062450501 | AY13: 0.0059296804 | AZ13: 0.0065790786 | BA13: 0.0011692979 | BB13: 0.00028654123 | BC13: 0.0022295461 | BD13: 0 | BE13: 0 | BF13: 0 | BG13: 0.007414348 | BH13: 0.0070196222 | BI13: 0.0078759988 | BJ13: 0.01172425 | BK13: -0.0011822349 | BL13: 0.0015691728 | BM13: 0.010542015 | BN13: 0.013293423 | BO13: 0.0011825658 | BP13: 0.00079713036 | BQ13: 0.0020776709 | BR13: 0 | BS13: 0 | BT13: 0 | BU13: 0.0031273362 | BV13: 0.0025644157 | BW13: 0.0036902567 | BX13: 0.004309902 | BY13: 0.003361546 | BZ13: 0.0057679276 | CA13: 0.00094901421 | CB13: 0.00074953142 | CC13: 0.97363305 | CD13: 7265 | CE13: 0.0045423262 | CF13: 0.00072493155 | CG13: 0.0011662767 | CH13: 4.639582 | CI13: 3.8792236 | CJ13: 6.405379 | CK13: 4.639582 | CL13: 3.8792236 | CM13: 6.405379 | CN13: 18.489148 | CO13: 17.120368 | CP13: 19.873209 | CQ13: 4.7008626 | CR13: 2.9447912 | CS13: 6.8126629 | CT13: 1.1640808 | CU13: 0.68079136 | CV13: 2.8266944 | CW13: 0.74421681 | CX13: 0.51435544 | CY13: 1.0647944 | CZ13: 0.42458042 | DA13: 0.24874888 | DB13: 0.70625726 | DC13: 0 | DD13: 0 | DE13: 0 | DF13: 0.20059553 | DG13: 0.20059553 | DH13: 0.79940447 | DI13: 0.36760607 | DJ13: 0.10086374 | DK13: 14.626475 | DL13: 1.1559367 | DM13: 0.2715383 | DN13: 0.0097082922 | DO13: 0.9 | DP13: 17.326203 | DQ13: 0.13383552 | DR13: -0.1008379 | DS13: 0 | DT13: 0 | DX13: 0.0054 | DY13: 0.0062 | DZ13: 0.0047
... A15: Uinta_2020 | B15: 10.546107 | C15: 10.285607 | D15: 10.815668 | E15: 5.8726323 | F15: 4.7375277 | G15: 7.0345028 | H15: 0 | I15: 0 | J15: 0 | K15: 16.418739 | L15: 15.274613 | M15: 17.584309 | N15: 4.7375277 | O15: 7.0345028 | P15: 2.3677981 | Q15: 1.7530518 | R15: 3.2232782 | S15: 0 | T15: 1.3191311 | U15: 20.105669 | V15: 18.449824 | W15: 21.724096 | X15: 1000 | Y15: 0.070991531 | Z15: 8.3545392 | AA15: 52.98 | AB15: 350.73927 | AC15: 9185 | AD15: 32340 | AE15: 1.7099474 | AF15: 56 | AG15: 41.13 | AH15: 42 | AI15: 24.905 | AJ15: 0 | AK15: 0 | AL15: 11.865238 | AM15: Yes | AN15: No | AO15: 20230328 | AP15: 18912 | AQ15: 3.521132 | AR15: 0.53291611 | AS15: 0.03783253 | AT15: 0.0022449493 | AU15: 0.70703016 | AV15: 0.29296984 | AW15: 0 | AX15: 0.030068225 | AY15: 0.028674538 | AZ15: 0.031510386 | BA15: 0.016743584 | BB15: 0.010670732 | BC15: 0.022959633 | BD15: 0 | BE15: 0 | BF15: 0 | BG15: 0.046811809 | BH15: 0.043549767 | BI15: 0.050134987 | BJ15: 0.057323689 | BK15: -0.0047210145 | BL15: 0.004614333 | BM15: 0.052602674 | BN15: 0.061938022 | BO15: 0.0067508782 | BP15: 0.0049981624 | BQ15: 0.0091899554 | BR15: 0 | BS15: 0 | BT15: 0 | BU15: 0.0037610021 | BV15: 0.0030840217 | BW15: 0.0044379825 | BX15: 0.01051188 | BY15: 0.0080821841 | BZ15: 0.013627938 | CA15: 0.0029610829 | CB15: 0.0021748096 | CC15: 0.9481536 | CD15: 5371 | CE15: 0.0078197729 | CF15: 0.0027114861 | CG15: 0.0046369391 | CH15: 8.2404304 | CI15: 7.6256842 | CJ15: 9.0959106 | CK15: 8.2404304 | CL15: 7.6256842 | CM15: 9.0959106 | CN15: 11.865238 | CO15: 11.367294 | CP15: 12.372243 | CQ15: 8.3755421 | CR15: 6.2608101 | CS15: 10.581536 | CT15: 1.809119 | CU15: 1.3290974 | CV15: 2.4350056 | CW15: 0.2653703 | CX15: 0.17108015 | CY15: 0.41351091 | CZ15: 0.29330879 | DA15: 0.13699981 | DB15: 0.87323479 | DC15: 0 | DD15: 0 | DE15: 0 | DF15: 0.409853 | DG15: 0.409853 | DH15: 0.590147 | DI15: 0.18337649 | DJ15: 0.11776603 | DK15: 16.418739 | DL15: 1.4761386 | DM15: 0.065302414 | DN15: 0.024005542 | DO15: 0.9 | DP15: 17.326203 | DQ15: 0.08050515 | DR15: -0.082370586 | DS15: 0 | DT15: 0 | DX15: 0.0189 | DY15: 0.0198 | DZ15: 0.0179
A16: Fort_Worth_2021 | B16: 3.5016955 | C16: 3.2833694 | D16: 3.7428101 | E16: 15.138765 | F16: 13.030171 | G16: 17.581124 | H16: 0.75265304 | I16: 0.52351724 | J16: 1.0772285 | K16: 19.393114 | L16: 17.218757 | M16: 21.850881 | N16: 13.030171 | O16: 17.581124 | P16: 2.5528017 | Q16: 2.1109539 | R16: 3.0565756 | S16: 1.6072708 | T16: 2.186488 | U16: 25.739674 | V16: 23.080581 | W16: 28.645476 | X16: 1000 | Y16: 0.065015162 | Z16: 10.889258 | AA16: 55.886 | AB16: 636.66735 | AC16: 7474 | AD16: 12982 | AE16: 1.6224651 | AF16: 80 | AG16: 80 | AH16: 49 | AI16: 40.006 | AJ16: 49 | AK16: 23 | AL16: 5.6881835 | AM16: Yes | AN16: No | AO16: 20230328 | AP16: 8001 | AQ16: 1.7370821 | AR16: 0.7587345 | AS16: 0.049329247 | AT16: 0.00205596 | AU16: 0.15345486 | AV16: 0.83086326 | AW16: 0.015681874 | AX16: 0.0055000393 | AY16: 0.0050480761 | AZ16: 0.005999178 | BA16: 0.02377814 | BB16: 0.019413076 | BC16: 0.02883414 | BD16: 0.0011821763 | BE16: 0.00070783542 | BF16: 0.0018540895 | BG16: 0.030460355 | BH16: 0.02704514 | BI16: 0.034320719 | BJ16: 0.040428764 | BK16: -0.0041765812 | BL16: 0.0045640813 | BM16: 0.036252183 | BN16: 0.044992846 | BO16: 0.0040096319 | BP16: 0.0033156308 | BQ16: 0.004800899 | BR16: 0.0025245064 | BS16: 0.0019803151 | BT16: 0.0031013627 | BU16: 0.0034342708 | BV16: 0.002816102 | BW16: 0.0040524395 | BX16: 0.009968409 | BY16: 0.0083660291 | BZ16: 0.011602155 | CA16: 0.0099987502 | CB16: 0.0099987502 | CC16: 0.98912832 | CD16: 4606 | CE16: 0.010638298 | CF16: 0.0053526893 | CG16: 0.0086856274 | CH16: 17.691567 | CI16: 17.249719 | CJ16: 18.195341 | CK16: 19.298838 | CL16: 18.510521 | CM16: 20.169877 | CN16: 5.6881835 | CO16: 5.0762896 | CP16: 6.322866 | CQ16: 17.72156 | CR16: 14.944751 | CS16: 20.94021 | CT16: 1.0166129 | CU16: 0.81235059 | CV16: 1.2215896 | CW16: 0.94529093 | CX16: 0.63345602 | CY16: 1.323353 | CZ16: 0.59089787 | DA16: 0.34228087 | DB16: 0.83922829 | DC16: Null | DD16: Null | DE16: Null | DF16: 0.68732508 | DG16: 0.74976836 | DH16: 0.22099088 | DI16: 0.24656858 | DJ16: 0.099178231 | DK16: 19.393114 | DL16: 5.4781952 | DM16: 0.13822565 | DN16: 0.010661119 | DO16: 0.9 | DP16: 17.326203 | DQ16: 0.11288133 | DR16: -0.10329695 | DS16: 0.029240759 | DT16: 0.06007805 | DX16: 0.006 | DY16: 0.0068 | DZ16: 0.0051
A17: Permian_2019_F2021_bounds | B17: 22.148702 | C17: 21.735113 | D17: 22.645529 | E17: 104.3653 | F17: 99.447983 | G17: 110.04035 | H17: 0 | I17: 0 | J17: 0 | K17: 126.51401 | L17: 121.56414 | M17: 132.25819 | N17: 99.447983 | O17: 110.04035 | P17: 75.485924 | Q17: 68.82265 | R17: 83.688109 | S17: 0 | T17: 17.29491 | U17: 219.29484 | V17: 207.36829 | W17: 232.04808 | X17: 1000 | Y17: 0.066200513 | Z17: 16.353134 | AA17: 58.47 | AB17: 4755.8021 | AC17: 17164 | AD17: 152653 | AE17: 1.8250769 | AF17: 1052 | AG17: 998.006 | AH17: 540 | AI17: 166.933 | AJ17: 681 | AK17: 278 | AL17: 39.443612 | AM17: Yes | AN17: No | AO17: 20230328 | AP17: 83641 | AQ17: 8.894194 | AR17: 0.33531015 | AS17: 0.022197704 | AT17: 0.002093444 | AU17: 0.34217279 | AV17: 0.65782721 | AW17: 0 | AX17: 0.0046571958 | AY17: 0.0043978385 | AZ17: 0.0049687511 | BA17: 0.021944837 | BB17: 0.018861237 | BC17: 0.025503598 | BD17: 0 | BE17: 0 | BF17: 0 | BG17: 0.026602033 | BH17: 0.025561228 | BI17: 0.027809861 | BJ17: 0.04611101 | BK17: -0.0025077886 | BL17: 0.0026816161 | BM17: 0.043603221 | BN17: 0.048792626 | BO17: 0.015872385 | BP17: 0.014471302 | BQ17: 0.017597054 | BR17: 0 | BS17: 0 | BT17: 0 | BU17: 0.0036365916 | BV17: 0.0029820052 | BW17: 0.0042911781 | BX17: 0.019508977 | BY17: 0.017453307 | BZ17: 0.021888232 | CA17: 0.012577564 | CB17: 0.011932019 | CC17: 0.77723967 | CD17: 9404 | CE17: 0.057422373 | CF17: 0.0097257632 | CG17: 0.017751276 | CH17: 179.85123 | CI17: 173.18795 | CJ17: 188.05341 | CK17: 179.85123 | CL17: 173.18795 | CM17: 188.05341 | CN17: 39.443612 | CO17: 35.916939 | CP17: 43.053523 | CQ17: 179.92729 | CR17: 165.2598 | CS17: 196.87586 | CT17: 22.333899 | CU17: 20.041045 | CV17: 24.937251 | CW17: 34.922741 | CX17: 31.38451 | CY17: 39.550834 | CZ17: 18.229284 | DA17: 13.569312 | DB17: 24.782488 | DC17: 0 | DD17: 0 | DE17: 0 | DF17: 0.82013382 | DG17: 0.82013382 | DH17: 0.17986618 | DI17: 0.42308642 | DJ17: 0.34422003 | DK17: 126.51401 | DL17: 4.4396245 | DM17: 0.5057212 | DN17: 0.011491852 | DO17: 0.9 | DP17: 17.326203 | DQ17: 0.058154851 | DR17: -0.054391392 | DS17: 0 | DT17: 0 | DX17: 0.006 | DY17: 0.0068 | DZ17: 0.0051
A18: Permian_2019_F2021_bounds_Delaware | B18: 13.618146 | C18: 13.368396 | D18: 13.906352 | E18: 57.866334 | F18: 54.50886 | G18: 61.619504 | H18: 0 | I18: 0 | J18: 0 | K18: 71.484479 | L18: 68.148976 | M18: 75.257285 | N18: 54.50886 | O18: 61.619504 | P18: 37.214472 | Q18: 34.109332 | R18: 41.35431 | S18: 0 | T18: 13.139793 | U18: 121.83874 | V18: 114.57394 | W18: 129.61674 | X18: 1000 | Y18: 0.079024395 | Z18: 16.353134 | AA18: 53.834 | AB18: 3613.2165 | AC18: 7955 | AD18: 100870 | AE18: 1.8250769 | AF18: 922 | AG18: 875.148 | AH18: 447 | AI18: 117.859 | AJ18: 558 | AK18: 202 | AL18: 26.757939 | AM18: Yes | AN18: No | AO18: 20230328 | AP18: 55268 | AQ18: 12.681964 | AR18: 0.28080623 | AS18: 0.022190542 | AT18: 0.0024989708 | AU18: 0.39189647 | AV18: 0.60810353 | AW18: 0 | AX18: 0.0037689814 | AY18: 0.003522829 | AZ18: 0.0040530367 | BA18: 0.016015186 | BB18: 0.012706071 | BC18: 0.019714298 | BD18: 0 | BE18: 0 | BF18: 0 | BG18: 0.019784167 | BH18: 0.018861028 | BI18: 0.020828335 | BJ18: 0.0337203 | BK18: -0.0020106208 | BL18: 0.0021526514 | BM18: 0.031709679 | BN18: 0.035872951 | BO18: 0.010299541 | BP18: 0.0094401571 | BQ18: 0.01144529 | BR18: 0 | BS18: 0 | BT18: 0 | BU18: 0.0036365916 | BV18: 0.0029820052 | BW18: 0.0042911781 | BX18: 0.013936133 | BY18: 0.012422162 | BZ18: 0.015736468 | CA18: 0.016682348 | CB18: 0.015834624 | CC18: 0.72979374 | CD18: 4358 | CE18: 0.10256999 | CF18: 0.014815713 | CG18: 0.027044286 | CH18: 95.080806 | CI18: 91.975665 | CJ18: 99.220643 | CK18: 95.080806 | CL18: 91.975665 | CM18: 99.220643 | CN18: 26.757939 | CO18: 24.143026 | CP18: 29.411308 | CQ18: 95.140759 | CR18: 83.076043 | CS18: 108.50894 | CT18: 9.544423 | CU18: 8.0163724 | CV18: 11.521331 | CW18: 24.126113 | CX18: 22.06504 | CY18: 26.915883 | CZ18: 3.5439364 | DA18: 2.6744617 | DB18: 6.8036968 | DC18: 0 | DD18: 0 | DE18: 0 | DF18: 0.78038188 | DG18: 0.78038188 | DH18: 0.21961812 | DI18: 0.41328555 | DJ18: 0.30543943 | DK18: 71.484479 | DL18: 3.8309006 | DM18: 0.8290997 | DN18: 0.011491852 | DO18: 0.9 | DP18: 17.326203 | DQ18: 0.063840824 | DR18: -0.059625543 | DS18: 0 | DT18: 0 | DX18: 0.006 | DY18: 0.0068 | DZ18: 0.0051
A19: Permian_2019_F2021_Midland | B19: 8.943957 | C19: 8.5812303 | D19: 9.3585013 | E19: 46.320256 | F19: 42.849983 | G19: 50.10698 | H19: 0 | I19: 0 | J19: 0 | K19: 55.264213 | L19: 51.75283 | M19: 59.060329 | N19: 42.849983 | O19: 50.10698 | P19: 38.320203 | Q19: 31.78791 | R19: 47.375104 | S19: 0 | T19: 4.1551174 | U19: 97.739534 | V19: 89.163126 | W19: 107.897 | X19: 1000 | Y19: 0.11291444 | Z19: 16.353134 | AA19: 109.707 | AB19: 1142.5856 | AC19: 9209 | AD19: 51783 | AE19: 1.8250769 | AF19: 130 | AG19: 124.363 | AH19: 93 | AI19: 49.05 | AJ19: 123 | AK19: 76 | AL19: 13.099074 | AM19: Yes | AN19: No | AO19: 20230328 | AP19: 28373 | AQ19: 5.6239841 | AR19: 0.4216751 | AS19: 0.047613209 | AT19: 0.0035706682 | AU19: 0.2402536 | AV19: 0.7597464 | AW19: 0 | AX19: 0.007827822 | AY19: 0.0070749645 | AZ19: 0.0086882296 | BA19: 0.040539855 | BB19: 0.03333713 | BC19: 0.048399393 | BD19: 0 | BE19: 0 | BF19: 0 | BG19: 0.048367677 | BH19: 0.045294487 | BI19: 0.051690068 | BJ19: 0.085542415 | BK19: -0.0075061397 | BL19: 0.0088898957 | BM19: 0.078036275 | BN19: 0.09443231 | BO19: 0.033538146 | BP19: 0.027821031 | BQ19: 0.041463067 | BR19: 0 | BS19: 0 | BT19: 0 | BU19: 0.0036365916 | BV19: 0.0029820052 | BW19: 0.0042911781 | BX19: 0.037174737 | BY19: 0.030803036 | BZ19: 0.045754245 | CA19: 0.0045818207 | CB19: 0.0043831459 | CC19: 0.92333209 | CD19: 5045 | CE19: 0.018434093 | CF19: 0.0053263112 | CG19: 0.0097224975 | CH19: 84.640459 | CI19: 78.108166 | CJ19: 93.69536 | CK19: 84.640459 | CL19: 78.108166 | CM19: 93.69536 | CN19: 13.099074 | CO19: 11.988427 | CP19: 14.26154 | CQ19: 84.692902 | CR19: 76.434283 | CS19: 93.697522 | CT19: 12.806178 | CU19: 11.355719 | CV19: 14.288722 | CW19: 10.881274 | CX19: 8.2420504 | CY19: 15.634552 | CZ19: 14.632752 | DA19: 9.5841244 | DB19: 22.283186 | DC19: 0 | DD19: 0 | DE19: 0 | DF19: 0.86597895 | DG19: 0.86597895 | DH19: 0.13402105 | DI19: 0.43457483 | DJ19: 0.39206235 | DK19: 55.264213 | DL19: 5.705342 | DM19: 0.22647882 | DN19: 0.011491852 | DO19: 0.9 | DP19: 17.326203 | DQ19: 0.10391132 | DR19: -0.087738922 | DS19: 0 | DT19: 0 | DX19: 0.006 | DY19: 0.0068 | DZ19: 0.0051
A20: Northeast_Pennsylvania_2021 | B20: 1.1107842 | C20: 0.98236924 | D20: 1.2763473 | E20: 19.430811 | F20: 15.450309 | G20: 22.976908 | H20: 0 | I20: 0 | J20: 0 | K20: 20.541595 | L20: 16.581193 | M20: 24.063487 | N20: 15.450309 | O20: 22.976908 | P20: 8.3888537 | Q20: 5.8558225 | R20: 11.146641 | S20: 0 | T20: 9.0260916 | U20: 37.956541 | V20: 31.826936 | W20: 43.92599 | X20: 1000 | Y20: 0.073058183 | Z20: 495.44526 | AA20: 495.44526 | AB20: 5095.6288 | AC20: 2996 | AD20: 4039 | AE20: 1.2580446 | AF20: 12 | AG20: 11 | AH20: 12 | AI20: 11.47 | AJ20: 4 | AK20: 4 | AL20: 10.136876 | AM20: Yes | AN20: No | AO20: 20230328 | AP20: 3210 | AQ20: 1.348173 | AR20: 0.86124593 | AS20: 0.062921063 | AT20: 0.0023103026 | AU20: 0.020145114 | AV20: 0.97985489 | AW20: 0 | AX20: 0.00021798767 | AY20: 0.00018872656 | AZ20: 0.00025571346 | BA20: 0.0038132313 | BB20: 0.0029062196 | BC20: 0.0046212579 | BD20: 0 | BE20: 0 | BF20: 0 | BG20: 0.004031219 | BH20: 0.0032540034 | BI20: 0.0047223782 | BJ20: 0.0074488433 | BK20: -0.0012029143 | BL20: 0.0011714843 | BM20: 0.0062459291 | BN20: 0.0086203276 | BO20: 0.0016462843 | BP20: 0.0011491855 | BQ20: 0.0021874909 | BR20: 0 | BS20: 0 | BT20: 0 | BU20: 0.0017713401 | BV20: 0.0014524989 | BW20: 0.0020901813 | BX20: 0.0034176244 | BY20: 0.0026016843 | BZ20: 0.0042776722 | CA20: 0.0037383178 | CB20: 0.0034267913 | CC20: 1 | CD20: 2381 | CE20: 0.0050398992 | CF20: 0.0038284379 | CG20: 0.0048173037 | CH20: 27.819665 | CI20: 25.286634 | CJ20: 30.577453 | CK20: 27.819665 | CL20: 25.286634 | CM20: 30.577453 | CN20: 10.136876 | CO20: 8.3837643 | CP20: 11.927135 | CQ20: 28.133483 | CR20: 23.695833 | CS20: 32.175263 | CT20: 1.3883667 | CU20: 0.41255719 | CV20: 2.548771 | CW20: 6.9026293 | CX20: 4.7297497 | CY20: 9.3505775 | CZ20: 0.09785773 | DA20: 0.013578159 | DB20: 0.39998094 | DC20: 0 | DD20: 0 | DE20: 0 | DF20: 0.73293438 | DG20: 0.73293438 | DH20: 0.26706562 | DI20: 0.45881195 | DJ20: 0.22101087 | DK20: 20.541595 | DL20: 18.493792 | DM20: 2.1401213 | DN20: 0.0054988291 | DO20: 0.9 | DP20: 17.326203 | DQ20: 0.1572749 | DR20: -0.16149121 | DS20: 0 | DT20: 0 | DX20: 0.0031 | DY20: 0.0035 | DZ20: 0.0026
A21: GHGI 2022 (for 2020) | AK21: 1 | AT21: 0.0048 | AX21: =BG21 -> 0.004942 | AY21: =BH21 -> 0.0039430226 | AZ21: =BI21 -> 0.0059850499 | BG21: 0.004942 | BH21: =$BG$21+BK21*$BG$21/$BJ$21 -> 0.0039430226 | BI21: =$BG$21+BL21*$BG$21/$BJ$21 -> 0.0059850499 | BJ21: =BG21+BU21 -> 0.010092 | BK21: -0.00204 | BL21: 0.00213 | BM21: =BJ21+BK21 -> 0.008052 | BN21: =BJ21+BL21 -> 0.012222 | BU21: 0.00515 | BV21: =$BU$21+BK21*$BU$21/$BJ$21 -> 0.0041089774 | BW21: =$BU$21+BL21*$BU$21/$BJ$21 -> 0.0062369501
A22: GHGI NM 2019
A23: GHGI TX 2021
A24: GHGI CA 2021
A25: GHGI CO 2021
A26: GHGI PA 2021 | AA26: Fraction of national gas covered | AB26: =AB27/AB30 -> 0.28137144
A27: Totals excluding repeats | U27: =U3+U7+U13+U14+U15+U16 -> 712.69993 | V27: =V3+V7+V13+V14+V15+V16 -> 671.65113 | W27: =W3+W7+W13+W14+W15+W16 -> 755.79972 | AB27: =AB3+AB7+AB13+AB14+AB15+AB16 -> 23994.401 | AC27: =AC3+AC7+AC13+AC14+AC15+AC16 -> 170569 | AD27: =AD3+AD7+AD13+AD14+AD15+AD16 -> 549072 | AI27: =AI3+AI7+AI13+AI14+AI15+AI16 -> 601.409 | AP27: 1 | AQ27: =AQ3+AQ7+AQ13+AQ14+AQ15+AQ16 -> 18.606751 | AR27: =AD27/AC27 -> 3.2190609 | BE27: =U27/$AB27 -> 0.02970276 | BF27: =V27/$AB27 -> 0.027991994 | BG27: =W27/$AB27 -> 0.031499004 | BR27: =BR3+BR7+BR13+BR14+BR15+BR16 -> 0.0025245064 | BU27: =AI27/BR27 -> 238228.35 | BV27: =BV3+BV7+BV13+BV14+BV15+BV16 -> 0.016581009 | CH27: =CH3+CH7+CH13+CH14+CH15+CH16 -> 532.8099
A28: Totals including repeats (no 2019 subcampaigns) | U28: =SUM(U2:U16) -> 1357.3744 | V28: =SUM(V2:V16) -> 1268.7274 | W28: =SUM(W2:W16) -> 1452.2201 | AB28: =SUM(AB2:AB16) -> 45847.976 | AC28: =SUM(AC2:AC16) -> 398499 | AD28: =SUM(AD2:AD16) -> 1714261 | AI28: =SUM(AI2:AI16) -> 1240.421 | AP28: 1 | AQ28: =SUM(AQ2:AQ16) -> 62.970182 | AR28: =AQ28/BR27 -> 24943.562 | BE28: =U28/$AB28 -> 0.029605984 | BF28: =V28/$AB28 -> 0.027672485 | BG28: =W28/$AB28 -> 0.031674684 | BR28: =SUM(BR2:BR16) -> 0.0050364846 | BU28: =AI28/BR28 -> 246287.06 | CG28: Aerially measured/Total emissions | CH28: =CH27/U27 -> 0.74759359
A29: Totals excluding high-prod campaigns | U29: =U3+U7+U13+U15+U16 -> 636.351 | V29: =V3+V7+V13+V15+V16 -> 604.59374 | W29: =W3+W7+W13+W15+W16 -> 669.47152 | AB29: =AB3+AB7+AB13+AB15+AB16 -> 13751.921 | BE29: =U29/$AB29 -> 0.046273608 | BF29: =V29/$AB29 -> 0.043964311 | BG29: =W29/$AB29 -> 0.048682036
T30: Social cost of methane [$/t] | U30: 1500 | AA30: 2021 US gas prod | AB30: 85276.605 | BX30: Methane fractional loss partial | CO30: GHGI midstream sub-aerial fraction | CP30: =0.7303 -> 0.7303
A31: Permian total | T31: Hours per day | U31: 8760 | AC31: =SUM(Y2:Y6) -> 0.25094269 | AD31: =SUM(Z2:Z6) -> 65.379118 | AF31: =SUM(AB2:AB6) -> 29423.657 | AG31: =SUM(AC2:AC6) -> 162037 | AH31: =SUM(AD2:AD6) -> 643575 | AI31: =SUM(AE2:AE6) -> 8.5003077 | AJ31: =SUM(AF2:AF6) -> 3866 | AK31: =SUM(AG2:AG6) -> 3609.664 | AQ31: =SUM(AL2:AL6) -> 272.18659 | AR31: =AQ31/BR31 -> 1319.3069 | BR31: =SUM(BM2:BM6) -> 0.20631029 | BX31: FracLossProd
A32: San Joaquin total | T32: GWP20 (IPCC 2021) | U32: 82.5 | V32: https://report.ipcc.ch/ar6/wg1/IPCC_AR6_WGI_FullReport.pdf | W32: Table 7.15 | AC32: =SUM(Y7:Y11) -> 0.67541901 | AD32: =SUM(Z7:Z11) -> 80.237423 | AF32: =SUM(AB7:AB11) -> 1224.3124 | AG32: =SUM(AC7:AC11) -> 180339 | AH32: =SUM(AD7:AD11) -> 870400 | AI32: =SUM(AE7:AE11) -> 9.4819814 | AJ32: =SUM(AF7:AF11) -> 352 | AK32: =SUM(AG7:AG11) -> 326.168 | AQ32: =SUM(AL7:AL11) -> 15.645909 | AR32: =AQ32/BR32 -> 86.78219 | BR32: =SUM(BM7:BM11) -> 0.1802894 | BX32: Methane fractional loss total
A33: Denver total | T33: Emissions [tCH4/yr] | U33: =U27*$U$31 -> 6243251.4 | V33: =V27*$U$31 -> 5883663.9 | W33: =W27*$U$31 -> 6620805.6 | AC33: =Y12+Y13 -> 0.13643788 | AD33: =Z12+Z13 -> 21.262557 | AF33: =AB12+AB13 -> 3970.1203 | AG33: =AC12+AC13 -> 23359 | AH33: =AD12+AD13 -> 127167 | AI33: =AE12+AE13 -> 3.2176052 | AJ33: =AF12+AF13 -> 74 | AK33: =AG12+AG13 -> 58.743 | AQ33: =AL12+AL13 -> 36.968505 | AR33: =AQ33/BR33 -> 1816.9091 | BR33: =BM12+BM13 -> 0.020346921 | BX33: FracLossP2.5
A34: Per+SJ+DJ | T34: Emissions [tCO2e/yr] | U34: =U33*$U$32 -> 5.1506824e+08 | V34: =V33*$U$32 -> 4.8540228e+08 | W34: =W33*$U$32 -> 5.4621646e+08 | AC34: =SUM(AC31:AC33) -> 1.0627996 | AD34: =SUM(AD31:AD33) -> 166.8791 | AQ34: =SUM(AQ31:AQ33) -> 324.801 | AR34: =AQ34/BR34 -> 798.14158 | BR34: =SUM(BR31:BR33) -> 0.4069466 | BX34: FracLossP97.5
T35: Annual social cost of emissions [$/yr] | U35: =U33*$U$30 -> 9.3648771e+09 | V35: =V33*$U$30 -> 8.8254959e+09 | W35: =W33*$U$30 -> 9.9312084e+09 | BX35: FracLossP2.5Full
T36: NG cost [$/mcf] | U36: 3 | AA36: =AB27*$U31/$U37 -> 1.2128734e+10 | BX36: FracLossP97.5Full
T37: tCH4/mcf(NG) | U37: 0.01733 | AA37: =AB30*$U31/$U37 -> 4.3105774e+10 | BX37: FracLossMid
T38: Annual NG emissions [mcf/yr] | U38: =U33/$U$37 -> 3.6025686e+08 | V38: =V33/$U$37 -> 3.3950744e+08 | W38: =W33/$U$37 -> 3.8204302e+08 | BX38: FracLossMidP2.5
T39: Annual NG value | U39: =U38*$U$36 -> 1.0807706e+09 | V39: =V38*$U$36 -> 1.0185223e+09 | W39: =W38*$U$36 -> 1.1461291e+09 | BX39: FracLossMidP97.5
T40: Price/t(CH4) | U40: =U36/U37 -> 173.11021 | BX40: FracLossMidPartial
BS41: FracLossMidGHGI
...

Sheet Tables for paper
I1: REVISIT
A2: Table 7 | B2: {='By site'!AA1:AA20} -> Transition point | C2: {='By site'!Z1:Z20} -> Min detected emission | D2: {='By site'!AF1:AF20} -> # production plumes | E2: {='By site'!AG1:AG20} -> # production plumes sel | H2: Table 8 | I2: Avg emissions/site | K2: Table 23 | L2: {='By site'!CD1:CD20} -> Well sites covered | M2: {='By site'!AF1:AF20} -> # production plumes | N2: {='By site'!AH1:AH20} -> # prod sources overall | O2: {='By site'!AQ1:AQ20} -> Avg visits/well site | P2: {='By site'!AI1:AI20} -> # avg prod sources sim | Q2: {='By site'!CG1:CG20} -> Avg % sites emitting
A3: Kairos_Permian | B3: 25.365 | C3: 7.0962343 | D3: 1083 | E3: 1081.878 | H3: Kairos_Permian | I3: =1000*'By site'!K2/'By site'!CD2 -> 5.5978907 | K3: Kairos_Permian | L3: 18030 | M3: 1083 | N3: 537 | O3: 3.7698281 | P3: 258.721 | Q3: 0.014349473
A4: Permian_2019 | B4: 59.283 | C4: 15.029525 | D4: 1749 | E4: 1645.742 | H4: Permian_2019 | I4: =1000*'By site'!K3/'By site'!CD3 -> 6.5952486 | K4: Permian_2019 | L4: 46337 | M4: 1749 | N4: 1054 | O4: 3.8655934 | P4: 483.449 | Q4: 0.010433325
A5: Permian_2020 | B5: 83.968 | C5: 8.0919112 | D5: 284 | E5: 246.309 | H5: Permian_2020 | I5: =1000*'By site'!K4/'By site'!CD4 -> 6.1230245 | K5: Permian_2020 | L5: 9380 | M5: 284 | N5: 239 | O5: 2.8557569 | P5: 101.24 | Q5: 0.010793177
A6: Permian_summer2021 | B6: 68.187 | C6: 11.813408 | D6: 416 | E6: 360.585 | H6: Permian_summer2021 | I6: =1000*'By site'!K5/'By site'!CD5 -> 6.2382059 | K6: Permian_summer2021 | L6: 10432 | M6: 416 | N6: 296 | O6: 4.8271664 | P6: 124.71 | Q6: 0.011954563
A7: Permian_fall2021 | B7: 77.865 | C7: 23.348039 | D7: 334 | E7: 275.15 | H7: Permian_fall2021 | I7: =1000*'By site'!K6/'By site'!CD6 -> 6.088963 | K7: Permian_fall2021 | L7: 10777 | M7: 334 | N7: 232 | O7: 4.7946553 | P7: 92.785 | Q7: 0.0086095388
A8: San_Joaquin_2016 | B8: 40.415 | C8: 9 | D8: 77 | E8: 69.132 | H8: San_Joaquin_2016 | I8: =1000*'By site'!K7/'By site'!CD7 -> 0.2081912 | K8: San_Joaquin_2016 | L8: 23779 | M8: 77 | N8: 40 | O8: 1.9552546 | P8: 15.074 | Q8: 0.00063392069
A9: San_Joaquin_2017 | B9: 40.99 | C9: 11 | D9: 86 | E9: 80.173 | H9: San_Joaquin_2017 | I9: =1000*'By site'!K8/'By site'!CD8 -> 0.30893291 | K9: San_Joaquin_2017 | L9: 23103 | M9: 86 | N9: 54 | O9: 4.7679522 | P9: 15.945 | Q9: 0.00069017011
A10: San_Joaquin_summer2020 | B10: 36.556644 | C10: 23.632192 | D10: 94 | E10: 90.462 | H10: San_Joaquin_summer2020 | I10: =1000*'By site'!K9/'By site'!CD9 -> 0.35324617 | K10: San_Joaquin_summer2020 | L10: 15992 | M10: 94 | N10: 39 | O10: 7.4688594 | P10: 13.337 | Q10: 0.00083397949
A11: San_Joaquin_fall2020 | B11: 37.591104 | C11: 20.646402 | D11: 48 | E11: 45.261 | H11: San_Joaquin_fall2020 | I11: =1000*'By site'!K10/'By site'!CD10 -> 0.26911197 | K11: San_Joaquin_fall2020 | L11: 16579 | M11: 48 | N11: 27 | O11: 7.2219675 | P11: 8.067 | Q11: 0.00048657941
A12: San_Joaquin_fall2021 | B12: 23.223 | C12: 15.95883 | D12: 47 | E12: 41.14 | H12: San_Joaquin_fall2021 | I12: =1000*'By site'!K11/'By site'!CD11 -> 0.20801016 | K12: San_Joaquin_fall2021 | L12: 16743 | M12: 47 | N12: 35 | O12: 3.5712238 | P12: 15.716 | Q12: 0.00093866093
A13: Denver_summer2021 | B13: 75.042 | C13: 11.102345 | D13: 34 | E13: 27.151 | H13: Denver_summer2021 | I13: =1000*'By site'!K12/'By site'!CD12 -> 2.0040841 | K13: Denver_summer2021 | L13: 7254 | M13: 34 | N13: 27 | O13: 5.0860215 | P13: 8.491 | Q13: 0.0011705266
A14: Denver_fall2021 | B14: 66.55 | C14: 10.160213 | D14: 40 | E14: 31.592 | H14: Denver_fall2021 | I14: =1000*'By site'!K13/'By site'!CD13 -> 2.0132795 | K14: Denver_fall2021 | L14: 7265 | M14: 40 | N14: 33 | O14: 5.8016518 | P14: 8.473 | Q14: 0.0011662767
... A21: Northeast_Pennsylvania_2021 | B21: 495.44526 | C21: 495.44526 | D21: 12 | E21: 11 | H21: Northeast_Pennsylvania_2021 | I21: =1000*'By site'!K20/'By site'!CD20 -> 8.6272975 | K21: Northeast_Pennsylvania_2021 | L21: 2381 | M21: 12 | N21: 12 | O21: 1.348173 | P21: 11.47 | Q21: 0.0048173037
A23: Table 24 | B23: Methane emissions [t/hr] | C23: {='By site'!AB1:AB20} -> Total covered production (t(CH4)/hr) | D23: Methane loss rate [%] | G23: Table 25 | H23: Production: Simulated [%] | I23: Production: Aerial [%] | J23: Production: Aerial partial [%] | K23: Production: Total [%] | N23: Table 26 | O23: Midstream: Simulated [%] | P23: Midstream: Aerial [%] | Q23: Midstream: Aerial partial [%] | R23: Midstream: Total [%] | T23: Table 27 | U23: Production: Simulated full distribution [%] | V23: Production: GHGI [%] | W23: % difference
A24: Kairos_Permian | B24: =ROUND('By site'!U2, 0) & " [" & ROUND('By site'!V2, 0) & ", " & ROUND('By site'!W2, 0) & "]" -> 187 [176, 200] | C24: 1952.0451 | D24: =ROUND('By site'!BJ2*100, 2) & " [" & ROUND('By site'!BM2*100, 2) & ", " & ROUND('By site'!BN2*100, 2) & "]" -> 9.57 [8.99, 10.26] | G24: Kairos_Permian | H24: =ROUND('By site'!AX2*100, 2) & CHAR(10) & "[" & ROUND('By site'!AY2*100, 2) & ", " & ROUND('By site'!AZ2*100, 2) & "]" -> 0.93 [0.89, 0.97] | I24: =ROUND('By site'!BA2*100, 2) & CHAR(10) & "[" & ROUND('By site'!BB2*100, 2) & ", " & ROUND('By site'!BC2*100, 2) & "]" -> 4 [3.33, 4.81] | J24: =ROUND('By site'!BD2*100, 2) & CHAR(10) & "[" & ROUND('By site'!BE2*100, 2) & ", " & ROUND('By site'!BF2*100, 2) & "]" -> 0.25 [0.18, 0.32] | K24: =ROUND('By site'!BG2*100, 2) & CHAR(10) & "[" & ROUND('By site'!BH2*100, 2) & ", " & ROUND('By site'!BI2*100, 2) & "]" -> 5.17 [4.83, 5.59] | N24: Kairos_Permian | O24: =ROUND('By site'!BU2*100, 2) & CHAR(10) & "[" & ROUND('By site'!BV2*100, 2) & ", " & ROUND('By site'!BW2*100, 2) & "]" -> 0.38 [0.31, 0.45] | P24: =ROUND('By site'!BO2*100, 2) & CHAR(10) & "[" & ROUND('By site'!BP2*100, 2) & ", " & ROUND('By site'!BQ2*100, 2) & "]" -> 3.77 [3.43, 4.27] | Q24: =ROUND('By site'!BR2*100, 2) & CHAR(10) & "[" & ROUND('By site'!BS2*100, 2) & ", " & ROUND('By site'!BT2*100, 2) & "]" -> 0.25 [0.21, 0.29] | R24: =ROUND('By site'!BX2*100, 2) & CHAR(10) & "[" & ROUND('By site'!BY2*100, 2) & ", " & ROUND('By site'!BZ2*100, 2) & "]" -> 4.4 [3.99, 4.97] | T24: Kairos_Permian | U24: {='By site'!BG2:BG20/'By site'!DL2:DL20} -> 0.012022885 | V24: {='By site'!DX2:DX20} -> 0.0073 | W24: =(U24-V24)/V24 -> 0.64697049
A25: Permian_2019 | B25: =ROUND('By site'!U3, 0) & " [" & ROUND('By site'!V3, 0) & ", " & ROUND('By site'!W3, 0) & "]" -> 556 [533, 580] | C25: 10526.815 | D25: =ROUND('By site'!BJ3*100, 2) & " [" & ROUND('By site'!BM3*100, 2) & ", " & ROUND('By site'!BN3*100, 2) & "]" -> 5.29 [5.06, 5.51] | G25: Permian_2019 | H25: =ROUND('By site'!AX3*100, 2) & CHAR(10) & "[" & ROUND('By site'!AY3*100, 2) & ", " & ROUND('By site'!AZ3*100, 2) & "]" -> 0.66 [0.64, 0.68] | I25: =ROUND('By site'!BA3*100, 2) & CHAR(10) & "[" & ROUND('By site'!BB3*100, 2) & ", " & ROUND('By site'!BC3*100, 2) & "]" -> 2.24 [2.06, 2.43] | J25: =ROUND('By site'!BD3*100, 2) & CHAR(10) & "[" & ROUND('By site'!BE3*100, 2) & ", " & ROUND('By site'!BF3*100, 2) & "]" -> 0 [0, 0] | K25: =ROUND('By site'!BG3*100, 2) & CHAR(10) & "[" & ROUND('By site'!BH3*100, 2) & ", " & ROUND('By site'!BI3*100, 2) & "]" -> 2.9 [2.81, 3] | N25: Permian_2019 | O25: =ROUND('By site'!BU3*100, 2) & CHAR(10) & "[" & ROUND('By site'!BV3*100, 2) & ", " & ROUND('By site'!BW3*100, 2) & "]" -> 0.36 [0.3, 0.43] | P25: =ROUND('By site'!BO3*100, 2) & CHAR(10) & "[" & ROUND('By site'!BP3*100, 2) & ", " & ROUND('By site'!BQ3*100, 2) & "]" -> 2.02 [1.9, 2.15] | Q25: =ROUND('By site'!BR3*100, 2) & CHAR(10) & "[" & ROUND('By site'!BS3*100, 2) & ", " & ROUND('By site'!BT3*100, 2) & "]" -> 0 [0, 0] | R25: =ROUND('By site'!BX3*100, 2) & CHAR(10) & "[" & ROUND('By site'!BY3*100, 2) & ", " & ROUND('By site'!BZ3*100, 2) & "]" -> 2.38 [2.19, 2.58] | T25: Permian_2019 | U25: 0.0079478448 | V25: 0.0065 | W25: =(U25-V25)/V25 -> 0.22274536
A26: Permian_2020 | B26: =ROUND('By site'!U4, 0) & " [" & ROUND('By site'!V4, 0) & ", " & ROUND('By site'!W4, 0) & "]" -> 134 [123, 145] | C26: 4766.5264 | D26: =ROUND('By site'!BJ4*100, 2) & " [" & ROUND('By site'!BM4*100, 2) & ", " & ROUND('By site'!BN4*100, 2) & "]" -> 2.81 [2.59, 3.05] | G26: Permian_2020 | H26: =ROUND('By site'!AX4*100, 2) & CHAR(10) & "[" & ROUND('By site'!AY4*100, 2) & ", " & ROUND('By site'!AZ4*100, 2) & "]" -> 0.47 [0.44, 0.5] | I26: =ROUND('By site'!BA4*100, 2) & CHAR(10) & "[" & ROUND('By site'!BB4*100, 2) & ", " & ROUND('By site'!BC4*100, 2) & "]" -> 0.73 [0.62, 0.84] | J26: =ROUND('By site'!BD4*100, 2) & CHAR(10) & "[" & ROUND('By site'!BE4*100, 2) & ", " & ROUND('By site'!BF4*100, 2) & "]" -> 0 [0, 0] | K26: =ROUND('By site'!BG4*100, 2) & CHAR(10) & "[" & ROUND('By site'!BH4*100, 2) & ", " & ROUND('By site'!BI4*100, 2) & "]" -> 1.2 [1.13, 1.27] | N26: Permian_2020 | O26: =ROUND('By site'!BU4*100, 2) & CHAR(10) & "[" & ROUND('By site'!BV4*100, 2) & ", " & ROUND('By site'!BW4*100, 2) & "]" -> 0.34 [0.28, 0.41] | P26: =ROUND('By site'!BO4*100, 2) & CHAR(10) & "[" & ROUND('By site'!BP4*100, 2) & ", " & ROUND('By site'!BQ4*100, 2) & "]" -> 1.26 [1.12, 1.42] | Q26: =ROUND('By site'!BR4*100, 2) & CHAR(10) & "[" & ROUND('By site'!BS4*100, 2) & ", " & ROUND('By site'!BT4*100, 2) & "]" -> 0 [0, 0] | R26: =ROUND('By site'!BX4*100, 2) & CHAR(10) & "[" & ROUND('By site'!BY4*100, 2) & ", " & ROUND('By site'!BZ4*100, 2) & "]" -> 1.61 [1.4, 1.83] | T26: Permian_2020 | U26: 0.005671728 | V26: 0.006 | W26: =(U26-V26)/V26 -> -0.054711998
A27: Permian_summer2021 | B27: =ROUND('By site'!U5, 0) & " [" & ROUND('By site'!V5, 0) & ", " & ROUND('By site'!W5, 0) & "]" -> 131 [122, 140] | C27: 5950.4297 | D27: =ROUND('By site'!BJ5*100, 2) & " [" & ROUND('By site'!BM5*100, 2) & ", " & ROUND('By site'!BN5*100, 2) & "]" -> 2.19 [2.05, 2.35] | G27: Permian_summer2021 | H27: =ROUND('By site'!AX5*100, 2) & CHAR(10) & "[" & ROUND('By site'!AY5*100, 2) & ", " & ROUND('By site'!AZ5*100, 2) & "]" -> 0.47 [0.44, 0.5] | I27: =ROUND('By site'!BA5*100, 2) & CHAR(10) & "[" & ROUND('By site'!BB5*100, 2) & ", " & ROUND('By site'!BC5*100, 2) & "]" -> 0.62 [0.5, 0.75] | J27: =ROUND('By site'!BD5*100, 2) & CHAR(10) & "[" & ROUND('By site'!BE5*100, 2) & ", " & ROUND('By site'!BF5*100, 2) & "]" -> 0 [0, 0] | K27: =ROUND('By site'!BG5*100, 2) & CHAR(10) & "[" & ROUND('By site'!BH5*100, 2) & ", " & ROUND('By site'!BI5*100, 2) & "]" -> 1.09 [1.04, 1.15] | N27: Permian_summer2021 | O27: =ROUND('By site'!BU5*100, 2) & CHAR(10) & "[" & ROUND('By site'!BV5*100, 2) & ", " & ROUND('By site'!BW5*100, 2) & "]" -> 0.34 [0.28, 0.41] | P27: =ROUND('By site'!BO5*100, 2) & CHAR(10) & "[" & ROUND('By site'!BP5*100, 2) & ", " & ROUND('By site'!BQ5*100, 2) & "]" -> 0.76 [0.7, 0.83] | Q27: =ROUND('By site'!BR5*100, 2) & CHAR(10) & "[" & ROUND('By site'!BS5*100, 2) & ", " & ROUND('By site'!BT5*100, 2) & "]" -> 0 [0, 0] | R27: =ROUND('By site'!BX5*100, 2) & CHAR(10) & "[" & ROUND('By site'!BY5*100, 2) & ", " & ROUND('By site'!BZ5*100, 2) & "]" -> 1.1 [0.98, 1.23] | T27: Permian_summer2021 | U27: 0.0058452266 | V27: 0.006 | W27: =(U27-V27)/V27 -> -0.025795572
A28: Permian_fall2021 | B28: =ROUND('By site'!U6, 0) & " [" & ROUND('By site'!V6, 0) & ", " & ROUND('By site'!W6, 0) & "]" -> 131 [121, 141] | C28: 6227.8408 | D28: =ROUND('By site'!BJ6*100, 2) & " [" & ROUND('By site'!BM6*100, 2) & ", " & ROUND('By site'!BN6*100, 2) & "]" -> 2.1 [1.94, 2.27] | G28: Permian_fall2021 | H28: =ROUND('By site'!AX6*100, 2) & CHAR(10) & "[" & ROUND('By site'!AY6*100, 2) & ", " & ROUND('By site'!AZ6*100, 2) & "]" -> 0.49 [0.46, 0.51] | I28: =ROUND('By site'!BA6*100, 2) & CHAR(10) & "[" & ROUND('By site'!BB6*100, 2) & ", " & ROUND('By site'!BC6*100, 2) & "]" -> 0.57 [0.44, 0.7] | J28: =ROUND('By site'!BD6*100, 2) & CHAR(10) & "[" & ROUND('By site'!BE6*100, 2) & ", " & ROUND('By site'!BF6*100, 2) & "]" -> 0 [0, 0] | K28: =ROUND('By site'!BG6*100, 2) & CHAR(10) & "[" & ROUND('By site'!BH6*100, 2) & ", " & ROUND('By site'!BI6*100, 2) & "]" -> 1.05 [0.99, 1.11] | N28: Permian_fall2021 | O28: =ROUND('By site'!BU6*100, 2) & CHAR(10) & "[" & ROUND('By site'!BV6*100, 2) & ", " & ROUND('By site'!BW6*100, 2) & "]" -> 0.34 [0.28, 0.41] | P28: =ROUND('By site'!BO6*100, 2) & CHAR(10) & "[" & ROUND('By site'!BP6*100, 2) & ", " & ROUND('By site'!BQ6*100, 2) & "]" -> 0.71 [0.63, 0.79] | Q28: =ROUND('By site'!BR6*100, 2) & CHAR(10) & "[" & ROUND('By site'!BS6*100, 2) & ", " & ROUND('By site'!BT6*100, 2) & "]" -> 0 [0, 0] | R28: =ROUND('By site'!BX6*100, 2) & CHAR(10) & "[" & ROUND('By site'!BY6*100, 2) & ", " & ROUND('By site'!BZ6*100, 2) & "]" -> 1.05 [0.91, 1.19] | T28: Permian_fall2021 | U28: 0.0058952504 | V28: 0.006 | W28: =(U28-V28)/V28 -> -0.017458268
