Workbook

Sheet ReadMe
A1: These data represent model outputs for Sherwin et al. 2023
A2: Methane emissions quantities are presented in metric ton per hour
A3: Field descriptions
A4: Run# : Number identifying the Run in question. A Run is A full simulation of A selected scenario.
A5: Batch counter: Each scenario run often includes multiple batches of Monte Carlo iterations, run in series to circumvent memory and CPU limitations. This tracks each batch through a numerical identifier of 1-10.
A6: scenario: the scenario to Run, including the aerial campaign, basin, year, any additional geographic restrictions, etc.
A7: Prod simulation (t/h): Estimated scenario-wide production emissions in metric tons per hour from the Rutherford et al. simulation.
A8: Prod simulation P2.5: The 2.5% confidence interval of the above.
A9: Prod simulation P97.5: The 97.5% confidence interval of the above.
A10: Prod aerial (t/h): Estimated scenario-wide production emissions from aerially measured plumes above the transition point, in metric tons per hour.
A11: Prod aerial P2.5: The 2.5% confidence interval of the above.
A12: Prod aerial P97.5: The 97.5% confidence interval of the above.
... A141: Total aerial mid emissions inc below transition P97.5: The 97.5% confidence interval of the above.

Sheet By site
A1: Scenario | B1: Prod simulation (t/h) | C1: Prod simulation P2.5 | D1: Prod simulation P97.5 | E1: Prod aerial (t/h) | F1: Prod aerial P2.5 | G1: Prod aerial P97.5 | H1: Prod partial (t/h) | I1: Prod partial P2.5 | J1: Prod partial P97.5 | K1: Prod emissions (t/h) | L1: Prod emissions P2.5 | M1: Prod emissions P97.5 | N1: Aerial midstream emissions (t/h) | O1: Aerial midstream emissions P2.5 | P1: Aerial midstream emissions P97.5 | Q1: Midstream partial detect (t/h) | R1: Midstream GHGI below min detect (t/h) | S1: Total emissions (t/h) | T1: Total emissions P2.5 | U1: Total emissions P97.5 | V1: N | W1: % SDev of MC iterations | X1: Min detected emission | Y1: Transition point | Z1: Total covered production (t(CH4)/hr) | AA1: Wells covered | AB1: Well visits | AC1: Wells per site | AD1: # production plumes | AE1: # production plumes sel | AF1: # prod sources overall | AG1: # avg prod sources sim | AH1: # midstream plumes | AI1: # midstream sources | AJ1: # avg midstream sources sim | AK1: Total sim emissions | AL1: Stratify by covered prod | AM1: Include repeats | AN1: Date | AO1: Remove negative Kairos emissions | AP1: Well site visits | AQ1: Avg visits/well site | AR1: SD to SErr factor | AS1: SErr of mean total emissions | AT1: SErr of sample mean | AU1: Simulation % prod | AV1: Aerial % prod | AW1: Partial % prod | AX1: Methane fractional loss simulation prod | AY1: Methane fractional loss simulation prodP2.5 | AZ1: Methane fractional loss simulation prodP97.5 | BA1: Methane fractional loss aerial prod | BB1: AerialFracLossProdP2.5 | BC1: AerialFracLossProdP97.5 | BD1: Methane fractional loss partial prod | BE1: Methane fractional loss partial prodP2.5 | BF1: Methane fractional loss partial prodP97.5 | BG1: FracLossProd | BH1: FracLossProdP2.5 | BI1: FracLossProdP97.5 | BJ1: Methane fractional loss total | BK1: FracLossP2.5 | BL1: FracLossP97.5 | BM1: FracLossP2.5Full | BN1: FracLossP97.5Full | BO1: FracLossMidAerial | BP1: FracLossMidAerialP2.5 | BQ1: FracLossMidAerialP97.5 | BR1: FracLossMidPartial | BS1: FracLossMidPartialP2.5 | BT1: FracLossMidPartialP97.5 | BU1: FracLossMidGHGI | BV1: FracLossMidGHGIP2.5 | BW1: FracLossMidGHGIP97.5 | BX1: FracLossMidstream total | BY1: FracLossMidstream totalP2.5 | BZ1: FracLossMidstream totalP97.5 | CA1: % well site visits with plume | CB1: % well site visits with selected plume | CC1: Fraction sim retained | CD1: Well sites covered | CE1: % well sites ever emitting | CF1: Avg % wells emitting | CG1: Avg % sites emitting | CH1: Total aerial | CI1: Total aerialP2.5 | CJ1: Total aerialP97.5 | CK1: Total aerial+partial emissions | CL1: Total aerial+partial emissionsP2.5 | CM1: Total aerial+partial emissionsP97.5 | CN1: Total sim emissions | CO1: Total sim emissionsP2.5 | CP1: Total sim emissionsP97.5 | CQ1: Total aerial all segments inc below transition | CR1: Total aerial all segments inc below transition P2.5 | CS1: Total aerial all segments inc below transition P97.5 | CT1: Total pipeline emissions | CU1: Total pipeline emissions P2.5 | CV1: Total pipeline emissions P97.5 | CW1: Total compressor emissions | CX1: Total compressor emissions P2.5 | CY1: Total compressor emissions P97.5 | CZ1: Total processing emissions | DA1: Total processing emissions P2.5 | DB1: Total processing emissions P97.5 | DC1: Total other midstream emissions | DD1: Total other midstream emissions P2.5 | DE1: Total other midstream emissions P97.5 | DF1: Frac aerial | DG1: Frac aerial+partial | DH1: Frac sim | DI1: Frac midstream | DJ1: Frac midstream aerial | DK1: Total production emissions | DL1: Total/Sim | DM1: Production/site covered | DN1: State GHGI | DO1: NG methane fraction | DP1: kgCH4 per mcfNG | DQ1: Full upper errorbar % total | DR1: Full lower errorbar % total | DS1: Partial prod % total | DT1: Partial mid % total | DU1: Tot sim emissions loss rate | DV1: Tot sim emissions loss rate P2.5 | DW1: Tot sim emissions loss rate P97.5 | DX1: Prod-only state GHGI loss | DY1: Prod-only state GHGI loss low | DZ1: Prod-only state GHGI loss high | EA1: Total aerial prod emissions inc below transition | EB1: Total aerial prod emissions inc below transition P2.5 | EC1: Total aerial prod emissions inc below transition P97.5 | ED1: Total aerial mid emissions inc below transition | EE1: Total aerial mid emissions inc below transition P2.5 | EF1: Total aerial mid emissions inc below transition P97.5
A2: Kairos_Permian | B2: 17.949236 | C2: 17.537877 | D2: 18.326477 | E2: 86.439044 | F2: 80.887803 | G2: 92.586852 | H2: 4.7362825 | I2: 4.0506016 | J2: 5.4966805 | K2: 109.12456 | L2: 103.53614 | M2: 115.4366 | N2: 66.44672 | O2: 58.44482 | P2: 77.813722 | Q2: 4.9425544 | R2: 7.4248658 | S2: 187.9387 | T2: 176.45072 | U2: 202.73171 | V2: 1000 | W2: 0.065284961 | X2: 5.9464547 | Y2: 24.391 | Z2: 1952.0451 | AA2: 21637 | AB2: 81564 | AC2: 1.2 | AD2: 1279 | AE2: 1276.96 | AF2: 627 | AG2: 299.736 | AH2: 706 | AI2: 331 | AJ2: 184.211 | AK2: 25.374101 | AL2: Yes | AM2: No | AN2: 20230824 | AO2: Yes | AP2: 67970 | AQ2: 3.7698281 | AR2: 0.51503795 | AS2: 0.033624232 | AT2: 0.0020644917 | AU2: 0.16501373 | AV2: 0.79148808 | AW2: 0.04349819 | AX2: 0.0091950926 | AY2: 0.008785934 | AZ2: 0.009570316 | BA2: 0.044281273 | BB2: 0.038759723 | BC2: 0.0503962 | BD2: 0.0024263181 | BE2: 0.0017443047 | BF2: 0.0031826491 | BG2: 0.055902684 | BH2: 0.053039827 | BI2: 0.059136233 | BJ2: 0.096277847 | BK2: -0.0058851013 | BL2: 0.0075782075 | BM2: 0.090392745 | BN2: 0.10385605 | BO2: 0.034039541 | BP2: 0.029940301 | BQ2: 0.039862665 | BR2: 0.0025319878 | BS2: 0.0021693303 | BT2: 0.0029253546 | BU2: 0.0038036343 | BV2: 0.0031189801 | BW2: 0.0044882884 | BX2: 0.040375163 | BY2: 0.03559885 | BZ2: 0.046925173 | CA2: 0.018817125 | CB2: 0.018787112 | CC2: 0.76596466 | CD2: 18030 | CE2: 0.034775374 | CF2: 0.013852937 | CG2: 0.016624293 | CH2: 152.88576 | CI2: 144.88386 | CJ2: 164.25277 | CK2: 157.82832 | CL2: 149.11849 | CM2: 169.96319 | CN2: 25.374101 | CO2: 23.626267 | CP2: 27.087818 | CQ2: 152.95561 | CR2: 142.98763 | CS2: 166.1631 | CT2: 18.669003 | CU2: 15.095086 | CV2: 27.920795 | CW2: 7.2095898 | CX2: 6.0012421 | CY2: 8.6169078 | CZ2: 3.7403708 | DA2: 2.9425011 | DB2: 5.0281384 | DC2: 0 | DD2: 0 | DE2: 0 | DF2: 0.81348615 | DG2: 0.83978517 | DH2: 0.13501352 | DI2: 0.41935784 | DJ2: 0.35355172 | DK2: 109.12456 | DL2: 4.6567979 | DM2: 0.10826651 | DN2: 0.012478177 | DO2: 0.9 | DP2: 17.326203 | DQ2: 0.07870007 | DR2: -0.061124579 | DS2: 0.025201315 | DT2: 0.026299014 | DU2: 0.012004715 | DV2: 0.011645611 | DW2: 0.01244977 | DX2: 0.0072701048 | DY2: 0.0082075578 | DZ2: 0.0063326517 | EA2: 86.50889 | EB2: 80.962233 | EC2: 92.655731 | ED2: 66.44672 | EE2: 66.44672 | EF2: 66.44672
A3: Permian_2019 | B3: 69.887169 | C3: 68.750616 | D3: 71.051484 | E3: 236.25522 | F3: 226.93674 | G3: 246.25314 | H3: 0 | I3: 0 | J3: 0 | K3: 306.14239 | L3: 296.87295 | M3: 315.91848 | N3: 212.44677 | O3: 199.32948 | P3: 227.91639 | Q3: 0 | R3: 38.281727 | S3: 556.87089 | T3: 534.28271 | U3: 581.67074 | V3: 1000 | W3: 0.031547769 | X3: 15.029525 | Y3: 60.218 | Z3: 10526.815 | AA3: 84570 | AB3: 326908 | AC3: 1.8250769 | AD3: 1749 | AE3: 1643.569 | AF3: 1054 | AG3: 483.465 | AH3: 1272 | AI3: 679 | AJ3: 374.746 | AK3: 108.1689 | AL3: Yes | AM3: No | AN3: 20230824 | AO3: Yes | AP3: 179120 | AQ3: 3.8655934 | AR3: 0.50861822 | AS3: 0.01604577 | AT3: 0.00099762804 | AU3: 0.22850677 | AV3: 0.77149323 | AW3: 0 | AX3: 0.0066389664 | AY3: 0.0064266905 | AZ3: 0.0068564274 | BA3: 0.022443183 | BB3: 0.020702752 | BC3: 0.024310511 | BD3: 0 | BE3: 0 | BF3: 0 | BG3: 0.029082149 | BH3: 0.028201594 | BI3: 0.030010833 | BJ3: 0.052900227 | BK3: -0.002145775 | BL3: 0.0023558741 | BM3: 0.050754452 | BN3: 0.055256101 | BO3: 0.020181486 | BP3: 0.018935403 | BQ3: 0.021651031 | BR3: 0 | BS3: 0 | BT3: 0 | BU3: 0.0036365916 | BV3: 0.0029820052 | BW3: 0.0042911781 | BX3: 0.023818078 | BY3: 0.021917408 | BZ3: 0.025942209 | CA3: 0.0097644038 | CB3: 0.0091757983 | CC3: 0.83093639 | CD3: 46337 | CE3: 0.022746401 | CF3: 0.0057167435 | CG3: 0.010433671 | CH3: 448.70199 | CI3: 435.5847 | CJ3: 464.17162 | CK3: 448.70199 | CL3: 435.5847 | CM3: 464.17162 | CN3: 108.1689 | CO3: 100.14163 | CP3: 116.22392 | CQ3: 449.26781 | CR3: 433.62456 | CS3: 467.27897 | CT3: 102.3386 | CU3: 96.637768 | CV3: 108.85519 | CW3: 80.590539 | CX3: 74.292014 | CY3: 88.324986 | CZ3: 29.517629 | DA3: 21.442073 | DB3: 40.664693 | DC3: 0 | DD3: 0 | DE3: 0 | DF3: 0.80575561 | DG3: 0.80575561 | DH3: 0.19424439 | DI3: 0.4502452 | DJ3: 0.38150078 | DK3: 306.14239 | DL3: 3.6399366 | DM3: 0.22717946 | DN3: 0.011491852 | DO3: 0.9 | DP3: 17.326203 | DQ3: 0.044536084 | DR3: -0.040563378 | DS3: 0 | DT3: 0 | DU3: 0.0079897581 | DV3: 0.0078212118 | DW3: 0.0081680502 | DX3: 0.0065125 | DY3: 0.0074087833 | DZ3: 0.0056162167 | EA3: 236.82104 | EB3: 227.47578 | EC3: 246.81428 | ED3: 212.44677 | EE3: 212.44677 | EF3: 212.44677
A4: Permian_2020 | B4: 22.418959 | C4: 21.546608 | D4: 23.261921 | E4: 35.058145 | F4: 31.693702 | G4: 38.527668 | H4: 0 | I4: 0 | J4: 0 | K4: 57.477104 | L4: 54.072428 | M4: 61.192677 | N4: 60.228533 | O4: 53.577013 | P4: 67.26759 | Q4: 0 | R4: 16.369542 | S4: 134.07518 | T4: 123.6984 | U4: 144.97153 | V4: 1000 | W4: 0.051132684 | X4: 8.0919112 | Y4: 82.316 | Z4: 4766.5264 | AA4: 17120 | AB4: 48890 | AC4: 1.8250769 | AD4: 284 | AE4: 247.415 | AF4: 239 | AG4: 101.235 | AH4: 316 | AI4: 233 | AJ4: 121.168 | AK4: 38.788502 | AL4: Yes | AM4: No | AN4: 20230824 | AO4: Yes | AP4: 26787 | AQ4: 2.8557569 | AR4: 0.59175152 | AS4: 0.030257843 | AT4: 0.0016169574 | AU4: 0.39107142 | AV4: 0.60892858 | AW4: 0 | AX4: 0.0047034166 | AY4: 0.0043941377 | AZ4: 0.0050022758 | BA4: 0.007355072 | BB4: 0.0061622607 | BC4: 0.0085851379 | BD4: 0 | BE4: 0 | BF4: 0 | BG4: 0.012058489 | BH4: 0.0113442 | BI4: 0.012838002 | BJ4: 0.028128488 | BK4: -0.0021770112 | BL4: 0.0022860158 | BM4: 0.025951477 | BN4: 0.030414504 | BO4: 0.012635728 | BP4: 0.011240264 | BQ4: 0.014112497 | BR4: 0 | BS4: 0 | BT4: 0 | BU4: 0.0034342708 | BV4: 0.002816102 | BW4: 0.0040524395 | BX4: 0.016069999 | BY4: 0.014056366 | BZ4: 0.018164937 | CA4: 0.010602158 | CB4: 0.0092363833 | CC4: 0.8290576 | CD4: 9380 | CE4: 0.025479744 | CF4: 0.0059132593 | CG4: 0.010792644 | CH4: 95.286678 | CI4: 88.635158 | CJ4: 102.32573 | CK4: 95.286678 | CL4: 88.635158 | CM4: 102.32573 | CN4: 38.788502 | CO4: 34.969632 | CP4: 42.577981 | CQ4: 95.801608 | CR4: 88.285477 | CS4: 103.67904 | CT4: 17.644208 | CU4: 13.399358 | CV4: 22.704427 | CW4: 33.432969 | CX4: 29.60506 | CY4: 37.754447 | CZ4: 9.062626 | DA4: 6.377116 | DB4: 11.713379 | DC4: 0.088730642 | DD4: 0.03622415 | DE4: 0.30939668 | DF4: 0.71069519 | DG4: 0.71069519 | DH4: 0.28930481 | DI4: 0.57130598 | DJ4: 0.44921345 | DK4: 57.477104 | DL4: 2.1255297 | DM4: 0.50815846 | DN4: 0.010661119 | DO4: 0.9 | DP4: 17.326203 | DQ4: 0.081270992 | DR4: -0.077391203 | DS4: 0 | DT4: 0 | DU4: 0.0056732949 | DV4: 0.0054105065 | DW4: 0.0060023972 | DX4: 0.0059587926 | DY4: 0.0068052114 | DZ4: 0.0051123738 | EA4: 35.573075 | EB4: 32.202297 | EC4: 39.053627 | ED4: 60.228533 | EE4: 60.228533 | EF4: 60.228533
A5: Permian_summer2021 | B5: 28.035492 | C5: 27.286162 | D5: 28.839748 | E5: 37.007811 | F5: 33.8575 | G5: 40.558534 | H5: 0 | I5: 0 | J5: 0 | K5: 65.043303 | L5: 61.866059 | M5: 68.665582 | N5: 44.998112 | O5: 41.446604 | P5: 49.119481 | Q5: 0 | R5: 20.435387 | S5: 130.4768 | T5: 121.9305 | U5: 139.44976 | V5: 1000 | W5: 0.046159285 | X5: 11.813408 | Y5: 68.239 | Z5: 5950.4297 | AA5: 19040 | AB5: 91907 | AC5: 1.8250769 | AD5: 416 | AE5: 360.455 | AF5: 296 | AG5: 124.633 | AH5: 477 | AI5: 232 | AJ5: 125.111 | AK5: 48.470878 | AL5: Yes | AM5: No | AN5: 20230824 | AO5: Yes | AP5: 50357 | AQ5: 4.8271664 | AR5: 0.45514928 | AS5: 0.021009366 | AT5: 0.0014596848 | AU5: 0.43242074 | AV5: 0.56757926 | AW5: 0 | AX5: 0.0047115071 | AY5: 0.0044348317 | AZ5: 0.0050084632 | BA5: 0.0062193511 | BB5: 0.0050561593 | BC5: 0.0075303869 | BD5: 0 | BE5: 0 | BF5: 0 | BG5: 0.010930858 | BH5: 0.010396906 | BI5: 0.011539601 | BJ5: 0.021927291 | BK5: -0.0014362501 | BL5: 0.0015079519 | BM5: 0.020491041 | BN5: 0.023435243 | BO5: 0.0075621619 | BP5: 0.0069653127 | BQ5: 0.0082547788 | BR5: 0 | BS5: 0 | BT5: 0 | BU5: 0.0034342708 | BV5: 0.002816102 | BW5: 0.0040524395 | BX5: 0.010996433 | BY5: 0.0097814148 | BZ5: 0.012307218 | CA5: 0.0082610163 | CB5: 0.0071579919 | CC5: 0.80220578 | CD5: 10432 | CE5: 0.028374233 | CF5: 0.0065458508 | CG5: 0.011947182 | CH5: 82.005924 | CI5: 78.454415 | CJ5: 86.127292 | CK5: 82.005924 | CL5: 78.454415 | CM5: 86.127292 | CN5: 48.470878 | CO5: 44.043179 | CP5: 52.953504 | CQ5: 82.622908 | CR5: 77.793161 | CS5: 87.911525 | CT5: 12.870078 | CU5: 11.356977 | CV5: 14.653754 | CW5: 25.134453 | CX5: 22.258573 | CY5: 28.558758 | CZ5: 6.9935818 | DA5: 5.4335233 | DB5: 8.8362515 | DC5: 0 | DD5: 0 | DE5: 0 | DF5: 0.62850882 | DG5: 0.62850882 | DH5: 0.37149118 | DI5: 0.50149495 | DJ5: 0.3448736 | DK5: 65.043303 | DL5: 1.8611524 | DM5: 0.57040162 | DN5: 0.010661119 | DO5: 0.9 | DP5: 17.326203 | DQ5: 0.068766579 | DR5: -0.065499204 | DS5: 0 | DT5: 0 | DU5: 0.0058732674 | DV5: 0.0056955695 | DW5: 0.0060878971 | DX5: 0.0059587926 | DY5: 0.0068052114 | DZ5: 0.0051123738 | EA5: 37.624795 | EB5: 34.434465 | EC5: 41.16314 | ED5: 44.998112 | EE5: 44.998112 | EF5: 44.998112
A6: Permian_fall2021 | B6: 30.408612 | C6: 29.575523 | D6: 31.171923 | E6: 35.27673 | F6: 31.724665 | G6: 39.4759 | H6: 0 | I6: 0 | J6: 0 | K6: 65.685341 | L6: 62.017391 | M6: 69.946107 | N6: 43.978515 | O6: 39.275178 | P6: 49.315794 | Q6: 0 | R6: 21.388092 | S6: 131.05195 | T6: 121.04007 | U6: 141.5938 | V6: 1000 | W6: 0.057633536 | X6: 23.348039 | Y6: 78.149 | Z6: 6227.8408 | AA6: 19670 | AB6: 94306 | AC6: 1.8250769 | AD6: 334 | AE6: 274.889 | AF6: 232 | AG6: 92.781 | AH6: 368 | AI6: 179 | AJ6: 91.039 | AK6: 51.796703 | AL6: Yes | AM6: No | AN6: 20230824 | AO6: Yes | AP6: 51672 | AQ6: 4.7946553 | AR6: 0.45668979 | AS6: 0.026320648 | AT6: 0.0018225324 | AU6: 0.46495622 | AV6: 0.53504378 | AW6: 0 | AX6: 0.0048826893 | AY6: 0.0045897803 | AZ6: 0.0051510648 | BA6: 0.0056643595 | BB6: 0.0044154758 | BC6: 0.0071407618 | BD6: 0 | BE6: 0 | BF6: 0 | BG6: 0.010547049 | BH6: 0.0099580886 | BI6: 0.011231197 | BJ6: 0.021042919 | BK6: -0.0016075998 | BL6: 0.0016926981 | BM6: 0.019435319 | BN6: 0.022735617 | BO6: 0.007061599 | BP6: 0.0063063875 | BQ6: 0.0079186022 | BR6: 0 | BS6: 0 | BT6: 0 | BU6: 0.0034342708 | BV6: 0.002816102 | BW6: 0.0040524395 | BX6: 0.01049587 | BY6: 0.0091224895 | BZ6: 0.011971042 | CA6: 0.0064638489 | CB6: 0.0053198831 | CC6: 0.82718383 | CD6: 10777 | CE6: 0.021527327 | CF6: 0.0047168785 | CG6: 0.0086091677 | CH6: 79.255244 | CI6: 74.551907 | CJ6: 84.592523 | CK6: 79.255244 | CL6: 74.551907 | CM6: 84.592523 | CN6: 51.796703 | CO6: 47.113758 | CP6: 56.409871 | CQ6: 79.866955 | CR6: 73.806453 | CS6: 86.531421 | CT6: 6.8343134 | CU6: 6.0176534 | CV6: 7.7567595 | CW6: 27.32647 | CX6: 23.514045 | CY6: 31.695012 | CZ6: 9.8177308 | DA6: 7.2913321 | DB6: 12.761947 | DC6: 0 | DD6: 0 | DE6: 0 | DF6: 0.60476044 | DG6: 0.60476044 | DH6: 0.39523956 | DI6: 0.49878196 | DJ6: 0.33557753 | DK6: 65.685341 | DL6: 1.7867944 | DM6: 0.5778826 | DN6: 0.010661119 | DO6: 0.9 | DP6: 17.326203 | DQ6: 0.080440911 | DR6: -0.076405496 | DS6: 0 | DT6: 0 | DU6: 0.0059028177 | DV6: 0.0057221948 | DW6: 0.0061122776 | DX6: 0.0059587926 | DY6: 0.0068052114 | DZ6: 0.0051123738 | EA6: 35.888441 | EB6: 32.37951 | EC6: 40.063604 | ED6: 43.978515 | EE6: 43.978515 | EF6: 43.978515
A7: San_Joaquin_2016 | B7: 2.5884228 | C7: 2.4758083 | D7: 2.7082191 | E7: 2.3943748 | F7: 1.6400097 | G7: 3.2628229 | H7: 0 | I7: 0 | J7: 0 | K7: 4.9827976 | L7: 4.2218361 | M7: 5.8614517 | N7: 4.7765104 | O7: 3.6840538 | P7: 6.2638668 | Q7: 0 | R7: 1.1897866 | S7: 10.949095 | T7: 9.3371676 | U7: 12.873706 | V7: 1000 | W7: 0.10407868 | X7: 9 | Y7: 40.481 | Z7: 264.97396 | AA7: 41547 | AB7: 81234 | AC7: 1.7471737 | AD7: 77 | AE7: 69.063 | AF7: 40 | AG7: 15.063 | AH7: 48 | AI7: 36 | AJ7: 18.145 | AK7: 3.7782094 | AL7: Yes | AM7: No | AN7: 20230824 | AO7: Yes | AP7: 46494 | AQ7: 1.9552546 | AR7: 0.71515197 | AS7: 0.074432072 | AT7: 0.0032912568 | AU7: 0.52705446 | AV7: 0.47294554 | AW7: 0 | AX7: 0.0097685932 | AY7: 0.0091743111 | AZ7: 0.010400775 | BA7: 0.0090362647 | BB7: 0.0050553757 | BC7: 0.013619186 | BD7: 0 | BE7: 0 | BF7: 0 | BG7: 0.018804858 | BH7: 0.015933023 | BI7: 0.02212086 | BJ7: 0.041321399 | BK7: -0.0060833413 | BL7: 0.0072633997 | BM7: 0.035238058 | BN7: 0.048584799 | BO7: 0.018026339 | BP7: 0.013903456 | BQ7: 0.023639556 | BR7: 0 | BS7: 0 | BT7: 0 | BU7: 0.004490202 | BV7: 0.0036819657 | BW7: 0.0052984384 | BX7: 0.022516541 | BY7: 0.017585422 | BZ7: 0.028937995 | CA7: 0.0016561277 | CB7: 0.0014854175 | CC7: 0.98865334 | CD7: 23779 | CE7: 0.0016821565 | CF7: 0.00036255325 | CG7: 0.00063345809 | CH7: 7.1708852 | CI7: 6.0784286 | CJ7: 8.6582416 | CK7: 7.1708852 | CL7: 6.0784286 | CM7: 8.6582416 | CN7: 3.7782094 | CO7: 3.4514333 | CP7: 4.1121673 | CQ7: 7.1875083 | CR7: 5.7940559 | CS7: 8.9156944 | CT7: 1.8771848 | CU7: 1.3034701 | CV7: 2.5236448 | CW7: 0 | CX7: 0 | CY7: 0 | CZ7: 0.76623666 | DA7: 0.51978097 | DB7: 1.0606335 | DC7: 1.8184148 | DD7: 1.0171988 | DE7: 3.1070131 | DF7: 0.65492841 | DG7: 0.65492841 | DH7: 0.34507159 | DI7: 0.54491056 | DJ7: 0.43624493 | DK7: 4.9827976 | DL7: 1.9031899 | DM7: 0.011143192 | DN7: 0.057351807 | DO7: 0.9 | DP7: 17.326203 | DQ7: 0.17577221 | DR7: -0.1472022 | DS7: 0 | DT7: 0 | DU7: 0.0098807134 | DV7: 0.0094268497 | DW7: 0.010367167 | DX7: 0.051203662 | DY7: 0.052310328 | DZ7: 0.050096995 | EA7: 2.410998 | EB7: 1.6533101 | EC7: 3.2784123 | ED7: 4.7765104 | EE7: 4.7765104 | EF7: 4.7765104
A8: San_Joaquin_2017 | B8: 2.6739115 | C8: 2.6003058 | D8: 2.7568221 | E8: 4.4825122 | F8: 3.7366869 | G8: 5.393349 | H8: 0 | I8: 0 | J8: 0 | K8: 7.1564237 | L8: 6.4037304 | M8: 8.068697 | N8: 7.4277283 | O8: 6.1603741 | P8: 8.912532 | Q8: 0 | R8: 1.2427775 | S8: 15.826929 | T8: 14.121902 | U8: 17.787288 | V8: 1000 | W8: 0.11874017 | X8: 11 | Y8: 40.928 | Z8: 284.66581 | AA8: 40365 | AB8: 192459 | AC8: 1.7471737 | AD8: 86 | AE8: 80.232 | AF8: 54 | AG8: 15.961 | AH8: 144 | AI8: 89 | AJ8: 25.304 | AK8: 3.916689 | AL8: Yes | AM8: No | AN8: 20230824 | AO8: Yes | AP8: 110154 | AQ8: 4.7679522 | AR8: 0.45796686 | AS8: 0.054379065 | AT8: 0.003754894 | AU8: 0.38015493 | AV8: 0.61984507 | AW8: 0 | AX8: 0.00939316 | AY8: 0.0088285581 | AZ8: 0.010029136 | BA8: 0.015746577 | BB8: 0.010025633 | BC8: 0.022733263 | BD8: 0 | BE8: 0 | BF8: 0 | BG8: 0.025139737 | BH8: 0.022495608 | BI8: 0.028344454 | BJ8: 0.055598279 | BK8: -0.0059895767 | BL8: 0.0068865256 | BM8: 0.049608703 | BN8: 0.062484805 | BO8: 0.0260928 | BP8: 0.021640723 | BQ8: 0.031308754 | BR8: 0 | BS8: 0 | BT8: 0 | BU8: 0.0043657419 | BV8: 0.0035799084 | BW8: 0.0051515755 | BX8: 0.030458542 | BY8: 0.025220632 | BZ8: 0.03646033 | CA8: 0.00078072517 | CB8: 0.00072836211 | CC8: 0.9842903 | CD8: 23103 | CE8: 0.0023373588 | CF8: 0.00039541682 | CG8: 0.00069086266 | CH8: 11.91024 | CI8: 10.642886 | CJ8: 13.395044 | CK8: 11.91024 | CL8: 10.642886 | CM8: 13.395044 | CN8: 3.916689 | CO8: 3.6193833 | CP8: 4.2232996 | CQ8: 11.913405 | CR8: 10.427573 | CS8: 13.643937 | CT8: 2.4076637 | CU8: 1.7444199 | CV8: 3.2988699 | CW8: 0 | CX8: 0 | CY8: 0 | CZ8: 0.14157401 | DA8: 0.076737805 | DB8: 0.50433829 | DC8: 4.2579973 | DD8: 3.3318956 | DE8: 5.6079082 | DF8: 0.75252787 | DG8: 0.75252787 | DH8: 0.24747213 | DI8: 0.54783288 | DJ8: 0.46930874 | DK8: 7.1564237 | DL8: 2.6343374 | DM8: 0.012321595 | DN8: 0.054455461 | DO8: 0.9 | DP8: 17.326203 | DQ8: 0.1238554 | DR8: -0.10770513 | DS8: 0 | DT8: 0 | DU8: 0.009543098 | DV8: 0.0092593838 | DW8: 0.0098815667 | DX8: 0.048477731 | DY8: 0.049553722 | DZ8: 0.047401739 | EA8: 4.485677 | EB8: 3.7356983 | EC8: 5.4009017 | ED8: 7.4277283 | EE8: 7.4277283 | EF8: 7.4277283
A9: San_Joaquin_summer2020 | B9: 1.8230472 | C9: 1.7774686 | D9: 1.8744825 | E9: 3.83504 | F9: 3.1464273 | G9: 4.6760267 | H9: 0 | I9: 0 | J9: 0 | K9: 5.6580872 | L9: 4.9669079 | M9: 6.4909911 | N9: 4.186525 | O9: 3.5505099 | P9: 5.1136291 | Q9: 0 | R9: 0.87037445 | S9: 10.714987 | T9: 9.5832978 | U9: 12.097399 | V9: 1000 | W9: 0.14995685 | X9: 23.632192 | Y9: 35.77 | Z9: 231.42089 | AA9: 31919 | AB9: 238393 | AC9: 1.995878 | AD9: 94 | AE9: 90.564 | AF9: 39 | AG9: 13.333 | AH9: 151 | AI9: 65 | AJ9: 16.96 | AK9: 2.6934216 | AL9: Yes | AM9: No | AN9: 20230824 | AO9: Yes | AP9: 119442 | AQ9: 7.4688594 | AR9: 0.3659088 | AS9: 0.054870531 | AT9: 0.004742052 | AU9: 0.33540985 | AV9: 0.66459015 | AW9: 0 | AX9: 0.0078776259 | AY9: 0.0073393744 | AZ9: 0.0084850421 | BA9: 0.016571711 | BB9: 0.0084396686 | BC9: 0.026503185 | BD9: 0 | BE9: 0 | BF9: 0 | BG9: 0.024449337 | BH9: 0.021462661 | BI9: 0.028048424 | BJ9: 0.046300862 | BK9: -0.0048901758 | BL9: 0.0059735833 | BM9: 0.041410687 | BN9: 0.052274446 | BO9: 0.018090524 | BP9: 0.015342219 | BQ9: 0.022096662 | BR9: 0 | BS9: 0 | BT9: 0 | BU9: 0.0037610021 | BV9: 0.0030840217 | BW9: 0.0044379825 | BX9: 0.021851526 | BY9: 0.018426241 | BZ9: 0.026534645 | CA9: 0.00078699285 | CB9: 0.00075822575 | CC9: 0.98379429 | CD9: 15992 | CE9: 0.0024387194 | CF9: 0.00041771359 | CG9: 0.00083372936 | CH9: 8.021565 | CI9: 7.3855499 | CJ9: 8.9486691 | CK9: 8.021565 | CL9: 7.3855499 | CM9: 8.9486691 | CN9: 2.6934216 | CO9: 2.4911757 | CP9: 2.9015244 | CQ9: 8.022306 | CR9: 7.0487771 | CS9: 9.2509629 | CT9: 3.5632366 | CU9: 3.0004511 | CV9: 4.2583337 | CW9: 0.5266195 | CX9: 0.34442037 | CY9: 1.2390651 | CZ9: 0.020346104 | DA9: 0.01271307 | DB9: 0.081317379 | DC9: 0.076322793 | DD9: 0.048395611 | DE9: 0.24665568 | DF9: 0.74862414 | DG9: 0.74862414 | DH9: 0.25137586 | DI9: 0.47193743 | DJ9: 0.39070483 | DK9: 5.6580872 | DL9: 3.0533676 | DM9: 0.014471041 | DN9: 0.061625508 | DO9: 0.9 | DP9: 17.326203 | DQ9: 0.12901625 | DR9: -0.10561079 | DS9: 0 | DT9: 0 | DU9: 0.0080073811 | DV9: 0.0077949438 | DW9: 0.0082505775 | DX9: 0.056475809 | DY9: 0.057402754 | DZ9: 0.055548863 | EA9: 3.835781 | EB9: 3.1490195 | EC9: 4.6769439 | ED9: 4.186525 | EE9: 4.186525 | EF9: 4.186525
A10: San_Joaquin_fall2020 | B10: 1.9853749 | C10: 1.9309536 | D10: 2.0442348 | E10: 2.5864734 | F10: 1.9714052 | G10: 3.3893828 | H10: 0 | I10: 0 | J10: 0 | K10: 4.5718482 | L10: 3.9600905 | M10: 5.3844707 | N10: 3.7997189 | O10: 2.9637207 | P10: 4.9852126 | Q10: 0 | R10: 0.92232287 | S10: 9.29389 | T10: 8.0011889 | U10: 10.828309 | V10: 1000 | W10: 0.19321813 | X10: 20.646402 | Y10: 41.385 | Z10: 245.23328 | AA10: 33090 | AB10: 238974 | AC10: 1.995878 | AD10: 48 | AE10: 45.035 | AF10: 27 | AG10: 8.085 | AH10: 63 | AI10: 34 | AJ10: 9.245 | AK10: 2.9076977 | AL10: Yes | AM10: No | AN10: 20230824 | AO10: Yes | AP10: 119733 | AQ10: 7.2219675 | AR10: 0.37211076 | AS10: 0.071898547 | AT10: 0.0061100938 | AU10: 0.45631004 | AV10: 0.54368996 | AW10: 0 | AX10: 0.0080958625 | AY10: 0.0074994912 | AZ10: 0.0087408754 | BA10: 0.010546992 | BB10: 0.0038068102 | BC10: 0.01934562 | BD10: 0 | BE10: 0 | BF10: 0 | BG10: 0.018642854 | BH10: 0.016148259 | BI10: 0.021956526 | BJ10: 0.03789816 | BK10: -0.005271312 | BL10: 0.006256978 | BM10: 0.032626848 | BN10: 0.044155138 | BO10: 0.015494304 | BP10: 0.012085312 | BQ10: 0.020328451 | BR10: 0 | BS10: 0 | BT10: 0 | BU10: 0.0037610021 | BV10: 0.0030840217 | BW10: 0.0044379825 | BX10: 0.019255306 | BY10: 0.015169334 | BZ10: 0.024766433 | CA10: 0.00040089198 | CB10: 0.00037612855 | CC10: 0.98127098 | CD10: 16579 | CE10: 0.0016285663 | CF10: 0.00024433364 | CG10: 0.00048766512 | CH10: 6.3861923 | CI10: 5.5501941 | CJ10: 7.5716859 | CK10: 6.3861923 | CL10: 5.5501941 | CM10: 7.5716859 | CN10: 2.9076977 | CO10: 2.6872584 | CP10: 3.1325758 | CQ10: 6.382907 | CR10: 5.2543018 | CS10: 7.7487476 | CT10: 2.8777994 | CU10: 2.2102215 | CV10: 3.799683 | CW10: 0.69395435 | CX10: 0.43572647 | CY10: 1.6694555 | CZ10: 0.22796518 | DA10: 0.15395558 | DB10: 0.29015932 | DC10: 0 | DD10: 0 | DE10: 0 | DF10: 0.68712476 | DG10: 0.68712476 | DH10: 0.31287524 | DI10: 0.50806418 | DJ10: 0.40882028 | DK10: 4.5718482 | DL10: 2.2596438 | DM10: 0.014791801 | DN10: 0.061625508 | DO10: 0.9 | DP10: 17.326203 | DQ10: 0.1650732 | DR10: -0.13909369 | DS10: 0 | DT10: 0 | DU10: 0.0082503622 | DV10: 0.008006355 | DW10: 0.0085084677 | DX10: 0.056475809 | DY10: 0.057402754 | DZ10: 0.055548863 | EA10: 2.5831881 | EB10: 1.9661413 | EC10: 3.3870737 | ED10: 3.7997189 | EE10: 3.7997189 | EF10: 3.7997189
A11: San_Joaquin_fall2021 | B11: 1.7377204 | C11: 1.6743381 | D11: 1.8085958 | E11: 1.7482036 | F11: 1.2952748 | G11: 2.2882188 | H11: 0 | I11: 0 | J11: 0 | K11: 3.485924 | L11: 3.0311374 | M11: 4.0294486 | N11: 0.79207098 | O11: 0.55198034 | P11: 1.0892979 | Q11: 0 | R11: 0.74474802 | S11: 5.022743 | T11: 4.3649797 | U11: 5.7629903 | V11: 1000 | W11: 0.11255104 | X11: 15.95883 | Y11: 23.31 | Z11: 198.01851 | AA11: 33418 | AB11: 119340 | AC11: 1.995878 | AD11: 47 | AE11: 41.169 | AF11: 35 | AG11: 15.748 | AH11: 17 | AI11: 12 | AJ11: 6.313 | AK11: 2.4824684 | AL11: Yes | AM11: No | AN11: 20230824 | AO11: Yes | AP11: 59793 | AQ11: 3.5712238 | AR11: 0.52916543 | AS11: 0.059558118 | AT11: 0.0035591763 | AU11: 0.50823264 | AV11: 0.49176736 | AW11: 0 | AX11: 0.0087755456 | AY11: 0.0081706629 | AZ11: 0.0094519371 | BA11: 0.0088284859 | BB11: 0.0045060089 | BC11: 0.013982063 | BD11: 0 | BE11: 0 | BF11: 0 | BG11: 0.017604032 | BH11: 0.015307344 | BI11: 0.020348849 | BJ11: 0.025365018 | BK11: -0.0033217264 | BL11: 0.0037382735 | BM11: 0.022043292 | BN11: 0.029103292 | BO11: 0.0039999846 | BP11: 0.002787519 | BQ11: 0.0055009905 | BR11: 0 | BS11: 0 | BT11: 0 | BU11: 0.0037610021 | BV11: 0.0030840217 | BW11: 0.0044379825 | BX11: 0.0077609868 | BY11: 0.0058715407 | BZ11: 0.009938973 | CA11: 0.00078604519 | CB11: 0.00068852541 | CC11: 0.96134658 | CD11: 16743 | CE11: 0.0020904258 | CF11: 0.00047124304 | CG11: 0.00094057218 | CH11: 2.5402746 | CI11: 2.3001839 | CJ11: 2.8375015 | CK11: 2.5402746 | CL11: 2.3001839 | CM11: 2.8375015 | CN11: 2.4824684 | CO11: 2.2850314 | CP11: 2.6873985 | CQ11: 2.54999 | CR11: 2.0217207 | CS11: 3.1596323 | CT11: 0.53737716 | CU11: 0.36316853 | CV11: 0.77599238 | CW11: 0.25469382 | CX11: 0.12552468 | CY11: 0.44057962 | CZ11: 0 | DA11: 0 | DB11: 0 | DC11: 0 | DD11: 0 | DE11: 0 | DF11: 0.50573749 | DG11: 0.50573749 | DH11: 0.49426251 | DI11: 0.30597382 | DJ11: 0.157694 | DK11: 3.485924 | DL11: 1.928518 | DM11: 0.011826943 | DN11: 0.061625508 | DO11: 0.9 | DP11: 17.326203 | DQ11: 0.14736196 | DR11: -0.1309479 | DS11: 0 | DT11: 0 | DU11: 0.0091284473 | DV11: 0.0087323183 | DW11: 0.0095414825 | DX11: 0.056475809 | DY11: 0.057402754 | DZ11: 0.055548863 | EA11: 1.7579191 | EB11: 1.3033652 | EC11: 2.2997778 | ED11: 0.79207098 | EE11: 0.79207098 | EF11: 0.79207098
A12: Denver_summer2021 | B12: 12.251229 | C12: 11.964059 | D12: 12.533851 | E12: 2.296441 | F12: 1.6392361 | G12: 3.1189373 | H12: 0 | I12: 0 | J12: 0 | K12: 14.54767 | L12: 13.823386 | M12: 15.395625 | N12: 0.70508496 | O12: 0.45768856 | P12: 1.0584702 | Q12: 0 | R12: 6.246524 | S12: 21.499279 | T12: 19.593733 | U12: 23.522516 | V12: 1000 | W12: 0.048455062 | X12: 11.102345 | Y12: 73.004 | Z12: 1997.3945 | AA12: 11671 | AB12: 59356 | AC12: 1.6088026 | AD12: 34 | AE12: 27.399 | AF12: 27 | AG12: 8.499 | AH12: 24 | AI12: 9 | AJ12: 4.383 | AK12: 18.497753 | AL12: Yes | AM12: No | AN12: 20230824 | AO12: Yes | AP12: 36894 | AQ12: 5.0860215 | AR12: 0.44341553 | AS12: 0.021485727 | AT12: 0.0015322836 | AU12: 0.84524808 | AV12: 0.15475192 | AW12: 0 | AX12: 0.0061336051 | AY12: 0.0058093663 | AZ12: 0.0064527084 | BA12: 0.0011497183 | BB12: 0.00040768041 | BC12: 0.0020783836 | BD12: 0 | BE12: 0 | BF12: 0 | BG12: 0.0072833235 | BH12: 0.0069207088 | BI12: 0.0077078541 | BJ12: 0.010763662 | BK12: -0.00095401599 | BL12: 0.0010129379 | BM12: 0.009809646 | BN12: 0.0117766 | BO12: 0.00035300236 | BP12: 0.0002291428 | BQ12: 0.00052992547 | BR12: 0 | BS12: 0 | BT12: 0 | BU12: 0.0031273362 | BV12: 0.0025644157 | BW12: 0.0036902567 | BX12: 0.0034803385 | BY12: 0.0027935585 | BZ12: 0.0042201822 | CA12: 0.00092155906 | CB12: 0.00074264108 | CC12: 0.97610079 | CD12: 7254 | CE12: 0.0037220844 | CF12: 0.00072821523 | CG12: 0.0011716294 | CH12: 3.001526 | CI12: 2.7541296 | CJ12: 3.3549113 | CK12: 3.001526 | CL12: 2.7541296 | CM12: 3.3549113 | CN12: 18.497753 | CO12: 17.086208 | CP12: 19.904749 | CQ12: 3.0468877 | CR12: 2.3191682 | CS12: 3.9131664 | CT12: 0.21890852 | CU12: 0.12325878 | CV12: 0.41892933 | CW12: 0.2490261 | CX12: 0.13215532 | CY12: 0.44085606 | CZ12: 0.23715034 | DA12: 0.13117839 | DB12: 0.49322093 | DC12: 0 | DD12: 0 | DE12: 0 | DF12: 0.13960674 | DG12: 0.13960674 | DH12: 0.86039326 | DI12: 0.3233426 | DJ12: 0.032795114 | DK12: 14.54767 | DL12: 1.1590676 | DM12: 0.27535077 | DN12: 0.0097082922 | DO12: 0.9 | DP12: 17.326203 | DQ12: 0.094100966 | DR12: -0.088633716 | DS12: 0 | DT12: 0 | DU12: 0.0062838104 | DV12: 0.0061247693 | DW12: 0.0064553489 | DX12: 0.0054262314 | DY12: 0.0061970023 | DZ12: 0.0046554604 | EA12: 2.3418027 | EB12: 1.6938917 | EC12: 3.1706608 | ED12: 0.70508496 | EE12: 0.70508496 | EF12: 0.70508496
A13: Denver_fall2021 | B13: 12.336306 | C13: 12.082029 | D13: 12.604461 | E13: 2.3001303 | F13: 1.5495884 | G13: 3.2403388 | H13: 0 | I13: 0 | J13: 0 | K13: 14.636437 | L13: 13.869038 | M13: 15.643301 | N13: 2.3460098 | O13: 1.5779409 | P13: 4.0896026 | Q13: 0 | R13: 6.1693766 | S13: 23.151823 | T13: 20.810451 | U13: 26.190139 | V13: 1000 | W13: 0.089451923 | X13: 10.160213 | Y13: 66.961 | Z13: 1972.7258 | AA13: 11688 | AB13: 67811 | AC13: 1.6088026 | AD13: 40 | AE13: 31.525 | AF13: 33 | AG13: 8.491 | AH13: 29 | AI13: 21 | AJ13: 7.086 | AK13: 18.505683 | AL13: Yes | AM13: No | AN13: 20230824 | AO13: Yes | AP13: 42149 | AQ13: 5.8016518 | AR13: 0.41516829 | AS13: 0.037137602 | AT13: 0.0028287182 | AU13: 0.84730981 | AV13: 0.15269019 | AW13: 0 | AX13: 0.006253432 | AY13: 0.0059429635 | AZ13: 0.0065808438 | BA13: 0.0011659656 | BB13: 0.00024956769 | BC13: 0.0023139428 | BD13: 0 | BE13: 0 | BF13: 0 | BG13: 0.0074193975 | BH13: 0.0070303935 | BI13: 0.0079297899 | BJ13: 0.011735956 | BK13: -0.0011868718 | BL13: 0.0015401612 | BM13: 0.010549084 | BN13: 0.013276117 | BO13: 0.0011892225 | BP13: 0.0007998785 | BQ13: 0.002073072 | BR13: 0 | BS13: 0 | BT13: 0 | BU13: 0.0031273362 | BV13: 0.0025644157 | BW13: 0.0036902567 | BX13: 0.0043165586 | BY13: 0.0033642942 | BZ13: 0.0057633287 | CA13: 0.00094901421 | CB13: 0.00074794183 | CC13: 0.97507636 | CD13: 7265 | CE13: 0.0045423262 | CF13: 0.00072647159 | CG13: 0.0011687543 | CH13: 4.6461401 | CI13: 3.8780713 | CJ13: 6.3897329 | CK13: 4.6461401 | CL13: 3.8780713 | CM13: 6.3897329 | CN13: 18.505683 | CO13: 17.140917 | CP13: 19.884325 | CQ13: 4.7049276 | CR13: 3.5230673 | CS13: 6.6542947 | CT13: 1.1762972 | CU13: 0.68793592 | CV13: 2.8995366 | CW13: 0.74633917 | CX13: 0.51714222 | CY13: 1.1003391 | CZ13: 0.42337341 | DA13: 0.2476022 | DB13: 0.69329311 | DC13: 0 | DD13: 0 | DE13: 0 | DF13: 0.20067685 | DG13: 0.20067685 | DH13: 0.79932315 | DI13: 0.36780591 | DJ13: 0.10132988 | DK13: 14.636437 | DL13: 1.1568874 | DM13: 0.2715383 | DN13: 0.0097082922 | DO13: 0.9 | DP13: 17.326203 | DQ13: 0.13123754 | DR13: -0.10112989 | DS13: 0 | DT13: 0 | DU13: 0.0064133037 | DV13: 0.0062773948 | DW13: 0.0065596581 | DX13: 0.0054262314 | DY13: 0.0061970023 | DZ13: 0.0046554604 | EA13: 2.3589178 | EB13: 1.6133525 | EC13: 3.3019338 | ED13: 2.3460098 | EE13: 2.3460098 | EF13: 2.3460098
... A15: Uinta_2020 | B15: 10.54538 | C15: 10.307794 | D15: 10.817069 | E15: 5.8874223 | F15: 4.8821175 | G15: 6.9994631 | H15: 0 | I15: 0 | J15: 0 | K15: 16.432802 | L15: 15.381345 | M15: 17.563159 | N15: 2.3769867 | O15: 1.71401 | P15: 3.2267439 | Q15: 0 | R15: 1.3191311 | S15: 20.12892 | T15: 18.580249 | U15: 21.782142 | V15: 1000 | W15: 0.068822073 | X15: 8.3545392 | Y15: 52.276 | Z15: 350.73927 | AA15: 9185 | AB15: 32340 | AC15: 1.7099474 | AD15: 56 | AE15: 41.321 | AF15: 42 | AG15: 24.904 | AH15: 52 | AI15: 25 | AJ15: 16.313 | AK15: 11.864511 | AL15: Yes | AM15: No | AN15: 20230824 | AO15: Yes | AP15: 18912 | AQ15: 3.521132 | AR15: 0.53291611 | AS15: 0.036676391 | AT15: 0.002176345 | AU15: 0.64437362 | AV15: 0.35562638 | AW15: 0 | AX15: 0.030066152 | AY15: 0.028795057 | AZ15: 0.0315197 | BA15: 0.016785752 | BB15: 0.011407334 | BC15: 0.022735211 | BD15: 0 | BE15: 0 | BF15: 0 | BG15: 0.046851904 | BH15: 0.043854071 | BI15: 0.050074688 | BJ15: 0.057389982 | BK15: -0.0044154487 | BL15: 0.0047135354 | BM15: 0.052974533 | BN15: 0.062103517 | BO15: 0.006777076 | BP15: 0.0048868494 | BQ15: 0.0091998365 | BR15: 0 | BS15: 0 | BT15: 0 | BU15: 0.0037610021 | BV15: 0.0030840217 | BW15: 0.0044379825 | BX15: 0.010538078 | BY15: 0.0079708711 | BZ15: 0.013637819 | CA15: 0.0029610829 | CB15: 0.0021849091 | CC15: 0.9491794 | CD15: 5371 | CE15: 0.0078197729 | CF15: 0.0027113772 | CG15: 0.0046367529 | CH15: 8.264409 | CI15: 7.6014323 | CJ15: 9.1141662 | CK15: 8.264409 | CL15: 7.6014323 | CM15: 9.1141662 | CN15: 11.864511 | CO15: 11.389481 | CP15: 12.373644 | CQ15: 8.3956193 | CR15: 7.0899648 | CS15: 9.7845749 | CT15: 1.8189227 | CU15: 1.2905822 | CV15: 2.5020193 | CW15: 0.26324361 | CX15: 0.1673733 | CY15: 0.41561695 | CZ15: 0.29482037 | DA15: 0.13770585 | DB15: 0.87175457 | DC15: 0 | DD15: 0 | DE15: 0 | DF15: 0.41057148 | DG15: 0.41057148 | DH15: 0.58942852 | DI15: 0.18362124 | DJ15: 0.11808669 | DK15: 16.432802 | DL15: 1.4791031 | DM15: 0.065302414 | DN15: 0.024005542 | DO15: 0.9 | DP15: 17.326203 | DQ15: 0.082130728 | DR15: -0.076937061 | DS15: 0 | DT15: 0 | DU15: 0.031676156 | DV15: 0.030788602 | DW15: 0.032767489 | DX15: 0.018855842 | DY15: 0.019782788 | DZ15: 0.017928897 | EA15: 6.0186327 | EB15: 5.0149387 | EC15: 7.131709 | ED15: 2.3769867 | EE15: 2.3769867 | EF15: 2.3769867
A16: Fort_Worth_2021 | B16: 3.4034497 | C16: 3.1595124 | D16: 3.6500938 | E16: 10.183699 | F16: 8.8845659 | G16: 11.660232 | H16: 2.1418002 | I16: 1.5970947 | J16: 2.8464694 | K16: 15.728949 | L16: 14.074943 | M16: 17.388204 | N16: 1.7170087 | O16: 1.4159273 | P16: 2.0538342 | Q16: 1.9084621 | R16: 2.2362656 | S16: 21.590685 | T16: 19.485616 | U16: 23.748722 | V16: 1000 | W16: 0.05814708 | X16: 6.5248199 | Y16: 45.47 | Z16: 651.16169 | AA16: 7399 | AB16: 13711 | AC16: 1.6224651 | AD16: 80 | AE16: 79.965 | AF16: 49 | AG16: 40.003 | AH16: 49 | AI16: 23 | AJ16: 20.183 | AK16: 5.6397152 | AL16: Yes | AM16: No | AN16: 20230824 | AO16: Yes | AP16: 8450 | AQ16: 1.8530702 | AR16: 0.73460532 | AS16: 0.042715154 | AT16: 0.0018387721 | AU16: 0.21742682 | AV16: 0.64661132 | AW16: 0.13596186 | AX16: 0.0052267351 | AY16: 0.0047167761 | AZ16: 0.0057423529 | BA16: 0.015639278 | BB16: 0.012923397 | BC16: 0.018726019 | BD16: 0.0032891987 | BE16: 0.0021504737 | BF16: 0.0047623332 | BG16: 0.024155212 | BH16: 0.021615127 | BI16: 0.026703359 | BJ16: 0.03315718 | BK16: -0.0032327909 | BL16: 0.003314134 | BM16: 0.029924389 | BN16: 0.036471314 | BO16: 0.0026368393 | BP16: 0.0021744634 | BQ16: 0.0031541079 | BR16: 0.0029308575 | BS16: 0.0022939769 | BT16: 0.0035999912 | BU16: 0.0034342708 | BV16: 0.002816102 | BW16: 0.0040524395 | BX16: 0.0090019675 | BY16: 0.0074985068 | BZ16: 0.010528442 | CA16: 0.0094674556 | CB16: 0.0094633136 | CC16: 0.97212897 | CD16: 4560 | CE16: 0.010745614 | CF16: 0.0054065414 | CG16: 0.0087725877 | CH16: 11.900708 | CI16: 11.599626 | CJ16: 12.237533 | CK16: 13.80917 | CL16: 13.093376 | CM16: 14.58171 | CN16: 5.6397152 | CO16: 4.9932502 | CP16: 6.2888872 | CQ16: 11.939516 | CR16: 10.629987 | CS16: 13.439376 | CT16: 0.6844968 | CU16: 0.54572855 | CV16: 0.83383951 | CW16: 0.63410841 | CX16: 0.43887576 | CY16: 0.88613162 | CZ16: 0.3984035 | DA16: 0.2348546 | DB16: 0.56404919 | DC16: Null | DD16: Null | DE16: Null | DF16: 0.55119576 | DG16: 0.63958901 | DH16: 0.26121158 | DI16: 0.27149484 | DJ16: 0.079525768 | DK16: 15.728949 | DL16: 4.4927116 | DM16: 0.14279862 | DN16: 0.010661119 | DO16: 0.9 | DP16: 17.326203 | DQ16: 0.099940368 | DR16: -0.097493756 | DS16: 0.099199409 | DT16: 0.08839325 | DU16: 0.0053765721 | DV16: 0.0050505174 | DW16: 0.0057366468 | DX16: 0.0059587926 | DY16: 0.0068052114 | DZ16: 0.0051123738 | EA16: 10.222507 | EB16: 8.9262012 | EC16: 11.698713 | ED16: 1.7170087 | EE16: 1.7170087 | EF16: 1.7170087
A17: Permian_2019_F2021_bounds | B17: 22.063708 | C17: 21.67341 | D17: 22.526622 | E17: 104.29991 | F17: 99.333127 | G17: 109.63602 | H17: 0 | I17: 0 | J17: 0 | K17: 126.36362 | L17: 121.41145 | M17: 131.69006 | N17: 75.482503 | O17: 68.900213 | P17: 83.495337 | Q17: 0 | R17: 17.29491 | S17: 219.14103 | T17: 207.58202 | U17: 231.72464 | V17: 1000 | W17: 0.066136435 | X17: 16.353134 | Y17: 57.668 | Z17: 4755.8021 | AA17: 17164 | AB17: 152653 | AC17: 1.8250769 | AD17: 1052 | AE17: 998.613 | AF17: 540 | AG17: 166.918 | AH17: 681 | AI17: 278 | AJ17: 101.691 | AK17: 39.358618 | AL17: Yes | AM17: No | AN17: 20230824 | AO17: Yes | AP17: 83641 | AQ17: 8.894194 | AR17: 0.33531015 | AS17: 0.022176218 | AT17: 0.0020914177 | AU17: 0.17535153 | AV17: 0.82464847 | AW17: 0 | AX17: 0.0046393242 | AY17: 0.0043945728 | AZ17: 0.0049296127 | BA17: 0.021931087 | BB17: 0.01881647 | BC17: 0.025277305 | BD17: 0 | BE17: 0 | BF17: 0 | BG17: 0.026570411 | BH17: 0.025529121 | BI17: 0.027690399 | BJ17: 0.046078669 | BK17: -0.0024305067 | BL17: 0.0026459485 | BM17: 0.043648162 | BN17: 0.048724617 | BO17: 0.015871666 | BP17: 0.014487611 | BQ17: 0.01755652 | BR17: 0 | BS17: 0 | BT17: 0 | BU17: 0.0036365916 | BV17: 0.0029820052 | BW17: 0.0042911781 | BX17: 0.019508258 | BY17: 0.017469617 | BZ17: 0.021847699 | CA17: 0.012577564 | CB17: 0.011939276 | CC17: 0.77560142 | CD17: 9404 | CE17: 0.057422373 | CF17: 0.0097248893 | CG17: 0.017749681 | CH17: 179.78241 | CI17: 173.20012 | CJ17: 187.79525 | CK17: 179.78241 | CL17: 173.20012 | CM17: 187.79525 | CN17: 39.358618 | CO17: 35.855237 | CP17: 42.934616 | CQ17: 179.84925 | CR17: 171.42087 | CS17: 189.22673 | CT17: 22.387646 | CU17: 20.223011 | CV17: 25.202306 | CW17: 34.851298 | CX17: 31.256958 | CY17: 39.188833 | CZ17: 18.243559 | DA17: 13.584862 | DB17: 24.827197 | DC17: 0 | DD17: 0 | DE17: 0 | DF17: 0.82039575 | DG17: 0.82039575 | DH17: 0.17960425 | DI17: 0.4233689 | DJ17: 0.34444733 | DK17: 126.36362 | DL17: 4.4420488 | DM17: 0.5057212 | DN17: 0.011491852 | DO17: 0.9 | DP17: 17.326203 | DQ17: 0.057418444 | DR17: -0.05274675 | DS17: 0 | DT17: 0 | DU17: 0.005981605 | DV17: 0.0058340389 | DW17: 0.0061619239 | DX17: 0.0059587926 | DY17: 0.0068052114 | DZ17: 0.0051123738 | EA17: 104.36675 | EB17: 99.410519 | EC17: 109.70599 | ED17: 75.482503 | EE17: 75.482503 | EF17: 75.482503
A18: Permian_2019_F2021_bounds_Delaware | B18: 13.612118 | C18: 13.35869 | D18: 13.876676 | E18: 58.05212 | F18: 54.670143 | G18: 62.143897 | H18: 0 | I18: 0 | J18: 0 | K18: 71.664238 | L18: 68.315502 | M18: 75.750912 | N18: 37.324334 | O18: 34.304423 | P18: 41.369954 | Q18: 0 | R18: 13.139793 | S18: 122.12836 | T18: 115.14815 | U18: 130.04751 | V18: 1000 | W18: 0.079974417 | X18: 16.353134 | Y18: 53.091 | Z18: 3613.2165 | AA18: 7955 | AB18: 100870 | AC18: 1.8250769 | AD18: 922 | AE18: 875.852 | AF18: 447 | AG18: 117.84 | AH18: 558 | AI18: 202 | AJ18: 64.356 | AK18: 26.751911 | AL18: Yes | AM18: No | AN18: 20230824 | AO18: Yes | AP18: 55268 | AQ18: 12.681964 | AR18: 0.28080623 | AS18: 0.022457314 | AT18: 0.0025290131 | AU18: 0.19169824 | AV18: 0.80830176 | AW18: 0 | AX18: 0.003767313 | AY18: 0.0035175358 | AZ18: 0.0040280608 | BA18: 0.016066604 | BB18: 0.012733339 | BC18: 0.020099447 | BD18: 0 | BE18: 0 | BF18: 0 | BG18: 0.019833917 | BH18: 0.018907116 | BI18: 0.020964952 | BJ18: 0.033800456 | BK18: -0.0019318556 | BL18: 0.0021917167 | BM18: 0.0318686 | BN18: 0.035992172 | BO18: 0.010329947 | BP18: 0.0094941511 | BQ18: 0.011449619 | BR18: 0 | BS18: 0 | BT18: 0 | BU18: 0.0036365916 | BV18: 0.0029820052 | BW18: 0.0042911781 | BX18: 0.013966538 | BY18: 0.012476156 | BZ18: 0.015740798 | CA18: 0.016682348 | CB18: 0.015847362 | CC18: 0.72667104 | CD18: 4358 | CE18: 0.10256999 | CF18: 0.014813325 | CG18: 0.027039927 | CH18: 95.376454 | CI18: 92.356544 | CJ18: 99.422074 | CK18: 95.376454 | CL18: 92.356544 | CM18: 99.422074 | CN18: 26.751911 | CO18: 24.13332 | CP18: 29.381632 | CQ18: 95.437568 | CR18: 90.840697 | CS18: 100.97903 | CT18: 9.4905619 | CU18: 7.9426943 | CV18: 11.495823 | CW18: 24.203649 | CX18: 22.178392 | CY18: 26.633276 | CZ18: 3.6301224 | DA18: 2.7325727 | DB18: 6.9063209 | DC18: 0 | DD18: 0 | DE18: 0 | DF18: 0.78095083 | DG18: 0.78095083 | DH18: 0.21904917 | DI18: 0.41320632 | DJ18: 0.30561554 | DK18: 71.664238 | DL18: 3.8257389 | DM18: 0.8290997 | DN18: 0.011491852 | DO18: 0.9 | DP18: 17.326203 | DQ18: 0.064836876 | DR18: -0.057151067 | DS18: 0 | DT18: 0 | DU18: 0.0051844047 | DV18: 0.0050439527 | DW18: 0.0053523063 | DX18: 0.0059587926 | DY18: 0.0068052114 | DZ18: 0.0051123738 | EA18: 58.113234 | EB18: 54.737798 | EC18: 62.205218 | ED18: 37.324334 | EE18: 37.324334 | EF18: 37.324334
A19: Permian_2019_F2021_Midland | B19: 8.9299514 | C19: 8.5840591 | D19: 9.3224772 | E19: 46.308109 | F19: 42.904067 | G19: 50.278547 | H19: 0 | I19: 0 | J19: 0 | K19: 55.238061 | L19: 51.803919 | M19: 59.165305 | N19: 38.287789 | O19: 31.60915 | P19: 46.756878 | Q19: 0 | R19: 4.1551174 | S19: 97.680967 | T19: 89.032106 | U19: 107.27592 | V19: 1000 | W19: 0.10623786 | X19: 16.353134 | Y19: 110.343 | Z19: 1142.5856 | AA19: 9209 | AB19: 51783 | AC19: 1.8250769 | AD19: 130 | AE19: 124.303 | AF19: 93 | AG19: 49.073 | AH19: 123 | AI19: 76 | AJ19: 37.304 | AK19: 13.085069 | AL19: Yes | AM19: No | AN19: 20230824 | AO19: Yes | AP19: 28373 | AQ19: 5.6239841 | AR19: 0.4216751 | AS19: 0.044797861 | AT19: 0.0033595362 | AU19: 0.16271794 | AV19: 0.83728206 | AW19: 0 | AX19: 0.0078155642 | AY19: 0.0070976474 | AZ19: 0.0086302713 | BA19: 0.040529224 | BB19: 0.033463964 | BC19: 0.048770068 | BD19: 0 | BE19: 0 | BF19: 0 | BG19: 0.048344788 | BH19: 0.0453392 | BI19: 0.051781944 | BJ19: 0.085491156 | BK19: -0.0075695509 | BL19: 0.0083975785 | BM19: 0.077921605 | BN19: 0.093888735 | BO19: 0.033509776 | BP19: 0.027664578 | BQ19: 0.04092199 | BR19: 0 | BS19: 0 | BT19: 0 | BU19: 0.0036365916 | BV19: 0.0029820052 | BW19: 0.0042911781 | BX19: 0.037146368 | BY19: 0.030646583 | BZ19: 0.045213168 | CA19: 0.0045818207 | CB19: 0.0043810313 | CC19: 0.92101673 | CD19: 5045 | CE19: 0.018434093 | CF19: 0.0053288088 | CG19: 0.0097270565 | CH19: 84.595898 | CI19: 77.917259 | CJ19: 93.064987 | CK19: 84.595898 | CL19: 77.917259 | CM19: 93.064987 | CN19: 13.085069 | CO19: 11.991255 | CP19: 14.225516 | CQ19: 84.647544 | CR19: 76.795929 | CS19: 93.488488 | CT19: 12.825228 | CU19: 11.433367 | CV19: 14.397576 | CW19: 10.741881 | CX19: 8.2250254 | CY19: 15.236024 | CZ19: 14.720679 | DA19: 9.5201831 | DB19: 21.975769 | DC19: 0 | DD19: 0 | DE19: 0 | DF19: 0.86604251 | DG19: 0.86604251 | DH19: 0.13395749 | DI19: 0.43450412 | DJ19: 0.39196612 | DK19: 55.238061 | DL19: 5.697101 | DM19: 0.22647882 | DN19: 0.011491852 | DO19: 0.9 | DP19: 17.326203 | DQ19: 0.098202828 | DR19: -0.088538823 | DS19: 0 | DT19: 0 | DU19: 0.0084859929 | DV19: 0.0081188214 | DW19: 0.0090176379 | DX19: 0.0059587926 | DY19: 0.0068052114 | DZ19: 0.0051123738 | EA19: 46.359755 | EB19: 42.967533 | EC19: 50.331608 | ED19: 38.287789 | EE19: 38.287789 | EF19: 38.287789
A20: Northeast_Pennsylvania_2021 | B20: 4.4611271 | C20: 4.0613797 | D20: 4.8952977 | E20: 19.417722 | F20: 16.02279 | G20: 22.573456 | H20: 0 | I20: 0 | J20: 0 | K20: 23.878849 | L20: 20.494595 | M20: 27.015012 | N20: 3.4130667 | O20: 1.8663807 | P20: 5.1851604 | Q20: 0 | R20: 9.0260916 | S20: 36.318007 | T20: 30.945463 | U20: 41.425716 | V20: 1000 | W20: 0.062812101 | X20: 495.44526 | Y20: 495.44526 | Z20: 5095.6288 | AA20: 2996 | AB20: 4039 | AC20: 1.2580446 | AD20: 12 | AE20: 11 | AF20: 12 | AG20: 11.46 | AH20: 4 | AI20: 4 | AJ20: 3 | AK20: 13.487219 | AL20: Yes | AM20: No | AN20: 20230824 | AO20: Yes | AP20: 3210 | AQ20: 1.348173 | AR20: 0.86124593 | AS20: 0.054096667 | AT20: 0.0019862931 | AU20: 0.18813372 | AV20: 0.81186628 | AW20: 0 | AX20: 0.00087548117 | AY20: 0.00078439328 | AZ20: 0.00097441288 | BA20: 0.0038106625 | BB20: 0.0030370811 | BC20: 0.0045297396 | BD20: 0 | BE20: 0 | BF20: 0 | BG20: 0.0046861437 | BH20: 0.0040219952 | BI20: 0.0053016052 | BJ20: 0.0071272866 | BK20: -0.0010543437 | BL20: 0.0010023708 | BM20: 0.0060729429 | BN20: 0.0081296574 | BO20: 0.00066980286 | BP20: 0.00036627093 | BQ20: 0.0010175703 | BR20: 0 | BS20: 0 | BT20: 0 | BU20: 0.0017713401 | BV20: 0.0014524989 | BW20: 0.0020901813 | BX20: 0.002441143 | BY20: 0.0018187698 | BZ20: 0.0031077516 | CA20: 0.0037383178 | CB20: 0.0034267913 | CC20: 1 | CD20: 2381 | CE20: 0.0050398992 | CF20: 0.0038251001 | CG20: 0.0048131037 | CH20: 22.830788 | CI20: 21.284102 | CJ20: 24.602882 | CK20: 22.830788 | CL20: 21.284102 | CM20: 24.602882 | CN20: 13.487219 | CO20: 11.462775 | CP20: 15.546086 | CQ20: 23.147659 | CR20: 19.536813 | CS20: 26.543253 | CT20: 0.54267648 | CU20: 0.075298571 | CV20: 1.3763328 | CW20: 2.8703903 | CX20: 1.687602 | CY20: 4.2835393 | CZ20: 0 | DA20: 0 | DB20: 0 | DC20: 0 | DD20: 0 | DE20: 0 | DF20: 0.62863593 | DG20: 0.62863593 | DH20: 0.37136407 | DI20: 0.342507 | DJ20: 0.093977269 | DK20: 23.878849 | DL20: 5.3529947 | DM20: 2.1401213 | DN20: 0.0054988291 | DO20: 0.9 | DP20: 17.326203 | DQ20: 0.14064596 | DR20: -0.14793695 | DS20: 0 | DT20: 0 | DU20: 0.00087548117 | DV20: 0.0007970321 | DW20: 0.0009606857 | DX20: 0.0030734467 | DY20: 0.0035100156 | DZ20: 0.0026368779 | EA20: 19.734592 | EB20: 16.599461 | EC20: 22.902167 | ED20: 3.4130667 | EE20: 3.4130667 | EF20: 3.4130667
A21: GHGI 2022 (for 2020) | AI21: 1 | AT21: 0.0048 | AX21: =BG21 -> 0.004942 | AY21: =BH21 -> 0.0039430226 | AZ21: =BI21 -> 0.0059850499 | BG21: 0.004942 | BH21: =$BG$21+BK21*$BG$21/$BJ$21 -> 0.0039430226 | BI21: =$BG$21+BL21*$BG$21/$BJ$21 -> 0.0059850499 | BJ21: =BG21+BU21 -> 0.010092 | BK21: -0.00204 | BL21: 0.00213 | BM21: =BJ21+BK21 -> 0.008052 | BN21: =BJ21+BL21 -> 0.012222 | BU21: 0.00515 | BV21: =$BU$21+BK21*$BU$21/$BJ$21 -> 0.0041089774 | BW21: =$BU$21+BL21*$BU$21/$BJ$21 -> 0.0062369501
Y22: Fraction of national gas covered | Z22: =Z23/Z26 -> 0.28154141
A23: Totals excluding repeats | K23: =K3+K7+K13+K14+K15+K16 -> 408.27607 | L23: =L3+L7+L13+L14+L15+L16 -> 388.94682 | M23: =M3+M7+M13+M14+M15+M16 -> 429.07881 | N23: =N3+N7+N13+N14+N15+N16 -> 231.50213 | O23: =O3+O7+O13+O14+O15+O16 -> 213.32286 | P23: =P3+P7+P13+P14+P15+P16 -> 253.81009 | Q23: =Q3+Q7+Q13+Q14+Q15+Q16 -> 1.9084621 | R23: =R3+R7+R13+R14+R15+R16 -> 67.339202 | ... U23: =U3+U7+U13+U14+U15+U16 -> 752.80355 | Z23: =Z3+Z7+Z13+Z14+Z15+Z16 -> 24008.895 | AA23: =AA3+AA7+AA13+AA14+AA15+AA16 -> 170494 | AB23: =AB3+AB7+AB13+AB14+AB15+AB16 -> 549801 | AG23: =AG3+AG7+AG13+AG14+AG15+AG16 -> 601.456 | AP23: 1 | AQ23: =AQ3+AQ7+AQ13+AQ14+AQ15+AQ16 -> 18.722739 | AR23: =AB23/AA23 -> 3.2247528 | BE23: =S23/$Z23 -> 0.029531798 | BF23: =T23/$Z23 -> 0.027884212 | BG23: =U23/$Z23 -> 0.031355193 | BR23: =BR3+BR7+BR13+BR14+BR15+BR16 -> 0.0029308575 | BU23: =AG23/BR23 -> 205215.03 | BV23: =BV3+BV7+BV13+BV14+BV15+BV16 -> 0.016581009 | CH23: =CH3+CH7+CH13+CH14+CH15+CH16 -> 527.09956 | EA23: =EA3+EA7+EA13+EA14+EA15+EA16 -> 296.4095 | EB23: =EB3+EB7+EB13+EB14+EB15+EB16 -> 277.42953 | EC23: =EC3+EC7+EC13+EC14+EC15+EC16 -> 317.20406 | ED23: =ED3+ED7+ED13+ED14+ED15+ED16 -> 231.50213 | EE23: =EE3+EE7+EE13+EE14+EE15+EE16 -> 231.50213 | EF23: =EF3+EF7+EF13+EF14+EF15+EF16 -> 231.50213
A24: Totals including repeats (no 2019 subcampaigns) | N24: =N23+Q23+R23 -> 300.74979 | S24: =SUM(S2:S16) -> 1354.9263 | T24: =SUM(T2:T16) -> 1268.2539 | U24: =SUM(U2:U16) -> 1451.5489 | Z24: =SUM(Z2:Z16) -> 45862.47 | AA24: =SUM(AA2:AA16) -> 398424 | AB24: =SUM(AB2:AB16) -> 1714990 | AG24: =SUM(AG2:AG16) -> 1281.467 | AP24: 1 | AQ24: =SUM(AQ2:AQ16) -> 63.08617 | AR24: =AQ24/BR23 -> 21524.817 | BE24: =S24/$Z24 -> 0.029543248 | BF24: =T24/$Z24 -> 0.027653415 | BG24: =U24/$Z24 -> 0.031650036 | BR24: =SUM(BR2:BR16) -> 0.0054628453 | BU24: =AG24/BR24 -> 234578.67 | CG24: Aerially measured/Total emissions | CH24: =CH23/S23 -> 0.74341373 | DZ24: Aerially measured/Total emissions | EA24: =EA23/K23 -> 0.72600264 | ED24: =ED23/N24 -> 0.76974992
A25: Totals excluding high-prod campaigns | S25: =S3+S7+S13+S15+S16 -> 632.69141 | T25: =T3+T7+T13+T15+T16 -> 602.49619 | U25: =U3+U7+U13+U15+U16 -> 666.26545 | Z25: =Z3+Z7+Z13+Z15+Z16 -> 13766.415 | BE25: =S25/$Z25 -> 0.045959053 | BF25: =T25/$Z25 -> 0.043765656 | BG25: =U25/$Z25 -> 0.048397889
R26: Social cost of methane [$/t] | S26: 1500 | Y26: 2021 US gas prod | Z26: 85276.605 | CO26: GHGI midstream sub-aerial fraction | CP26: =0.7303 -> 0.7303
A27: Permian total | R27: Hours per day | S27: 8760 | Y27: [Enverus, t(CH4)/h] | AA27: =SUM(W2:W6) -> 0.25175823 | AB27: =SUM(X2:X6) -> 64.229338 | AD27: =SUM(Z2:Z6) -> 29423.657 | AE27: =SUM(AA2:AA6) -> 162037 | AF27: =SUM(AB2:AB6) -> 643575 | AG27: =SUM(AC2:AC6) -> 8.5003077 | AH27: =SUM(AD2:AD6) -> 4062 | AI27: =SUM(AE2:AE6) -> 3803.288 | AQ27: =SUM(AK2:AK6) -> 272.59908 | AR27: =AQ27/BR27 -> 1316.7445 | BR27: =SUM(BM2:BM6) -> 0.20702503
A28: San Joaquin total | R28: GWP20 (IPCC 2021) | S28: 82.5 | T28: https://report.ipcc.ch/ar6/wg1/IPCC_AR6_WGI_FullReport.pdf | U28: Table 7.15 | AA28: =SUM(W7:W11) -> 0.67854487 | AB28: =SUM(X7:X11) -> 80.237423 | AD28: =SUM(Z7:Z11) -> 1224.3124 | AE28: =SUM(AA7:AA11) -> 180339 | AF28: =SUM(AB7:AB11) -> 870400 | AG28: =SUM(AC7:AC11) -> 9.4819814 | AH28: =SUM(AD7:AD11) -> 352 | AI28: =SUM(AE7:AE11) -> 326.063 | AQ28: =SUM(AK7:AK11) -> 15.778486 | AR28: =AQ28/BR28 -> 87.208847 | BR28: =SUM(BM7:BM11) -> 0.18092759
A29: Denver total | R29: Emissions [tCH4/yr] | S29: =S23*$S$27 -> 6211066.5 | T29: =T23*$S$27 -> 5864549.6 | U29: =U23*$S$27 -> 6594559.1 | AA29: =W12+W13 -> 0.13790699 | AB29: =X12+X13 -> 21.262557 | AD29: =Z12+Z13 -> 3970.1203 | AE29: =AA12+AA13 -> 23359 | AF29: =AB12+AB13 -> 127167 | AG29: =AC12+AC13 -> 3.2176052 | AH29: =AD12+AD13 -> 74 | AI29: =AE12+AE13 -> 58.924 | AQ29: =AK12+AK13 -> 37.003436 | AR29: =AQ29/BR29 -> 1817.5709 | BR29: =BM12+BM13 -> 0.02035873
A30: Per+SJ+DJ | R30: Emissions [tCO2e/yr] | S30: =S29*$S$28 -> 5.1241299e+08 | T30: =T29*$S$28 -> 4.8382534e+08 | U30: =U29*$S$28 -> 5.4405113e+08 | AA30: =SUM(AA27:AA29) -> 1.0682101 | AB30: =SUM(AB27:AB29) -> 165.72932 | AQ30: =SUM(AQ27:AQ29) -> 325.381 | AR30: =AQ30/BR30 -> 796.89434 | BR30: =SUM(BR27:BR29) -> 0.40831135
R31: Annual social cost of emissions [$/yr] | S31: =S29*$S$26 -> 9.3165998e+09 | T31: =T29*$S$26 -> 8.7968244e+09 | U31: =U29*$S$26 -> 9.8918387e+09
R32: NG cost [$/mcf] | S32: 3 | Y32: =Z23*$S27/$S33 -> 1.213606e+10
R33: tCH4/mcf(NG) | S33: 0.01733 | Y33: =Z26*$S27/$S33 -> 4.3105774e+10
R34: Annual NG emissions [mcf/yr] | S34: =S29/$S$33 -> 3.5839968e+08 | T34: =T29/$S$33 -> 3.3840448e+08 | U34: =U29/$S$33 -> 3.8052851e+08
R35: Annual NG value | S35: =S34*$S$32 -> 1.075199e+09 | T35: =T34*$S$32 -> 1.0152134e+09 | U35: =U34*$S$32 -> 1.1415855e+09
R36: Price/t(CH4) | S36: =S32/S33 -> 173.11021

Sheet Tables for paper
I1: REVISIT | J1: From Jupyter code
A2: Table 7 | B2: {='By site'!Y1:Y20} -> Transition point | C2: {='By site'!X1:X20} -> Min detected emission | D2: {='By site'!AD1:AD20} -> # production plumes | E2: {='By site'!AE1:AE20} -> # production plumes sel | H2: Table 5 | I2: Avg emissions/site | J2: Logormal fit mean | K2: Lognormal/This study | M2: Table 23 | N2: {='By site'!CD1:CD20} -> Well sites covered | O2: {='By site'!AD1:AD20} -> # production plumes | P2: {='By site'!AF1:AF20} -> # prod sources overall | Q2: {='By site'!AQ1:AQ20} -> Avg visits/well site | R2: {='By site'!AG1:AG20} -> # avg prod sources sim | S2: {='By site'!CG1:CG20} -> Avg % sites emitting
A3: Kairos_Permian | B3: 24.391 | C3: 5.9464547 | D3: 1279 | E3: 1276.96 | H3: Kairos_Permian | I3: =1000*'By site'!K2/'By site'!CD2 -> 6.0523884 | J3: 3.188375 | K3: =J3/I3 -> 0.52679617 | M3: Kairos_Permian | N3: 18030 | O3: 1279 | P3: 627 | Q3: 3.7698281 | R3: 299.736 | S3: 0.016624293
A4: Permian_2019 | B4: 60.218 | C4: 15.029525 | D4: 1749 | E4: 1643.569 | H4: Permian_2019 | I4: =1000*'By site'!K3/'By site'!CD3 -> 6.6068669 | J4: 3.823909 | K4: =J4/I4 -> 0.57877796 | M4: Permian_2019 | N4: 46337 | O4: 1749 | P4: 1054 | Q4: 3.8655934 | R4: 483.465 | S4: 0.010433671
A5: Permian_2020 | B5: 82.316 | C5: 8.0919112 | D5: 284 | E5: 247.415 | H5: Permian_2020 | I5: =1000*'By site'!K4/'By site'!CD4 -> 6.127623 | J5: 5.315017 | K5: =J5/I5 -> 0.86738642 | M5: Permian_2020 | N5: 9380 | O5: 284 | P5: 239 | Q5: 2.8557569 | R5: 101.235 | S5: 0.010792644
A6: Permian_summer2021 | B6: 68.239 | C6: 11.813408 | D6: 416 | E6: 360.455 | H6: Permian_summer2021 | I6: =1000*'By site'!K5/'By site'!CD5 -> 6.2349792 | J6: 7.700567 | K6: =J6/I6 -> 1.235059 | M6: Permian_summer2021 | N6: 10432 | O6: 416 | P6: 296 | Q6: 4.8271664 | R6: 124.633 | S6: 0.011947182
A7: Permian_fall2021 | B7: 78.149 | C7: 23.348039 | D7: 334 | E7: 274.889 | H7: Permian_fall2021 | I7: =1000*'By site'!K6/'By site'!CD6 -> 6.094956 | J7: 7.498451 | K7: =J7/I7 -> 1.2302715 | M7: Permian_fall2021 | N7: 10777 | O7: 334 | P7: 232 | Q7: 4.7946553 | R7: 92.781 | S7: 0.0086091677
A8: San_Joaquin_2016 | B8: 40.481 | C8: 9 | D8: 77 | E8: 69.063 | H8: San_Joaquin_2016 | I8: =1000*'By site'!K7/'By site'!CD7 -> 0.20954614 | J8: 0.521041 | K8: =J8/I8 -> 2.4865216 | M8: San_Joaquin_2016 | N8: 23779 | O8: 77 | P8: 40 | Q8: 1.9552546 | R8: 15.063 | S8: 0.00063345809
A9: San_Joaquin_2017 | B9: 40.928 | C9: 11 | D9: 86 | E9: 80.232 | H9: San_Joaquin_2017 | I9: =1000*'By site'!K8/'By site'!CD8 -> 0.30976166 | J9: 0.539929 | K9: =J9/I9 -> 1.7430466 | M9: San_Joaquin_2017 | N9: 23103 | O9: 86 | P9: 54 | Q9: 4.7679522 | R9: 15.961 | S9: 0.00069086266
A10: San_Joaquin_summer2020 | B10: 35.77 | C10: 23.632192 | D10: 94 | E10: 90.564 | H10: San_Joaquin_summer2020 | I10: =1000*'By site'!K9/'By site'!CD9 -> 0.35380735 | J10: 0.545917 | K10: =J10/I10 -> 1.5429781 | M10: San_Joaquin_summer2020 | N10: 15992 | O10: 94 | P10: 39 | Q10: 7.4688594 | R10: 13.333 | S10: 0.00083372936
A11: San_Joaquin_fall2020 | B11: 41.385 | C11: 20.646402 | D11: 48 | E11: 45.035 | H11: San_Joaquin_fall2020 | I11: =1000*'By site'!K10/'By site'!CD10 -> 0.2757614 | J11: 0.523525 | K11: =J11/I11 -> 1.8984709 | M11: San_Joaquin_fall2020 | N11: 16579 | O11: 48 | P11: 27 | Q11: 7.2219675 | R11: 8.085 | S11: 0.00048766512
A12: San_Joaquin_fall2021 | B12: 23.31 | C12: 15.95883 | D12: 47 | E12: 41.169 | H12: San_Joaquin_fall2021 | I12: =1000*'By site'!K11/'By site'!CD11 -> 0.20820188 | J12: 0.509176 | K12: =J12/I12 -> 2.445588 | M12: San_Joaquin_fall2021 | N12: 16743 | O12: 47 | P12: 35 | Q12: 3.5712238 | R12: 15.748 | S12: 0.00094057218
A13: Denver_summer2021 | B13: 73.004 | C13: 11.102345 | D13: 34 | E13: 27.399 | H13: Denver_summer2021 | I13: =1000*'By site'!K12/'By site'!CD12 -> 2.0054687 | J13: 4.579421 | K13: =J13/I13 -> 2.2834667 | M13: Denver_summer2021 | N13: 7254 | O13: 34 | P13: 27 | Q13: 5.0860215 | R13: 8.499 | S13: 0.0011716294
A14: Denver_fall2021 | B14: 66.961 | C14: 10.160213 | D14: 40 | E14: 31.525 | H14: Denver_fall2021 | I14: =1000*'By site'!K13/'By site'!CD13 -> 2.0146506 | J14: 4.605823 | K14: =J14/I14 -> 2.2861646 | M14: Denver_fall2021 | N14: 7265 | O14: 40 | P14: 33 | Q14: 5.8016518 | R14: 8.491 | S14: 0.0011687543
... A17: Fort_Worth_2021 | B17: 45.47 | C17: 6.5248199 | D17: 80 | E17: 79.965 | H17: Fort_Worth_2021 | I17: =1000*'By site'!K16/'By site'!CD16 -> 3.4493309 | J17: 1.691088 | K17: =J17/I17 -> 0.49026552 | M17: Fort_Worth_2021 | N17: 4560 | O17: 80 | P17: 49 | Q17: 1.8530702 | R17: 40.003 | S17: 0.0087725877
A18: Permian_2019_F2021_bounds | B18: 57.668 | C18: 16.353134 | D18: 1052 | E18: 998.613 | H18: Permian_2019_F2021_bounds | I18: =1000*'By site'!K17/'By site'!CD17 -> 13.43722 | M18: Permian_2019_F2021_bounds | N18: 9404 | O18: 1052 | P18: 540 | Q18: 8.894194 | R18: 166.918 | S18: 0.017749681
A19: Permian_2019_F2021_bounds_Delaware | B19: 53.091 | C19: 16.353134 | D19: 922 | E19: 875.852 | H19: Permian_2019_F2021_bounds_Delaware | I19: =1000*'By site'!K18/'By site'!CD18 -> 16.444295 | M19: Permian_2019_F2021_bounds_Delaware | N19: 4358 | O19: 922 | P19: 447 | Q19: 12.681964 | R19: 117.84 | S19: 0.027039927
A20: Permian_2019_F2021_Midland | B20: 110.343 | C20: 16.353134 | D20: 130 | E20: 124.303 | H20: Permian_2019_F2021_Midland | I20: =1000*'By site'!K19/'By site'!CD19 -> 10.94907 | M20: Permian_2019_F2021_Midland | N20: 5045 | O20: 130 | P20: 93 | Q20: 5.6239841 | R20: 49.073 | S20: 0.0097270565
A21: Northeast_Pennsylvania_2021 | B21: 495.44526 | C21: 495.44526 | D21: 12 | E21: 11 | H21: Northeast_Pennsylvania_2021 | I21: =1000*'By site'!K20/'By site'!CD20 -> 10.028916 | M21: Northeast_Pennsylvania_2021 | N21: 2381 | O21: 12 | P21: 12 | Q21: 1.348173 | R21: 11.46 | S21: 0.0048131037
A23: Table 24 | B23: Methane emissions [t/hr] | C23: {='By site'!Z1:Z20} -> Total covered production (t(CH4)/hr) | D23: Methane loss rate [%] | G23: Table 25 | H23: Production: Simulated [%] | I23: Production: Aerial [%] | J23: Production: Aerial partial [%] | K23: Production: Total [%] | N23: Table 26 | O23: Midstream: Simulated [%] | P23: Midstream: Aerial [%] | Q23: Midstream: Aerial partial [%] | R23: Midstream: Total [%] | T23: Table 27 | U23: Production: Simulated full distribution [%] | V23: Production: GHGI [%] | W23: % difference
